Workbook
Name ANALYTES: #REF!

Sheet CGL4f4n
C2: Facteur qualitatif
C3: X | D3: opérateur | I3: bloc X
C4: Y | D4: cuve A,B,C,D | H4: bloc Y | I4: pierre | J4: paul | K4: jack | L4: sophie | M4: ∑y | P4: Tolérance - | Q4: 98 | R4: =+Q4 -> 98 | S4: 0 | T4: =X40 -> 0.71565917
C5: couleur case | D5: jour | H5: A | I5: 100.88989 | J5: 100.15521 | K5: 99.825844 | L5: 100.20354 | M5: =SUM(I5:L6) -> 801.42347 | P5: Tolérance + | Q5: 102 | R5: =+Q5 -> 102 | S5: 0 | T5: =T4 -> 0.71565917
D6: lundi | I6: 100.3822 | J6: 100.75705 | K6: 99.062255 | L6: 100.14748
D7: mercreci | H7: B | I7: 100.4044 | J7: 100.31918 | K7: 101.04923 | L7: 100.74764 | M7: =SUM(I7:L8) -> 804.79058 | P7: moyenne | Q7: =AVERAGE(I5:L12) -> 100.09145
D8: jeudi | I8: 100.96028 | J8: 100.48333 | K8: 100.32299 | L8: 100.50352 | P8: S² totale | Q8: =I35 -> 0.31074751
D9: samedi | H9: C | I9: 99.346741 | J9: 99.624133 | K9: 100.68022 | L9: 100.30694 | M9: =SUM(I9:L10) -> 799.20615 | P9: S totale | Q9: =SQRT(Q8) -> 0.55744731
C10: couleur chiffre | D10: type de sonde | I10: 99.382118 | J10: 99.484906 | K10: 100.55717 | L10: 99.823923 | P10: Min | Q10: =MIN(I5:L12) -> 99.006633 | V10: -3 | W10: =Q$7+V10*SQRT(Q$8) -> 98.419105 | X10: =NORMDIST(W10,Q$7,SQRT(Q$8),0) -> 0.0079502552
D11: O | H11: D | I11: 99.420242 | J11: 100.16106 | K11: 99.554138 | L11: 99.006633 | M11: =SUM(I11:L12) -> 797.50611 | P11: Max | Q11: =MAX(I5:L12) -> 101.04923 | V11: -2.9 | W11: =Q$7+V11*SQRT(Q$8) -> 98.47485 | X11: =NORMDIST(W11,Q$7,SQRT(Q$8),0) -> 0.010678197
D12: P | I12: 99.78997 | J12: 100.19625 | K12: 99.597993 | L12: 99.779816 | P12: Cpk | Q12: =MIN((Q5-Q7)/(3*SQRT(Q8)),(Q7-Q4)/(3*SQRT(Q8))) -> 1.1412457 | V12: -2.8 | W12: =Q$7+V12*SQRT(Q$8) -> 98.530594 | X12: =NORMDIST(W12,Q$7,SQRT(Q$8),0) -> 0.014199461
D13: Q | H13: ∑x | I13: =SUM(I5:I12) -> 800.57585 | J13: =SUM(J5:J12) -> 801.18112 | K13: =SUM(K5:K12) -> 800.64984 | L13: =SUM(L5:L12) -> 800.51949 | M13: =SUM(M5:M12) -> 3202.9263 | N13: =SUM(I10:L10) -> 399.24811 | V13: -2.7 | W13: =Q$7+V13*SQRT(Q$8) -> 98.586339 | X13: =NORMDIST(W13,Q$7,SQRT(Q$8),0) -> 0.018694026
D14: R | N14: =SUM(I11:L11) -> 398.14208 | V14: -2.6 | W14: =Q$7+V14*SQRT(Q$8) -> 98.642084 | X14: =NORMDIST(W14,Q$7,SQRT(Q$8),0) -> 0.024366373
V15: -2.5 | W15: =Q$7+V15*SQRT(Q$8) -> 98.697829 | X15: =NORMDIST(W15,Q$7,SQRT(Q$8),0) -> 0.031443869
V16: -2.4 | W16: =Q$7+V16*SQRT(Q$8) -> 98.753573 | X16: =NORMDIST(W16,Q$7,SQRT(Q$8),0) -> 0.040173358
V17: -2.3 | W17: =Q$7+V17*SQRT(Q$8) -> 98.809318 | X17: =NORMDIST(W17,Q$7,SQRT(Q$8),0) -> 0.050815632
V18: -2.2 | W18: =Q$7+V18*SQRT(Q$8) -> 98.865063 | X18: =NORMDIST(W18,Q$7,SQRT(Q$8),0) -> 0.063637571
V19: -2.1 | W19: =Q$7+V19*SQRT(Q$8) -> 98.920808 | X19: =NORMDIST(W19,Q$7,SQRT(Q$8),0) -> 0.078901799
V20: -2 | W20: =Q$7+V20*SQRT(Q$8) -> 98.976552 | X20: =NORMDIST(W20,Q$7,SQRT(Q$8),0) -> 0.096853936
V21: -1.9 | W21: =Q$7+V21*SQRT(Q$8) -> 99.032297 | X21: =NORMDIST(W21,Q$7,SQRT(Q$8),0) -> 0.11770765
V22: -1.8 | W22: =Q$7+V22*SQRT(Q$8) -> 99.088042 | X22: =NORMDIST(W22,Q$7,SQRT(Q$8),0) -> 0.14162802
V23: -1.7 | W23: =Q$7+V23*SQRT(Q$8) -> 99.143787 | X23: =NORMDIST(W23,Q$7,SQRT(Q$8),0) -> 0.16871384
V24: -1.6 | W24: =Q$7+V24*SQRT(Q$8) -> 99.199531 | X24: =NORMDIST(W24,Q$7,SQRT(Q$8),0) -> 0.19897994
V25: -1.5 | W25: =Q$7+V25*SQRT(Q$8) -> 99.255276 | X25: =NORMDIST(W25,Q$7,SQRT(Q$8),0) -> 0.23234051
V26: -1.4 | W26: =Q$7+V26*SQRT(Q$8) -> 99.311021 | X26: =NORMDIST(W26,Q$7,SQRT(Q$8),0) -> 0.26859483
... V32: -0.8 | W32: =Q$7+V32*SQRT(Q$8) -> 99.645489 | X32: =NORMDIST(W32,Q$7,SQRT(Q$8),0) -> 0.51967522
C33: étape d'identification | G33: ANOVA | P33: Prérequis | V33: -0.7 | W33: =Q$7+V33*SQRT(Q$8) -> 99.701234 | X33: =NORMDIST(W33,Q$7,SQRT(Q$8),0) -> 0.56014968
C34: Origine | D34: niveau | E34: SB² | F34: CI | G34: SCE | H34: ddl | I34: CM | J34: Fobs | K34: F5% | L34: contrib% | M34: β | N34: puissance | P34: Cochran | V34: -0.6 | W34: =Q$7+V34*SQRT(Q$8) -> 99.756979 | X34: =NORMDIST(W34,Q$7,SQRT(Q$8),0) -> 0.59776878
C35: Total | D35: =COUNT(I5:L12) -> 32 | E35: =SUM(I5:L12)^2 -> 10258737 | F35: =E35/D35 -> 320585.53 | G35: =DEVSQ(I5:L12) -> 9.6331727 | H35: =D35-1 -> 31 | I35: =G35/H35 -> 0.31074751 | J35: x | K35: x | L35: =SUM(L37:L40) -> 0.67214013 | M35: x | N35: x | P35: Cobs | Q35: =MAX(I49:L56)/SUM(I49:L56) -> 0.19063579 | R35: 16 | V35: -0.5 | W35: =Q$7+V35*SQRT(Q$8) -> 99.812723 | X35: =NORMDIST(W35,Q$7,SQRT(Q$8),0) -> 0.631567
C36: modèle | D36: x | E36: x | F36: x | G36: =SUM(G38:G41) -> 7.0618249 | H36: =SUM(H38:H41) -> 12 | I36: =G36/H36 -> 0.5884854 | J36: =I36/I37 -> 4.3483897 | K36: =FINV(0.05,H36,H37) -> 2.3079544 | L36: =G36/G35 -> 0.73307363 | M36: x | N36: x | P36: C 1% | Q36: =1/((1+(R35-1)/FINV(0.01/R35,R36-1,(R35)*(R36-1)))) -> 0.54506394 | R36: 2 | V36: -0.4 | W36: =Q$7+V36*SQRT(Q$8) -> 99.868468 | X36: =NORMDIST(W36,Q$7,SQRT(Q$8),0) -> 0.66063668
C37: résiduel | D37: x | E37: x | F37: x | G37: =G35-G36 -> 2.5713479 | H37: =H35-H36 -> 19 | I37: =G37/H37 -> 0.1353341 | J37: x | K37: x | L37: =G37/G35 -> 0.26692637 | M37: x | N37: x | P37: Cobs < C 1% = OK | V37: -0.3 | W37: =Q$7+V37*SQRT(Q$8) -> 99.924213 | X37: =NORMDIST(W37,Q$7,SQRT(Q$8),0) -> 0.68416836
C38: =D3 -> opérateur | D38: 4 | E38: =SUM(I5:I12)^2+SUM(J5:J12)^2+SUM(K5:K12)^2+SUM(L5:L12)^2 -> 2564684.5 | F38: =E38*D38/$D$35 -> 320585.56 | G38: =F38-$F$35 -> 0.034750222 | H38: =D38-1 -> 3 | I38: =G38/H38 -> 0.011583407 | J38: =I38/I$37 -> 0.085591195 | K38: =FINV(0.05,H38,H$37) -> 3.12735 | L38: =G38/$G$35 -> 0.0036073496 | M38: =1-FDIST(K38/J38,H38,H$37) -> 0.99999996 | N38: =1-M38 -> 4.3312564e-08 | O38: =K38*I37/G35 -> 0.043935379 | V38: -0.2 | W38: =Q$7+V38*SQRT(Q$8) -> 99.979958 | X38: =NORMDIST(W38,Q$7,SQRT(Q$8),0) -> 0.70148817
C39: =D4 -> cuve A,B,C,D | D39: 4 | E39: =SUM(I5:L6)^2+SUM(I7:L8)^2+SUM(I9:L10)^2+SUM(I11:L12)^2 -> 2564713.9 | F39: =E39*D39/D35 -> 320589.24 | G39: =F39-$F$35 -> 3.7105985 | H39: =D39-1 -> 3 | I39: =G39/H39 -> 1.2368662 | J39: =I39/I$37 -> 9.1393536 | K39: =FINV(0.05,H39,H$37) -> 3.12735 | L39: =G39/$G$35 -> 0.38518966 | M39: =1-FDIST(K39/J39,H39,H$37) -> 0.20489766 | N39: =1-M39 -> 0.79510234 | O39: =+O38 -> 0.043935379 | V39: -0.1 | W39: =Q$7+V39*SQRT(Q$8) -> 100.0357 | X39: =NORMDIST(W39,Q$7,SQRT(Q$8),0) -> 0.7120898
C40: =D5 -> jour | D40: 4 | E40: =SUM(I5:I6,K7:K8,J9:J10,L11:L12)^2+SUM(J5:J6,L7:L8,I9:I10,K11:K12)^2+SUM(K5:K6,I7:I8,L9:L10,J11:J12)^2+SUM(L5:L6,J7:J8,K9:K10,I11:I12)^2 -> 2564685.5 | F40: =E40*D40/$D$35 -> 320585.69 | G40: =F40-$F$35 -> 0.15814531 | H40: =D40-1 -> 3 | I40: =G40/H40 -> 0.052715105 | J40: =I40/I$37 -> 0.38951828 | K40: =FINV(0.05,H40,H$37) -> 3.12735 | L40: =G40/$G$35 -> 0.016416742 | M40: =1-FDIST(K40/J40,H40,H$37) -> 0.99882766 | N40: =1-M40 -> 0.0011723425 | O40: =+O39 -> 0.043935379 | V40: 0 | W40: =Q$7+V40*SQRT(Q$8) -> 100.09145 | X40: =NORMDIST(W40,Q$7,SQRT(Q$8),0) -> 0.71565917
C41: =D10 -> type de sonde | D41: 4 | E41: =SUM(I5:I6,L7:L8,K9:K10,J11:J12)^2+SUM(J5:J6,K7:K8,L9:L10,I11:I12)^2+SUM(K5:K6,J7:J8,I9:I10,L11:L12)^2+SUM(L5:L6,I7:I8,J9:J10,K11:K12)^2 -> 2564709.5 | F41: =E41*D41/$D$35 -> 320588.69 | G41: =F41-$F$35 -> 3.1583308 | H41: =D41-1 -> 3 | I41: =G41/H41 -> 1.0527769 | J41: =I41/I$37 -> 7.7790959 | K41: =FINV(0.05,H41,H$37) -> 3.12735 | L41: =G41/$G$35 -> 0.32785987 | M41: =1-FDIST(K41/J41,H41,H$37) -> 0.24682398 | N41: =1-M41 -> 0.75317602 | O41: =+O40 -> 0.043935379 | V41: 0.1 | W41: =Q$7+V41*SQRT(Q$8) -> 100.14719 | X41: =NORMDIST(W41,Q$7,SQRT(Q$8),0) -> 0.7120898
J42: si Fobs < F5% = équivalence | O42: =+O41 -> 0.043935379 | V42: 0.2 | W42: =Q$7+V42*SQRT(Q$8) -> 100.20294 | X42: =NORMDIST(W42,Q$7,SQRT(Q$8),0) -> 0.70148817
C43: R² | D43: =L36 -> 0.73307363 | E43: <Coeffcient de détermination : ce qui est expliqué par le modèle | V43: 0.3 | W43: =Q$7+V43*SQRT(Q$8) -> 100.25868 | X43: =NORMDIST(W43,Q$7,SQRT(Q$8),0) -> 0.68416836
V44: 0.4 | W44: =Q$7+V44*SQRT(Q$8) -> 100.31443 | X44: =NORMDIST(W44,Q$7,SQRT(Q$8),0) -> 0.66063668
C45: R²ajusté | D45: =(I35-I37)/I35 -> 0.56448855 | E45: < expliqué par le modèle (ajusté) | V45: 0.5 | W45: =Q$7+V45*SQRT(Q$8) -> 100.37017 | X45: =NORMDIST(W45,Q$7,SQRT(Q$8),0) -> 0.631567
V46: 0.6 | W46: =Q$7+V46*SQRT(Q$8) -> 100.42592 | X46: =NORMDIST(W46,Q$7,SQRT(Q$8),0) -> 0.59776878
...

Sheet Récapitulatif
B1: Profil d'exactitude
B2: Probabilité tolérance (bêta) | C2: =#REF! -> #REF! | E2: 20 | F2: 100
B3: Limite d'acceptabilité | C3: =#REF! -> #REF! | E3: 0.01 | F3: =E3*F2/E2 -> 0.05
B5: Niveaux | C5: Niveau A | D5: Niveau B | E5: Niveau C | F5: Niveau D | G5: Niveau E
A6: 2 | B6: Valeur cible | C6: ='80%'!B2 -> 80 | D6: ='90%'!B2 -> 90 | E6: ='100%'!B2 -> 100 | F6: ='110%'!B2 -> 110 | G6: ='120%'!B2 -> 120
A7: 30 | B7: Moyenne niveau | C7: ='80%'!B22 -> #REF! | D7: ='90%'!B22 -> #REF! | E7: ='100%'!B22 -> #REF! | F7: ='110%'!B22 -> #REF! | G7: ='120%'!B22 -> #REF! | K7: =ADDRESS($A8,2,,,C$5) -> 'Niveau A'!$B$31
A8: 31 | B8: Ecart-type de répétabilité (sr) | C8: ='80%'!B23 -> #DIV/0! | D8: ='90%'!B23 -> #DIV/0! | E8: ='100%'!B23 -> #DIV/0! | F8: ='110%'!B23 -> #DIV/0! | G8: ='120%'!B23 -> #DIV/0!
A9: 32 | B9: Ecart-type inter-séries (sL) | C9: ='80%'!B24 -> #REF! | D9: ='90%'!B24 -> #REF! | E9: ='100%'!B24 -> #REF! | F9: ='110%'!B24 -> #REF! | G9: ='120%'!B24 -> #REF!
A10: 33 | B10: Ecart-type de fidélité (sFI) | C10: ='80%'!B25 -> #DIV/0! | D10: ='90%'!B25 -> #DIV/0! | E10: ='100%'!B25 -> #DIV/0! | F10: ='110%'!B25 -> #DIV/0! | G10: ='120%'!B25 -> #DIV/0!
A11: 37 | B11: Rapport des variances (R) | C11: ='80%'!B29 -> #REF! | D11: ='90%'!B29 -> #REF! | E11: ='100%'!B29 -> #REF! | F11: ='110%'!B29 -> #REF! | G11: ='120%'!B29 -> #REF!
A12: 39 | B12: Coefficient intermédiaire | C12: ='80%'!B31 -> #REF! | D12: ='90%'!B31 -> #REF! | E12: ='100%'!B31 -> #REF! | F12: ='110%'!B31 -> #REF! | G12: ='120%'!B31 -> #REF!
A13: 40 | B13: Nombre de degrés liberté | C13: ='80%'!B32 -> #REF! | D13: ='90%'!B32 -> #REF! | E13: ='100%'!B32 -> #REF! | F13: ='110%'!B32 -> #REF! | G13: ='120%'!B32 -> #REF!
A14: 47 | B14: Valeur basse tolérance | C14: ='80%'!B39 -> #REF! | D14: ='90%'!B39 -> #REF! | E14: ='100%'!B39 -> #REF! | F14: ='110%'!B39 -> #REF! | G14: ='120%'!B39 -> #REF!
A15: 48 | B15: Valeur haute tolérance | C15: ='80%'!B40 -> #REF! | D15: ='90%'!B40 -> #REF! | E15: ='100%'!B40 -> #REF! | F15: ='110%'!B40 -> #REF! | G15: ='120%'!B40 -> #REF!
A16: 35 | B16: Biais (%) | C16: ='80%'!B27 -> #REF! | D16: ='90%'!B27 -> #REF! | E16: ='100%'!B27 -> #REF! | F16: ='110%'!B27 -> #REF! | G16: ='120%'!B27 -> #REF!
B17: Recouvrement (justesse) | C17: =C7/C$6 -> #REF! | D17: =D7/D$6 -> #REF! | E17: =E7/E$6 -> #REF! | F17: =F7/F$6 -> #REF! | G17: =G7/G$6 -> #REF!
B18: Limite basse tolérance (%) | C18: =C14/C$6 -> #REF! | D18: =D14/D$6 -> #REF! | E18: =E14/E$6 -> #REF! | F18: =F14/F$6 -> #REF! | G18: =G14/G$6 -> #REF!
B19: Limite haute tolérance (%) | C19: =C15/C$6 -> #REF! | D19: =D15/D$6 -> #REF! | E19: =E15/E$6 -> #REF! | F19: =F15/F$6 -> #REF! | G19: =G15/G$6 -> #REF!
B20: Limite d'acceptabilité basse | C20: =1-$C$3 -> #REF! | D20: =1-$C$3 -> #REF! | E20: =1-$C$3 -> #REF! | F20: =1-$C$3 -> #REF! | G20: =1-$C$3 -> #REF!
B21: Limite d'acceptabilité haute | C21: =1+$C$3 -> #REF! | D21: =1+$C$3 -> #REF! | E21: =1+$C$3 -> #REF! | F21: =1+$C$3 -> #REF! | G21: =1+$C$3 -> #REF!
B27: Incertitude
B28: Ecart-type de l'IT (sIT) | C28: =C$12*C$10 -> #REF! | D28: =D$12*D$10 -> #REF! | E28: =E$12*E$10 -> #REF! | F28: =F$12*F$10 -> #REF! | G28: =G$12*G$10 -> #REF!
B29: Incertitude élargie relative | C29: =2*C28/C7 -> #REF! | D29: =2*D28/D7 -> #REF! | E29: =2*E28/E7 -> #REF! | F29: =2*F28/F7 -> #REF! | G29: =2*G28/G7 -> #REF!

Sheet 80%
A1: Niveau A
A2: Valeur cible | B2: 80
B4: Répétition 1 | C4: Répétition 2 | D4: Répétition 3 | E4: Répétition 4 | F4: Répétition 5 | H4: nk | I4: SCEk
A5: Jour (Série) 1 | B5: =#REF!*$B$2 -> #REF! | C5: =#REF!*$B$2 -> #REF! | H5: =COUNT(B5:F5) -> 0 | I5: =IF(H5=0,"",DEVSQ(B5:F5))
A6: Jour (Série) 2
A7: Jour (Série) 3 | B7: =#REF!*$B$2 -> #REF! | C7: =#REF!*$B$2 -> #REF! | H7: =COUNT(B7:F7) -> 0 | I7: =IF(H7=0,"",DEVSQ(B7:F7))
A8: Jour (Série) 4 | B8: =#REF!*$B$2 -> #REF! | C8: =#REF!*$B$2 -> #REF! | H8: =COUNT(B8:F8) -> 0 | I8: =IF(H8=0,"",DEVSQ(B8:F8))
A9: Jour (Série) 5 | B9: =#REF!*$B$2 -> #REF! | C9: =#REF!*$B$2 -> #REF! | H9: =COUNT(B9:F9) -> 0 | I9: =IF(H9=0,"",DEVSQ(B9:F9))
A11: Nombre de séries (K) | B11: =COUNT(B5:B9) -> 0
A12: Nombre de mesures (IK) | B12: =COUNT(B5:F9) -> 0
A13: Nombre de répétitions (I) | B13: =IF(H5*B11<>B12,"Calcul impossible",H5) -> 0
A14: SCE résiduelle | B14: =SUM(I5:I9) -> 0
A15: SCE totale | B15: =DEVSQ(B5:F9) -> #REF!
A16: SCE inter-séries | B16: =B15-B14 -> #REF!
A17: Valeur intermédiaire de s²L | B17: =((B16/(B11-1))-B18)/B13 -> #REF!
A18: Variance de répétabilité (s²r) | B18: =B14/(B12-B11) -> #DIV/0!
A19: Variance inter-séries (s²L) | B19: =IF(B17<0,0,B17) -> #REF!
A20: Variance de fidélité (s²FI) | B20: =SUM(B18:B19) -> #DIV/0!
A21: Fidélité
A22: Moyenne niveau | B22: =AVERAGE(B5:F9) -> #REF!
A23: Ecart-type de répétabilité (sr) | B23: =SQRT(B18) -> #DIV/0!
A24: Ecart-type inter-séries (sL) | B24: =SQRT(B19) -> #REF!
A25: Ecart-type de fidélité (sFI) | B25: =SQRT(B20) -> #DIV/0!
A26: Justesse
A27: Biais (%) | B27: =B22/B2-1 -> #REF!
A28: Facteur de couverture
A29: Rapport des variances (R) | B29: =B19/B18 -> #REF!
A30: Coefficient B² | B30: =(B29+1)/(B13*B29+1) -> #REF!
A31: Coefficient intermédiaire | B31: =SQRT(1+1/(B12*B30)) -> #REF!
A32: Nombre de degrés liberté | B32: =(B29+1)^2/((B29+1/B13)^2/(B11-1)+(1-1/B13)/B12) -> #REF!
A33: Probabilité tolérance (bêta) | B33: =Récapitulatif!C2 -> #REF!
A34: t Student bas | B34: =TINV(1-B33,ROUNDDOWN(B32,0)) -> #REF!
A35: t Student haut | B35: =TINV(1-B33,ROUNDUP(B32,0)) -> #REF!
A36: t Student interpolé | B36: =B34-(B34-B35)*(B32-ROUNDDOWN(B32,0)) -> #REF!
A37: Facteur de couverture (ktol) | B37: =B36*B31 -> #REF!
A38: Intervalle de tolérance
A39: Valeur basse tolérance | B39: =B22-B37*B25 -> #REF!
A40: Valeur haute tolérance | B40: =B22+B37*B25 -> #REF!

Sheet 90%
A1: Niveau B
A2: Valeur cible | B2: 90
B4: Répétition 1 | C4: Répétition 2 | D4: Répétition 3 | E4: Répétition 4 | F4: Répétition 5 | H4: nk | I4: SCEk
A5: Jour (Série) 1 | B5: =#REF!*$B$2 -> #REF! | C5: =#REF!*$B$2 -> #REF! | H5: =COUNT(B5:F5) -> 0 | I5: =IF(H5=0,"",DEVSQ(B5:F5))
A6: Jour (Série) 2 | B6: =#REF!*$B$2 -> #REF! | C6: =#REF!*$B$2 -> #REF! | H6: =COUNT(B6:F6) -> 0 | I6: =IF(H6=0,"",DEVSQ(B6:F6))
A7: Jour (Série) 3 | I7: =IF(H7=0,"",DEVSQ(B7:F7))
A8: Jour (Série) 4 | B8: =#REF!*$B$2 -> #REF! | C8: =#REF!*$B$2 -> #REF! | H8: =COUNT(B8:F8) -> 0 | I8: =IF(H8=0,"",DEVSQ(B8:F8))
A9: Jour (Série) 5 | B9: =#REF!*$B$2 -> #REF! | C9: =#REF!*$B$2 -> #REF! | H9: =COUNT(B9:F9) -> 0 | I9: =IF(H9=0,"",DEVSQ(B9:F9))
A11: Nombre de séries (K) | B11: =COUNT(B5:B9) -> 0
A12: Nombre de mesures (IK) | B12: =COUNT(B5:F9) -> 0
A13: Nombre de répétitions (I) | B13: =IF(H5*B11<>B12,"Calcul impossible",H5) -> 0
A14: SCE résiduelle | B14: =SUM(I5:I9) -> 0
A15: SCE totale | B15: =DEVSQ(B5:F9) -> #REF!
A16: SCE inter-séries | B16: =B15-B14 -> #REF!
A17: Valeur intermédiaire de s²L | B17: =((B16/(B11-1))-B18)/B13 -> #REF!
A18: Variance de répétabilité (s²r) | B18: =B14/(B12-B11) -> #DIV/0!
A19: Variance inter-séries (s²L) | B19: =IF(B17<0,0,B17) -> #REF!
A20: Variance de fidélité (s²FI) | B20: =SUM(B18:B19) -> #DIV/0!
A21: Fidélité
A22: Moyenne niveau | B22: =AVERAGE(B5:F9) -> #REF!
A23: Ecart-type de répétabilité (sr) | B23: =SQRT(B18) -> #DIV/0!
A24: Ecart-type inter-séries (sL) | B24: =SQRT(B19) -> #REF!
A25: Ecart-type de fidélité (sFI) | B25: =SQRT(B20) -> #DIV/0!
A26: Justesse
A27: Biais (%) | B27: =B22/B2-1 -> #REF!
A28: Facteur de couverture
A29: Rapport des variances (R) | B29: =B19/B18 -> #REF!
A30: Coefficient B² | B30: =(B29+1)/(B13*B29+1) -> #REF!
A31: Coefficient intermédiaire | B31: =SQRT(1+1/(B12*B30)) -> #REF!
A32: Nombre de degrés liberté | B32: =(B29+1)^2/((B29+1/B13)^2/(B11-1)+(1-1/B13)/B12) -> #REF!
A33: Probabilité tolérance (bêta) | B33: =Récapitulatif!C2 -> #REF!
A34: t Student bas | B34: =TINV(1-B33,ROUNDDOWN(B32,0)) -> #REF!
A35: t Student haut | B35: =TINV(1-B33,ROUNDUP(B32,0)) -> #REF!
A36: t Student interpolé | B36: =B34-(B34-B35)*(B32-ROUNDDOWN(B32,0)) -> #REF!
A37: Facteur de couverture (ktol) | B37: =B36*B31 -> #REF!
A38: Intervalle de tolérance
A39: Valeur basse tolérance | B39: =B22-B37*B25 -> #REF!
A40: Valeur haute tolérance | B40: =B22+B37*B25 -> #REF!

Sheet 100%
A1: Niveau C
A2: Valeur cible | B2: 100
B4: Répétition 1 | C4: Répétition 2 | D4: Répétition 3 | E4: Répétition 4 | F4: Répétition 5 | H4: nk | I4: SCEk
A5: Jour (Série) 1 | B5: =#REF!*$B$2 -> #REF! | C5: =#REF!*$B$2 -> #REF! | H5: =COUNT(B5:F5) -> 0 | I5: =IF(H5=0,"",DEVSQ(B5:F5))
A6: Jour (Série) 2 | B6: =#REF!*$B$2 -> #REF! | C6: =#REF!*$B$2 -> #REF! | H6: =COUNT(B6:F6) -> 0 | I6: =IF(H6=0,"",DEVSQ(B6:F6))
A7: Jour (Série) 3 | B7: =#REF!*$B$2 -> #REF! | C7: =#REF!*$B$2 -> #REF! | H7: =COUNT(B7:F7) -> 0 | I7: =IF(H7=0,"",DEVSQ(B7:F7))
A8: Jour (Série) 4 | I8: =IF(H8=0,"",DEVSQ(B8:F8))
A9: Jour (Série) 5 | B9: =#REF!*$B$2 -> #REF! | C9: =#REF!*$B$2 -> #REF! | H9: =COUNT(B9:F9) -> 0 | I9: =IF(H9=0,"",DEVSQ(B9:F9))
A11: Nombre de séries (K) | B11: =COUNT(B5:B9) -> 0
A12: Nombre de mesures (IK) | B12: =COUNT(B5:F9) -> 0
A13: Nombre de répétitions (I) | B13: =IF(H5*B11<>B12,"Calcul impossible",H5) -> 0
A14: SCE résiduelle | B14: =SUM(I5:I9) -> 0
A15: SCE totale | B15: =DEVSQ(B5:F9) -> #REF!
A16: SCE inter-séries | B16: =B15-B14 -> #REF!
A17: Valeur intermédiaire de s²L | B17: =((B16/(B11-1))-B18)/B13 -> #REF!
A18: Variance de répétabilité (s²r) | B18: =B14/(B12-B11) -> #DIV/0!
A19: Variance inter-séries (s²L) | B19: =IF(B17<0,0,B17) -> #REF!
A20: Variance de fidélité (s²FI) | B20: =SUM(B18:B19) -> #DIV/0!
A21: Fidélité
A22: Moyenne niveau | B22: =AVERAGE(B5:F9) -> #REF!
A23: Ecart-type de répétabilité (sr) | B23: =SQRT(B18) -> #DIV/0!
A24: Ecart-type inter-séries (sL) | B24: =SQRT(B19) -> #REF!
A25: Ecart-type de fidélité (sFI) | B25: =SQRT(B20) -> #DIV/0!
A26: Justesse
A27: Biais (%) | B27: =B22/B2-1 -> #REF!
A28: Facteur de couverture
A29: Rapport des variances (R) | B29: =B19/B18 -> #REF!
A30: Coefficient B² | B30: =(B29+1)/(B13*B29+1) -> #REF!
A31: Coefficient intermédiaire | B31: =SQRT(1+1/(B12*B30)) -> #REF!
A32: Nombre de degrés liberté | B32: =(B29+1)^2/((B29+1/B13)^2/(B11-1)+(1-1/B13)/B12) -> #REF!
A33: Probabilité tolérance (bêta) | B33: =Récapitulatif!C2 -> #REF!
A34: t Student bas | B34: =TINV(1-B33,ROUNDDOWN(B32,0)) -> #REF!
A35: t Student haut | B35: =TINV(1-B33,ROUNDUP(B32,0)) -> #REF!
A36: t Student interpolé | B36: =B34-(B34-B35)*(B32-ROUNDDOWN(B32,0)) -> #REF!
A37: Facteur de couverture (ktol) | B37: =B36*B31 -> #REF!
A38: Intervalle de tolérance
A39: Valeur basse tolérance | B39: =B22-B37*B25 -> #REF!
A40: Valeur haute tolérance | B40: =B22+B37*B25 -> #REF!

Sheet 110%
A1: Niveau D
A2: Valeur cible | B2: 110
B4: Répétition 1 | C4: Répétition 2 | D4: Répétition 3 | E4: Répétition 4 | F4: Répétition 5 | H4: nk | I4: SCEk
A5: Jour (Série) 1 | B5: =#REF!*$B$2 -> #REF! | C5: =#REF!*$B$2 -> #REF! | H5: =COUNT(B5:F5) -> 0 | I5: =IF(H5=0,"",DEVSQ(B5:F5))
A6: Jour (Série) 2 | B6: =#REF!*$B$2 -> #REF! | C6: =#REF!*$B$2 -> #REF! | H6: =COUNT(B6:F6) -> 0 | I6: =IF(H6=0,"",DEVSQ(B6:F6))
A7: Jour (Série) 3 | B7: =#REF!*$B$2 -> #REF! | C7: =#REF!*$B$2 -> #REF! | H7: =COUNT(B7:F7) -> 0 | I7: =IF(H7=0,"",DEVSQ(B7:F7))
A8: Jour (Série) 4 | B8: =#REF!*$B$2 -> #REF! | C8: =#REF!*$B$2 -> #REF! | H8: =COUNT(B8:F8) -> 0 | I8: =IF(H8=0,"",DEVSQ(B8:F8))
A9: Jour (Série) 5 | I9: =IF(H9=0,"",DEVSQ(B9:F9))
A11: Nombre de séries (K) | B11: =COUNT(B5:B9) -> 0
A12: Nombre de mesures (IK) | B12: =COUNT(B5:F9) -> 0
A13: Nombre de répétitions (I) | B13: =IF(H5*B11<>B12,"Calcul impossible",H5) -> 0
A14: SCE résiduelle | B14: =SUM(I5:I9) -> 0
A15: SCE totale | B15: =DEVSQ(B5:F9) -> #REF!
A16: SCE inter-séries | B16: =B15-B14 -> #REF!
A17: Valeur intermédiaire de s²L | B17: =((B16/(B11-1))-B18)/B13 -> #REF!
A18: Variance de répétabilité (s²r) | B18: =B14/(B12-B11) -> #DIV/0!
A19: Variance inter-séries (s²L) | B19: =IF(B17<0,0,B17) -> #REF!
A20: Variance de fidélité (s²FI) | B20: =SUM(B18:B19) -> #DIV/0!
A21: Fidélité
A22: Moyenne niveau | B22: =AVERAGE(B5:F9) -> #REF!
A23: Ecart-type de répétabilité (sr) | B23: =SQRT(B18) -> #DIV/0!
A24: Ecart-type inter-séries (sL) | B24: =SQRT(B19) -> #REF!
A25: Ecart-type de fidélité (sFI) | B25: =SQRT(B20) -> #DIV/0!
A26: Justesse
A27: Biais (%) | B27: =B22/B2-1 -> #REF!
A28: Facteur de couverture
A29: Rapport des variances (R) | B29: =B19/B18 -> #REF!
A30: Coefficient B² | B30: =(B29+1)/(B13*B29+1) -> #REF!
A31: Coefficient intermédiaire | B31: =SQRT(1+1/(B12*B30)) -> #REF!
A32: Nombre de degrés liberté | B32: =(B29+1)^2/((B29+1/B13)^2/(B11-1)+(1-1/B13)/B12) -> #REF!
A33: Probabilité tolérance (bêta) | B33: =Récapitulatif!C2 -> #REF!
A34: t Student bas | B34: =TINV(1-B33,ROUNDDOWN(B32,0)) -> #REF!
A35: t Student haut | B35: =TINV(1-B33,ROUNDUP(B32,0)) -> #REF!
A36: t Student interpolé | B36: =B34-(B34-B35)*(B32-ROUNDDOWN(B32,0)) -> #REF!
A37: Facteur de couverture (ktol) | B37: =B36*B31 -> #REF!
A38: Intervalle de tolérance
A39: Valeur basse tolérance | B39: =B22-B37*B25 -> #REF!
A40: Valeur haute tolérance | B40: =B22+B37*B25 -> #REF!

Sheet 120%
A1: Niveau E
A2: Valeur cible | B2: 120
B4: Répétition 1 | C4: Répétition 2 | D4: Répétition 3 | E4: Répétition 4 | F4: Répétition 5 | H4: nk | I4: SCEk
A5: Jour (Série) 1
A6: Jour (Série) 2 | B6: =#REF!*$B$2 -> #REF! | C6: =#REF!*$B$2 -> #REF! | H6: =COUNT(B6:F6) -> 0 | I6: =IF(H6=0,"",DEVSQ(B6:F6))
A7: Jour (Série) 3 | B7: =#REF!*$B$2 -> #REF! | C7: =#REF!*$B$2 -> #REF! | H7: =COUNT(B7:F7) -> 0 | I7: =IF(H7=0,"",DEVSQ(B7:F7))
A8: Jour (Série) 4 | B8: =#REF!*$B$2 -> #REF! | C8: =#REF!*$B$2 -> #REF! | H8: =COUNT(B8:F8) -> 0 | I8: =IF(H8=0,"",DEVSQ(B8:F8))
A9: Jour (Série) 5 | B9: =#REF!*$B$2 -> #REF! | C9: =#REF!*$B$2 -> #REF! | H9: =COUNT(B9:F9) -> 0 | I9: =IF(H9=0,"",DEVSQ(B9:F9))
A11: Nombre de séries (K) | B11: =COUNT(B5:B9) -> 0
A12: Nombre de mesures (IK) | B12: =COUNT(B5:F9) -> 0
A13: Nombre de répétitions (I) | B13: =IF(H6*B11<>B12,"Calcul impossible",H6) -> 0
A14: SCE résiduelle | B14: =SUM(I5:I9) -> 0
A15: SCE totale | B15: =DEVSQ(B5:F9) -> #REF!
A16: SCE inter-séries | B16: =B15-B14 -> #REF!
A17: Valeur intermédiaire de s²L | B17: =((B16/(B11-1))-B18)/B13 -> #REF!
A18: Variance de répétabilité (s²r) | B18: =B14/(B12-B11) -> #DIV/0!
A19: Variance inter-séries (s²L) | B19: =IF(B17<0,0,B17) -> #REF!
A20: Variance de fidélité (s²FI) | B20: =SUM(B18:B19) -> #DIV/0!
A21: Fidélité
A22: Moyenne niveau | B22: =AVERAGE(B5:F9) -> #REF!
A23: Ecart-type de répétabilité (sr) | B23: =SQRT(B18) -> #DIV/0!
A24: Ecart-type inter-séries (sL) | B24: =SQRT(B19) -> #REF!
A25: Ecart-type de fidélité (sFI) | B25: =SQRT(B20) -> #DIV/0!
A26: Justesse
A27: Biais (%) | B27: =B22/B2-1 -> #REF!
A28: Facteur de couverture
A29: Rapport des variances (R) | B29: =B19/B18 -> #REF!
A30: Coefficient B² | B30: =(B29+1)/(B13*B29+1) -> #REF!
A31: Coefficient intermédiaire | B31: =SQRT(1+1/(B12*B30)) -> #REF!
A32: Nombre de degrés liberté | B32: =(B29+1)^2/((B29+1/B13)^2/(B11-1)+(1-1/B13)/B12) -> #REF!
A33: Probabilité tolérance (bêta) | B33: =Récapitulatif!C2 -> #REF!
A34: t Student bas | B34: =TINV(1-B33,ROUNDDOWN(B32,0)) -> #REF!
A35: t Student haut | B35: =TINV(1-B33,ROUNDUP(B32,0)) -> #REF!
A36: t Student interpolé | B36: =B34-(B34-B35)*(B32-ROUNDDOWN(B32,0)) -> #REF!
A37: Facteur de couverture (ktol) | B37: =B36*B31 -> #REF!
A38: Intervalle de tolérance
A39: Valeur basse tolérance | B39: =B22-B37*B25 -> #REF!
A40: Valeur haute tolérance | B40: =B22+B37*B25 -> #REF!
