Workbook
Name ANALYTES: #REF!

Sheet CL 3f3n
C4: Facteur qualitatif | H4: X | P4: Tolérance - | Q4: 35 | R4: =+Q4 -> 35 | S4: 0 | T4: =X39 -> 0.42093273
C5: X | D5: opérateur | G5: Y | H5: pierre | J5: paul | L5: jack | N5: ∑ | P5: Tolérance + | Q5: 45 | R5: =+Q5 -> 45 | S5: 0 | T5: =T4 -> 0.42093273
C6: Y | D6: fournisseur | G6: A | H6: =40+RAND()*2 -> 40.509045 | I6: =40+RAND()*2 -> 41.630909 | J6: =41+RAND() -> 41.208394 | K6: =40+RAND() -> 40.254527 | L6: =40+RAND() -> 40.977566 | M6: =40+RAND() -> 40.937165 | N6: =SUM(H6:M7) -> 487.67309
C7: case | D7: jour | H7: =40+RAND()*2 -> 40.188866 | I7: =40+RAND()*2 -> 40.066398 | J7: =40+RAND() -> 40.392261 | K7: =40+RAND() -> 40.096696 | L7: =40+RAND() -> 40.846003 | M7: =40+RAND() -> 40.565261 | P7: moyenne | Q7: =AVERAGE(H6:M11) -> 40.556217
D8: lundi | G8: B | H8: =41+RAND() -> 41.757599 | I8: =41+RAND() -> 41.201986 | J8: =41+RAND() -> 41.554142 | K8: =41+RAND() -> 41.882309 | L8: =41+RAND() -> 41.211937 | M8: =41+RAND() -> 41.948366 | N8: =SUM(H8:M9) -> 498.82615 | P8: S² totale | Q8: =I34 -> 0.89824484
D9: mercreci | H9: =41+RAND() -> 41.609171 | I9: =41+RAND() -> 41.870678 | J9: =41+RAND() -> 41.616646 | K9: =41+RAND() -> 41.441772 | L9: =41+RAND() -> 41.269325 | M9: =41+RAND() -> 41.462221 | P9: S totale | Q9: =SQRT(Q8) -> 0.94775779 | V9: -3 | W9: =Q$7+V9*SQRT(Q$8) -> 37.712944 | X9: =NORMDIST(W9,Q$7,SQRT(Q$8),0) -> 0.0046761403
D10: jeudi | G10: C | H10: =40-RAND() -> 39.787275 | I10: =40-RAND() -> 39.486971 | J10: =40-RAND() -> 39.005014 | K10: =40-RAND() -> 39.174683 | L10: =40-RAND() -> 39.877577 | M10: =40-RAND() -> 39.924189 | N10: =SUM(H10:M11) -> 473.52457 | P10: Min | Q10: =MIN(H6:M11) -> 39.005014 | V10: -2.9 | W10: =Q$7+V10*SQRT(Q$8) -> 37.807719 | X10: =NORMDIST(W10,Q$7,SQRT(Q$8),0) -> 0.0062806473
H11: =40-RAND() -> 39.531121 | I11: =40-RAND() -> 39.006872 | J11: =40-RAND() -> 39.457162 | K11: =40-RAND() -> 39.291223 | L11: =40-RAND() -> 39.845381 | M11: =40-RAND() -> 39.1371 | P11: Max | Q11: =MAX(H6:M11) -> 41.948366 | V11: -2.8 | W11: =Q$7+V11*SQRT(Q$8) -> 37.902495 | X11: =NORMDIST(W11,Q$7,SQRT(Q$8),0) -> 0.0083517663
G12: ∑ | H12: =SUM(H6:I11) -> 486.64689 | J12: =SUM(J6:K11) -> 485.37483 | L12: =SUM(L6:M11) -> 488.00209 | N12: =SUM(N6:O11) -> 1460.0238 | P12: Cpk | Q12: =MIN((Q5-Q7)/(3*SQRT(Q8)),(Q7-Q4)/(3*SQRT(Q8))) -> 1.5629109 | V12: -2.7 | W12: =Q$7+V12*SQRT(Q$8) -> 37.997271 | X12: =NORMDIST(W12,Q$7,SQRT(Q$8),0) -> 0.010995356
V13: -2.6 | W13: =Q$7+V13*SQRT(Q$8) -> 38.092047 | X13: =NORMDIST(W13,Q$7,SQRT(Q$8),0) -> 0.014331688
V14: -2.5 | W14: =Q$7+V14*SQRT(Q$8) -> 38.186822 | X14: =NORMDIST(W14,Q$7,SQRT(Q$8),0) -> 0.018494494
V15: -2.4 | W15: =Q$7+V15*SQRT(Q$8) -> 38.281598 | X15: =NORMDIST(W15,Q$7,SQRT(Q$8),0) -> 0.023628959
V16: -2.3 | W16: =Q$7+V16*SQRT(Q$8) -> 38.376374 | X16: =NORMDIST(W16,Q$7,SQRT(Q$8),0) -> 0.029888478
V17: -2.2 | W17: =Q$7+V17*SQRT(Q$8) -> 38.47115 | X17: =NORMDIST(W17,Q$7,SQRT(Q$8),0) -> 0.03743002
V18: -2.1 | W18: =Q$7+V18*SQRT(Q$8) -> 38.565926 | X18: =NORMDIST(W18,Q$7,SQRT(Q$8),0) -> 0.046408055
V19: -2 | W19: =Q$7+V19*SQRT(Q$8) -> 38.660701 | X19: =NORMDIST(W19,Q$7,SQRT(Q$8),0) -> 0.056967051
V20: -1.9 | W20: =Q$7+V20*SQRT(Q$8) -> 38.755477 | X20: =NORMDIST(W20,Q$7,SQRT(Q$8),0) -> 0.069232683
V21: -1.8 | W21: =Q$7+V21*SQRT(Q$8) -> 38.850253 | X21: =NORMDIST(W21,Q$7,SQRT(Q$8),0) -> 0.083302041
V22: -1.7 | W22: =Q$7+V22*SQRT(Q$8) -> 38.945029 | X22: =NORMDIST(W22,Q$7,SQRT(Q$8),0) -> 0.099233241
V23: -1.6 | W23: =Q$7+V23*SQRT(Q$8) -> 39.039804 | X23: =NORMDIST(W23,Q$7,SQRT(Q$8),0) -> 0.117035
V24: -1.5 | W24: =Q$7+V24*SQRT(Q$8) -> 39.13458 | X24: =NORMDIST(W24,Q$7,SQRT(Q$8),0) -> 0.13665685
... V31: -0.8 | W31: =Q$7+V31*SQRT(Q$8) -> 39.798011 | X31: =NORMDIST(W31,Q$7,SQRT(Q$8),0) -> 0.3056599
C32: étape d'identification | G32: ANOVA | P32: Prérequis | V32: -0.7 | W32: =Q$7+V32*SQRT(Q$8) -> 39.892786 | X32: =NORMDIST(W32,Q$7,SQRT(Q$8),0) -> 0.32946596
C33: Origine | D33: niveau | E33: SB² | F33: CI | G33: SCE | H33: ddl | I33: CM | J33: Fobs | K33: F5% | L33: contrib% | M33: équiv β | N33: diff 1-β | P33: Cochran | V33: -0.6 | W33: =Q$7+V33*SQRT(Q$8) -> 39.987562 | X33: =NORMDIST(W33,Q$7,SQRT(Q$8),0) -> 0.35159257
C34: Total | D34: =COUNT(H6:M11) -> 36 | E34: =SUM(H6:M11)^2 -> 2131669.5 | F34: =E34/D34 -> 59213.042 | G34: =DEVSQ(H6:M11) -> 31.438569 | H34: =D34-1 -> 35 | I34: =G34/H34 -> 0.89824484 | J34: x | K34: x | L34: =SUM(L36:L39) -> 1 | M34: x | N34: x | P34: Cobs | Q34: =MAX(I48:I56)/SUM(I48:I56) -> 0.60191889 | R34: 9 | V34: -0.5 | W34: =Q$7+V34*SQRT(Q$8) -> 40.082338 | X34: =NORMDIST(W34,Q$7,SQRT(Q$8),0) -> 0.37147183
C35: modèle | D35: x | E35: x | F35: x | G35: =SUM(G37:G39) -> 27.255868 | H35: =SUM(H37:H39) -> 6 | I35: =G35/H35 -> 4.5426446 | J35: =I35/I36 -> 31.495599 | K35: =FINV(0.05,H35,H36) -> 2.4324341 | L35: =G35/G34 -> 0.86695636 | M35: x | N35: x | P35: C 1% | Q35: =1/((1+(R34-1)/FINV(0.01/R34,R35-1,(R34)*(R35-1)))) -> 0.73460939 | R35: 2 | V35: -0.4 | W35: =Q$7+V35*SQRT(Q$8) -> 40.177114 | X35: =NORMDIST(W35,Q$7,SQRT(Q$8),0) -> 0.38856989
C36: résiduel | D36: x | E36: x | F36: x | G36: =G34-G35 -> 4.1827017 | H36: =H34-H35 -> 29 | I36: =G36/H36 -> 0.14423109 | J36: x | K36: x | L36: =G36/G34 -> 0.13304364 | M36: x | N36: x | P36: Cobs < C 1% = OK | V36: -0.3 | W36: =Q$7+V36*SQRT(Q$8) -> 40.27189 | X36: =NORMDIST(W36,Q$7,SQRT(Q$8),0) -> 0.40241063
C37: =D5 -> opérateur | D37: 3 | E37: =SUM(H6:I11)^2+SUM(J6:K11)^2+SUM(L6:M11)^2 -> 710559.96 | F37: =E37*D37/$D$34 -> 59213.33 | G37: =F37-$F$34 -> 0.2877004 | H37: =D37-1 -> 2 | I37: =G37/H37 -> 0.1438502 | J37: =I37/I$36 -> 0.99735914 | K37: =FINV(0.05,H37,H$36) -> 3.3276545 | L37: =G37/$G$34 -> 0.0091511924 | M37: =1-FDIST(K37/J37,H37,H$36) -> 0.95035696 | N37: =1-M37 -> 0.049643045 | O37: =K37*I36/G34 -> 0.01526632 | V37: -0.2 | W37: =Q$7+V37*SQRT(Q$8) -> 40.366665 | X37: =NORMDIST(W37,Q$7,SQRT(Q$8),0) -> 0.41259771
C38: =D6 -> fournisseur | D38: 3 | E38: =SUM(H6:M7)^2+SUM(H8:M9)^2+SUM(H10:M11)^2 -> 710878.09 | F38: =E38*D38/D34 -> 59239.841 | G38: =F38-$F$34 -> 26.798381 | H38: =D38-1 -> 2 | I38: =G38/H38 -> 13.39919 | J38: =I38/I$36 -> 92.900845 | K38: =FINV(0.05,H38,H$36) -> 3.3276545 | L38: =G38/$G$34 -> 0.85240459 | M38: =1-FDIST(K38/J38,H38,H$36) -> 0.035142881 | N38: =1-M38 -> 0.96485712 | O38: =O37 -> 0.01526632 | V38: -0.1 | W38: =Q$7+V38*SQRT(Q$8) -> 40.461441 | X38: =NORMDIST(W38,Q$7,SQRT(Q$8),0) -> 0.41883332
C39: =D7 -> jour | D39: 3 | E39: =SUM(J6:K7,L8:M9,H10:I11)^2+SUM(L6:M7,H8:I9,J10:K11)^2+SUM(H6:I7,J8:K9,L10:M11)^2 -> 710558.54 | F39: =E39*D39/$D$34 -> 59213.212 | G39: =F39-$F$34 -> 0.16978649 | H39: =D39-1 -> 2 | I39: =G39/H39 -> 0.084893247 | J39: =I39/I$36 -> 0.58859186 | K39: =FINV(0.05,H39,H$36) -> 3.3276545 | L39: =G39/$G$34 -> 0.0054005796 | M39: =1-FDIST(K39/J39,H39,H$36) -> 0.99155252 | N39: =1-M39 -> 0.0084474828 | O39: =O38 -> 0.01526632 | V39: 0 | W39: =Q$7+V39*SQRT(Q$8) -> 40.556217 | X39: =NORMDIST(W39,Q$7,SQRT(Q$8),0) -> 0.42093273
J40: Fobs < F5% = équivalence | O40: =O39 -> 0.01526632 | V40: 0.1 | W40: =Q$7+V40*SQRT(Q$8) -> 40.650993 | X40: =NORMDIST(W40,Q$7,SQRT(Q$8),0) -> 0.41883332
C41: R² | D41: =L35 -> 0.86695636 | E41: <Coefficient de détermination : ce qui est expliqué par le modèle | V41: 0.2 | W41: =Q$7+V41*SQRT(Q$8) -> 40.745768 | X41: =NORMDIST(W41,Q$7,SQRT(Q$8),0) -> 0.41259771
L42: S²répéta | M42: =I55 -> 0.14473067 | V42: 0.3 | W42: =Q$7+V42*SQRT(Q$8) -> 40.840544 | X42: =NORMDIST(W42,Q$7,SQRT(Q$8),0) -> 0.40241063
C43: R²ajusté | D43: =(I34-I36)/I34 -> 0.83943009 | E43: < expliqué par le modèle (ajusté) | L43: SCE | M43: =M42*9 -> 1.302576 | V43: 0.4 | W43: =Q$7+V43*SQRT(Q$8) -> 40.93532 | X43: =NORMDIST(W43,Q$7,SQRT(Q$8),0) -> 0.38856989
L44: contri % | M44: =M43/G34 -> 0.041432421 | V44: 0.5 | W44: =Q$7+V44*SQRT(Q$8) -> 41.030096 | X44: =NORMDIST(W44,Q$7,SQRT(Q$8),0) -> 0.37147183
C45: Catégorie | D45: =TRUNC(SQRT(I34/I55)*SQRT(2),0) -> 3 | E45: < nombre de catégorie détectable par la méthode | V45: 0.6 | W45: =Q$7+V45*SQRT(Q$8) -> 41.124872 | X45: =NORMDIST(W45,Q$7,SQRT(Q$8),0) -> 0.35159257
V46: 0.7 | W46: =Q$7+V46*SQRT(Q$8) -> 41.219647 | X46: =NORMDIST(W46,Q$7,SQRT(Q$8),0) -> 0.32946596
V47: 0.8 | W47: =Q$7+V47*SQRT(Q$8) -> 41.314423 | X47: =NORMDIST(W47,Q$7,SQRT(Q$8),0) -> 0.3056599
B48: Morgan GERMA | R48: version 1 | V48: 0.9 | W48: =Q$7+V48*SQRT(Q$8) -> 41.409199 | X48: =NORMDIST(W48,Q$7,SQRT(Q$8),0) -> 0.28075237
I49: =VAR(H6:I7) -> 0.50826751 | J49: =VAR(J6:K7) -> 0.24525417 | K49: =VAR(L6:M7) -> 0.034531318 | R49: 42795 | V49: 1 | W49: =Q$7+V49*SQRT(Q$8) -> 41.503975 | X49: =NORMDIST(W49,Q$7,SQRT(Q$8),0) -> 0.25530861
...

Sheet Récapitulatif
B1: Profil d'exactitude
B2: Probabilité tolérance (bêta) | C2: =#REF! -> #REF! | E2: 20 | F2: 100
B3: Limite d'acceptabilité | C3: =#REF! -> #REF! | E3: 0.01 | F3: =E3*F2/E2 -> 0.05
B5: Niveaux | C5: Niveau A | D5: Niveau B | E5: Niveau C | F5: Niveau D | G5: Niveau E
A6: 2 | B6: Valeur cible | C6: ='80%'!B2 -> 80 | D6: ='90%'!B2 -> 90 | E6: ='100%'!B2 -> 100 | F6: ='110%'!B2 -> 110 | G6: ='120%'!B2 -> 120
A7: 30 | B7: Moyenne niveau | C7: ='80%'!B22 -> #REF! | D7: ='90%'!B22 -> #REF! | E7: ='100%'!B22 -> #REF! | F7: ='110%'!B22 -> #REF! | G7: ='120%'!B22 -> #REF! | K7: =ADDRESS($A8,2,,,C$5) -> 'Niveau A'!$B$31
A8: 31 | B8: Ecart-type de répétabilité (sr) | C8: ='80%'!B23 -> #DIV/0! | D8: ='90%'!B23 -> #DIV/0! | E8: ='100%'!B23 -> #DIV/0! | F8: ='110%'!B23 -> #DIV/0! | G8: ='120%'!B23 -> #DIV/0!
A9: 32 | B9: Ecart-type inter-séries (sL) | C9: ='80%'!B24 -> #REF! | D9: ='90%'!B24 -> #REF! | E9: ='100%'!B24 -> #REF! | F9: ='110%'!B24 -> #REF! | G9: ='120%'!B24 -> #REF!
A10: 33 | B10: Ecart-type de fidélité (sFI) | C10: ='80%'!B25 -> #DIV/0! | D10: ='90%'!B25 -> #DIV/0! | E10: ='100%'!B25 -> #DIV/0! | F10: ='110%'!B25 -> #DIV/0! | G10: ='120%'!B25 -> #DIV/0!
A11: 37 | B11: Rapport des variances (R) | C11: ='80%'!B29 -> #REF! | D11: ='90%'!B29 -> #REF! | E11: ='100%'!B29 -> #REF! | F11: ='110%'!B29 -> #REF! | G11: ='120%'!B29 -> #REF!
A12: 39 | B12: Coefficient intermédiaire | C12: ='80%'!B31 -> #REF! | D12: ='90%'!B31 -> #REF! | E12: ='100%'!B31 -> #REF! | F12: ='110%'!B31 -> #REF! | G12: ='120%'!B31 -> #REF!
A13: 40 | B13: Nombre de degrés liberté | C13: ='80%'!B32 -> #REF! | D13: ='90%'!B32 -> #REF! | E13: ='100%'!B32 -> #REF! | F13: ='110%'!B32 -> #REF! | G13: ='120%'!B32 -> #REF!
A14: 47 | B14: Valeur basse tolérance | C14: ='80%'!B39 -> #REF! | D14: ='90%'!B39 -> #REF! | E14: ='100%'!B39 -> #REF! | F14: ='110%'!B39 -> #REF! | G14: ='120%'!B39 -> #REF!
A15: 48 | B15: Valeur haute tolérance | C15: ='80%'!B40 -> #REF! | D15: ='90%'!B40 -> #REF! | E15: ='100%'!B40 -> #REF! | F15: ='110%'!B40 -> #REF! | G15: ='120%'!B40 -> #REF!
A16: 35 | B16: Biais (%) | C16: ='80%'!B27 -> #REF! | D16: ='90%'!B27 -> #REF! | E16: ='100%'!B27 -> #REF! | F16: ='110%'!B27 -> #REF! | G16: ='120%'!B27 -> #REF!
B17: Recouvrement (justesse) | C17: =C7/C$6 -> #REF! | D17: =D7/D$6 -> #REF! | E17: =E7/E$6 -> #REF! | F17: =F7/F$6 -> #REF! | G17: =G7/G$6 -> #REF!
B18: Limite basse tolérance (%) | C18: =C14/C$6 -> #REF! | D18: =D14/D$6 -> #REF! | E18: =E14/E$6 -> #REF! | F18: =F14/F$6 -> #REF! | G18: =G14/G$6 -> #REF!
B19: Limite haute tolérance (%) | C19: =C15/C$6 -> #REF! | D19: =D15/D$6 -> #REF! | E19: =E15/E$6 -> #REF! | F19: =F15/F$6 -> #REF! | G19: =G15/G$6 -> #REF!
B20: Limite d'acceptabilité basse | C20: =1-$C$3 -> #REF! | D20: =1-$C$3 -> #REF! | E20: =1-$C$3 -> #REF! | F20: =1-$C$3 -> #REF! | G20: =1-$C$3 -> #REF!
B21: Limite d'acceptabilité haute | C21: =1+$C$3 -> #REF! | D21: =1+$C$3 -> #REF! | E21: =1+$C$3 -> #REF! | F21: =1+$C$3 -> #REF! | G21: =1+$C$3 -> #REF!
B27: Incertitude
B28: Ecart-type de l'IT (sIT) | C28: =C$12*C$10 -> #REF! | D28: =D$12*D$10 -> #REF! | E28: =E$12*E$10 -> #REF! | F28: =F$12*F$10 -> #REF! | G28: =G$12*G$10 -> #REF!
B29: Incertitude élargie relative | C29: =2*C28/C7 -> #REF! | D29: =2*D28/D7 -> #REF! | E29: =2*E28/E7 -> #REF! | F29: =2*F28/F7 -> #REF! | G29: =2*G28/G7 -> #REF!

Sheet 80%
A1: Niveau A
A2: Valeur cible | B2: 80
B4: Répétition 1 | C4: Répétition 2 | D4: Répétition 3 | E4: Répétition 4 | F4: Répétition 5 | H4: nk | I4: SCEk
A5: Jour (Série) 1 | B5: =#REF!*$B$2 -> #REF! | C5: =#REF!*$B$2 -> #REF! | H5: =COUNT(B5:F5) -> 0 | I5: =IF(H5=0,"",DEVSQ(B5:F5))
A6: Jour (Série) 2
A7: Jour (Série) 3 | B7: =#REF!*$B$2 -> #REF! | C7: =#REF!*$B$2 -> #REF! | H7: =COUNT(B7:F7) -> 0 | I7: =IF(H7=0,"",DEVSQ(B7:F7))
A8: Jour (Série) 4 | B8: =#REF!*$B$2 -> #REF! | C8: =#REF!*$B$2 -> #REF! | H8: =COUNT(B8:F8) -> 0 | I8: =IF(H8=0,"",DEVSQ(B8:F8))
A9: Jour (Série) 5 | B9: =#REF!*$B$2 -> #REF! | C9: =#REF!*$B$2 -> #REF! | H9: =COUNT(B9:F9) -> 0 | I9: =IF(H9=0,"",DEVSQ(B9:F9))
A11: Nombre de séries (K) | B11: =COUNT(B5:B9) -> 0
A12: Nombre de mesures (IK) | B12: =COUNT(B5:F9) -> 0
A13: Nombre de répétitions (I) | B13: =IF(H5*B11<>B12,"Calcul impossible",H5) -> 0
A14: SCE résiduelle | B14: =SUM(I5:I9) -> 0
A15: SCE totale | B15: =DEVSQ(B5:F9) -> #REF!
A16: SCE inter-séries | B16: =B15-B14 -> #REF!
A17: Valeur intermédiaire de s²L | B17: =((B16/(B11-1))-B18)/B13 -> #REF!
A18: Variance de répétabilité (s²r) | B18: =B14/(B12-B11) -> #DIV/0!
A19: Variance inter-séries (s²L) | B19: =IF(B17<0,0,B17) -> #REF!
A20: Variance de fidélité (s²FI) | B20: =SUM(B18:B19) -> #DIV/0!
A21: Fidélité
A22: Moyenne niveau | B22: =AVERAGE(B5:F9) -> #REF!
A23: Ecart-type de répétabilité (sr) | B23: =SQRT(B18) -> #DIV/0!
A24: Ecart-type inter-séries (sL) | B24: =SQRT(B19) -> #REF!
A25: Ecart-type de fidélité (sFI) | B25: =SQRT(B20) -> #DIV/0!
A26: Justesse
A27: Biais (%) | B27: =B22/B2-1 -> #REF!
A28: Facteur de couverture
A29: Rapport des variances (R) | B29: =B19/B18 -> #REF!
A30: Coefficient B² | B30: =(B29+1)/(B13*B29+1) -> #REF!
A31: Coefficient intermédiaire | B31: =SQRT(1+1/(B12*B30)) -> #REF!
A32: Nombre de degrés liberté | B32: =(B29+1)^2/((B29+1/B13)^2/(B11-1)+(1-1/B13)/B12) -> #REF!
A33: Probabilité tolérance (bêta) | B33: =Récapitulatif!C2 -> #REF!
A34: t Student bas | B34: =TINV(1-B33,ROUNDDOWN(B32,0)) -> #REF!
A35: t Student haut | B35: =TINV(1-B33,ROUNDUP(B32,0)) -> #REF!
A36: t Student interpolé | B36: =B34-(B34-B35)*(B32-ROUNDDOWN(B32,0)) -> #REF!
A37: Facteur de couverture (ktol) | B37: =B36*B31 -> #REF!
A38: Intervalle de tolérance
A39: Valeur basse tolérance | B39: =B22-B37*B25 -> #REF!
A40: Valeur haute tolérance | B40: =B22+B37*B25 -> #REF!

Sheet 90%
A1: Niveau B
A2: Valeur cible | B2: 90
B4: Répétition 1 | C4: Répétition 2 | D4: Répétition 3 | E4: Répétition 4 | F4: Répétition 5 | H4: nk | I4: SCEk
A5: Jour (Série) 1 | B5: =#REF!*$B$2 -> #REF! | C5: =#REF!*$B$2 -> #REF! | H5: =COUNT(B5:F5) -> 0 | I5: =IF(H5=0,"",DEVSQ(B5:F5))
A6: Jour (Série) 2 | B6: =#REF!*$B$2 -> #REF! | C6: =#REF!*$B$2 -> #REF! | H6: =COUNT(B6:F6) -> 0 | I6: =IF(H6=0,"",DEVSQ(B6:F6))
A7: Jour (Série) 3 | I7: =IF(H7=0,"",DEVSQ(B7:F7))
A8: Jour (Série) 4 | B8: =#REF!*$B$2 -> #REF! | C8: =#REF!*$B$2 -> #REF! | H8: =COUNT(B8:F8) -> 0 | I8: =IF(H8=0,"",DEVSQ(B8:F8))
A9: Jour (Série) 5 | B9: =#REF!*$B$2 -> #REF! | C9: =#REF!*$B$2 -> #REF! | H9: =COUNT(B9:F9) -> 0 | I9: =IF(H9=0,"",DEVSQ(B9:F9))
A11: Nombre de séries (K) | B11: =COUNT(B5:B9) -> 0
A12: Nombre de mesures (IK) | B12: =COUNT(B5:F9) -> 0
A13: Nombre de répétitions (I) | B13: =IF(H5*B11<>B12,"Calcul impossible",H5) -> 0
A14: SCE résiduelle | B14: =SUM(I5:I9) -> 0
A15: SCE totale | B15: =DEVSQ(B5:F9) -> #REF!
A16: SCE inter-séries | B16: =B15-B14 -> #REF!
A17: Valeur intermédiaire de s²L | B17: =((B16/(B11-1))-B18)/B13 -> #REF!
A18: Variance de répétabilité (s²r) | B18: =B14/(B12-B11) -> #DIV/0!
A19: Variance inter-séries (s²L) | B19: =IF(B17<0,0,B17) -> #REF!
A20: Variance de fidélité (s²FI) | B20: =SUM(B18:B19) -> #DIV/0!
A21: Fidélité
A22: Moyenne niveau | B22: =AVERAGE(B5:F9) -> #REF!
A23: Ecart-type de répétabilité (sr) | B23: =SQRT(B18) -> #DIV/0!
A24: Ecart-type inter-séries (sL) | B24: =SQRT(B19) -> #REF!
A25: Ecart-type de fidélité (sFI) | B25: =SQRT(B20) -> #DIV/0!
A26: Justesse
A27: Biais (%) | B27: =B22/B2-1 -> #REF!
A28: Facteur de couverture
A29: Rapport des variances (R) | B29: =B19/B18 -> #REF!
A30: Coefficient B² | B30: =(B29+1)/(B13*B29+1) -> #REF!
A31: Coefficient intermédiaire | B31: =SQRT(1+1/(B12*B30)) -> #REF!
A32: Nombre de degrés liberté | B32: =(B29+1)^2/((B29+1/B13)^2/(B11-1)+(1-1/B13)/B12) -> #REF!
A33: Probabilité tolérance (bêta) | B33: =Récapitulatif!C2 -> #REF!
A34: t Student bas | B34: =TINV(1-B33,ROUNDDOWN(B32,0)) -> #REF!
A35: t Student haut | B35: =TINV(1-B33,ROUNDUP(B32,0)) -> #REF!
A36: t Student interpolé | B36: =B34-(B34-B35)*(B32-ROUNDDOWN(B32,0)) -> #REF!
A37: Facteur de couverture (ktol) | B37: =B36*B31 -> #REF!
A38: Intervalle de tolérance
A39: Valeur basse tolérance | B39: =B22-B37*B25 -> #REF!
A40: Valeur haute tolérance | B40: =B22+B37*B25 -> #REF!

Sheet 100%
A1: Niveau C
A2: Valeur cible | B2: 100
B4: Répétition 1 | C4: Répétition 2 | D4: Répétition 3 | E4: Répétition 4 | F4: Répétition 5 | H4: nk | I4: SCEk
A5: Jour (Série) 1 | B5: =#REF!*$B$2 -> #REF! | C5: =#REF!*$B$2 -> #REF! | H5: =COUNT(B5:F5) -> 0 | I5: =IF(H5=0,"",DEVSQ(B5:F5))
A6: Jour (Série) 2 | B6: =#REF!*$B$2 -> #REF! | C6: =#REF!*$B$2 -> #REF! | H6: =COUNT(B6:F6) -> 0 | I6: =IF(H6=0,"",DEVSQ(B6:F6))
A7: Jour (Série) 3 | B7: =#REF!*$B$2 -> #REF! | C7: =#REF!*$B$2 -> #REF! | H7: =COUNT(B7:F7) -> 0 | I7: =IF(H7=0,"",DEVSQ(B7:F7))
A8: Jour (Série) 4 | I8: =IF(H8=0,"",DEVSQ(B8:F8))
A9: Jour (Série) 5 | B9: =#REF!*$B$2 -> #REF! | C9: =#REF!*$B$2 -> #REF! | H9: =COUNT(B9:F9) -> 0 | I9: =IF(H9=0,"",DEVSQ(B9:F9))
A11: Nombre de séries (K) | B11: =COUNT(B5:B9) -> 0
A12: Nombre de mesures (IK) | B12: =COUNT(B5:F9) -> 0
A13: Nombre de répétitions (I) | B13: =IF(H5*B11<>B12,"Calcul impossible",H5) -> 0
A14: SCE résiduelle | B14: =SUM(I5:I9) -> 0
A15: SCE totale | B15: =DEVSQ(B5:F9) -> #REF!
A16: SCE inter-séries | B16: =B15-B14 -> #REF!
A17: Valeur intermédiaire de s²L | B17: =((B16/(B11-1))-B18)/B13 -> #REF!
A18: Variance de répétabilité (s²r) | B18: =B14/(B12-B11) -> #DIV/0!
A19: Variance inter-séries (s²L) | B19: =IF(B17<0,0,B17) -> #REF!
A20: Variance de fidélité (s²FI) | B20: =SUM(B18:B19) -> #DIV/0!
A21: Fidélité
A22: Moyenne niveau | B22: =AVERAGE(B5:F9) -> #REF!
A23: Ecart-type de répétabilité (sr) | B23: =SQRT(B18) -> #DIV/0!
A24: Ecart-type inter-séries (sL) | B24: =SQRT(B19) -> #REF!
A25: Ecart-type de fidélité (sFI) | B25: =SQRT(B20) -> #DIV/0!
A26: Justesse
A27: Biais (%) | B27: =B22/B2-1 -> #REF!
A28: Facteur de couverture
A29: Rapport des variances (R) | B29: =B19/B18 -> #REF!
A30: Coefficient B² | B30: =(B29+1)/(B13*B29+1) -> #REF!
A31: Coefficient intermédiaire | B31: =SQRT(1+1/(B12*B30)) -> #REF!
A32: Nombre de degrés liberté | B32: =(B29+1)^2/((B29+1/B13)^2/(B11-1)+(1-1/B13)/B12) -> #REF!
A33: Probabilité tolérance (bêta) | B33: =Récapitulatif!C2 -> #REF!
A34: t Student bas | B34: =TINV(1-B33,ROUNDDOWN(B32,0)) -> #REF!
A35: t Student haut | B35: =TINV(1-B33,ROUNDUP(B32,0)) -> #REF!
A36: t Student interpolé | B36: =B34-(B34-B35)*(B32-ROUNDDOWN(B32,0)) -> #REF!
A37: Facteur de couverture (ktol) | B37: =B36*B31 -> #REF!
A38: Intervalle de tolérance
A39: Valeur basse tolérance | B39: =B22-B37*B25 -> #REF!
A40: Valeur haute tolérance | B40: =B22+B37*B25 -> #REF!

Sheet 110%
A1: Niveau D
A2: Valeur cible | B2: 110
B4: Répétition 1 | C4: Répétition 2 | D4: Répétition 3 | E4: Répétition 4 | F4: Répétition 5 | H4: nk | I4: SCEk
A5: Jour (Série) 1 | B5: =#REF!*$B$2 -> #REF! | C5: =#REF!*$B$2 -> #REF! | H5: =COUNT(B5:F5) -> 0 | I5: =IF(H5=0,"",DEVSQ(B5:F5))
A6: Jour (Série) 2 | B6: =#REF!*$B$2 -> #REF! | C6: =#REF!*$B$2 -> #REF! | H6: =COUNT(B6:F6) -> 0 | I6: =IF(H6=0,"",DEVSQ(B6:F6))
A7: Jour (Série) 3 | B7: =#REF!*$B$2 -> #REF! | C7: =#REF!*$B$2 -> #REF! | H7: =COUNT(B7:F7) -> 0 | I7: =IF(H7=0,"",DEVSQ(B7:F7))
A8: Jour (Série) 4 | B8: =#REF!*$B$2 -> #REF! | C8: =#REF!*$B$2 -> #REF! | H8: =COUNT(B8:F8) -> 0 | I8: =IF(H8=0,"",DEVSQ(B8:F8))
A9: Jour (Série) 5 | I9: =IF(H9=0,"",DEVSQ(B9:F9))
A11: Nombre de séries (K) | B11: =COUNT(B5:B9) -> 0
A12: Nombre de mesures (IK) | B12: =COUNT(B5:F9) -> 0
A13: Nombre de répétitions (I) | B13: =IF(H5*B11<>B12,"Calcul impossible",H5) -> 0
A14: SCE résiduelle | B14: =SUM(I5:I9) -> 0
A15: SCE totale | B15: =DEVSQ(B5:F9) -> #REF!
A16: SCE inter-séries | B16: =B15-B14 -> #REF!
A17: Valeur intermédiaire de s²L | B17: =((B16/(B11-1))-B18)/B13 -> #REF!
A18: Variance de répétabilité (s²r) | B18: =B14/(B12-B11) -> #DIV/0!
A19: Variance inter-séries (s²L) | B19: =IF(B17<0,0,B17) -> #REF!
A20: Variance de fidélité (s²FI) | B20: =SUM(B18:B19) -> #DIV/0!
A21: Fidélité
A22: Moyenne niveau | B22: =AVERAGE(B5:F9) -> #REF!
A23: Ecart-type de répétabilité (sr) | B23: =SQRT(B18) -> #DIV/0!
A24: Ecart-type inter-séries (sL) | B24: =SQRT(B19) -> #REF!
A25: Ecart-type de fidélité (sFI) | B25: =SQRT(B20) -> #DIV/0!
A26: Justesse
A27: Biais (%) | B27: =B22/B2-1 -> #REF!
A28: Facteur de couverture
A29: Rapport des variances (R) | B29: =B19/B18 -> #REF!
A30: Coefficient B² | B30: =(B29+1)/(B13*B29+1) -> #REF!
A31: Coefficient intermédiaire | B31: =SQRT(1+1/(B12*B30)) -> #REF!
A32: Nombre de degrés liberté | B32: =(B29+1)^2/((B29+1/B13)^2/(B11-1)+(1-1/B13)/B12) -> #REF!
A33: Probabilité tolérance (bêta) | B33: =Récapitulatif!C2 -> #REF!
A34: t Student bas | B34: =TINV(1-B33,ROUNDDOWN(B32,0)) -> #REF!
A35: t Student haut | B35: =TINV(1-B33,ROUNDUP(B32,0)) -> #REF!
A36: t Student interpolé | B36: =B34-(B34-B35)*(B32-ROUNDDOWN(B32,0)) -> #REF!
A37: Facteur de couverture (ktol) | B37: =B36*B31 -> #REF!
A38: Intervalle de tolérance
A39: Valeur basse tolérance | B39: =B22-B37*B25 -> #REF!
A40: Valeur haute tolérance | B40: =B22+B37*B25 -> #REF!

Sheet 120%
A1: Niveau E
A2: Valeur cible | B2: 120
B4: Répétition 1 | C4: Répétition 2 | D4: Répétition 3 | E4: Répétition 4 | F4: Répétition 5 | H4: nk | I4: SCEk
A5: Jour (Série) 1
A6: Jour (Série) 2 | B6: =#REF!*$B$2 -> #REF! | C6: =#REF!*$B$2 -> #REF! | H6: =COUNT(B6:F6) -> 0 | I6: =IF(H6=0,"",DEVSQ(B6:F6))
A7: Jour (Série) 3 | B7: =#REF!*$B$2 -> #REF! | C7: =#REF!*$B$2 -> #REF! | H7: =COUNT(B7:F7) -> 0 | I7: =IF(H7=0,"",DEVSQ(B7:F7))
A8: Jour (Série) 4 | B8: =#REF!*$B$2 -> #REF! | C8: =#REF!*$B$2 -> #REF! | H8: =COUNT(B8:F8) -> 0 | I8: =IF(H8=0,"",DEVSQ(B8:F8))
A9: Jour (Série) 5 | B9: =#REF!*$B$2 -> #REF! | C9: =#REF!*$B$2 -> #REF! | H9: =COUNT(B9:F9) -> 0 | I9: =IF(H9=0,"",DEVSQ(B9:F9))
A11: Nombre de séries (K) | B11: =COUNT(B5:B9) -> 0
A12: Nombre de mesures (IK) | B12: =COUNT(B5:F9) -> 0
A13: Nombre de répétitions (I) | B13: =IF(H6*B11<>B12,"Calcul impossible",H6) -> 0
A14: SCE résiduelle | B14: =SUM(I5:I9) -> 0
A15: SCE totale | B15: =DEVSQ(B5:F9) -> #REF!
A16: SCE inter-séries | B16: =B15-B14 -> #REF!
A17: Valeur intermédiaire de s²L | B17: =((B16/(B11-1))-B18)/B13 -> #REF!
A18: Variance de répétabilité (s²r) | B18: =B14/(B12-B11) -> #DIV/0!
A19: Variance inter-séries (s²L) | B19: =IF(B17<0,0,B17) -> #REF!
A20: Variance de fidélité (s²FI) | B20: =SUM(B18:B19) -> #DIV/0!
A21: Fidélité
A22: Moyenne niveau | B22: =AVERAGE(B5:F9) -> #REF!
A23: Ecart-type de répétabilité (sr) | B23: =SQRT(B18) -> #DIV/0!
A24: Ecart-type inter-séries (sL) | B24: =SQRT(B19) -> #REF!
A25: Ecart-type de fidélité (sFI) | B25: =SQRT(B20) -> #DIV/0!
A26: Justesse
A27: Biais (%) | B27: =B22/B2-1 -> #REF!
A28: Facteur de couverture
A29: Rapport des variances (R) | B29: =B19/B18 -> #REF!
A30: Coefficient B² | B30: =(B29+1)/(B13*B29+1) -> #REF!
A31: Coefficient intermédiaire | B31: =SQRT(1+1/(B12*B30)) -> #REF!
A32: Nombre de degrés liberté | B32: =(B29+1)^2/((B29+1/B13)^2/(B11-1)+(1-1/B13)/B12) -> #REF!
A33: Probabilité tolérance (bêta) | B33: =Récapitulatif!C2 -> #REF!
A34: t Student bas | B34: =TINV(1-B33,ROUNDDOWN(B32,0)) -> #REF!
A35: t Student haut | B35: =TINV(1-B33,ROUNDUP(B32,0)) -> #REF!
A36: t Student interpolé | B36: =B34-(B34-B35)*(B32-ROUNDDOWN(B32,0)) -> #REF!
A37: Facteur de couverture (ktol) | B37: =B36*B31 -> #REF!
A38: Intervalle de tolérance
A39: Valeur basse tolérance | B39: =B22-B37*B25 -> #REF!
A40: Valeur haute tolérance | B40: =B22+B37*B25 -> #REF!
