Workbook
Name ANALYTES: #REF!

Sheet GR&R croisé
B2: GAGE R&R
G4: plan d'expériences croisée
C5: Facteur qualitatif | G5: X | H5: Y | I5: r1 | J5: r2 | K5: r3 | L5: r4 | M5: r5 | N5: r6
C6: X | D6: opérateur | G6: marie | H6: 1 | I6: 30.684 | J6: 30.436 | K6: 30.451 | O6: =+SUM(I6:N6) -> 91.571 | P6: Tolérance - | Q6: 25 | R6: =+Q6 -> 25 | S6: 0 | T6: =X63 -> 1.3559413 | U6: =VAR(I6:N6) -> 0.019336333
C7: Y | D7: pièce | H7: 2 | I7: 30.943 | J7: 30.408 | K7: 30.214 | O7: =+SUM(I7:N7) -> 91.565 | P7: Tolérance + | Q7: 35 | R7: =+Q7 -> 35 | S7: 0 | T7: =T6 -> 1.3559413 | U7: =VAR(I7:N7) -> 0.14255033
H8: 3 | I8: 30.896 | J8: 30.419 | K8: 30.374 | O8: =+SUM(I8:N8) -> 91.689 | U8: =VAR(I8:N8) -> 0.083673
C9: Les N observations sont obtenues sous | H9: 4 | I9: 30.989 | J9: 30.004 | K9: 30.272 | O9: =+SUM(I9:N9) -> 91.265 | P9: moyenne | Q9: =AVERAGE(I6:N35) -> 30.531644 | U9: =VAR(I9:N9) -> 0.25935633
C10: condition de répétabilité : même méthode, | H10: 5 | I10: 30.166 | J10: 30.826 | K10: 30.63 | O10: =+SUM(I10:N10) -> 91.622 | P10: S² totale | Q10: =I58 -> 0.086564209 | U10: =VAR(I10:N10) -> 0.11488533
C11: même sujet, laps de temps le plus | H11: 6 | I11: 30.515 | J11: 30.846 | K11: 30.019 | O11: =+SUM(I11:N11) -> 91.38 | P11: S totale | Q11: =SQRT(Q10) -> 0.29421796 | U11: =VAR(I11:N11) -> 0.173251
C12: court possible, | H12: 7 | I12: 30.382 | J12: 30.954 | K12: 30.677 | O12: =+SUM(I12:N12) -> 92.013 | P12: Min | Q12: =MIN(I6:N35) -> 30.001 | U12: =VAR(I12:N12) -> 0.081823
C13: Les pièces sont tirées au hasard et représentent | H13: 8 | I13: 30.431 | J13: 30.158 | K13: 30.007 | O13: =+SUM(I13:N13) -> 90.596 | P13: Max | Q13: =MAX(I6:N35) -> 30.993 | U13: =VAR(I13:N13) -> 0.046184333
C14: l'étendu des pièces observables (Cf et NC) | H14: 9 | I14: 30.7 | J14: 30.695 | K14: 30.634 | O14: =+SUM(I14:N14) -> 92.029 | U14: =VAR(I14:N14) -> 0.0013503333
H15: 10 | I15: 30.468 | J15: 30.108 | K15: 30.965 | O15: =+SUM(I15:N15) -> 91.541 | P15: Cpc | Q15: =(Q7-Q6)/(6*SQRT(K60)) -> 5.5325071 | R15: > 4 | U15: =VAR(I15:N15) -> 0.18517633
G16: pierre | H16: 1 | I16: 30.823 | J16: 30.93 | K16: 30.359 | O16: =+SUM(I16:N16) -> 92.112 | P16: *GRR% | Q16: =SQRT(N57)/((Q7-Q6)/6) -> 0.18074988 | R16: < 25% | U16: =VAR(I16:N16) -> 0.092131
H17: 2 | I17: 30.841 | J17: 30.378 | K17: 30.442 | O17: =+SUM(I17:N17) -> 91.661 | P17: *basé sur les Tolérances | U17: =VAR(I17:N17) -> 0.062944333
H18: 3 | I18: 30.981 | J18: 30.001 | K18: 30.648 | O18: =+SUM(I18:N18) -> 91.63 | U18: =VAR(I18:N18) -> 0.24831633
H19: 4 | I19: 30.689 | J19: 30.62 | K19: 30.429 | O19: =+SUM(I19:N19) -> 91.738 | P19: Cp méthode | Q19: =(Q7-Q6)/(6*SQRT(I58)) -> 5.6647346 | R19: > 1,33 | U19: =VAR(I19:N19) -> 0.018140333
H20: 5 | I20: 30.946 | J20: 30.406 | K20: 30.684 | O20: =+SUM(I20:N20) -> 92.036 | U20: =VAR(I20:N20) -> 0.072921333
H21: 6 | I21: 30.24 | J21: 30.829 | K21: 30.558 | O21: =+SUM(I21:N21) -> 91.627 | U21: =VAR(I21:N21) -> 0.086914333
H22: 7 | I22: 30.15 | J22: 30.61 | K22: 30.197 | O22: =+SUM(I22:N22) -> 90.957 | U22: =VAR(I22:N22) -> 0.064063
H23: 8 | I23: 30.722 | J23: 30.592 | K23: 30.66 | O23: =+SUM(I23:N23) -> 91.974 | U23: =VAR(I23:N23) -> 0.004228
H24: 9 | I24: 30.004 | J24: 30.59 | K24: 30.167 | O24: =+SUM(I24:N24) -> 90.761 | U24: =VAR(I24:N24) -> 0.091482333
H25: 10 | I25: 30.663 | J25: 30.759 | K25: 30.254 | O25: =+SUM(I25:N25) -> 91.676 | U25: =VAR(I25:N25) -> 0.071920333
G26: paul | H26: 1 | I26: 30.936 | J26: 30.686 | K26: 30.631 | O26: =+SUM(I26:N26) -> 92.253 | U26: =VAR(I26:N26) -> 0.026425
H27: 2 | I27: 30.136 | J27: 30.661 | K27: 30.216 | O27: =+SUM(I27:N27) -> 91.013 | U27: =VAR(I27:N27) -> 0.080008333
H28: 3 | I28: 30.714 | J28: 30.094 | K28: 30.204 | O28: =+SUM(I28:N28) -> 91.012 | U28: =VAR(I28:N28) -> 0.10943333
H29: 4 | I29: 30.449 | J29: 30.678 | K29: 30.993 | O29: =+SUM(I29:N29) -> 92.12 | U29: =VAR(I29:N29) -> 0.074600333
H30: 5 | I30: 30.892 | J30: 30.888 | K30: 30.344 | O30: =+SUM(I30:N30) -> 92.124 | U30: =VAR(I30:N30) -> 0.099376
H31: 6 | I31: 30.892 | J31: 30.033 | K31: 30.931 | O31: =+SUM(I31:N31) -> 91.856 | U31: =VAR(I31:N31) -> 0.25763433
H32: 7 | I32: 30.579 | J32: 30.365 | K32: 30.381 | O32: =+SUM(I32:N32) -> 91.325 | U32: =VAR(I32:N32) -> 0.014209333
H33: 8 | I33: 30.791 | J33: 30.471 | K33: 30.722 | O33: =+SUM(I33:N33) -> 91.984 | U33: =VAR(I33:N33) -> 0.028360333
H34: 9 | I34: 30.183 | J34: 30.203 | K34: 30.126 | O34: =+SUM(I34:N34) -> 90.512 | U34: =VAR(I34:N34) -> 0.0015963333 | V34: -3 | W34: =Q$9+V34*SQRT(Q$10) -> 29.648991 | X34: =NORMDIST(W34,Q$9,SQRT(Q$10),0) -> 0.015063147
H35: 10 | I35: 30.987 | J35: 30.359 | K35: 30.86 | O35: =+SUM(I35:N35) -> 92.206 | U35: =VAR(I35:N35) -> 0.11025233 | V35: -2.9 | W35: =Q$9+V35*SQRT(Q$10) -> 29.678412 | X35: =NORMDIST(W35,Q$9,SQRT(Q$10),0) -> 0.02023171
V36: -2.7 | W36: =Q$9+V36*SQRT(Q$10) -> 29.737256 | X36: =NORMDIST(W36,Q$9,SQRT(Q$10),0) -> 0.035419098
V37: -2.6 | W37: =Q$9+V37*SQRT(Q$10) -> 29.766678 | X37: =NORMDIST(W37,Q$9,SQRT(Q$10),0) -> 0.046166349
V38: -2.5 | W38: =Q$9+V38*SQRT(Q$10) -> 29.7961 | X38: =NORMDIST(W38,Q$9,SQRT(Q$10),0) -> 0.059575902
V39: -2.4 | W39: =Q$9+V39*SQRT(Q$10) -> 29.825521 | X39: =NORMDIST(W39,Q$9,SQRT(Q$10),0) -> 0.076115442
V40: -2.3 | W40: =Q$9+V40*SQRT(Q$10) -> 29.854943 | X40: =NORMDIST(W40,Q$9,SQRT(Q$10),0) -> 0.09627909
V41: -2.2 | W41: =Q$9+V41*SQRT(Q$10) -> 29.884365 | X41: =NORMDIST(W41,Q$9,SQRT(Q$10),0) -> 0.12057249
V42: -2.1 | W42: =Q$9+V42*SQRT(Q$10) -> 29.913787 | X42: =NORMDIST(W42,Q$9,SQRT(Q$10),0) -> 0.14949324
...

Sheet Gage R&R emboité
C3: Facteur qualitatif | G3: plan d'expériences emboité | L3: =SUM(H3:K3) -> 0 | M3: =SUM(I3:L3) -> 0
C4: X | D4: lot | E4: 3 | G4: X | H4: Y | I4: Z | J4: r1 | L4: Tolérance - | M4: 0 | N4: =M4 -> 0 | O4: 0 | P4: =R63 -> 0 | Q4: 0 | R4: =V63 -> 1.3020094
C5: Y | D5: opérateur | E5: 3 | G5: lot 1 | H5: Pierre | I5: pièce 1 | J5: =1+RAND() -> 1.2735824 | K5: =AVERAGE(J5:J7) -> 1.3072347 | L5: Tolérance + | M5: 3 | N5: =M5 -> 3 | O5: 0 | P5: =P4 -> 0 | Q5: 0 | R5: =R4 -> 1.3020094
C6: Z | D6: pièce | E6: 3 | I6: pièce 2 | J6: =1+RAND() -> 1.6171634
I7: pièce 3 | J7: =1+RAND() -> 1.0309583 | L7: moyenne | M7: =AVERAGE(J5:J31) -> 1.4565112
C8: Lorsque le plan est emboité, on évalue | H8: Paul | I8: pièce 4 | J8: =1+RAND() -> 1.6572237 | K8: =AVERAGE(J8:J10) -> 1.5965132 | L8: S² totale | M8: =I53 -> 0.093884065
C9: les variances intermédiaires de fidélité. | I9: pièce 5 | J9: =1+RAND() -> 1.1829556 | L9: S totale | M9: =SQRT(M8) -> 0.30640507
I10: pièce 6 | J10: =1+RAND() -> 1.9493603 | L10: Min | M10: =MIN(J5:J31) -> 1.0110956
C11: les facteurs opérateur et lot sont croisés | H11: Marie | I11: pièce 7 | J11: =1+RAND() -> 1.8070567 | K11: =AVERAGE(J11:J13) -> 1.6411094 | L11: Max | M11: =MAX(J5:J31) -> 1.9897031
C12: le facteur pièce est lui emboité dans Op/lot | I12: pièce 8 | J12: =1+RAND() -> 1.8121037
I13: pièce 9 | J13: =1+RAND() -> 1.3041677
G14: lot 2 | H14: Pierre | I14: pièce 10 | J14: =1+RAND() -> 1.5741422 | K14: =AVERAGE(J14:J16) -> 1.5017424
I15: pièce 11 | J15: =1+RAND() -> 1.3042364
I16: pièce 12 | J16: =1+RAND() -> 1.6268486
H17: Paul | I17: pièce 13 | J17: =1+RAND() -> 1.6222145 | K17: =AVERAGE(J17:J19) -> 1.4025039
I18: pièce 14 | J18: =1+RAND() -> 1.5742016
I19: pièce 15 | J19: =1+RAND() -> 1.0110956
H20: Marie | I20: pièce 16 | J20: =1+RAND() -> 1.7814293 | K20: =AVERAGE(J20:J22) -> 1.5161467
I21: pièce 17 | J21: =1+RAND() -> 1.5312156
I22: pièce 18 | J22: =1+RAND() -> 1.2357953
G23: lot 3 | H23: Pierre | I23: pièce 19 | J23: =1+RAND() -> 1.0454798 | K23: =AVERAGE(J23:J25) -> 1.489363
I24: pièce 20 | J24: =1+RAND() -> 1.9897031
I25: pièce 21 | J25: =1+RAND() -> 1.432906
H26: Paul | I26: pièce 22 | J26: =1+RAND() -> 1.0587915 | K26: =AVERAGE(J26:J28) -> 1.3360582
I27: pièce 23 | J27: =1+RAND() -> 1.1793298
I28: pièce 24 | J28: =1+RAND() -> 1.7700532
H29: Marie | I29: pièce 25 | J29: =1+RAND() -> 1.7320689 | K29: =AVERAGE(J29:J31) -> 1.3179295
I30: pièce 26 | J30: =1+RAND() -> 1.0758348
I31: pièce 27 | J31: =1+RAND() -> 1.1458848
T33: -3 | U33: =M$7+T33*SQRT(M$8) -> 0.53729602 | V33: =NORMDIST(U33,M$7,SQRT(M$8),0) -> 0.014464018
T34: -2.9 | U34: =M$7+T34*SQRT(M$8) -> 0.56793653 | V34: =NORMDIST(U34,M$7,SQRT(M$8),0) -> 0.019427004
T35: -2.8 | U35: =M$7+T35*SQRT(M$8) -> 0.59857703 | V35: =NORMDIST(U35,M$7,SQRT(M$8),0) -> 0.025833292
T36: -2.7 | U36: =M$7+T36*SQRT(M$8) -> 0.62921754 | V36: =NORMDIST(U36,M$7,SQRT(M$8),0) -> 0.034010321
T37: -2.6 | U37: =M$7+T37*SQRT(M$8) -> 0.65985805 | V37: =NORMDIST(U37,M$7,SQRT(M$8),0) -> 0.044330106
T38: -2.5 | U38: =M$7+T38*SQRT(M$8) -> 0.69049855 | V38: =NORMDIST(U38,M$7,SQRT(M$8),0) -> 0.057206301
T39: -2.4 | U39: =M$7+T39*SQRT(M$8) -> 0.72113906 | V39: =NORMDIST(U39,M$7,SQRT(M$8),0) -> 0.073087989
T40: -2.3 | U40: =M$7+T40*SQRT(M$8) -> 0.75177957 | V40: =NORMDIST(U40,M$7,SQRT(M$8),0) -> 0.092449639
T41: -2.2 | U41: =M$7+T41*SQRT(M$8) -> 0.78242007 | V41: =NORMDIST(U41,M$7,SQRT(M$8),0) -> 0.11577678
T42: -2.1 | U42: =M$7+T42*SQRT(M$8) -> 0.81306058 | V42: =NORMDIST(U42,M$7,SQRT(M$8),0) -> 0.14354722
T43: -2 | U43: =M$7+T43*SQRT(M$8) -> 0.84370109 | V43: =NORMDIST(U43,M$7,SQRT(M$8),0) -> 0.17620781
...

Sheet Récapitulatif
B1: Profil d'exactitude
B2: Probabilité tolérance (bêta) | C2: =#REF! -> #REF! | E2: 20 | F2: 100
B3: Limite d'acceptabilité | C3: =#REF! -> #REF! | E3: 0.01 | F3: =E3*F2/E2 -> 0.05
B5: Niveaux | C5: Niveau A | D5: Niveau B | E5: Niveau C | F5: Niveau D | G5: Niveau E
A6: 2 | B6: Valeur cible | C6: ='80%'!B2 -> 80 | D6: ='90%'!B2 -> 90 | E6: ='100%'!B2 -> 100 | F6: ='110%'!B2 -> 110 | G6: ='120%'!B2 -> 120
A7: 30 | B7: Moyenne niveau | C7: ='80%'!B22 -> #REF! | D7: ='90%'!B22 -> #REF! | E7: ='100%'!B22 -> #REF! | F7: ='110%'!B22 -> #REF! | G7: ='120%'!B22 -> #REF! | K7: =ADDRESS($A8,2,,,C$5) -> 'Niveau A'!$B$31
A8: 31 | B8: Ecart-type de répétabilité (sr) | C8: ='80%'!B23 -> #DIV/0! | D8: ='90%'!B23 -> #DIV/0! | E8: ='100%'!B23 -> #DIV/0! | F8: ='110%'!B23 -> #DIV/0! | G8: ='120%'!B23 -> #DIV/0!
A9: 32 | B9: Ecart-type inter-séries (sL) | C9: ='80%'!B24 -> #REF! | D9: ='90%'!B24 -> #REF! | E9: ='100%'!B24 -> #REF! | F9: ='110%'!B24 -> #REF! | G9: ='120%'!B24 -> #REF!
A10: 33 | B10: Ecart-type de fidélité (sFI) | C10: ='80%'!B25 -> #DIV/0! | D10: ='90%'!B25 -> #DIV/0! | E10: ='100%'!B25 -> #DIV/0! | F10: ='110%'!B25 -> #DIV/0! | G10: ='120%'!B25 -> #DIV/0!
A11: 37 | B11: Rapport des variances (R) | C11: ='80%'!B29 -> #REF! | D11: ='90%'!B29 -> #REF! | E11: ='100%'!B29 -> #REF! | F11: ='110%'!B29 -> #REF! | G11: ='120%'!B29 -> #REF!
A12: 39 | B12: Coefficient intermédiaire | C12: ='80%'!B31 -> #REF! | D12: ='90%'!B31 -> #REF! | E12: ='100%'!B31 -> #REF! | F12: ='110%'!B31 -> #REF! | G12: ='120%'!B31 -> #REF!
A13: 40 | B13: Nombre de degrés liberté | C13: ='80%'!B32 -> #REF! | D13: ='90%'!B32 -> #REF! | E13: ='100%'!B32 -> #REF! | F13: ='110%'!B32 -> #REF! | G13: ='120%'!B32 -> #REF!
A14: 47 | B14: Valeur basse tolérance | C14: ='80%'!B39 -> #REF! | D14: ='90%'!B39 -> #REF! | E14: ='100%'!B39 -> #REF! | F14: ='110%'!B39 -> #REF! | G14: ='120%'!B39 -> #REF!
A15: 48 | B15: Valeur haute tolérance | C15: ='80%'!B40 -> #REF! | D15: ='90%'!B40 -> #REF! | E15: ='100%'!B40 -> #REF! | F15: ='110%'!B40 -> #REF! | G15: ='120%'!B40 -> #REF!
A16: 35 | B16: Biais (%) | C16: ='80%'!B27 -> #REF! | D16: ='90%'!B27 -> #REF! | E16: ='100%'!B27 -> #REF! | F16: ='110%'!B27 -> #REF! | G16: ='120%'!B27 -> #REF!
B17: Recouvrement (justesse) | C17: =C7/C$6 -> #REF! | D17: =D7/D$6 -> #REF! | E17: =E7/E$6 -> #REF! | F17: =F7/F$6 -> #REF! | G17: =G7/G$6 -> #REF!
B18: Limite basse tolérance (%) | C18: =C14/C$6 -> #REF! | D18: =D14/D$6 -> #REF! | E18: =E14/E$6 -> #REF! | F18: =F14/F$6 -> #REF! | G18: =G14/G$6 -> #REF!
B19: Limite haute tolérance (%) | C19: =C15/C$6 -> #REF! | D19: =D15/D$6 -> #REF! | E19: =E15/E$6 -> #REF! | F19: =F15/F$6 -> #REF! | G19: =G15/G$6 -> #REF!
B20: Limite d'acceptabilité basse | C20: =1-$C$3 -> #REF! | D20: =1-$C$3 -> #REF! | E20: =1-$C$3 -> #REF! | F20: =1-$C$3 -> #REF! | G20: =1-$C$3 -> #REF!
B21: Limite d'acceptabilité haute | C21: =1+$C$3 -> #REF! | D21: =1+$C$3 -> #REF! | E21: =1+$C$3 -> #REF! | F21: =1+$C$3 -> #REF! | G21: =1+$C$3 -> #REF!
B27: Incertitude
B28: Ecart-type de l'IT (sIT) | C28: =C$12*C$10 -> #REF! | D28: =D$12*D$10 -> #REF! | E28: =E$12*E$10 -> #REF! | F28: =F$12*F$10 -> #REF! | G28: =G$12*G$10 -> #REF!
B29: Incertitude élargie relative | C29: =2*C28/C7 -> #REF! | D29: =2*D28/D7 -> #REF! | E29: =2*E28/E7 -> #REF! | F29: =2*F28/F7 -> #REF! | G29: =2*G28/G7 -> #REF!

Sheet 80%
A1: Niveau A
A2: Valeur cible | B2: 80
B4: Répétition 1 | C4: Répétition 2 | D4: Répétition 3 | E4: Répétition 4 | F4: Répétition 5 | H4: nk | I4: SCEk
A5: Jour (Série) 1 | B5: =#REF!*$B$2 -> #REF! | C5: =#REF!*$B$2 -> #REF! | H5: =COUNT(B5:F5) -> 0 | I5: =IF(H5=0,"",DEVSQ(B5:F5))
A6: Jour (Série) 2
A7: Jour (Série) 3 | B7: =#REF!*$B$2 -> #REF! | C7: =#REF!*$B$2 -> #REF! | H7: =COUNT(B7:F7) -> 0 | I7: =IF(H7=0,"",DEVSQ(B7:F7))
A8: Jour (Série) 4 | B8: =#REF!*$B$2 -> #REF! | C8: =#REF!*$B$2 -> #REF! | H8: =COUNT(B8:F8) -> 0 | I8: =IF(H8=0,"",DEVSQ(B8:F8))
A9: Jour (Série) 5 | B9: =#REF!*$B$2 -> #REF! | C9: =#REF!*$B$2 -> #REF! | H9: =COUNT(B9:F9) -> 0 | I9: =IF(H9=0,"",DEVSQ(B9:F9))
A11: Nombre de séries (K) | B11: =COUNT(B5:B9) -> 0
A12: Nombre de mesures (IK) | B12: =COUNT(B5:F9) -> 0
A13: Nombre de répétitions (I) | B13: =IF(H5*B11<>B12,"Calcul impossible",H5) -> 0
A14: SCE résiduelle | B14: =SUM(I5:I9) -> 0
A15: SCE totale | B15: =DEVSQ(B5:F9) -> #REF!
A16: SCE inter-séries | B16: =B15-B14 -> #REF!
A17: Valeur intermédiaire de s²L | B17: =((B16/(B11-1))-B18)/B13 -> #REF!
A18: Variance de répétabilité (s²r) | B18: =B14/(B12-B11) -> #DIV/0!
A19: Variance inter-séries (s²L) | B19: =IF(B17<0,0,B17) -> #REF!
A20: Variance de fidélité (s²FI) | B20: =SUM(B18:B19) -> #DIV/0!
A21: Fidélité
A22: Moyenne niveau | B22: =AVERAGE(B5:F9) -> #REF!
A23: Ecart-type de répétabilité (sr) | B23: =SQRT(B18) -> #DIV/0!
A24: Ecart-type inter-séries (sL) | B24: =SQRT(B19) -> #REF!
A25: Ecart-type de fidélité (sFI) | B25: =SQRT(B20) -> #DIV/0!
A26: Justesse
A27: Biais (%) | B27: =B22/B2-1 -> #REF!
A28: Facteur de couverture
A29: Rapport des variances (R) | B29: =B19/B18 -> #REF!
A30: Coefficient B² | B30: =(B29+1)/(B13*B29+1) -> #REF!
A31: Coefficient intermédiaire | B31: =SQRT(1+1/(B12*B30)) -> #REF!
A32: Nombre de degrés liberté | B32: =(B29+1)^2/((B29+1/B13)^2/(B11-1)+(1-1/B13)/B12) -> #REF!
A33: Probabilité tolérance (bêta) | B33: =Récapitulatif!C2 -> #REF!
A34: t Student bas | B34: =TINV(1-B33,ROUNDDOWN(B32,0)) -> #REF!
A35: t Student haut | B35: =TINV(1-B33,ROUNDUP(B32,0)) -> #REF!
A36: t Student interpolé | B36: =B34-(B34-B35)*(B32-ROUNDDOWN(B32,0)) -> #REF!
A37: Facteur de couverture (ktol) | B37: =B36*B31 -> #REF!
A38: Intervalle de tolérance
A39: Valeur basse tolérance | B39: =B22-B37*B25 -> #REF!
A40: Valeur haute tolérance | B40: =B22+B37*B25 -> #REF!

Sheet 90%
A1: Niveau B
A2: Valeur cible | B2: 90
B4: Répétition 1 | C4: Répétition 2 | D4: Répétition 3 | E4: Répétition 4 | F4: Répétition 5 | H4: nk | I4: SCEk
A5: Jour (Série) 1 | B5: =#REF!*$B$2 -> #REF! | C5: =#REF!*$B$2 -> #REF! | H5: =COUNT(B5:F5) -> 0 | I5: =IF(H5=0,"",DEVSQ(B5:F5))
A6: Jour (Série) 2 | B6: =#REF!*$B$2 -> #REF! | C6: =#REF!*$B$2 -> #REF! | H6: =COUNT(B6:F6) -> 0 | I6: =IF(H6=0,"",DEVSQ(B6:F6))
A7: Jour (Série) 3 | I7: =IF(H7=0,"",DEVSQ(B7:F7))
A8: Jour (Série) 4 | B8: =#REF!*$B$2 -> #REF! | C8: =#REF!*$B$2 -> #REF! | H8: =COUNT(B8:F8) -> 0 | I8: =IF(H8=0,"",DEVSQ(B8:F8))
A9: Jour (Série) 5 | B9: =#REF!*$B$2 -> #REF! | C9: =#REF!*$B$2 -> #REF! | H9: =COUNT(B9:F9) -> 0 | I9: =IF(H9=0,"",DEVSQ(B9:F9))
A11: Nombre de séries (K) | B11: =COUNT(B5:B9) -> 0
A12: Nombre de mesures (IK) | B12: =COUNT(B5:F9) -> 0
A13: Nombre de répétitions (I) | B13: =IF(H5*B11<>B12,"Calcul impossible",H5) -> 0
A14: SCE résiduelle | B14: =SUM(I5:I9) -> 0
A15: SCE totale | B15: =DEVSQ(B5:F9) -> #REF!
A16: SCE inter-séries | B16: =B15-B14 -> #REF!
A17: Valeur intermédiaire de s²L | B17: =((B16/(B11-1))-B18)/B13 -> #REF!
A18: Variance de répétabilité (s²r) | B18: =B14/(B12-B11) -> #DIV/0!
A19: Variance inter-séries (s²L) | B19: =IF(B17<0,0,B17) -> #REF!
A20: Variance de fidélité (s²FI) | B20: =SUM(B18:B19) -> #DIV/0!
A21: Fidélité
A22: Moyenne niveau | B22: =AVERAGE(B5:F9) -> #REF!
A23: Ecart-type de répétabilité (sr) | B23: =SQRT(B18) -> #DIV/0!
A24: Ecart-type inter-séries (sL) | B24: =SQRT(B19) -> #REF!
A25: Ecart-type de fidélité (sFI) | B25: =SQRT(B20) -> #DIV/0!
A26: Justesse
A27: Biais (%) | B27: =B22/B2-1 -> #REF!
A28: Facteur de couverture
A29: Rapport des variances (R) | B29: =B19/B18 -> #REF!
A30: Coefficient B² | B30: =(B29+1)/(B13*B29+1) -> #REF!
A31: Coefficient intermédiaire | B31: =SQRT(1+1/(B12*B30)) -> #REF!
A32: Nombre de degrés liberté | B32: =(B29+1)^2/((B29+1/B13)^2/(B11-1)+(1-1/B13)/B12) -> #REF!
A33: Probabilité tolérance (bêta) | B33: =Récapitulatif!C2 -> #REF!
A34: t Student bas | B34: =TINV(1-B33,ROUNDDOWN(B32,0)) -> #REF!
A35: t Student haut | B35: =TINV(1-B33,ROUNDUP(B32,0)) -> #REF!
A36: t Student interpolé | B36: =B34-(B34-B35)*(B32-ROUNDDOWN(B32,0)) -> #REF!
A37: Facteur de couverture (ktol) | B37: =B36*B31 -> #REF!
A38: Intervalle de tolérance
A39: Valeur basse tolérance | B39: =B22-B37*B25 -> #REF!
A40: Valeur haute tolérance | B40: =B22+B37*B25 -> #REF!

Sheet 100%
A1: Niveau C
A2: Valeur cible | B2: 100
B4: Répétition 1 | C4: Répétition 2 | D4: Répétition 3 | E4: Répétition 4 | F4: Répétition 5 | H4: nk | I4: SCEk
A5: Jour (Série) 1 | B5: =#REF!*$B$2 -> #REF! | C5: =#REF!*$B$2 -> #REF! | H5: =COUNT(B5:F5) -> 0 | I5: =IF(H5=0,"",DEVSQ(B5:F5))
A6: Jour (Série) 2 | B6: =#REF!*$B$2 -> #REF! | C6: =#REF!*$B$2 -> #REF! | H6: =COUNT(B6:F6) -> 0 | I6: =IF(H6=0,"",DEVSQ(B6:F6))
A7: Jour (Série) 3 | B7: =#REF!*$B$2 -> #REF! | C7: =#REF!*$B$2 -> #REF! | H7: =COUNT(B7:F7) -> 0 | I7: =IF(H7=0,"",DEVSQ(B7:F7))
A8: Jour (Série) 4 | I8: =IF(H8=0,"",DEVSQ(B8:F8))
A9: Jour (Série) 5 | B9: =#REF!*$B$2 -> #REF! | C9: =#REF!*$B$2 -> #REF! | H9: =COUNT(B9:F9) -> 0 | I9: =IF(H9=0,"",DEVSQ(B9:F9))
A11: Nombre de séries (K) | B11: =COUNT(B5:B9) -> 0
A12: Nombre de mesures (IK) | B12: =COUNT(B5:F9) -> 0
A13: Nombre de répétitions (I) | B13: =IF(H5*B11<>B12,"Calcul impossible",H5) -> 0
A14: SCE résiduelle | B14: =SUM(I5:I9) -> 0
A15: SCE totale | B15: =DEVSQ(B5:F9) -> #REF!
A16: SCE inter-séries | B16: =B15-B14 -> #REF!
A17: Valeur intermédiaire de s²L | B17: =((B16/(B11-1))-B18)/B13 -> #REF!
A18: Variance de répétabilité (s²r) | B18: =B14/(B12-B11) -> #DIV/0!
A19: Variance inter-séries (s²L) | B19: =IF(B17<0,0,B17) -> #REF!
A20: Variance de fidélité (s²FI) | B20: =SUM(B18:B19) -> #DIV/0!
A21: Fidélité
A22: Moyenne niveau | B22: =AVERAGE(B5:F9) -> #REF!
A23: Ecart-type de répétabilité (sr) | B23: =SQRT(B18) -> #DIV/0!
A24: Ecart-type inter-séries (sL) | B24: =SQRT(B19) -> #REF!
A25: Ecart-type de fidélité (sFI) | B25: =SQRT(B20) -> #DIV/0!
A26: Justesse
A27: Biais (%) | B27: =B22/B2-1 -> #REF!
A28: Facteur de couverture
A29: Rapport des variances (R) | B29: =B19/B18 -> #REF!
A30: Coefficient B² | B30: =(B29+1)/(B13*B29+1) -> #REF!
A31: Coefficient intermédiaire | B31: =SQRT(1+1/(B12*B30)) -> #REF!
A32: Nombre de degrés liberté | B32: =(B29+1)^2/((B29+1/B13)^2/(B11-1)+(1-1/B13)/B12) -> #REF!
A33: Probabilité tolérance (bêta) | B33: =Récapitulatif!C2 -> #REF!
A34: t Student bas | B34: =TINV(1-B33,ROUNDDOWN(B32,0)) -> #REF!
A35: t Student haut | B35: =TINV(1-B33,ROUNDUP(B32,0)) -> #REF!
A36: t Student interpolé | B36: =B34-(B34-B35)*(B32-ROUNDDOWN(B32,0)) -> #REF!
A37: Facteur de couverture (ktol) | B37: =B36*B31 -> #REF!
A38: Intervalle de tolérance
A39: Valeur basse tolérance | B39: =B22-B37*B25 -> #REF!
A40: Valeur haute tolérance | B40: =B22+B37*B25 -> #REF!

Sheet 110%
A1: Niveau D
A2: Valeur cible | B2: 110
B4: Répétition 1 | C4: Répétition 2 | D4: Répétition 3 | E4: Répétition 4 | F4: Répétition 5 | H4: nk | I4: SCEk
A5: Jour (Série) 1 | B5: =#REF!*$B$2 -> #REF! | C5: =#REF!*$B$2 -> #REF! | H5: =COUNT(B5:F5) -> 0 | I5: =IF(H5=0,"",DEVSQ(B5:F5))
A6: Jour (Série) 2 | B6: =#REF!*$B$2 -> #REF! | C6: =#REF!*$B$2 -> #REF! | H6: =COUNT(B6:F6) -> 0 | I6: =IF(H6=0,"",DEVSQ(B6:F6))
A7: Jour (Série) 3 | B7: =#REF!*$B$2 -> #REF! | C7: =#REF!*$B$2 -> #REF! | H7: =COUNT(B7:F7) -> 0 | I7: =IF(H7=0,"",DEVSQ(B7:F7))
A8: Jour (Série) 4 | B8: =#REF!*$B$2 -> #REF! | C8: =#REF!*$B$2 -> #REF! | H8: =COUNT(B8:F8) -> 0 | I8: =IF(H8=0,"",DEVSQ(B8:F8))
A9: Jour (Série) 5 | I9: =IF(H9=0,"",DEVSQ(B9:F9))
A11: Nombre de séries (K) | B11: =COUNT(B5:B9) -> 0
A12: Nombre de mesures (IK) | B12: =COUNT(B5:F9) -> 0
A13: Nombre de répétitions (I) | B13: =IF(H5*B11<>B12,"Calcul impossible",H5) -> 0
A14: SCE résiduelle | B14: =SUM(I5:I9) -> 0
A15: SCE totale | B15: =DEVSQ(B5:F9) -> #REF!
A16: SCE inter-séries | B16: =B15-B14 -> #REF!
A17: Valeur intermédiaire de s²L | B17: =((B16/(B11-1))-B18)/B13 -> #REF!
A18: Variance de répétabilité (s²r) | B18: =B14/(B12-B11) -> #DIV/0!
A19: Variance inter-séries (s²L) | B19: =IF(B17<0,0,B17) -> #REF!
A20: Variance de fidélité (s²FI) | B20: =SUM(B18:B19) -> #DIV/0!
A21: Fidélité
A22: Moyenne niveau | B22: =AVERAGE(B5:F9) -> #REF!
A23: Ecart-type de répétabilité (sr) | B23: =SQRT(B18) -> #DIV/0!
A24: Ecart-type inter-séries (sL) | B24: =SQRT(B19) -> #REF!
A25: Ecart-type de fidélité (sFI) | B25: =SQRT(B20) -> #DIV/0!
A26: Justesse
A27: Biais (%) | B27: =B22/B2-1 -> #REF!
A28: Facteur de couverture
A29: Rapport des variances (R) | B29: =B19/B18 -> #REF!
A30: Coefficient B² | B30: =(B29+1)/(B13*B29+1) -> #REF!
A31: Coefficient intermédiaire | B31: =SQRT(1+1/(B12*B30)) -> #REF!
A32: Nombre de degrés liberté | B32: =(B29+1)^2/((B29+1/B13)^2/(B11-1)+(1-1/B13)/B12) -> #REF!
A33: Probabilité tolérance (bêta) | B33: =Récapitulatif!C2 -> #REF!
A34: t Student bas | B34: =TINV(1-B33,ROUNDDOWN(B32,0)) -> #REF!
A35: t Student haut | B35: =TINV(1-B33,ROUNDUP(B32,0)) -> #REF!
A36: t Student interpolé | B36: =B34-(B34-B35)*(B32-ROUNDDOWN(B32,0)) -> #REF!
A37: Facteur de couverture (ktol) | B37: =B36*B31 -> #REF!
A38: Intervalle de tolérance
A39: Valeur basse tolérance | B39: =B22-B37*B25 -> #REF!
A40: Valeur haute tolérance | B40: =B22+B37*B25 -> #REF!

Sheet 120%
A1: Niveau E
A2: Valeur cible | B2: 120
B4: Répétition 1 | C4: Répétition 2 | D4: Répétition 3 | E4: Répétition 4 | F4: Répétition 5 | H4: nk | I4: SCEk
A5: Jour (Série) 1
A6: Jour (Série) 2 | B6: =#REF!*$B$2 -> #REF! | C6: =#REF!*$B$2 -> #REF! | H6: =COUNT(B6:F6) -> 0 | I6: =IF(H6=0,"",DEVSQ(B6:F6))
A7: Jour (Série) 3 | B7: =#REF!*$B$2 -> #REF! | C7: =#REF!*$B$2 -> #REF! | H7: =COUNT(B7:F7) -> 0 | I7: =IF(H7=0,"",DEVSQ(B7:F7))
A8: Jour (Série) 4 | B8: =#REF!*$B$2 -> #REF! | C8: =#REF!*$B$2 -> #REF! | H8: =COUNT(B8:F8) -> 0 | I8: =IF(H8=0,"",DEVSQ(B8:F8))
A9: Jour (Série) 5 | B9: =#REF!*$B$2 -> #REF! | C9: =#REF!*$B$2 -> #REF! | H9: =COUNT(B9:F9) -> 0 | I9: =IF(H9=0,"",DEVSQ(B9:F9))
A11: Nombre de séries (K) | B11: =COUNT(B5:B9) -> 0
A12: Nombre de mesures (IK) | B12: =COUNT(B5:F9) -> 0
A13: Nombre de répétitions (I) | B13: =IF(H6*B11<>B12,"Calcul impossible",H6) -> 0
A14: SCE résiduelle | B14: =SUM(I5:I9) -> 0
A15: SCE totale | B15: =DEVSQ(B5:F9) -> #REF!
A16: SCE inter-séries | B16: =B15-B14 -> #REF!
A17: Valeur intermédiaire de s²L | B17: =((B16/(B11-1))-B18)/B13 -> #REF!
A18: Variance de répétabilité (s²r) | B18: =B14/(B12-B11) -> #DIV/0!
A19: Variance inter-séries (s²L) | B19: =IF(B17<0,0,B17) -> #REF!
A20: Variance de fidélité (s²FI) | B20: =SUM(B18:B19) -> #DIV/0!
A21: Fidélité
A22: Moyenne niveau | B22: =AVERAGE(B5:F9) -> #REF!
A23: Ecart-type de répétabilité (sr) | B23: =SQRT(B18) -> #DIV/0!
A24: Ecart-type inter-séries (sL) | B24: =SQRT(B19) -> #REF!
A25: Ecart-type de fidélité (sFI) | B25: =SQRT(B20) -> #DIV/0!
A26: Justesse
A27: Biais (%) | B27: =B22/B2-1 -> #REF!
A28: Facteur de couverture
A29: Rapport des variances (R) | B29: =B19/B18 -> #REF!
A30: Coefficient B² | B30: =(B29+1)/(B13*B29+1) -> #REF!
A31: Coefficient intermédiaire | B31: =SQRT(1+1/(B12*B30)) -> #REF!
A32: Nombre de degrés liberté | B32: =(B29+1)^2/((B29+1/B13)^2/(B11-1)+(1-1/B13)/B12) -> #REF!
A33: Probabilité tolérance (bêta) | B33: =Récapitulatif!C2 -> #REF!
A34: t Student bas | B34: =TINV(1-B33,ROUNDDOWN(B32,0)) -> #REF!
A35: t Student haut | B35: =TINV(1-B33,ROUNDUP(B32,0)) -> #REF!
A36: t Student interpolé | B36: =B34-(B34-B35)*(B32-ROUNDDOWN(B32,0)) -> #REF!
A37: Facteur de couverture (ktol) | B37: =B36*B31 -> #REF!
A38: Intervalle de tolérance
A39: Valeur basse tolérance | B39: =B22-B37*B25 -> #REF!
A40: Valeur haute tolérance | B40: =B22+B37*B25 -> #REF!
