Workbook
Name ANALYTES: #REF!

Sheet Gage R&R destructif
C3: Facteur qualitatif | G3: plan d'expériences emboité | L3: =SUM(H3:K3) -> 0 | M3: =SUM(I3:L3) -> 0
C4: X | D4: lot | E4: 3 | G4: X | H4: Y | I4: Z | J4: r1 | L4: Tolérance - | M4: 0 | N4: =M4 -> 0 | O4: 0 | P4: =R63 -> 0 | Q4: 0 | R4: =V63 -> 1.3258636
C5: Y | D5: opérateur | E5: 3 | G5: lot 1 | H5: Pierre | I5: pièce 1 | J5: =RAND() -> 0.10138731 | K5: =AVERAGE(J5:J7) -> 0.29761241 | L5: Tolérance + | M5: 1 | N5: =M5 -> 1 | O5: 0 | P5: =P4 -> 0 | Q5: 0 | R5: =R4 -> 1.3258636
C6: Z | D6: pièce | E6: 3 | I6: pièce 2 | J6: =RAND() -> 0.061922942
I7: pièce 3 | J7: =RAND() -> 0.72952696 | L7: moyenne | M7: =AVERAGE(J5:J31) -> 0.44757072
C8: Lorsque le plan est emboité, on évalue | H8: Paul | I8: pièce 4 | J8: =RAND() -> 0.12092229 | K8: =AVERAGE(J8:J10) -> 0.11880223 | L8: S² totale | M8: =I53 -> 0.090536237
C9: les variances intermédiaires de fidélité. | I9: pièce 5 | J9: =RAND() -> 0.15376142 | L9: S totale | M9: =SQRT(M8) -> 0.3008924
I10: pièce 6 | J10: =RAND() -> 0.081722975 | L10: Min | M10: =MIN(J5:J31) -> 0.061922942
C11: les facteurs opérateur et lot sont croisés | H11: Marie | I11: pièce 7 | J11: =RAND() -> 0.17094453 | K11: =AVERAGE(J11:J13) -> 0.40257421 | L11: Max | M11: =MAX(J5:J31) -> 0.99538532
C12: le facteur pièce est lui emboité dans Op/lot | I12: pièce 8 | J12: =RAND() -> 0.20523691
I13: pièce 9 | J13: =RAND() -> 0.8315412
G14: lot 2 | H14: Pierre | I14: pièce 10 | J14: =RAND() -> 0.16717711 | K14: =AVERAGE(J14:J16) -> 0.36674374
I15: pièce 11 | J15: =RAND() -> 0.32900246
I16: pièce 12 | J16: =RAND() -> 0.60405166
H17: Paul | I17: pièce 13 | J17: =RAND() -> 0.68934145 | K17: =AVERAGE(J17:J19) -> 0.72565542
I18: pièce 14 | J18: =RAND() -> 0.60169649
I19: pièce 15 | J19: =RAND() -> 0.88592832
H20: Marie | I20: pièce 16 | J20: =RAND() -> 0.096937126 | K20: =AVERAGE(J20:J22) -> 0.41864249
I21: pièce 17 | J21: =RAND() -> 0.49942719
I22: pièce 18 | J22: =RAND() -> 0.65956316
G23: lot 3 | H23: Pierre | I23: pièce 19 | J23: =RAND() -> 0.75236945 | K23: =AVERAGE(J23:J25) -> 0.5460679
I24: pièce 20 | J24: =RAND() -> 0.80164834
I25: pièce 21 | J25: =RAND() -> 0.084185928
H26: Paul | I26: pièce 22 | J26: =RAND() -> 0.77356565 | K26: =AVERAGE(J26:J28) -> 0.79994525
I27: pièce 23 | J27: =RAND() -> 0.63088478
I28: pièce 24 | J28: =RAND() -> 0.99538532
H29: Marie | I29: pièce 25 | J29: =RAND() -> 0.28311251 | K29: =AVERAGE(J29:J31) -> 0.35209286
I30: pièce 26 | J30: =RAND() -> 0.31788876
I31: pièce 27 | J31: =RAND() -> 0.4552773
T33: -3 | U33: =M$7+T33*SQRT(M$8) -> -0.45510648 | V33: =NORMDIST(U33,M$7,SQRT(M$8),0) -> 0.014729014
T34: -2.9 | U34: =M$7+T34*SQRT(M$8) -> -0.42501724 | V34: =NORMDIST(U34,M$7,SQRT(M$8),0) -> 0.019782927
T35: -2.8 | U35: =M$7+T35*SQRT(M$8) -> -0.394928 | V35: =NORMDIST(U35,M$7,SQRT(M$8),0) -> 0.026306585
T36: -2.7 | U36: =M$7+T36*SQRT(M$8) -> -0.36483876 | V36: =NORMDIST(U36,M$7,SQRT(M$8),0) -> 0.034633426
T37: -2.6 | U37: =M$7+T37*SQRT(M$8) -> -0.33474952 | V37: =NORMDIST(U37,M$7,SQRT(M$8),0) -> 0.045142281
T38: -2.5 | U38: =M$7+T38*SQRT(M$8) -> -0.30466028 | V38: =NORMDIST(U38,M$7,SQRT(M$8),0) -> 0.058254381
T39: -2.4 | U39: =M$7+T39*SQRT(M$8) -> -0.27457104 | V39: =NORMDIST(U39,M$7,SQRT(M$8),0) -> 0.074427039
T40: -2.3 | U40: =M$7+T40*SQRT(M$8) -> -0.2444818 | V40: =NORMDIST(U40,M$7,SQRT(M$8),0) -> 0.094143414
T41: -2.2 | U41: =M$7+T41*SQRT(M$8) -> -0.21439256 | V41: =NORMDIST(U41,M$7,SQRT(M$8),0) -> 0.11789794
T42: -2.1 | U42: =M$7+T42*SQRT(M$8) -> -0.18430332 | V42: =NORMDIST(U42,M$7,SQRT(M$8),0) -> 0.14617716
T43: -2 | U43: =M$7+T43*SQRT(M$8) -> -0.15421408 | V43: =NORMDIST(U43,M$7,SQRT(M$8),0) -> 0.17943613
...

Sheet Récapitulatif
B1: Profil d'exactitude
B2: Probabilité tolérance (bêta) | C2: =#REF! -> #REF! | E2: 20 | F2: 100
B3: Limite d'acceptabilité | C3: =#REF! -> #REF! | E3: 0.01 | F3: =E3*F2/E2 -> 0.05
B5: Niveaux | C5: Niveau A | D5: Niveau B | E5: Niveau C | F5: Niveau D | G5: Niveau E
A6: 2 | B6: Valeur cible | C6: ='80%'!B2 -> 80 | D6: ='90%'!B2 -> 90 | E6: ='100%'!B2 -> 100 | F6: ='110%'!B2 -> 110 | G6: ='120%'!B2 -> 120
A7: 30 | B7: Moyenne niveau | C7: ='80%'!B22 -> #REF! | D7: ='90%'!B22 -> #REF! | E7: ='100%'!B22 -> #REF! | F7: ='110%'!B22 -> #REF! | G7: ='120%'!B22 -> #REF! | K7: =ADDRESS($A8,2,,,C$5) -> 'Niveau A'!$B$31
A8: 31 | B8: Ecart-type de répétabilité (sr) | C8: ='80%'!B23 -> #DIV/0! | D8: ='90%'!B23 -> #DIV/0! | E8: ='100%'!B23 -> #DIV/0! | F8: ='110%'!B23 -> #DIV/0! | G8: ='120%'!B23 -> #DIV/0!
A9: 32 | B9: Ecart-type inter-séries (sL) | C9: ='80%'!B24 -> #REF! | D9: ='90%'!B24 -> #REF! | E9: ='100%'!B24 -> #REF! | F9: ='110%'!B24 -> #REF! | G9: ='120%'!B24 -> #REF!
A10: 33 | B10: Ecart-type de fidélité (sFI) | C10: ='80%'!B25 -> #DIV/0! | D10: ='90%'!B25 -> #DIV/0! | E10: ='100%'!B25 -> #DIV/0! | F10: ='110%'!B25 -> #DIV/0! | G10: ='120%'!B25 -> #DIV/0!
A11: 37 | B11: Rapport des variances (R) | C11: ='80%'!B29 -> #REF! | D11: ='90%'!B29 -> #REF! | E11: ='100%'!B29 -> #REF! | F11: ='110%'!B29 -> #REF! | G11: ='120%'!B29 -> #REF!
A12: 39 | B12: Coefficient intermédiaire | C12: ='80%'!B31 -> #REF! | D12: ='90%'!B31 -> #REF! | E12: ='100%'!B31 -> #REF! | F12: ='110%'!B31 -> #REF! | G12: ='120%'!B31 -> #REF!
A13: 40 | B13: Nombre de degrés liberté | C13: ='80%'!B32 -> #REF! | D13: ='90%'!B32 -> #REF! | E13: ='100%'!B32 -> #REF! | F13: ='110%'!B32 -> #REF! | G13: ='120%'!B32 -> #REF!
A14: 47 | B14: Valeur basse tolérance | C14: ='80%'!B39 -> #REF! | D14: ='90%'!B39 -> #REF! | E14: ='100%'!B39 -> #REF! | F14: ='110%'!B39 -> #REF! | G14: ='120%'!B39 -> #REF!
A15: 48 | B15: Valeur haute tolérance | C15: ='80%'!B40 -> #REF! | D15: ='90%'!B40 -> #REF! | E15: ='100%'!B40 -> #REF! | F15: ='110%'!B40 -> #REF! | G15: ='120%'!B40 -> #REF!
A16: 35 | B16: Biais (%) | C16: ='80%'!B27 -> #REF! | D16: ='90%'!B27 -> #REF! | E16: ='100%'!B27 -> #REF! | F16: ='110%'!B27 -> #REF! | G16: ='120%'!B27 -> #REF!
B17: Recouvrement (justesse) | C17: =C7/C$6 -> #REF! | D17: =D7/D$6 -> #REF! | E17: =E7/E$6 -> #REF! | F17: =F7/F$6 -> #REF! | G17: =G7/G$6 -> #REF!
B18: Limite basse tolérance (%) | C18: =C14/C$6 -> #REF! | D18: =D14/D$6 -> #REF! | E18: =E14/E$6 -> #REF! | F18: =F14/F$6 -> #REF! | G18: =G14/G$6 -> #REF!
B19: Limite haute tolérance (%) | C19: =C15/C$6 -> #REF! | D19: =D15/D$6 -> #REF! | E19: =E15/E$6 -> #REF! | F19: =F15/F$6 -> #REF! | G19: =G15/G$6 -> #REF!
B20: Limite d'acceptabilité basse | C20: =1-$C$3 -> #REF! | D20: =1-$C$3 -> #REF! | E20: =1-$C$3 -> #REF! | F20: =1-$C$3 -> #REF! | G20: =1-$C$3 -> #REF!
B21: Limite d'acceptabilité haute | C21: =1+$C$3 -> #REF! | D21: =1+$C$3 -> #REF! | E21: =1+$C$3 -> #REF! | F21: =1+$C$3 -> #REF! | G21: =1+$C$3 -> #REF!
B27: Incertitude
B28: Ecart-type de l'IT (sIT) | C28: =C$12*C$10 -> #REF! | D28: =D$12*D$10 -> #REF! | E28: =E$12*E$10 -> #REF! | F28: =F$12*F$10 -> #REF! | G28: =G$12*G$10 -> #REF!
B29: Incertitude élargie relative | C29: =2*C28/C7 -> #REF! | D29: =2*D28/D7 -> #REF! | E29: =2*E28/E7 -> #REF! | F29: =2*F28/F7 -> #REF! | G29: =2*G28/G7 -> #REF!

Sheet 80%
A1: Niveau A
A2: Valeur cible | B2: 80
B4: Répétition 1 | C4: Répétition 2 | D4: Répétition 3 | E4: Répétition 4 | F4: Répétition 5 | H4: nk | I4: SCEk
A5: Jour (Série) 1 | B5: =#REF!*$B$2 -> #REF! | C5: =#REF!*$B$2 -> #REF! | H5: =COUNT(B5:F5) -> 0 | I5: =IF(H5=0,"",DEVSQ(B5:F5))
A6: Jour (Série) 2
A7: Jour (Série) 3 | B7: =#REF!*$B$2 -> #REF! | C7: =#REF!*$B$2 -> #REF! | H7: =COUNT(B7:F7) -> 0 | I7: =IF(H7=0,"",DEVSQ(B7:F7))
A8: Jour (Série) 4 | B8: =#REF!*$B$2 -> #REF! | C8: =#REF!*$B$2 -> #REF! | H8: =COUNT(B8:F8) -> 0 | I8: =IF(H8=0,"",DEVSQ(B8:F8))
A9: Jour (Série) 5 | B9: =#REF!*$B$2 -> #REF! | C9: =#REF!*$B$2 -> #REF! | H9: =COUNT(B9:F9) -> 0 | I9: =IF(H9=0,"",DEVSQ(B9:F9))
A11: Nombre de séries (K) | B11: =COUNT(B5:B9) -> 0
A12: Nombre de mesures (IK) | B12: =COUNT(B5:F9) -> 0
A13: Nombre de répétitions (I) | B13: =IF(H5*B11<>B12,"Calcul impossible",H5) -> 0
A14: SCE résiduelle | B14: =SUM(I5:I9) -> 0
A15: SCE totale | B15: =DEVSQ(B5:F9) -> #REF!
A16: SCE inter-séries | B16: =B15-B14 -> #REF!
A17: Valeur intermédiaire de s²L | B17: =((B16/(B11-1))-B18)/B13 -> #REF!
A18: Variance de répétabilité (s²r) | B18: =B14/(B12-B11) -> #DIV/0!
A19: Variance inter-séries (s²L) | B19: =IF(B17<0,0,B17) -> #REF!
A20: Variance de fidélité (s²FI) | B20: =SUM(B18:B19) -> #DIV/0!
A21: Fidélité
A22: Moyenne niveau | B22: =AVERAGE(B5:F9) -> #REF!
A23: Ecart-type de répétabilité (sr) | B23: =SQRT(B18) -> #DIV/0!
A24: Ecart-type inter-séries (sL) | B24: =SQRT(B19) -> #REF!
A25: Ecart-type de fidélité (sFI) | B25: =SQRT(B20) -> #DIV/0!
A26: Justesse
A27: Biais (%) | B27: =B22/B2-1 -> #REF!
A28: Facteur de couverture
A29: Rapport des variances (R) | B29: =B19/B18 -> #REF!
A30: Coefficient B² | B30: =(B29+1)/(B13*B29+1) -> #REF!
A31: Coefficient intermédiaire | B31: =SQRT(1+1/(B12*B30)) -> #REF!
A32: Nombre de degrés liberté | B32: =(B29+1)^2/((B29+1/B13)^2/(B11-1)+(1-1/B13)/B12) -> #REF!
A33: Probabilité tolérance (bêta) | B33: =Récapitulatif!C2 -> #REF!
A34: t Student bas | B34: =TINV(1-B33,ROUNDDOWN(B32,0)) -> #REF!
A35: t Student haut | B35: =TINV(1-B33,ROUNDUP(B32,0)) -> #REF!
A36: t Student interpolé | B36: =B34-(B34-B35)*(B32-ROUNDDOWN(B32,0)) -> #REF!
A37: Facteur de couverture (ktol) | B37: =B36*B31 -> #REF!
A38: Intervalle de tolérance
A39: Valeur basse tolérance | B39: =B22-B37*B25 -> #REF!
A40: Valeur haute tolérance | B40: =B22+B37*B25 -> #REF!

Sheet 90%
A1: Niveau B
A2: Valeur cible | B2: 90
B4: Répétition 1 | C4: Répétition 2 | D4: Répétition 3 | E4: Répétition 4 | F4: Répétition 5 | H4: nk | I4: SCEk
A5: Jour (Série) 1 | B5: =#REF!*$B$2 -> #REF! | C5: =#REF!*$B$2 -> #REF! | H5: =COUNT(B5:F5) -> 0 | I5: =IF(H5=0,"",DEVSQ(B5:F5))
A6: Jour (Série) 2 | B6: =#REF!*$B$2 -> #REF! | C6: =#REF!*$B$2 -> #REF! | H6: =COUNT(B6:F6) -> 0 | I6: =IF(H6=0,"",DEVSQ(B6:F6))
A7: Jour (Série) 3 | I7: =IF(H7=0,"",DEVSQ(B7:F7))
A8: Jour (Série) 4 | B8: =#REF!*$B$2 -> #REF! | C8: =#REF!*$B$2 -> #REF! | H8: =COUNT(B8:F8) -> 0 | I8: =IF(H8=0,"",DEVSQ(B8:F8))
A9: Jour (Série) 5 | B9: =#REF!*$B$2 -> #REF! | C9: =#REF!*$B$2 -> #REF! | H9: =COUNT(B9:F9) -> 0 | I9: =IF(H9=0,"",DEVSQ(B9:F9))
A11: Nombre de séries (K) | B11: =COUNT(B5:B9) -> 0
A12: Nombre de mesures (IK) | B12: =COUNT(B5:F9) -> 0
A13: Nombre de répétitions (I) | B13: =IF(H5*B11<>B12,"Calcul impossible",H5) -> 0
A14: SCE résiduelle | B14: =SUM(I5:I9) -> 0
A15: SCE totale | B15: =DEVSQ(B5:F9) -> #REF!
A16: SCE inter-séries | B16: =B15-B14 -> #REF!
A17: Valeur intermédiaire de s²L | B17: =((B16/(B11-1))-B18)/B13 -> #REF!
A18: Variance de répétabilité (s²r) | B18: =B14/(B12-B11) -> #DIV/0!
A19: Variance inter-séries (s²L) | B19: =IF(B17<0,0,B17) -> #REF!
A20: Variance de fidélité (s²FI) | B20: =SUM(B18:B19) -> #DIV/0!
A21: Fidélité
A22: Moyenne niveau | B22: =AVERAGE(B5:F9) -> #REF!
A23: Ecart-type de répétabilité (sr) | B23: =SQRT(B18) -> #DIV/0!
A24: Ecart-type inter-séries (sL) | B24: =SQRT(B19) -> #REF!
A25: Ecart-type de fidélité (sFI) | B25: =SQRT(B20) -> #DIV/0!
A26: Justesse
A27: Biais (%) | B27: =B22/B2-1 -> #REF!
A28: Facteur de couverture
A29: Rapport des variances (R) | B29: =B19/B18 -> #REF!
A30: Coefficient B² | B30: =(B29+1)/(B13*B29+1) -> #REF!
A31: Coefficient intermédiaire | B31: =SQRT(1+1/(B12*B30)) -> #REF!
A32: Nombre de degrés liberté | B32: =(B29+1)^2/((B29+1/B13)^2/(B11-1)+(1-1/B13)/B12) -> #REF!
A33: Probabilité tolérance (bêta) | B33: =Récapitulatif!C2 -> #REF!
A34: t Student bas | B34: =TINV(1-B33,ROUNDDOWN(B32,0)) -> #REF!
A35: t Student haut | B35: =TINV(1-B33,ROUNDUP(B32,0)) -> #REF!
A36: t Student interpolé | B36: =B34-(B34-B35)*(B32-ROUNDDOWN(B32,0)) -> #REF!
A37: Facteur de couverture (ktol) | B37: =B36*B31 -> #REF!
A38: Intervalle de tolérance
A39: Valeur basse tolérance | B39: =B22-B37*B25 -> #REF!
A40: Valeur haute tolérance | B40: =B22+B37*B25 -> #REF!

Sheet 100%
A1: Niveau C
A2: Valeur cible | B2: 100
B4: Répétition 1 | C4: Répétition 2 | D4: Répétition 3 | E4: Répétition 4 | F4: Répétition 5 | H4: nk | I4: SCEk
A5: Jour (Série) 1 | B5: =#REF!*$B$2 -> #REF! | C5: =#REF!*$B$2 -> #REF! | H5: =COUNT(B5:F5) -> 0 | I5: =IF(H5=0,"",DEVSQ(B5:F5))
A6: Jour (Série) 2 | B6: =#REF!*$B$2 -> #REF! | C6: =#REF!*$B$2 -> #REF! | H6: =COUNT(B6:F6) -> 0 | I6: =IF(H6=0,"",DEVSQ(B6:F6))
A7: Jour (Série) 3 | B7: =#REF!*$B$2 -> #REF! | C7: =#REF!*$B$2 -> #REF! | H7: =COUNT(B7:F7) -> 0 | I7: =IF(H7=0,"",DEVSQ(B7:F7))
A8: Jour (Série) 4 | I8: =IF(H8=0,"",DEVSQ(B8:F8))
A9: Jour (Série) 5 | B9: =#REF!*$B$2 -> #REF! | C9: =#REF!*$B$2 -> #REF! | H9: =COUNT(B9:F9) -> 0 | I9: =IF(H9=0,"",DEVSQ(B9:F9))
A11: Nombre de séries (K) | B11: =COUNT(B5:B9) -> 0
A12: Nombre de mesures (IK) | B12: =COUNT(B5:F9) -> 0
A13: Nombre de répétitions (I) | B13: =IF(H5*B11<>B12,"Calcul impossible",H5) -> 0
A14: SCE résiduelle | B14: =SUM(I5:I9) -> 0
A15: SCE totale | B15: =DEVSQ(B5:F9) -> #REF!
A16: SCE inter-séries | B16: =B15-B14 -> #REF!
A17: Valeur intermédiaire de s²L | B17: =((B16/(B11-1))-B18)/B13 -> #REF!
A18: Variance de répétabilité (s²r) | B18: =B14/(B12-B11) -> #DIV/0!
A19: Variance inter-séries (s²L) | B19: =IF(B17<0,0,B17) -> #REF!
A20: Variance de fidélité (s²FI) | B20: =SUM(B18:B19) -> #DIV/0!
A21: Fidélité
A22: Moyenne niveau | B22: =AVERAGE(B5:F9) -> #REF!
A23: Ecart-type de répétabilité (sr) | B23: =SQRT(B18) -> #DIV/0!
A24: Ecart-type inter-séries (sL) | B24: =SQRT(B19) -> #REF!
A25: Ecart-type de fidélité (sFI) | B25: =SQRT(B20) -> #DIV/0!
A26: Justesse
A27: Biais (%) | B27: =B22/B2-1 -> #REF!
A28: Facteur de couverture
A29: Rapport des variances (R) | B29: =B19/B18 -> #REF!
A30: Coefficient B² | B30: =(B29+1)/(B13*B29+1) -> #REF!
A31: Coefficient intermédiaire | B31: =SQRT(1+1/(B12*B30)) -> #REF!
A32: Nombre de degrés liberté | B32: =(B29+1)^2/((B29+1/B13)^2/(B11-1)+(1-1/B13)/B12) -> #REF!
A33: Probabilité tolérance (bêta) | B33: =Récapitulatif!C2 -> #REF!
A34: t Student bas | B34: =TINV(1-B33,ROUNDDOWN(B32,0)) -> #REF!
A35: t Student haut | B35: =TINV(1-B33,ROUNDUP(B32,0)) -> #REF!
A36: t Student interpolé | B36: =B34-(B34-B35)*(B32-ROUNDDOWN(B32,0)) -> #REF!
A37: Facteur de couverture (ktol) | B37: =B36*B31 -> #REF!
A38: Intervalle de tolérance
A39: Valeur basse tolérance | B39: =B22-B37*B25 -> #REF!
A40: Valeur haute tolérance | B40: =B22+B37*B25 -> #REF!

Sheet 110%
A1: Niveau D
A2: Valeur cible | B2: 110
B4: Répétition 1 | C4: Répétition 2 | D4: Répétition 3 | E4: Répétition 4 | F4: Répétition 5 | H4: nk | I4: SCEk
A5: Jour (Série) 1 | B5: =#REF!*$B$2 -> #REF! | C5: =#REF!*$B$2 -> #REF! | H5: =COUNT(B5:F5) -> 0 | I5: =IF(H5=0,"",DEVSQ(B5:F5))
A6: Jour (Série) 2 | B6: =#REF!*$B$2 -> #REF! | C6: =#REF!*$B$2 -> #REF! | H6: =COUNT(B6:F6) -> 0 | I6: =IF(H6=0,"",DEVSQ(B6:F6))
A7: Jour (Série) 3 | B7: =#REF!*$B$2 -> #REF! | C7: =#REF!*$B$2 -> #REF! | H7: =COUNT(B7:F7) -> 0 | I7: =IF(H7=0,"",DEVSQ(B7:F7))
A8: Jour (Série) 4 | B8: =#REF!*$B$2 -> #REF! | C8: =#REF!*$B$2 -> #REF! | H8: =COUNT(B8:F8) -> 0 | I8: =IF(H8=0,"",DEVSQ(B8:F8))
A9: Jour (Série) 5 | I9: =IF(H9=0,"",DEVSQ(B9:F9))
A11: Nombre de séries (K) | B11: =COUNT(B5:B9) -> 0
A12: Nombre de mesures (IK) | B12: =COUNT(B5:F9) -> 0
A13: Nombre de répétitions (I) | B13: =IF(H5*B11<>B12,"Calcul impossible",H5) -> 0
A14: SCE résiduelle | B14: =SUM(I5:I9) -> 0
A15: SCE totale | B15: =DEVSQ(B5:F9) -> #REF!
A16: SCE inter-séries | B16: =B15-B14 -> #REF!
A17: Valeur intermédiaire de s²L | B17: =((B16/(B11-1))-B18)/B13 -> #REF!
A18: Variance de répétabilité (s²r) | B18: =B14/(B12-B11) -> #DIV/0!
A19: Variance inter-séries (s²L) | B19: =IF(B17<0,0,B17) -> #REF!
A20: Variance de fidélité (s²FI) | B20: =SUM(B18:B19) -> #DIV/0!
A21: Fidélité
A22: Moyenne niveau | B22: =AVERAGE(B5:F9) -> #REF!
A23: Ecart-type de répétabilité (sr) | B23: =SQRT(B18) -> #DIV/0!
A24: Ecart-type inter-séries (sL) | B24: =SQRT(B19) -> #REF!
A25: Ecart-type de fidélité (sFI) | B25: =SQRT(B20) -> #DIV/0!
A26: Justesse
A27: Biais (%) | B27: =B22/B2-1 -> #REF!
A28: Facteur de couverture
A29: Rapport des variances (R) | B29: =B19/B18 -> #REF!
A30: Coefficient B² | B30: =(B29+1)/(B13*B29+1) -> #REF!
A31: Coefficient intermédiaire | B31: =SQRT(1+1/(B12*B30)) -> #REF!
A32: Nombre de degrés liberté | B32: =(B29+1)^2/((B29+1/B13)^2/(B11-1)+(1-1/B13)/B12) -> #REF!
A33: Probabilité tolérance (bêta) | B33: =Récapitulatif!C2 -> #REF!
A34: t Student bas | B34: =TINV(1-B33,ROUNDDOWN(B32,0)) -> #REF!
A35: t Student haut | B35: =TINV(1-B33,ROUNDUP(B32,0)) -> #REF!
A36: t Student interpolé | B36: =B34-(B34-B35)*(B32-ROUNDDOWN(B32,0)) -> #REF!
A37: Facteur de couverture (ktol) | B37: =B36*B31 -> #REF!
A38: Intervalle de tolérance
A39: Valeur basse tolérance | B39: =B22-B37*B25 -> #REF!
A40: Valeur haute tolérance | B40: =B22+B37*B25 -> #REF!

Sheet 120%
A1: Niveau E
A2: Valeur cible | B2: 120
B4: Répétition 1 | C4: Répétition 2 | D4: Répétition 3 | E4: Répétition 4 | F4: Répétition 5 | H4: nk | I4: SCEk
A5: Jour (Série) 1
A6: Jour (Série) 2 | B6: =#REF!*$B$2 -> #REF! | C6: =#REF!*$B$2 -> #REF! | H6: =COUNT(B6:F6) -> 0 | I6: =IF(H6=0,"",DEVSQ(B6:F6))
A7: Jour (Série) 3 | B7: =#REF!*$B$2 -> #REF! | C7: =#REF!*$B$2 -> #REF! | H7: =COUNT(B7:F7) -> 0 | I7: =IF(H7=0,"",DEVSQ(B7:F7))
A8: Jour (Série) 4 | B8: =#REF!*$B$2 -> #REF! | C8: =#REF!*$B$2 -> #REF! | H8: =COUNT(B8:F8) -> 0 | I8: =IF(H8=0,"",DEVSQ(B8:F8))
A9: Jour (Série) 5 | B9: =#REF!*$B$2 -> #REF! | C9: =#REF!*$B$2 -> #REF! | H9: =COUNT(B9:F9) -> 0 | I9: =IF(H9=0,"",DEVSQ(B9:F9))
A11: Nombre de séries (K) | B11: =COUNT(B5:B9) -> 0
A12: Nombre de mesures (IK) | B12: =COUNT(B5:F9) -> 0
A13: Nombre de répétitions (I) | B13: =IF(H6*B11<>B12,"Calcul impossible",H6) -> 0
A14: SCE résiduelle | B14: =SUM(I5:I9) -> 0
A15: SCE totale | B15: =DEVSQ(B5:F9) -> #REF!
A16: SCE inter-séries | B16: =B15-B14 -> #REF!
A17: Valeur intermédiaire de s²L | B17: =((B16/(B11-1))-B18)/B13 -> #REF!
A18: Variance de répétabilité (s²r) | B18: =B14/(B12-B11) -> #DIV/0!
A19: Variance inter-séries (s²L) | B19: =IF(B17<0,0,B17) -> #REF!
A20: Variance de fidélité (s²FI) | B20: =SUM(B18:B19) -> #DIV/0!
A21: Fidélité
A22: Moyenne niveau | B22: =AVERAGE(B5:F9) -> #REF!
A23: Ecart-type de répétabilité (sr) | B23: =SQRT(B18) -> #DIV/0!
A24: Ecart-type inter-séries (sL) | B24: =SQRT(B19) -> #REF!
A25: Ecart-type de fidélité (sFI) | B25: =SQRT(B20) -> #DIV/0!
A26: Justesse
A27: Biais (%) | B27: =B22/B2-1 -> #REF!
A28: Facteur de couverture
A29: Rapport des variances (R) | B29: =B19/B18 -> #REF!
A30: Coefficient B² | B30: =(B29+1)/(B13*B29+1) -> #REF!
A31: Coefficient intermédiaire | B31: =SQRT(1+1/(B12*B30)) -> #REF!
A32: Nombre de degrés liberté | B32: =(B29+1)^2/((B29+1/B13)^2/(B11-1)+(1-1/B13)/B12) -> #REF!
A33: Probabilité tolérance (bêta) | B33: =Récapitulatif!C2 -> #REF!
A34: t Student bas | B34: =TINV(1-B33,ROUNDDOWN(B32,0)) -> #REF!
A35: t Student haut | B35: =TINV(1-B33,ROUNDUP(B32,0)) -> #REF!
A36: t Student interpolé | B36: =B34-(B34-B35)*(B32-ROUNDDOWN(B32,0)) -> #REF!
A37: Facteur de couverture (ktol) | B37: =B36*B31 -> #REF!
A38: Intervalle de tolérance
A39: Valeur basse tolérance | B39: =B22-B37*B25 -> #REF!
A40: Valeur haute tolérance | B40: =B22+B37*B25 -> #REF!
