Workbook

Sheet analyse de risque
I2: Facteurs quantitatifs
H3: C2 | I3: indice | J3: Capabilité du moyen de mesure: Uprocess / EMT | N3: C3 | O3: indice | P3: Capabilité process : Tolérance pdt/Uprocessus | T3: C4 | U3: indice | V3: Dérive de l'équipement : EMT/dérive
I4: -2 | J4: Capabilité limité | O4: -2 | P4: Cpk < 1 | U4: -2
C5: Critères | D5: Critères d'influences | I5: 0 | J5: Capabilité correcte | O5: 0 | P5: Cpk < 1,3 | U5: 0 | V5: l'historique montre une dérive "classique" donc 0
C6: C1 | D6: Conséquence d'une mauvaise mesure/process | I6: 2 | J6: Capabilité largement suffisante | O6: 2 | P6: Cpk < 1,66 | U6: 2
C7: C2 | D7: Capabilité/capacité du moyen de contrôle
C8: C3 | D8: Capabilité process (5M) | I8: Facteur qualitatifs
C9: C4 | D9: Dérive de l'équipement | H9: C1 | I9: indice | J9: Conséquence d'une mauvaise mesure | N9: C5 | O9: indice | P9: Détection des anomalies | T9: C6 | U9: indice | V9: Facteurs aggravants
C10: C5 | D10: Détection des anomalies | I10: -2 | J10: Conséquence grave | O10: -2 | P10: impossible | U10: -2 | V10: haute T°C, acide/base/force, etc
C11: C6 | D11: Facteurs aggravants | I11: 0 | J11: Conséquence moyenne | O11: 0 | P11: contrôle supplementaire | U11: 0
C12: C7 | D12: Contrainte des couts | I12: 2 | J12: Pas de conséquence | O12: 2 | P12: par l'operateur | U12: 2 | V12: RAS
C13: C8 | D13: Contraintes opérationnelles
C14: C9 | D14: intervention sur l'équipement | H14: C7 | I14: indice | J14: Contrainte des couts | N14: C8 | O14: indice | P14: Contraintes opérationnelles | T14: C9 | U14: indice | V14: Intervention sur l'équipement
I15: -2 | J15: elevé | O15: -2 | P15: competence externe | U15: -2 | V15: annuelle
I16: 0 | J16: acceptable | O16: 0 | P16: competence interne | U16: 0 | V16: reguliere
I17: 2 | J17: peu cher | O17: 2 | P17: simple d'utilisation | U17: 2 | V17: a chaque demarage
B20: Parc d'équipements | D20: Critère C
B21: Famille / service | D21: C1 | E21: C2 | F21: C3 | G21: C4 | H21: C5 | I21: C6 | J21: C7 | K21: C8 | L21: C9 | AC21: NG
B22: Moyenne Famille | D22: =AVERAGE(D24:D58) -> -1.375 | E22: =AVERAGE(E24:E58) -> 1.625 | F22: =AVERAGE(F24:F58) -> 0.375 | G22: =AVERAGE(G24:G58) -> -0.375 | H22: =AVERAGE(H24:H58) -> 1.25 | I22: =AVERAGE(I24:I58) -> -1.375 | J22: =AVERAGE(J24:J58) -> -0.375 | K22: =AVERAGE(K24:K58) -> -0.375 | L22: =AVERAGE(L24:L58) -> 1.625 | M22: Périodicité (en mois) | AB22: my | AC22: =AVERAGE(AC24:AC58) -> 0
B23: Ecart-type Famille | D23: =STDEVP(D24:D58) -> 0.48412292 | E23: =STDEVP(E24:E58) -> 0.48412292 | F23: =STDEVP(F24:F58) -> 0.48412292 | G23: =STDEVP(G24:G58) -> 0.48412292 | H23: =STDEVP(H24:H58) -> 0.96824584 | I23: =STDEVP(I24:I58) -> 0.48412292 | J23: =STDEVP(J24:J58) -> 0.48412292 | K23: =STDEVP(K24:K58) -> 0.48412292 | L23: =STDEVP(L24:L58) -> 0.48412292 | M23: Pact | N23: Pmoy | O23: Pmax | P23: OPPERET | AB23: S | AC23: =STDEVP(AC24:AC58) -> 7 | AD23: NG globale
B24: heat gun | C24: 295 XXX | D24: -1 | E24: 2 | F24: 0 | G24: 0 | H24: 2 | I24: -1 | J24: 0 | K24: 0 | L24: 2 | M24: 6 | N24: =M24+2*$AC$23 -> 20 | O24: =M24+5*$AC$23 -> 41 | P24: =N24+AD24*$AC$23 -> 25.422177 | T24: =IF(ISNUMBER(D24),(D24-D$22)/D$23,"") -> 0.77459667 | U24: =IF(ISNUMBER(E24),(E24-E$22)/E$23,"") -> 0.77459667 | V24: =IF(ISNUMBER(F24),(F24-F$22)/F$23,"") -> -0.77459667 | W24: =IF(ISNUMBER(G24),(G24-G$22)/G$23,"") -> 0.77459667 | X24: =IF(ISNUMBER(H24),(H24-H$22)/H$23,"") -> 0.77459667 | Y24: =IF(ISNUMBER(I24),(I24-I$22)/I$23,"") -> 0.77459667 | Z24: =IF(ISNUMBER(J24),(J24-J$22)/J$23,"") -> 0.77459667 | AA24: =IF(ISNUMBER(K24),(K24-K$22)/K$23,"") -> 0.77459667 | AB24: =IF(ISNUMBER(L24),(L24-L$22)/L$23,"") -> 0.77459667 | AC24: =IF(ISNUMBER(T24),SUM(T24:AB24),"") -> 5.4221767 | AD24: =IF(ISNUMBER(T24),(AC24-$AC$22)/$AC$23,"") -> 0.77459667
C25: 295 XXX | D25: -1 | E25: 2 | F25: 0 | G25: 0 | H25: 2 | I25: -1 | J25: 0 | K25: 0 | L25: 2 | M25: 6 | N25: =M25+2*$AC$23 -> 20 | O25: =M25+5*$AC$23 -> 41 | P25: =N25+AD25*$AC$23 -> 25.422177 | T25: =IF(ISNUMBER(D25),(D25-D$22)/D$23,"") -> 0.77459667 | U25: =IF(ISNUMBER(E25),(E25-E$22)/E$23,"") -> 0.77459667 | V25: =IF(ISNUMBER(F25),(F25-F$22)/F$23,"") -> -0.77459667 | W25: =IF(ISNUMBER(G25),(G25-G$22)/G$23,"") -> 0.77459667 | X25: =IF(ISNUMBER(H25),(H25-H$22)/H$23,"") -> 0.77459667 | Y25: =IF(ISNUMBER(I25),(I25-I$22)/I$23,"") -> 0.77459667 | Z25: =IF(ISNUMBER(J25),(J25-J$22)/J$23,"") -> 0.77459667 | AA25: =IF(ISNUMBER(K25),(K25-K$22)/K$23,"") -> 0.77459667 | AB25: =IF(ISNUMBER(L25),(L25-L$22)/L$23,"") -> 0.77459667 | AC25: =IF(ISNUMBER(T25),SUM(T25:AB25),"") -> 5.4221767 | AD25: =IF(ISNUMBER(T25),(AC25-$AC$22)/$AC$23,"") -> 0.77459667
C26: 295 XXX | D26: -1 | E26: 2 | F26: 0 | G26: 0 | H26: 2 | I26: -1 | J26: 0 | K26: 0 | L26: 2 | M26: 6 | N26: =M26+2*$AC$23 -> 20 | O26: =M26+5*$AC$23 -> 41 | P26: =N26+AD26*$AC$23 -> 25.422177 | T26: =IF(ISNUMBER(D26),(D26-D$22)/D$23,"") -> 0.77459667 | U26: =IF(ISNUMBER(E26),(E26-E$22)/E$23,"") -> 0.77459667 | V26: =IF(ISNUMBER(F26),(F26-F$22)/F$23,"") -> -0.77459667 | W26: =IF(ISNUMBER(G26),(G26-G$22)/G$23,"") -> 0.77459667 | X26: =IF(ISNUMBER(H26),(H26-H$22)/H$23,"") -> 0.77459667 | Y26: =IF(ISNUMBER(I26),(I26-I$22)/I$23,"") -> 0.77459667 | Z26: =IF(ISNUMBER(J26),(J26-J$22)/J$23,"") -> 0.77459667 | AA26: =IF(ISNUMBER(K26),(K26-K$22)/K$23,"") -> 0.77459667 | AB26: =IF(ISNUMBER(L26),(L26-L$22)/L$23,"") -> 0.77459667 | AC26: =IF(ISNUMBER(T26),SUM(T26:AB26),"") -> 5.4221767 | AD26: =IF(ISNUMBER(T26),(AC26-$AC$22)/$AC$23,"") -> 0.77459667
C27: 295 XXX | D27: -1 | E27: 2 | F27: 0 | G27: 0 | H27: 2 | I27: -1 | J27: 0 | K27: 0 | L27: 2 | M27: 6 | N27: =M27+2*$AC$23 -> 20 | O27: =M27+5*$AC$23 -> 41 | P27: =N27+AD27*$AC$23 -> 25.422177 | T27: =IF(ISNUMBER(D27),(D27-D$22)/D$23,"") -> 0.77459667 | U27: =IF(ISNUMBER(E27),(E27-E$22)/E$23,"") -> 0.77459667 | V27: =IF(ISNUMBER(F27),(F27-F$22)/F$23,"") -> -0.77459667 | W27: =IF(ISNUMBER(G27),(G27-G$22)/G$23,"") -> 0.77459667 | X27: =IF(ISNUMBER(H27),(H27-H$22)/H$23,"") -> 0.77459667 | Y27: =IF(ISNUMBER(I27),(I27-I$22)/I$23,"") -> 0.77459667 | Z27: =IF(ISNUMBER(J27),(J27-J$22)/J$23,"") -> 0.77459667 | AA27: =IF(ISNUMBER(K27),(K27-K$22)/K$23,"") -> 0.77459667 | AB27: =IF(ISNUMBER(L27),(L27-L$22)/L$23,"") -> 0.77459667 | AC27: =IF(ISNUMBER(T27),SUM(T27:AB27),"") -> 5.4221767 | AD27: =IF(ISNUMBER(T27),(AC27-$AC$22)/$AC$23,"") -> 0.77459667
C28: 295 XXX | D28: -1 | E28: 2 | F28: 0 | G28: 0 | H28: 2 | I28: -1 | J28: 0 | K28: 0 | L28: 2 | M28: 6 | N28: =M28+2*$AC$23 -> 20 | O28: =M28+5*$AC$23 -> 41 | P28: =N28+AD28*$AC$23 -> 25.422177 | T28: =IF(ISNUMBER(D28),(D28-D$22)/D$23,"") -> 0.77459667 | U28: =IF(ISNUMBER(E28),(E28-E$22)/E$23,"") -> 0.77459667 | V28: =IF(ISNUMBER(F28),(F28-F$22)/F$23,"") -> -0.77459667 | W28: =IF(ISNUMBER(G28),(G28-G$22)/G$23,"") -> 0.77459667 | X28: =IF(ISNUMBER(H28),(H28-H$22)/H$23,"") -> 0.77459667 | Y28: =IF(ISNUMBER(I28),(I28-I$22)/I$23,"") -> 0.77459667 | Z28: =IF(ISNUMBER(J28),(J28-J$22)/J$23,"") -> 0.77459667 | AA28: =IF(ISNUMBER(K28),(K28-K$22)/K$23,"") -> 0.77459667 | AB28: =IF(ISNUMBER(L28),(L28-L$22)/L$23,"") -> 0.77459667 | AC28: =IF(ISNUMBER(T28),SUM(T28:AB28),"") -> 5.4221767 | AD28: =IF(ISNUMBER(T28),(AC28-$AC$22)/$AC$23,"") -> 0.77459667
B29: soldering | C29: 295 XXX | D29: -2 | E29: 1 | F29: 1 | G29: -1 | H29: 0 | I29: -2 | J29: -1 | K29: -1 | L29: 1 | M29: 12 | N29: =M29+2*$AC$23 -> 26 | O29: =M29+5*$AC$23 -> 47 | P29: =N29+AD29*$AC$23 -> 16.963039 | T29: =IF(ISNUMBER(D29),(D29-D$22)/D$23,"") -> -1.2909944 | U29: =IF(ISNUMBER(E29),(E29-E$22)/E$23,"") -> -1.2909944 | V29: =IF(ISNUMBER(F29),(F29-F$22)/F$23,"") -> 1.2909944 | W29: =IF(ISNUMBER(G29),(G29-G$22)/G$23,"") -> -1.2909944 | X29: =IF(ISNUMBER(H29),(H29-H$22)/H$23,"") -> -1.2909944 | Y29: =IF(ISNUMBER(I29),(I29-I$22)/I$23,"") -> -1.2909944 | Z29: =IF(ISNUMBER(J29),(J29-J$22)/J$23,"") -> -1.2909944 | AA29: =IF(ISNUMBER(K29),(K29-K$22)/K$23,"") -> -1.2909944 | AB29: =IF(ISNUMBER(L29),(L29-L$22)/L$23,"") -> -1.2909944 | AC29: =IF(ISNUMBER(T29),SUM(T29:AB29),"") -> -9.0369611 | AD29: =IF(ISNUMBER(T29),(AC29-$AC$22)/$AC$23,"") -> -1.2909944
C30: 295 XXX | D30: -2 | E30: 1 | F30: 1 | G30: -1 | H30: 0 | I30: -2 | J30: -1 | K30: -1 | L30: 1 | M30: 12 | N30: =M30+2*$AC$23 -> 26 | O30: =M30+5*$AC$23 -> 47 | P30: =N30+AD30*$AC$23 -> 16.963039 | T30: =IF(ISNUMBER(D30),(D30-D$22)/D$23,"") -> -1.2909944 | U30: =IF(ISNUMBER(E30),(E30-E$22)/E$23,"") -> -1.2909944 | V30: =IF(ISNUMBER(F30),(F30-F$22)/F$23,"") -> 1.2909944 | W30: =IF(ISNUMBER(G30),(G30-G$22)/G$23,"") -> -1.2909944 | X30: =IF(ISNUMBER(H30),(H30-H$22)/H$23,"") -> -1.2909944 | Y30: =IF(ISNUMBER(I30),(I30-I$22)/I$23,"") -> -1.2909944 | Z30: =IF(ISNUMBER(J30),(J30-J$22)/J$23,"") -> -1.2909944 | AA30: =IF(ISNUMBER(K30),(K30-K$22)/K$23,"") -> -1.2909944 | AB30: =IF(ISNUMBER(L30),(L30-L$22)/L$23,"") -> -1.2909944 | AC30: =IF(ISNUMBER(T30),SUM(T30:AB30),"") -> -9.0369611 | AD30: =IF(ISNUMBER(T30),(AC30-$AC$22)/$AC$23,"") -> -1.2909944
C31: 295 XXX | D31: -2 | E31: 1 | F31: 1 | G31: -1 | H31: 0 | I31: -2 | J31: -1 | K31: -1 | L31: 1 | M31: 12 | N31: =M31+2*$AC$23 -> 26 | O31: =M31+5*$AC$23 -> 47 | P31: =N31+AD31*$AC$23 -> 16.963039 | T31: =IF(ISNUMBER(D31),(D31-D$22)/D$23,"") -> -1.2909944 | U31: =IF(ISNUMBER(E31),(E31-E$22)/E$23,"") -> -1.2909944 | V31: =IF(ISNUMBER(F31),(F31-F$22)/F$23,"") -> 1.2909944 | W31: =IF(ISNUMBER(G31),(G31-G$22)/G$23,"") -> -1.2909944 | X31: =IF(ISNUMBER(H31),(H31-H$22)/H$23,"") -> -1.2909944 | Y31: =IF(ISNUMBER(I31),(I31-I$22)/I$23,"") -> -1.2909944 | Z31: =IF(ISNUMBER(J31),(J31-J$22)/J$23,"") -> -1.2909944 | AA31: =IF(ISNUMBER(K31),(K31-K$22)/K$23,"") -> -1.2909944 | AB31: =IF(ISNUMBER(L31),(L31-L$22)/L$23,"") -> -1.2909944 | AC31: =IF(ISNUMBER(T31),SUM(T31:AB31),"") -> -9.0369611 | AD31: =IF(ISNUMBER(T31),(AC31-$AC$22)/$AC$23,"") -> -1.2909944
T32: =IF(ISNUMBER(D32),(D32-D$22)/D$23,"") | U32: =IF(ISNUMBER(E32),(E32-E$22)/E$23,"") | V32: =IF(ISNUMBER(F32),(F32-F$22)/F$23,"") | W32: =IF(ISNUMBER(G32),(G32-G$22)/G$23,"") | X32: =IF(ISNUMBER(H32),(H32-H$22)/H$23,"") | Y32: =IF(ISNUMBER(I32),(I32-I$22)/I$23,"") | Z32: =IF(ISNUMBER(J32),(J32-J$22)/J$23,"") | AA32: =IF(ISNUMBER(K32),(K32-K$22)/K$23,"") | AB32: =IF(ISNUMBER(L32),(L32-L$22)/L$23,"") | AC32: =IF(ISNUMBER(T32),SUM(T32:AB32),"") | AD32: =IF(ISNUMBER(T32),(AC32-$AC$22)/$AC$23,"")
T33: =IF(ISNUMBER(D33),(D33-D$22)/D$23,"") | U33: =IF(ISNUMBER(E33),(E33-E$22)/E$23,"") | V33: =IF(ISNUMBER(F33),(F33-F$22)/F$23,"") | W33: =IF(ISNUMBER(G33),(G33-G$22)/G$23,"") | X33: =IF(ISNUMBER(H33),(H33-H$22)/H$23,"") | Y33: =IF(ISNUMBER(I33),(I33-I$22)/I$23,"") | Z33: =IF(ISNUMBER(J33),(J33-J$22)/J$23,"") | AA33: =IF(ISNUMBER(K33),(K33-K$22)/K$23,"") | AB33: =IF(ISNUMBER(L33),(L33-L$22)/L$23,"") | AC33: =IF(ISNUMBER(T33),SUM(T33:AB33),"") | AD33: =IF(ISNUMBER(T33),(AC33-$AC$22)/$AC$23,"")
T34: =IF(ISNUMBER(D34),(D34-D$22)/D$23,"") | U34: =IF(ISNUMBER(E34),(E34-E$22)/E$23,"") | V34: =IF(ISNUMBER(F34),(F34-F$22)/F$23,"") | W34: =IF(ISNUMBER(G34),(G34-G$22)/G$23,"") | X34: =IF(ISNUMBER(H34),(H34-H$22)/H$23,"") | Y34: =IF(ISNUMBER(I34),(I34-I$22)/I$23,"") | Z34: =IF(ISNUMBER(J34),(J34-J$22)/J$23,"") | AA34: =IF(ISNUMBER(K34),(K34-K$22)/K$23,"") | AB34: =IF(ISNUMBER(L34),(L34-L$22)/L$23,"") | AC34: =IF(ISNUMBER(T34),SUM(T34:AB34),"") | AD34: =IF(ISNUMBER(T34),(AC34-$AC$22)/$AC$23,"")
T35: =IF(ISNUMBER(D35),(D35-D$22)/D$23,"") | U35: =IF(ISNUMBER(E35),(E35-E$22)/E$23,"") | V35: =IF(ISNUMBER(F35),(F35-F$22)/F$23,"") | W35: =IF(ISNUMBER(G35),(G35-G$22)/G$23,"") | X35: =IF(ISNUMBER(H35),(H35-H$22)/H$23,"") | Y35: =IF(ISNUMBER(I35),(I35-I$22)/I$23,"") | Z35: =IF(ISNUMBER(J35),(J35-J$22)/J$23,"") | AA35: =IF(ISNUMBER(K35),(K35-K$22)/K$23,"") | AB35: =IF(ISNUMBER(L35),(L35-L$22)/L$23,"") | AC35: =IF(ISNUMBER(T35),SUM(T35:AB35),"") | AD35: =IF(ISNUMBER(T35),(AC35-$AC$22)/$AC$23,"")
T36: =IF(ISNUMBER(D36),(D36-D$22)/D$23,"") | U36: =IF(ISNUMBER(E36),(E36-E$22)/E$23,"") | V36: =IF(ISNUMBER(F36),(F36-F$22)/F$23,"") | W36: =IF(ISNUMBER(G36),(G36-G$22)/G$23,"") | X36: =IF(ISNUMBER(H36),(H36-H$22)/H$23,"") | Y36: =IF(ISNUMBER(I36),(I36-I$22)/I$23,"") | Z36: =IF(ISNUMBER(J36),(J36-J$22)/J$23,"") | AA36: =IF(ISNUMBER(K36),(K36-K$22)/K$23,"") | AB36: =IF(ISNUMBER(L36),(L36-L$22)/L$23,"") | AC36: =IF(ISNUMBER(T36),SUM(T36:AB36),"") | AD36: =IF(ISNUMBER(T36),(AC36-$AC$22)/$AC$23,"")
T37: =IF(ISNUMBER(D37),(D37-D$22)/D$23,"") | U37: =IF(ISNUMBER(E37),(E37-E$22)/E$23,"") | V37: =IF(ISNUMBER(F37),(F37-F$22)/F$23,"") | W37: =IF(ISNUMBER(G37),(G37-G$22)/G$23,"") | X37: =IF(ISNUMBER(H37),(H37-H$22)/H$23,"") | Y37: =IF(ISNUMBER(I37),(I37-I$22)/I$23,"") | Z37: =IF(ISNUMBER(J37),(J37-J$22)/J$23,"") | AA37: =IF(ISNUMBER(K37),(K37-K$22)/K$23,"") | AB37: =IF(ISNUMBER(L37),(L37-L$22)/L$23,"") | AC37: =IF(ISNUMBER(T37),SUM(T37:AB37),"") | AD37: =IF(ISNUMBER(T37),(AC37-$AC$22)/$AC$23,"")
T38: =IF(ISNUMBER(D38),(D38-D$22)/D$23,"") | U38: =IF(ISNUMBER(E38),(E38-E$22)/E$23,"") | V38: =IF(ISNUMBER(F38),(F38-F$22)/F$23,"") | W38: =IF(ISNUMBER(G38),(G38-G$22)/G$23,"") | X38: =IF(ISNUMBER(H38),(H38-H$22)/H$23,"") | Y38: =IF(ISNUMBER(I38),(I38-I$22)/I$23,"") | Z38: =IF(ISNUMBER(J38),(J38-J$22)/J$23,"") | AA38: =IF(ISNUMBER(K38),(K38-K$22)/K$23,"") | AB38: =IF(ISNUMBER(L38),(L38-L$22)/L$23,"") | AC38: =IF(ISNUMBER(T38),SUM(T38:AB38),"") | AD38: =IF(ISNUMBER(T38),(AC38-$AC$22)/$AC$23,"")
T39: =IF(ISNUMBER(D39),(D39-D$22)/D$23,"") | U39: =IF(ISNUMBER(E39),(E39-E$22)/E$23,"") | V39: =IF(ISNUMBER(F39),(F39-F$22)/F$23,"") | W39: =IF(ISNUMBER(G39),(G39-G$22)/G$23,"") | X39: =IF(ISNUMBER(H39),(H39-H$22)/H$23,"") | Y39: =IF(ISNUMBER(I39),(I39-I$22)/I$23,"") | Z39: =IF(ISNUMBER(J39),(J39-J$22)/J$23,"") | AA39: =IF(ISNUMBER(K39),(K39-K$22)/K$23,"") | AB39: =IF(ISNUMBER(L39),(L39-L$22)/L$23,"") | AC39: =IF(ISNUMBER(T39),SUM(T39:AB39),"") | AD39: =IF(ISNUMBER(T39),(AC39-$AC$22)/$AC$23,"")
T40: =IF(ISNUMBER(D40),(D40-D$22)/D$23,"") | U40: =IF(ISNUMBER(E40),(E40-E$22)/E$23,"") | V40: =IF(ISNUMBER(F40),(F40-F$22)/F$23,"") | W40: =IF(ISNUMBER(G40),(G40-G$22)/G$23,"") | X40: =IF(ISNUMBER(H40),(H40-H$22)/H$23,"") | Y40: =IF(ISNUMBER(I40),(I40-I$22)/I$23,"") | Z40: =IF(ISNUMBER(J40),(J40-J$22)/J$23,"") | AA40: =IF(ISNUMBER(K40),(K40-K$22)/K$23,"") | AB40: =IF(ISNUMBER(L40),(L40-L$22)/L$23,"") | AC40: =IF(ISNUMBER(T40),SUM(T40:AB40),"") | AD40: =IF(ISNUMBER(T40),(AC40-$AC$22)/$AC$23,"")
T41: =IF(ISNUMBER(D41),(D41-D$22)/D$23,"") | U41: =IF(ISNUMBER(E41),(E41-E$22)/E$23,"") | V41: =IF(ISNUMBER(F41),(F41-F$22)/F$23,"") | W41: =IF(ISNUMBER(G41),(G41-G$22)/G$23,"") | X41: =IF(ISNUMBER(H41),(H41-H$22)/H$23,"") | Y41: =IF(ISNUMBER(I41),(I41-I$22)/I$23,"") | Z41: =IF(ISNUMBER(J41),(J41-J$22)/J$23,"") | AA41: =IF(ISNUMBER(K41),(K41-K$22)/K$23,"") | AB41: =IF(ISNUMBER(L41),(L41-L$22)/L$23,"") | AC41: =IF(ISNUMBER(T41),SUM(T41:AB41),"") | AD41: =IF(ISNUMBER(T41),(AC41-$AC$22)/$AC$23,"")
T42: =IF(ISNUMBER(D42),(D42-D$22)/D$23,"") | U42: =IF(ISNUMBER(E42),(E42-E$22)/E$23,"") | V42: =IF(ISNUMBER(F42),(F42-F$22)/F$23,"") | W42: =IF(ISNUMBER(G42),(G42-G$22)/G$23,"") | X42: =IF(ISNUMBER(H42),(H42-H$22)/H$23,"") | Y42: =IF(ISNUMBER(I42),(I42-I$22)/I$23,"") | Z42: =IF(ISNUMBER(J42),(J42-J$22)/J$23,"") | AA42: =IF(ISNUMBER(K42),(K42-K$22)/K$23,"") | AB42: =IF(ISNUMBER(L42),(L42-L$22)/L$23,"") | AC42: =IF(ISNUMBER(T42),SUM(T42:AB42),"") | AD42: =IF(ISNUMBER(T42),(AC42-$AC$22)/$AC$23,"")
T43: =IF(ISNUMBER(D43),(D43-D$22)/D$23,"") | U43: =IF(ISNUMBER(E43),(E43-E$22)/E$23,"") | V43: =IF(ISNUMBER(F43),(F43-F$22)/F$23,"") | W43: =IF(ISNUMBER(G43),(G43-G$22)/G$23,"") | X43: =IF(ISNUMBER(H43),(H43-H$22)/H$23,"") | Y43: =IF(ISNUMBER(I43),(I43-I$22)/I$23,"") | Z43: =IF(ISNUMBER(J43),(J43-J$22)/J$23,"") | AA43: =IF(ISNUMBER(K43),(K43-K$22)/K$23,"") | AB43: =IF(ISNUMBER(L43),(L43-L$22)/L$23,"") | AC43: =IF(ISNUMBER(T43),SUM(T43:AB43),"") | AD43: =IF(ISNUMBER(T43),(AC43-$AC$22)/$AC$23,"")
...

Sheet planning opperet
G1: X | H1: rebut
G2: P | H2: planifié - deadline
G3: R | H3: réalisé - succés
E4: Année : 2016 | R4: Année : 2017 | AE4: Année : 2018 | AR4: Année : 2019 | BE4: Année : 2020
E5: mois | R5: mois | AE5: mois | AR5: mois | BE5: mois
B6: Famille | C6: N° ID | D6: Opperet (mois) | E6: 1 | F6: 2 | G6: 3 | H6: 4 | I6: 5 | J6: 6 | K6: 7 | L6: 8 | M6: 9 | N6: 10 | O6: 11 | P6: 12 | R6: 1 | S6: 2 | T6: 3 | U6: 4 | V6: 5 | W6: 6 | X6: 7 | Y6: 8 | Z6: 9 | AA6: 10 | AB6: 11 | AC6: 12 | AE6: 1 | AF6: 2 | AG6: 3 | AH6: 4 | AI6: 5 | AJ6: 6 | AK6: 7 | AL6: 8 | AM6: 9 | AN6: 10 | AO6: 11 | AP6: 12 | AR6: 1 | AS6: 2 | AT6: 3 | AU6: 4 | AV6: 5 | AW6: 6 | AX6: 7 | AY6: 8 | AZ6: 9 | BA6: 10 | BB6: 11 | BC6: 12 | BE6: 1 | BF6: 2 | BG6: 3 | BH6: 4 | BI6: 5 | BJ6: 6 | BK6: 7 | BL6: 8 | BM6: 9 | BN6: 10 | BO6: 11 | BP6: 12
B7: ='analyse de risque'!B24 -> heat gun | C7: ='analyse de risque'!C24 -> 295 XXX | D7: ='analyse de risque'!P24 -> 25.422177 | G7: P | T7: P | AG7: P | AT7: P | BG7: P
B8: ='analyse de risque'!B25 -> 0 | C8: ='analyse de risque'!C25 -> 295 XXX | D8: ='analyse de risque'!P25 -> 25.422177 | H8: P | U8: P | AH8: P | AU8: P | BH8: P
B9: ='analyse de risque'!B26 -> 0 | C9: ='analyse de risque'!C26 -> 295 XXX | D9: ='analyse de risque'!P26 -> 25.422177 | I9: P | V9: P | AI9: P | AV9: P | BI9: P
B10: ='analyse de risque'!B27 -> 0 | C10: ='analyse de risque'!C27 -> 295 XXX | D10: ='analyse de risque'!P27 -> 25.422177 | N10: P | AA10: P | AN10: P | BA10: P | BN10: P
B11: ='analyse de risque'!B28 -> 0 | C11: ='analyse de risque'!C28 -> 295 XXX | D11: ='analyse de risque'!P28 -> 25.422177
B12: ='analyse de risque'!B29 -> soldering | C12: ='analyse de risque'!C29 -> 295 XXX | D12: ='analyse de risque'!P29 -> 16.963039
B13: ='analyse de risque'!B30 -> 0 | C13: ='analyse de risque'!C30 -> 295 XXX | D13: ='analyse de risque'!P30 -> 16.963039 | N13: X | AA13: X | AN13: X | BA13: X | BN13: X
B14: ='analyse de risque'!B31 -> 0 | C14: ='analyse de risque'!C31 -> 295 XXX | D14: ='analyse de risque'!P31 -> 16.963039
B15: ='analyse de risque'!B32 -> 0 | C15: ='analyse de risque'!C32 -> 0 | D15: ='analyse de risque'!P32 -> 0
B16: ='analyse de risque'!B33 -> 0 | C16: ='analyse de risque'!C33 -> 0 | D16: ='analyse de risque'!P33 -> 0
B17: ='analyse de risque'!B34 -> 0 | C17: ='analyse de risque'!C34 -> 0 | D17: ='analyse de risque'!P34 -> 0
B18: ='analyse de risque'!B35 -> 0 | C18: ='analyse de risque'!C35 -> 0 | D18: ='analyse de risque'!P35 -> 0
B19: ='analyse de risque'!B36 -> 0 | C19: ='analyse de risque'!C36 -> 0 | D19: ='analyse de risque'!P36 -> 0
B20: ='analyse de risque'!B37 -> 0 | C20: ='analyse de risque'!C37 -> 0 | D20: ='analyse de risque'!P37 -> 0
B21: ='analyse de risque'!B38 -> 0 | C21: ='analyse de risque'!C38 -> 0 | D21: ='analyse de risque'!P38 -> 0
B22: ='analyse de risque'!B39 -> 0 | C22: ='analyse de risque'!C39 -> 0 | D22: ='analyse de risque'!P39 -> 0
B23: ='analyse de risque'!B40 -> 0 | C23: ='analyse de risque'!C40 -> 0 | D23: ='analyse de risque'!P40 -> 0
B24: ='analyse de risque'!B41 -> 0 | C24: ='analyse de risque'!C41 -> 0 | D24: ='analyse de risque'!P41 -> 0
B25: ='analyse de risque'!B42 -> 0 | C25: ='analyse de risque'!C42 -> 0 | D25: ='analyse de risque'!P42 -> 0
... B33: ='analyse de risque'!B50 -> 0 | C33: ='analyse de risque'!C50 -> 0 | D33: ='analyse de risque'!P50 -> 0
