Workbook
Name ANALYTES: #REF!

Sheet PB7
C3: paramètre | D3: -1 | E3: 1 | H3: paramètre équipement | O3: Y | V3: 0 | W3: =AC44 -> 0.53619558
C4: T°C lavage | D4: 90 | E4: 95 | G4: essai | H4: =C4 -> T°C lavage | I4: =C5 -> durée (min) | J4: =C6 -> [X] | K4: =C7 -> durée rinçage | L4: =C8 -> T°C rinçage | M4: =C9 -> durée séchage | N4: =C10 -> 0 | O4: COT | S4: Tolérance - | T4: 198 | U4: =T4 -> 198 | V4: 0 | W4: =W3 -> 0.53619558
C5: durée (min) | D5: 55 | E5: 65 | G5: 1 | H5: 1 | I5: 1 | J5: 1 | K5: -1 | L5: 1 | M5: -1 | N5: -1 | O5: =200+RANDBETWEEN(-1,1) -> 199 | S5: Tolérance + | T5: 202 | U5: =T5 -> 202 | W5: =AVERAGE(O5:P5) -> 199 | Y5: =SUM(O5:P5) -> 199
C6: [X] | D6: 24 | E6: 26 | G6: 2 | H6: -1 | I6: 1 | J6: 1 | K6: 1 | L6: -1 | M6: 1 | N6: -1 | O6: =200+RANDBETWEEN(-1,1) -> 201 | U6: =+T4 -> 198 | W6: =AVERAGE(O6:P6) -> 201 | Y6: =SUM(O6:P6) -> 201
C7: durée rinçage | D7: 20 | E7: 30 | G7: 3 | H7: -1 | I7: -1 | J7: 1 | K7: 1 | L7: 1 | M7: -1 | N7: 1 | O7: =200+RANDBETWEEN(-1,1) -> 201 | S7: moyenne | T7: =AVERAGE(O5:P12) -> 200.625 | W7: =AVERAGE(O7:P7) -> 201 | Y7: =SUM(O7:P7) -> 201
C8: T°C rinçage | D8: 45 | E8: 55 | G8: 4 | H8: 1 | I8: -1 | J8: -1 | K8: 1 | L8: 1 | M8: 1 | N8: -1 | O8: =200+RANDBETWEEN(-1,1) -> 201 | S8: S² totale | T8: =K36 -> 0.55357143 | W8: =AVERAGE(O8:P8) -> 201 | Y8: =SUM(O8:P8) -> 201
C9: durée séchage | D9: 45 | E9: 55 | G9: 5 | H9: -1 | I9: 1 | J9: -1 | K9: -1 | L9: 1 | M9: 1 | N9: 1 | O9: =200+RANDBETWEEN(-1,1) -> 201 | S9: S totale | T9: =SQRT(T8) -> 0.74402381 | W9: =AVERAGE(O9:P9) -> 201 | Y9: =SUM(O9:P9) -> 201
G10: 6 | H10: 1 | I10: -1 | J10: 1 | K10: -1 | L10: -1 | M10: 1 | N10: 1 | O10: =200+RANDBETWEEN(-1,1) -> 201 | S10: Min | T10: =MIN(O5:P12) -> 199 | W10: =AVERAGE(O10:P10) -> 201 | Y10: =SUM(O10:P10) -> 201
B11: Veuillez étudier de 4 à 7 paramètres avec de "petites" | G11: 7 | H11: 1 | I11: 1 | J11: -1 | K11: 1 | L11: -1 | M11: -1 | N11: 1 | O11: =200+RANDBETWEEN(-1,1) -> 200 | S11: Max | T11: =MAX(O5:P12) -> 201 | W11: =AVERAGE(O11:P11) -> 200 | Y11: =SUM(O11:P11) -> 200
B12: variations cohérentes susceptibles de se produire en routine | G12: 8 | H12: -1 | I12: -1 | J12: -1 | K12: -1 | L12: -1 | M12: -1 | N12: -1 | O12: =200+RANDBETWEEN(-1,1) -> 201 | S12: Cpk | T12: =MIN((T5-T7)/(3*SQRT(T8)),(T7-T4)/(3*SQRT(T8))) -> 0.61601971 | W12: =AVERAGE(O12:P12) -> 201 | Y12: =SUM(O12:P12) -> 201
B13: Puis réaliser les 8 essais aléatoirement | G13: =AVERAGE(W5:W12) -> 200.625 | H13: =SUMPRODUCT(H5:H12,$W5:$W12)/8 -> -0.375 | I13: =SUMPRODUCT(I5:I12,$W5:$W12)/8 -> -0.375 | J13: =SUMPRODUCT(J5:J12,$W5:$W12)/8 -> -0.125 | K13: =SUMPRODUCT(K5:K12,$W5:$W12)/8 -> 0.125 | L13: =SUMPRODUCT(L5:L12,$W5:$W12)/8 -> -0.125 | M13: =SUMPRODUCT(M5:M12,$W5:$W12)/8 -> 0.375 | N13: =SUMPRODUCT(N5:N12,$W5:$W12)/8 -> 0.125
AA14: -3 | AB14: =T$7+AA14*SQRT(T$8) -> 198.39293 | AC14: =NORMDIST(AB14,T$7,SQRT(T$8),0) -> 0.0059565949
AA15: -2.9 | AB15: =T$7+AA15*SQRT(T$8) -> 198.46733 | AC15: =NORMDIST(AB15,T$7,SQRT(T$8),0) -> 0.0080004596 | AH15: =SUM(O11:P11) -> 200
W16: paramètre | X16: effet | Y16: T- | Z16: T+ | AA16: -2.8 | AB16: =T$7+AA16*SQRT(T$8) -> 198.54173 | AC16: =NORMDIST(AB16,T$7,SQRT(T$8),0) -> 0.010638707 | AH16: =SUM(O12:P12) -> 201
W17: =+C4 -> T°C lavage | X17: =H13 -> -0.375 | Y17: =-(T5-T4)/2 -> -2 | Z17: =-Y17 -> 2 | AA17: -2.7 | AB17: =T$7+AA17*SQRT(T$8) -> 198.61614 | AC17: =NORMDIST(AB17,T$7,SQRT(T$8),0) -> 0.014006185 | AG17: =SUM(M11:W11) -> 601
X18: =-X17 -> 0.375 | Y18: =Y17 -> -2 | Z18: =Z17 -> 2 | AA18: -2.6 | AB18: =T$7+AA18*SQRT(T$8) -> 198.69054 | AC18: =NORMDIST(AB18,T$7,SQRT(T$8),0) -> 0.018256095
W19: =+C5 -> durée (min) | X19: =I13 -> -0.375 | Y19: =Y18 -> -2 | Z19: =Z18 -> 2 | AA19: -2.5 | AB19: =T$7+AA19*SQRT(T$8) -> 198.76494 | AC19: =NORMDIST(AB19,T$7,SQRT(T$8),0) -> 0.02355879
X20: =-X19 -> 0.375 | Y20: =Y19 -> -2 | Z20: =Z19 -> 2 | AA20: -2.4 | AB20: =T$7+AA20*SQRT(T$8) -> 198.83934 | AC20: =NORMDIST(AB20,T$7,SQRT(T$8),0) -> 0.030099212
W21: =+C6 -> [X] | X21: =J13 -> -0.125 | Y21: =Y20 -> -2 | Z21: =Z20 -> 2 | AA21: -2.3 | AB21: =T$7+AA21*SQRT(T$8) -> 198.91375 | AC21: =NORMDIST(AB21,T$7,SQRT(T$8),0) -> 0.038072757
X22: =-X21 -> 0.125 | Y22: =Y21 -> -2 | Z22: =Z21 -> 2 | AA22: -2.2 | AB22: =T$7+AA22*SQRT(T$8) -> 198.98815 | AC22: =NORMDIST(AB22,T$7,SQRT(T$8),0) -> 0.047679379
W23: =+C7 -> durée rinçage | X23: =K13 -> 0.125 | Y23: =Y22 -> -2 | Z23: =Z22 -> 2 | AA23: -2.1 | AB23: =T$7+AA23*SQRT(T$8) -> 199.06255 | AC23: =NORMDIST(AB23,T$7,SQRT(T$8),0) -> 0.059115845
X24: =-X23 -> -0.125 | Y24: =Y23 -> -2 | Z24: =Z23 -> 2 | AA24: -2 | AB24: =T$7+AA24*SQRT(T$8) -> 199.13695 | AC24: =NORMDIST(AB24,T$7,SQRT(T$8),0) -> 0.072566181
W25: =+C8 -> T°C rinçage | X25: =L13 -> -0.125 | Y25: =Y24 -> -2 | Z25: =Z24 -> 2 | AA25: -1.9 | AB25: =T$7+AA25*SQRT(T$8) -> 199.21135 | AC25: =NORMDIST(AB25,T$7,SQRT(T$8),0) -> 0.088190477
X26: =-X25 -> 0.125 | Y26: =Y25 -> -2 | Z26: =Z25 -> 2 | AA26: -1.8 | AB26: =T$7+AA26*SQRT(T$8) -> 199.28576 | AC26: =NORMDIST(AB26,T$7,SQRT(T$8),0) -> 0.10611241
W27: =+C9 -> durée séchage | X27: =M13 -> 0.375 | Y27: =Y26 -> -2 | Z27: =Z26 -> 2 | AA27: -1.7 | AB27: =T$7+AA27*SQRT(T$8) -> 199.36016 | AC27: =NORMDIST(AB27,T$7,SQRT(T$8),0) -> 0.12640601
X28: =-X27 -> -0.375 | Y28: =Y27 -> -2 | Z28: =Z27 -> 2 | AA28: -1.6 | AB28: =T$7+AA28*SQRT(T$8) -> 199.43456 | AC28: =NORMDIST(AB28,T$7,SQRT(T$8),0) -> 0.14908237
W29: =+C10 -> 0 | X29: =N13 -> 0.125 | Y29: =Y28 -> -2 | Z29: =Z28 -> 2 | AA29: -1.5 | AB29: =T$7+AA29*SQRT(T$8) -> 199.50896 | AC29: =NORMDIST(AB29,T$7,SQRT(T$8),0) -> 0.17407722
X30: =-X29 -> -0.125 | Y30: =Y29 -> -2 | Z30: =Z29 -> 2 | AA30: -1.4 | AB30: =T$7+AA30*SQRT(T$8) -> 199.58337 | AC30: =NORMDIST(AB30,T$7,SQRT(T$8),0) -> 0.20124015
AA31: -1.3 | AB31: =T$7+AA31*SQRT(T$8) -> 199.65777 | AC31: =NORMDIST(AB31,T$7,SQRT(T$8),0) -> 0.23032676
AA32: -1.2 | AB32: =T$7+AA32*SQRT(T$8) -> 199.73217 | AC32: =NORMDIST(AB32,T$7,SQRT(T$8),0) -> 0.26099441
AA33: -1.1 | AB33: =T$7+AA33*SQRT(T$8) -> 199.80657 | AC33: =NORMDIST(AB33,T$7,SQRT(T$8),0) -> 0.2928027
F34: Etape d'identification | I34: ANOVA | AA34: -1 | AB34: =T$7+AA34*SQRT(T$8) -> 199.88098 | AC34: =NORMDIST(AB34,T$7,SQRT(T$8),0) -> 0.32521906
F35: Origine | G35: niveau | H35: effet | I35: SCE | J35: ddl | K35: CM | L35: Fobs | M35: F5% | N35: contrib% | O35: équiv β | P35: diff 1-β | AA35: -0.9 | AB35: =T$7+AA35*SQRT(T$8) -> 199.95538 | AC35: =NORMDIST(AB35,T$7,SQRT(T$8),0) -> 0.35763002
F36: Total | G36: =COUNT(O5:P12) -> 8 | H36: =G13 -> 200.625 | I36: =DEVSQ(O5:P12) -> 3.875 | J36: =G36-1 -> 7 | K36: =I36/J36 -> 0.55357143 | L36: x | M36: x | N36: =SUM(N38:N45) -> 1 | O36: x | P36: x | AA36: -0.8 | AB36: =T$7+AA36*SQRT(T$8) -> 200.02978 | AC36: =NORMDIST(AB36,T$7,SQRT(T$8),0) -> 0.38935791
F37: modèle | G37: x | H37: x | I37: =SUM(I39:I45) -> 7.75 | J37: =SUM(J39:J45) -> 7 | K37: =I37/J37 -> 1.1071429 | L37: =K37/K38 -> #DIV/0! | M37: =FINV(0.05,J37,J38) -> #NUM! | N37: =I37/I36 -> 2 | O37: x | P37: x | AA37: -0.7 | AB37: =T$7+AA37*SQRT(T$8) -> 200.10418 | AC37: =NORMDIST(AB37,T$7,SQRT(T$8),0) -> 0.41968272
F38: répéta | G38: x | H38: x | I38: =I36-I37 -> -3.875 | J38: =J36-J37 -> 0 | K38: =I38/J38 -> #DIV/0! | L38: x | M38: x | N38: =I38/I36 -> -1 | O38: x | P38: x | AA38: -0.6 | AB38: =T$7+AA38*SQRT(T$8) -> 200.17859 | AC38: =NORMDIST(AB38,T$7,SQRT(T$8),0) -> 0.4478682
F39: =C4 -> T°C lavage | G39: 2 | H39: =H13 -> -0.375 | I39: =H39^2*8*2 -> 2.25 | J39: =G39-1 -> 1 | K39: =I39/J39 -> 2.25 | L39: =K39/K$38 -> #DIV/0! | M39: =FINV(0.05,J39,J$38) -> #NUM! | N39: =I39/$I$36 -> 0.58064516 | O39: =1-FDIST(M39/L39,J39,J$38) -> #NUM! | P39: =1-O39 -> #NUM! | Q39: =M39*K38/I36 -> #NUM! | AA39: -0.5 | AB39: =T$7+AA39*SQRT(T$8) -> 200.25299 | AC39: =NORMDIST(AB39,T$7,SQRT(T$8),0) -> 0.47319094
F40: =C5 -> durée (min) | G40: 2 | H40: =I13 -> -0.375 | I40: =H40^2*8*2 -> 2.25 | J40: =G40-1 -> 1 | K40: =I40/J40 -> 2.25 | L40: =K40/K$38 -> #DIV/0! | M40: =FINV(0.05,J40,J$38) -> #NUM! | N40: =I40/$I$36 -> 0.58064516 | O40: =1-FDIST(M40/L40,J40,J$38) -> #NUM! | P40: =1-O40 -> #NUM! | Q40: =Q39 -> #NUM! | AA40: -0.4 | AB40: =T$7+AA40*SQRT(T$8) -> 200.32739 | AC40: =NORMDIST(AB40,T$7,SQRT(T$8),0) -> 0.49497091
F41: =C6 -> [X] | G41: 2 | H41: =J13 -> -0.125 | I41: =H41^2*8*2 -> 0.25 | J41: =G41-1 -> 1 | K41: =I41/J41 -> 0.25 | L41: =K41/K$38 -> #DIV/0! | M41: =FINV(0.05,J41,J$38) -> #NUM! | N41: =I41/$I$36 -> 0.064516129 | O41: =1-FDIST(M41/L41,J41,J$38) -> #NUM! | P41: =1-O41 -> #NUM! | Q41: =Q40 -> #NUM! | AA41: -0.3 | AB41: =T$7+AA41*SQRT(T$8) -> 200.40179 | AC41: =NORMDIST(AB41,T$7,SQRT(T$8),0) -> 0.51260163
F42: =C7 -> durée rinçage | G42: 2 | H42: =K13 -> 0.125 | I42: =H42^2*8*2 -> 0.25 | J42: =G42-1 -> 1 | K42: =I42/J42 -> 0.25 | L42: =K42/K$38 -> #DIV/0! | M42: =FINV(0.05,J42,J$38) -> #NUM! | N42: =I42/$I$36 -> 0.064516129 | O42: =1-FDIST(M42/L42,J42,J$38) -> #NUM! | P42: =1-O42 -> #NUM! | Q42: =Q41 -> #NUM! | AA42: -0.2 | AB42: =T$7+AA42*SQRT(T$8) -> 200.4762 | AC42: =NORMDIST(AB42,T$7,SQRT(T$8),0) -> 0.5255782
...

Sheet Récapitulatif
B1: Profil d'exactitude
B2: Probabilité tolérance (bêta) | C2: =#REF! -> #REF! | E2: 20 | F2: 100
B3: Limite d'acceptabilité | C3: =#REF! -> #REF! | E3: 0.01 | F3: =E3*F2/E2 -> 0.05
B5: Niveaux | C5: Niveau A | D5: Niveau B | E5: Niveau C | F5: Niveau D | G5: Niveau E
A6: 2 | B6: Valeur cible | C6: ='80%'!B2 -> 80 | D6: ='90%'!B2 -> 90 | E6: ='100%'!B2 -> 100 | F6: ='110%'!B2 -> 110 | G6: ='120%'!B2 -> 120
A7: 30 | B7: Moyenne niveau | C7: ='80%'!B22 -> #REF! | D7: ='90%'!B22 -> #REF! | E7: ='100%'!B22 -> #REF! | F7: ='110%'!B22 -> #REF! | G7: ='120%'!B22 -> #REF! | K7: =ADDRESS($A8,2,,,C$5) -> 'Niveau A'!$B$31
A8: 31 | B8: Ecart-type de répétabilité (sr) | C8: ='80%'!B23 -> #DIV/0! | D8: ='90%'!B23 -> #DIV/0! | E8: ='100%'!B23 -> #DIV/0! | F8: ='110%'!B23 -> #DIV/0! | G8: ='120%'!B23 -> #DIV/0!
A9: 32 | B9: Ecart-type inter-séries (sL) | C9: ='80%'!B24 -> #REF! | D9: ='90%'!B24 -> #REF! | E9: ='100%'!B24 -> #REF! | F9: ='110%'!B24 -> #REF! | G9: ='120%'!B24 -> #REF!
A10: 33 | B10: Ecart-type de fidélité (sFI) | C10: ='80%'!B25 -> #DIV/0! | D10: ='90%'!B25 -> #DIV/0! | E10: ='100%'!B25 -> #DIV/0! | F10: ='110%'!B25 -> #DIV/0! | G10: ='120%'!B25 -> #DIV/0!
A11: 37 | B11: Rapport des variances (R) | C11: ='80%'!B29 -> #REF! | D11: ='90%'!B29 -> #REF! | E11: ='100%'!B29 -> #REF! | F11: ='110%'!B29 -> #REF! | G11: ='120%'!B29 -> #REF!
A12: 39 | B12: Coefficient intermédiaire | C12: ='80%'!B31 -> #REF! | D12: ='90%'!B31 -> #REF! | E12: ='100%'!B31 -> #REF! | F12: ='110%'!B31 -> #REF! | G12: ='120%'!B31 -> #REF!
A13: 40 | B13: Nombre de degrés liberté | C13: ='80%'!B32 -> #REF! | D13: ='90%'!B32 -> #REF! | E13: ='100%'!B32 -> #REF! | F13: ='110%'!B32 -> #REF! | G13: ='120%'!B32 -> #REF!
A14: 47 | B14: Valeur basse tolérance | C14: ='80%'!B39 -> #REF! | D14: ='90%'!B39 -> #REF! | E14: ='100%'!B39 -> #REF! | F14: ='110%'!B39 -> #REF! | G14: ='120%'!B39 -> #REF!
A15: 48 | B15: Valeur haute tolérance | C15: ='80%'!B40 -> #REF! | D15: ='90%'!B40 -> #REF! | E15: ='100%'!B40 -> #REF! | F15: ='110%'!B40 -> #REF! | G15: ='120%'!B40 -> #REF!
A16: 35 | B16: Biais (%) | C16: ='80%'!B27 -> #REF! | D16: ='90%'!B27 -> #REF! | E16: ='100%'!B27 -> #REF! | F16: ='110%'!B27 -> #REF! | G16: ='120%'!B27 -> #REF!
B17: Recouvrement (justesse) | C17: =C7/C$6 -> #REF! | D17: =D7/D$6 -> #REF! | E17: =E7/E$6 -> #REF! | F17: =F7/F$6 -> #REF! | G17: =G7/G$6 -> #REF!
B18: Limite basse tolérance (%) | C18: =C14/C$6 -> #REF! | D18: =D14/D$6 -> #REF! | E18: =E14/E$6 -> #REF! | F18: =F14/F$6 -> #REF! | G18: =G14/G$6 -> #REF!
B19: Limite haute tolérance (%) | C19: =C15/C$6 -> #REF! | D19: =D15/D$6 -> #REF! | E19: =E15/E$6 -> #REF! | F19: =F15/F$6 -> #REF! | G19: =G15/G$6 -> #REF!
B20: Limite d'acceptabilité basse | C20: =1-$C$3 -> #REF! | D20: =1-$C$3 -> #REF! | E20: =1-$C$3 -> #REF! | F20: =1-$C$3 -> #REF! | G20: =1-$C$3 -> #REF!
B21: Limite d'acceptabilité haute | C21: =1+$C$3 -> #REF! | D21: =1+$C$3 -> #REF! | E21: =1+$C$3 -> #REF! | F21: =1+$C$3 -> #REF! | G21: =1+$C$3 -> #REF!
B27: Incertitude
B28: Ecart-type de l'IT (sIT) | C28: =C$12*C$10 -> #REF! | D28: =D$12*D$10 -> #REF! | E28: =E$12*E$10 -> #REF! | F28: =F$12*F$10 -> #REF! | G28: =G$12*G$10 -> #REF!
B29: Incertitude élargie relative | C29: =2*C28/C7 -> #REF! | D29: =2*D28/D7 -> #REF! | E29: =2*E28/E7 -> #REF! | F29: =2*F28/F7 -> #REF! | G29: =2*G28/G7 -> #REF!

Sheet 80%
A1: Niveau A
A2: Valeur cible | B2: 80
B4: Répétition 1 | C4: Répétition 2 | D4: Répétition 3 | E4: Répétition 4 | F4: Répétition 5 | H4: nk | I4: SCEk
A5: Jour (Série) 1 | B5: =#REF!*$B$2 -> #REF! | C5: =#REF!*$B$2 -> #REF! | H5: =COUNT(B5:F5) -> 0 | I5: =IF(H5=0,"",DEVSQ(B5:F5))
A6: Jour (Série) 2
A7: Jour (Série) 3 | B7: =#REF!*$B$2 -> #REF! | C7: =#REF!*$B$2 -> #REF! | H7: =COUNT(B7:F7) -> 0 | I7: =IF(H7=0,"",DEVSQ(B7:F7))
A8: Jour (Série) 4 | B8: =#REF!*$B$2 -> #REF! | C8: =#REF!*$B$2 -> #REF! | H8: =COUNT(B8:F8) -> 0 | I8: =IF(H8=0,"",DEVSQ(B8:F8))
A9: Jour (Série) 5 | B9: =#REF!*$B$2 -> #REF! | C9: =#REF!*$B$2 -> #REF! | H9: =COUNT(B9:F9) -> 0 | I9: =IF(H9=0,"",DEVSQ(B9:F9))
A11: Nombre de séries (K) | B11: =COUNT(B5:B9) -> 0
A12: Nombre de mesures (IK) | B12: =COUNT(B5:F9) -> 0
A13: Nombre de répétitions (I) | B13: =IF(H5*B11<>B12,"Calcul impossible",H5) -> 0
A14: SCE résiduelle | B14: =SUM(I5:I9) -> 0
A15: SCE totale | B15: =DEVSQ(B5:F9) -> #REF!
A16: SCE inter-séries | B16: =B15-B14 -> #REF!
A17: Valeur intermédiaire de s²L | B17: =((B16/(B11-1))-B18)/B13 -> #REF!
A18: Variance de répétabilité (s²r) | B18: =B14/(B12-B11) -> #DIV/0!
A19: Variance inter-séries (s²L) | B19: =IF(B17<0,0,B17) -> #REF!
A20: Variance de fidélité (s²FI) | B20: =SUM(B18:B19) -> #DIV/0!
A21: Fidélité
A22: Moyenne niveau | B22: =AVERAGE(B5:F9) -> #REF!
A23: Ecart-type de répétabilité (sr) | B23: =SQRT(B18) -> #DIV/0!
A24: Ecart-type inter-séries (sL) | B24: =SQRT(B19) -> #REF!
A25: Ecart-type de fidélité (sFI) | B25: =SQRT(B20) -> #DIV/0!
A26: Justesse
A27: Biais (%) | B27: =B22/B2-1 -> #REF!
A28: Facteur de couverture
A29: Rapport des variances (R) | B29: =B19/B18 -> #REF!
A30: Coefficient B² | B30: =(B29+1)/(B13*B29+1) -> #REF!
A31: Coefficient intermédiaire | B31: =SQRT(1+1/(B12*B30)) -> #REF!
A32: Nombre de degrés liberté | B32: =(B29+1)^2/((B29+1/B13)^2/(B11-1)+(1-1/B13)/B12) -> #REF!
A33: Probabilité tolérance (bêta) | B33: =Récapitulatif!C2 -> #REF!
A34: t Student bas | B34: =TINV(1-B33,ROUNDDOWN(B32,0)) -> #REF!
A35: t Student haut | B35: =TINV(1-B33,ROUNDUP(B32,0)) -> #REF!
A36: t Student interpolé | B36: =B34-(B34-B35)*(B32-ROUNDDOWN(B32,0)) -> #REF!
A37: Facteur de couverture (ktol) | B37: =B36*B31 -> #REF!
A38: Intervalle de tolérance
A39: Valeur basse tolérance | B39: =B22-B37*B25 -> #REF!
A40: Valeur haute tolérance | B40: =B22+B37*B25 -> #REF!

Sheet 90%
A1: Niveau B
A2: Valeur cible | B2: 90
B4: Répétition 1 | C4: Répétition 2 | D4: Répétition 3 | E4: Répétition 4 | F4: Répétition 5 | H4: nk | I4: SCEk
A5: Jour (Série) 1 | B5: =#REF!*$B$2 -> #REF! | C5: =#REF!*$B$2 -> #REF! | H5: =COUNT(B5:F5) -> 0 | I5: =IF(H5=0,"",DEVSQ(B5:F5))
A6: Jour (Série) 2 | B6: =#REF!*$B$2 -> #REF! | C6: =#REF!*$B$2 -> #REF! | H6: =COUNT(B6:F6) -> 0 | I6: =IF(H6=0,"",DEVSQ(B6:F6))
A7: Jour (Série) 3 | I7: =IF(H7=0,"",DEVSQ(B7:F7))
A8: Jour (Série) 4 | B8: =#REF!*$B$2 -> #REF! | C8: =#REF!*$B$2 -> #REF! | H8: =COUNT(B8:F8) -> 0 | I8: =IF(H8=0,"",DEVSQ(B8:F8))
A9: Jour (Série) 5 | B9: =#REF!*$B$2 -> #REF! | C9: =#REF!*$B$2 -> #REF! | H9: =COUNT(B9:F9) -> 0 | I9: =IF(H9=0,"",DEVSQ(B9:F9))
A11: Nombre de séries (K) | B11: =COUNT(B5:B9) -> 0
A12: Nombre de mesures (IK) | B12: =COUNT(B5:F9) -> 0
A13: Nombre de répétitions (I) | B13: =IF(H5*B11<>B12,"Calcul impossible",H5) -> 0
A14: SCE résiduelle | B14: =SUM(I5:I9) -> 0
A15: SCE totale | B15: =DEVSQ(B5:F9) -> #REF!
A16: SCE inter-séries | B16: =B15-B14 -> #REF!
A17: Valeur intermédiaire de s²L | B17: =((B16/(B11-1))-B18)/B13 -> #REF!
A18: Variance de répétabilité (s²r) | B18: =B14/(B12-B11) -> #DIV/0!
A19: Variance inter-séries (s²L) | B19: =IF(B17<0,0,B17) -> #REF!
A20: Variance de fidélité (s²FI) | B20: =SUM(B18:B19) -> #DIV/0!
A21: Fidélité
A22: Moyenne niveau | B22: =AVERAGE(B5:F9) -> #REF!
A23: Ecart-type de répétabilité (sr) | B23: =SQRT(B18) -> #DIV/0!
A24: Ecart-type inter-séries (sL) | B24: =SQRT(B19) -> #REF!
A25: Ecart-type de fidélité (sFI) | B25: =SQRT(B20) -> #DIV/0!
A26: Justesse
A27: Biais (%) | B27: =B22/B2-1 -> #REF!
A28: Facteur de couverture
A29: Rapport des variances (R) | B29: =B19/B18 -> #REF!
A30: Coefficient B² | B30: =(B29+1)/(B13*B29+1) -> #REF!
A31: Coefficient intermédiaire | B31: =SQRT(1+1/(B12*B30)) -> #REF!
A32: Nombre de degrés liberté | B32: =(B29+1)^2/((B29+1/B13)^2/(B11-1)+(1-1/B13)/B12) -> #REF!
A33: Probabilité tolérance (bêta) | B33: =Récapitulatif!C2 -> #REF!
A34: t Student bas | B34: =TINV(1-B33,ROUNDDOWN(B32,0)) -> #REF!
A35: t Student haut | B35: =TINV(1-B33,ROUNDUP(B32,0)) -> #REF!
A36: t Student interpolé | B36: =B34-(B34-B35)*(B32-ROUNDDOWN(B32,0)) -> #REF!
A37: Facteur de couverture (ktol) | B37: =B36*B31 -> #REF!
A38: Intervalle de tolérance
A39: Valeur basse tolérance | B39: =B22-B37*B25 -> #REF!
A40: Valeur haute tolérance | B40: =B22+B37*B25 -> #REF!

Sheet 100%
A1: Niveau C
A2: Valeur cible | B2: 100
B4: Répétition 1 | C4: Répétition 2 | D4: Répétition 3 | E4: Répétition 4 | F4: Répétition 5 | H4: nk | I4: SCEk
A5: Jour (Série) 1 | B5: =#REF!*$B$2 -> #REF! | C5: =#REF!*$B$2 -> #REF! | H5: =COUNT(B5:F5) -> 0 | I5: =IF(H5=0,"",DEVSQ(B5:F5))
A6: Jour (Série) 2 | B6: =#REF!*$B$2 -> #REF! | C6: =#REF!*$B$2 -> #REF! | H6: =COUNT(B6:F6) -> 0 | I6: =IF(H6=0,"",DEVSQ(B6:F6))
A7: Jour (Série) 3 | B7: =#REF!*$B$2 -> #REF! | C7: =#REF!*$B$2 -> #REF! | H7: =COUNT(B7:F7) -> 0 | I7: =IF(H7=0,"",DEVSQ(B7:F7))
A8: Jour (Série) 4 | I8: =IF(H8=0,"",DEVSQ(B8:F8))
A9: Jour (Série) 5 | B9: =#REF!*$B$2 -> #REF! | C9: =#REF!*$B$2 -> #REF! | H9: =COUNT(B9:F9) -> 0 | I9: =IF(H9=0,"",DEVSQ(B9:F9))
A11: Nombre de séries (K) | B11: =COUNT(B5:B9) -> 0
A12: Nombre de mesures (IK) | B12: =COUNT(B5:F9) -> 0
A13: Nombre de répétitions (I) | B13: =IF(H5*B11<>B12,"Calcul impossible",H5) -> 0
A14: SCE résiduelle | B14: =SUM(I5:I9) -> 0
A15: SCE totale | B15: =DEVSQ(B5:F9) -> #REF!
A16: SCE inter-séries | B16: =B15-B14 -> #REF!
A17: Valeur intermédiaire de s²L | B17: =((B16/(B11-1))-B18)/B13 -> #REF!
A18: Variance de répétabilité (s²r) | B18: =B14/(B12-B11) -> #DIV/0!
A19: Variance inter-séries (s²L) | B19: =IF(B17<0,0,B17) -> #REF!
A20: Variance de fidélité (s²FI) | B20: =SUM(B18:B19) -> #DIV/0!
A21: Fidélité
A22: Moyenne niveau | B22: =AVERAGE(B5:F9) -> #REF!
A23: Ecart-type de répétabilité (sr) | B23: =SQRT(B18) -> #DIV/0!
A24: Ecart-type inter-séries (sL) | B24: =SQRT(B19) -> #REF!
A25: Ecart-type de fidélité (sFI) | B25: =SQRT(B20) -> #DIV/0!
A26: Justesse
A27: Biais (%) | B27: =B22/B2-1 -> #REF!
A28: Facteur de couverture
A29: Rapport des variances (R) | B29: =B19/B18 -> #REF!
A30: Coefficient B² | B30: =(B29+1)/(B13*B29+1) -> #REF!
A31: Coefficient intermédiaire | B31: =SQRT(1+1/(B12*B30)) -> #REF!
A32: Nombre de degrés liberté | B32: =(B29+1)^2/((B29+1/B13)^2/(B11-1)+(1-1/B13)/B12) -> #REF!
A33: Probabilité tolérance (bêta) | B33: =Récapitulatif!C2 -> #REF!
A34: t Student bas | B34: =TINV(1-B33,ROUNDDOWN(B32,0)) -> #REF!
A35: t Student haut | B35: =TINV(1-B33,ROUNDUP(B32,0)) -> #REF!
A36: t Student interpolé | B36: =B34-(B34-B35)*(B32-ROUNDDOWN(B32,0)) -> #REF!
A37: Facteur de couverture (ktol) | B37: =B36*B31 -> #REF!
A38: Intervalle de tolérance
A39: Valeur basse tolérance | B39: =B22-B37*B25 -> #REF!
A40: Valeur haute tolérance | B40: =B22+B37*B25 -> #REF!

Sheet 110%
A1: Niveau D
A2: Valeur cible | B2: 110
B4: Répétition 1 | C4: Répétition 2 | D4: Répétition 3 | E4: Répétition 4 | F4: Répétition 5 | H4: nk | I4: SCEk
A5: Jour (Série) 1 | B5: =#REF!*$B$2 -> #REF! | C5: =#REF!*$B$2 -> #REF! | H5: =COUNT(B5:F5) -> 0 | I5: =IF(H5=0,"",DEVSQ(B5:F5))
A6: Jour (Série) 2 | B6: =#REF!*$B$2 -> #REF! | C6: =#REF!*$B$2 -> #REF! | H6: =COUNT(B6:F6) -> 0 | I6: =IF(H6=0,"",DEVSQ(B6:F6))
A7: Jour (Série) 3 | B7: =#REF!*$B$2 -> #REF! | C7: =#REF!*$B$2 -> #REF! | H7: =COUNT(B7:F7) -> 0 | I7: =IF(H7=0,"",DEVSQ(B7:F7))
A8: Jour (Série) 4 | B8: =#REF!*$B$2 -> #REF! | C8: =#REF!*$B$2 -> #REF! | H8: =COUNT(B8:F8) -> 0 | I8: =IF(H8=0,"",DEVSQ(B8:F8))
A9: Jour (Série) 5 | I9: =IF(H9=0,"",DEVSQ(B9:F9))
A11: Nombre de séries (K) | B11: =COUNT(B5:B9) -> 0
A12: Nombre de mesures (IK) | B12: =COUNT(B5:F9) -> 0
A13: Nombre de répétitions (I) | B13: =IF(H5*B11<>B12,"Calcul impossible",H5) -> 0
A14: SCE résiduelle | B14: =SUM(I5:I9) -> 0
A15: SCE totale | B15: =DEVSQ(B5:F9) -> #REF!
A16: SCE inter-séries | B16: =B15-B14 -> #REF!
A17: Valeur intermédiaire de s²L | B17: =((B16/(B11-1))-B18)/B13 -> #REF!
A18: Variance de répétabilité (s²r) | B18: =B14/(B12-B11) -> #DIV/0!
A19: Variance inter-séries (s²L) | B19: =IF(B17<0,0,B17) -> #REF!
A20: Variance de fidélité (s²FI) | B20: =SUM(B18:B19) -> #DIV/0!
A21: Fidélité
A22: Moyenne niveau | B22: =AVERAGE(B5:F9) -> #REF!
A23: Ecart-type de répétabilité (sr) | B23: =SQRT(B18) -> #DIV/0!
A24: Ecart-type inter-séries (sL) | B24: =SQRT(B19) -> #REF!
A25: Ecart-type de fidélité (sFI) | B25: =SQRT(B20) -> #DIV/0!
A26: Justesse
A27: Biais (%) | B27: =B22/B2-1 -> #REF!
A28: Facteur de couverture
A29: Rapport des variances (R) | B29: =B19/B18 -> #REF!
A30: Coefficient B² | B30: =(B29+1)/(B13*B29+1) -> #REF!
A31: Coefficient intermédiaire | B31: =SQRT(1+1/(B12*B30)) -> #REF!
A32: Nombre de degrés liberté | B32: =(B29+1)^2/((B29+1/B13)^2/(B11-1)+(1-1/B13)/B12) -> #REF!
A33: Probabilité tolérance (bêta) | B33: =Récapitulatif!C2 -> #REF!
A34: t Student bas | B34: =TINV(1-B33,ROUNDDOWN(B32,0)) -> #REF!
A35: t Student haut | B35: =TINV(1-B33,ROUNDUP(B32,0)) -> #REF!
A36: t Student interpolé | B36: =B34-(B34-B35)*(B32-ROUNDDOWN(B32,0)) -> #REF!
A37: Facteur de couverture (ktol) | B37: =B36*B31 -> #REF!
A38: Intervalle de tolérance
A39: Valeur basse tolérance | B39: =B22-B37*B25 -> #REF!
A40: Valeur haute tolérance | B40: =B22+B37*B25 -> #REF!

Sheet 120%
A1: Niveau E
A2: Valeur cible | B2: 120
B4: Répétition 1 | C4: Répétition 2 | D4: Répétition 3 | E4: Répétition 4 | F4: Répétition 5 | H4: nk | I4: SCEk
A5: Jour (Série) 1
A6: Jour (Série) 2 | B6: =#REF!*$B$2 -> #REF! | C6: =#REF!*$B$2 -> #REF! | H6: =COUNT(B6:F6) -> 0 | I6: =IF(H6=0,"",DEVSQ(B6:F6))
A7: Jour (Série) 3 | B7: =#REF!*$B$2 -> #REF! | C7: =#REF!*$B$2 -> #REF! | H7: =COUNT(B7:F7) -> 0 | I7: =IF(H7=0,"",DEVSQ(B7:F7))
A8: Jour (Série) 4 | B8: =#REF!*$B$2 -> #REF! | C8: =#REF!*$B$2 -> #REF! | H8: =COUNT(B8:F8) -> 0 | I8: =IF(H8=0,"",DEVSQ(B8:F8))
A9: Jour (Série) 5 | B9: =#REF!*$B$2 -> #REF! | C9: =#REF!*$B$2 -> #REF! | H9: =COUNT(B9:F9) -> 0 | I9: =IF(H9=0,"",DEVSQ(B9:F9))
A11: Nombre de séries (K) | B11: =COUNT(B5:B9) -> 0
A12: Nombre de mesures (IK) | B12: =COUNT(B5:F9) -> 0
A13: Nombre de répétitions (I) | B13: =IF(H6*B11<>B12,"Calcul impossible",H6) -> 0
A14: SCE résiduelle | B14: =SUM(I5:I9) -> 0
A15: SCE totale | B15: =DEVSQ(B5:F9) -> #REF!
A16: SCE inter-séries | B16: =B15-B14 -> #REF!
A17: Valeur intermédiaire de s²L | B17: =((B16/(B11-1))-B18)/B13 -> #REF!
A18: Variance de répétabilité (s²r) | B18: =B14/(B12-B11) -> #DIV/0!
A19: Variance inter-séries (s²L) | B19: =IF(B17<0,0,B17) -> #REF!
A20: Variance de fidélité (s²FI) | B20: =SUM(B18:B19) -> #DIV/0!
A21: Fidélité
A22: Moyenne niveau | B22: =AVERAGE(B5:F9) -> #REF!
A23: Ecart-type de répétabilité (sr) | B23: =SQRT(B18) -> #DIV/0!
A24: Ecart-type inter-séries (sL) | B24: =SQRT(B19) -> #REF!
A25: Ecart-type de fidélité (sFI) | B25: =SQRT(B20) -> #DIV/0!
A26: Justesse
A27: Biais (%) | B27: =B22/B2-1 -> #REF!
A28: Facteur de couverture
A29: Rapport des variances (R) | B29: =B19/B18 -> #REF!
A30: Coefficient B² | B30: =(B29+1)/(B13*B29+1) -> #REF!
A31: Coefficient intermédiaire | B31: =SQRT(1+1/(B12*B30)) -> #REF!
A32: Nombre de degrés liberté | B32: =(B29+1)^2/((B29+1/B13)^2/(B11-1)+(1-1/B13)/B12) -> #REF!
A33: Probabilité tolérance (bêta) | B33: =Récapitulatif!C2 -> #REF!
A34: t Student bas | B34: =TINV(1-B33,ROUNDDOWN(B32,0)) -> #REF!
A35: t Student haut | B35: =TINV(1-B33,ROUNDUP(B32,0)) -> #REF!
A36: t Student interpolé | B36: =B34-(B34-B35)*(B32-ROUNDDOWN(B32,0)) -> #REF!
A37: Facteur de couverture (ktol) | B37: =B36*B31 -> #REF!
A38: Intervalle de tolérance
A39: Valeur basse tolérance | B39: =B22-B37*B25 -> #REF!
A40: Valeur haute tolérance | B40: =B22+B37*B25 -> #REF!
