Workbook

Sheet Mode d'emploi
A1: AVERTISSEMENT
A2: Avant d'utiliser ce classeur, en faire une copie.
A3: Ces feuilles de calcul sont libres d'emploi.
A4: Elles ne sont fournies qu'à titre indicatif et sans garantie pour faciliter la mise en œuvre de la norme V03-110.
A5: L'Afnor décline toute responsabilité quant aux résultats obtenus ou aux conséquences résultant d'un usage inapproprié.
A6: Afin d'améliorer ce programme, merci de signaler toute erreur à max.feinberg@inra.paris.fr.
A7: Mode d'emploi
A8: 1) Remplir chaque feuille "Niveau" avec les données obtenues par prédiction inverse.
A9: Pour cela utiliser les cases dont le fond est blanc. Elles ne sont pas protégées. Si elles contiennent déjà des données, les effacer au préalable.
A10: Respecter la disposition Jour/Répétition prévue des données.
A11: 2) Dans chaque feuille "Niveau", saisir la valeur de référence dans la case "Valeur cible"
A12: 3) Remplir autant de feuilles "Niveau" qu'il y a de niveaux de concentration dans le plan de validation (6 max.)
... A21: Le t de Student est calculé par interpolation linéaire pour tenir compte du nombre de degrés de liberté.

Sheet Récapitulatif
B1: Profil d'exactitude
B2: Probabilité tolérance (bêta) | C2: 0.99 | E2: 20 | F2: 100
B3: Limite d'acceptabilité | C3: 0.1 | E3: 0.01 | F3: =E3*F2/E2 -> 0.05
B5: Niveaux | C5: Niveau A | D5: Niveau B | E5: Niveau C | F5: Niveau D | G5: Niveau E | H5: Niveau F | I5: Niveau G
A6: 2 | B6: =INDIRECT(ADDRESS(A6,1,,,$C$5)) -> Valeur cible | C6: =INDIRECT(ADDRESS($A6,2,,,C$5)) -> 2.00799 | D6: =INDIRECT(ADDRESS($A6,2,,,D$5)) -> 4.01598 | E6: =INDIRECT(ADDRESS($A6,2,,,E$5)) -> 8.03196 | F6: =INDIRECT(ADDRESS($A6,2,,,F$5)) -> 10.03995 | G6: =INDIRECT(ADDRESS($A6,2,,,G$5)) -> 12.04794 | H6: =INDIRECT(ADDRESS($A6,2,,,H$5)) -> 16.06392 | I6: =INDIRECT(ADDRESS($A6,2,,,I$5)) -> 20.0799
A7: 30 | B7: =INDIRECT(ADDRESS(A7,1,,,$C$5)) -> Moyenne niveau | C7: =INDIRECT(ADDRESS($A7,2,,,C$5)) -> 2.0176632 | D7: =INDIRECT(ADDRESS($A7,2,,,D$5)) -> 4.0165513 | E7: =INDIRECT(ADDRESS($A7,2,,,E$5)) -> 8.0071118 | F7: =INDIRECT(ADDRESS($A7,2,,,F$5)) -> 10.03294 | G7: =INDIRECT(ADDRESS($A7,2,,,G$5)) -> 12.052905 | H7: =INDIRECT(ADDRESS($A7,2,,,H$5)) -> 16.100244 | I7: =INDIRECT(ADDRESS($A7,2,,,I$5)) -> 20.060224 | M7: =ADDRESS($A8,2,,,C$5) -> 'Niveau A'!$B$31
A8: 31 | B8: =INDIRECT(ADDRESS(A8,1,,,$C$5)) -> Ecart-type de répétabilité (sr) | C8: =INDIRECT(ADDRESS($A8,2,,,C$5)) -> 0.0038894619 | D8: =INDIRECT(ADDRESS($A8,2,,,D$5)) -> 0.0063060196 | E8: =INDIRECT(ADDRESS($A8,2,,,E$5)) -> 0.010975756 | F8: =INDIRECT(ADDRESS($A8,2,,,F$5)) -> 0.0029505611 | G8: =INDIRECT(ADDRESS($A8,2,,,G$5)) -> 0.01525495 | H8: =INDIRECT(ADDRESS($A8,2,,,H$5)) -> 0.018068275 | I8: =INDIRECT(ADDRESS($A8,2,,,I$5)) -> 0.0090062384
A9: 32 | B9: =INDIRECT(ADDRESS(A9,1,,,$C$5)) -> Ecart-type inter-séries (sL) | C9: =INDIRECT(ADDRESS($A9,2,,,C$5)) -> 0.0088108303 | D9: =INDIRECT(ADDRESS($A9,2,,,D$5)) -> 0.01251209 | E9: =INDIRECT(ADDRESS($A9,2,,,E$5)) -> 0.013294108 | F9: =INDIRECT(ADDRESS($A9,2,,,F$5)) -> 0.021741868 | G9: =INDIRECT(ADDRESS($A9,2,,,G$5)) -> 0.0070558854 | H9: =INDIRECT(ADDRESS($A9,2,,,H$5)) -> 0.037925368 | I9: =INDIRECT(ADDRESS($A9,2,,,I$5)) -> 0.0078660294
A10: 33 | B10: =INDIRECT(ADDRESS(A10,1,,,$C$5)) -> Ecart-type de fidélité (sFI) | C10: =INDIRECT(ADDRESS($A10,2,,,C$5)) -> 0.0096311289 | D10: =INDIRECT(ADDRESS($A10,2,,,D$5)) -> 0.014011363 | E10: =INDIRECT(ADDRESS($A10,2,,,E$5)) -> 0.017239505 | F10: =INDIRECT(ADDRESS($A10,2,,,F$5)) -> 0.021941163 | G10: =INDIRECT(ADDRESS($A10,2,,,G$5)) -> 0.016807707 | H10: =INDIRECT(ADDRESS($A10,2,,,H$5)) -> 0.042009476 | I10: =INDIRECT(ADDRESS($A10,2,,,I$5)) -> 0.011957707
A11: 37 | B11: =INDIRECT(ADDRESS(A11,1,,,$C$5)) -> Rapport des variances (R) | C11: =INDIRECT(ADDRESS($A11,2,,,C$5)) -> 5.1316216 | D11: =INDIRECT(ADDRESS($A11,2,,,D$5)) -> 3.9368523 | E11: =INDIRECT(ADDRESS($A11,2,,,E$5)) -> 1.4670656 | F11: =INDIRECT(ADDRESS($A11,2,,,F$5)) -> 54.298084 | G11: =INDIRECT(ADDRESS($A11,2,,,G$5)) -> 0.21393481 | H11: =INDIRECT(ADDRESS($A11,2,,,H$5)) -> 4.4058145 | I11: =INDIRECT(ADDRESS($A11,2,,,I$5)) -> 0.76282383
A12: 39 | B12: =INDIRECT(ADDRESS(A12,1,,,$C$5)) -> Coefficient intermédiaire | C12: =INDIRECT(ADDRESS($A12,2,,,C$5)) -> 1.1388992 | D12: =INDIRECT(ADDRESS($A12,2,,,D$5)) -> 1.135042 | E12: =INDIRECT(ADDRESS($A12,2,,,E$5)) -> 1.1150147 | F12: =INDIRECT(ADDRESS($A12,2,,,F$5)) -> 1.1529591 | G12: =INDIRECT(ADDRESS($A12,2,,,G$5)) -> 1.0725082 | H12: =INDIRECT(ADDRESS($A12,2,,,H$5)) -> 1.1367609 | I12: =INDIRECT(ADDRESS($A12,2,,,I$5)) -> 1.0987597
A13: 40 | B13: =INDIRECT(ADDRESS(A13,1,,,$C$5)) -> Nombre de degrés liberté | C13: =INDIRECT(ADDRESS($A13,2,,,C$5)) -> 2.5052931 | D13: =INDIRECT(ADDRESS($A13,2,,,D$5)) -> 2.6516887 | E13: =INDIRECT(ADDRESS($A13,2,,,E$5)) -> 3.5912441 | F13: =INDIRECT(ADDRESS($A13,2,,,F$5)) -> 2.0490081 | G13: =INDIRECT(ADDRESS($A13,2,,,G$5)) -> 6.5838751 | H13: =INDIRECT(ADDRESS($A13,2,,,H$5)) -> 2.5852138 | I13: =INDIRECT(ADDRESS($A13,2,,,I$5)) -> 4.6047683
A14: 47 | B14: =INDIRECT(ADDRESS(A14,1,,,$C$5)) -> Valeur basse tolérance | C14: =INDIRECT(ADDRESS($A14,2,,,C$5)) -> 1.931434 | D14: =INDIRECT(ADDRESS($A14,2,,,D$5)) -> 3.9010381 | E14: =INDIRECT(ADDRESS($A14,2,,,E$5)) -> 7.9088925 | F14: =INDIRECT(ADDRESS($A14,2,,,F$5)) -> 9.7869321 | G14: =INDIRECT(ADDRESS($A14,2,,,G$5)) -> 11.988262 | H14: =INDIRECT(ADDRESS($A14,2,,,H$5)) -> 15.740418 | I14: =INDIRECT(ADDRESS($A14,2,,,I$5)) -> 20.004277
A15: 48 | B15: =INDIRECT(ADDRESS(A15,1,,,$C$5)) -> Valeur haute tolérance | C15: =INDIRECT(ADDRESS($A15,2,,,C$5)) -> 2.1038925 | D15: =INDIRECT(ADDRESS($A15,2,,,D$5)) -> 4.1320645 | E15: =INDIRECT(ADDRESS($A15,2,,,E$5)) -> 8.105331 | F15: =INDIRECT(ADDRESS($A15,2,,,F$5)) -> 10.278949 | G15: =INDIRECT(ADDRESS($A15,2,,,G$5)) -> 12.117548 | H15: =INDIRECT(ADDRESS($A15,2,,,H$5)) -> 16.46007 | I15: =INDIRECT(ADDRESS($A15,2,,,I$5)) -> 20.116171
A16: 35 | B16: =INDIRECT(ADDRESS(A16,1,,,$C$5)) -> Biais (%) | C16: =INDIRECT(ADDRESS($A16,2,,,C$5)) -> 0.0048173616 | D16: =INDIRECT(ADDRESS($A16,2,,,D$5)) -> 0.00014226148 | E16: =INDIRECT(ADDRESS($A16,2,,,E$5)) -> -0.0030936688 | F16: =INDIRECT(ADDRESS($A16,2,,,F$5)) -> -0.00069818106 | G16: =INDIRECT(ADDRESS($A16,2,,,G$5)) -> 0.00041211621 | H16: =INDIRECT(ADDRESS($A16,2,,,H$5)) -> 0.0022612094 | I16: =INDIRECT(ADDRESS($A16,2,,,I$5)) -> -0.00097986764
B17: Recouvrement (justesse) | C17: =C7/C$6 -> 1.0048174 | D17: =D7/D$6 -> 1.0001423 | E17: =E7/E$6 -> 0.99690633 | F17: =F7/F$6 -> 0.99930182 | G17: =G7/G$6 -> 1.0004121 | H17: =H7/H$6 -> 1.0022612 | I17: =I7/I$6 -> 0.99902013
B18: Limite basse tolérance (%) | C18: =C14/C$6 -> 0.96187429 | D18: =D14/D$6 -> 0.97137887 | E18: =E14/E$6 -> 0.98467778 | F18: =F14/F$6 -> 0.97479888 | G18: =G14/G$6 -> 0.99504664 | H18: =H14/H$6 -> 0.97986159 | I18: =I14/I$6 -> 0.99623392
B19: Limite haute tolérance (%) | C19: =C15/C$6 -> 1.0477604 | D19: =D15/D$6 -> 1.0289057 | E19: =E15/E$6 -> 1.0091349 | F19: =F15/F$6 -> 1.0238048 | G19: =G15/G$6 -> 1.0057776 | H19: =H15/H$6 -> 1.0246608 | I19: =I15/I$6 -> 1.0018063
B20: Limite d'acceptabilité basse | C20: =1-$C$3 -> 0.9 | D20: =1-$C$3 -> 0.9 | E20: =1-$C$3 -> 0.9 | F20: =1-$C$3 -> 0.9 | G20: =1-$C$3 -> 0.9 | H20: =1-$C$3 -> 0.9 | I20: =1-$C$3 -> 0.9
B21: Limite d'acceptabilité haute | C21: =1+$C$3 -> 1.1 | D21: =1+$C$3 -> 1.1 | E21: =1+$C$3 -> 1.1 | F21: =1+$C$3 -> 1.1 | G21: =1+$C$3 -> 1.1 | H21: =1+$C$3 -> 1.1 | I21: =1+$C$3 -> 1.1
B27: Incertitude
B28: Ecart-type de l'IT (sIT) | C28: =C$12*C$10 -> 0.010968885 | D28: =D$12*D$10 -> 0.015903486 | E28: =E$12*E$10 -> 0.019222302 | F28: =F$12*F$10 -> 0.025297264 | G28: =G$12*G$10 -> 0.018026404 | H28: =H$12*H$10 -> 0.04775473
B29: Incertitude élargie relative | C29: =2*C28/C7 -> 0.01087286 | D29: =2*D28/D7 -> 0.0079189754 | E29: =2*E28/E7 -> 0.0048013072 | F29: =2*F28/F7 -> 0.0050428416 | G29: =2*G28/G7 -> 0.0029912131 | H29: =2*H28/H7 -> 0.0059321747

Sheet Niveau A
A1: Niveau A
A2: =Libel!A2 -> Valeur cible | B2: 2.00799
B4: Répétition 1 | C4: Répétition 2 | D4: Répétition 3 | E4: Répétition 4 | F4: Répétition 5 | H4: nk | I4: SCEk
A5: =Libel!A5 -> Jour (Série) 1 | B5: 2.0062613 | C5: 2.0063108 | D5: 2.0159566 | H5: =COUNT(B5:F5) -> 3 | I5: =IF(H5=0,"",DEVSQ(B5:F5)) -> 6.2347758e-05
A6: =Libel!A6 -> Jour (Série) 2 | B6: 2.0253336 | C6: 2.0256221 | D6: 2.0314489 | H6: =COUNT(B6:F6) -> 3 | I6: =IF(H6=0,"",DEVSQ(B6:F6)) -> 2.3810417e-05
A7: =Libel!A7 -> Jour (Série) 3 | B7: 2.0156005 | C7: 2.0176933 | D7: 2.0147418 | H7: =COUNT(B7:F7) -> 3 | I7: =IF(H7=0,"",DEVSQ(B7:F7)) -> 4.6093098e-06
A8: =Libel!A8 -> Jour (Série) 4 | H8: =COUNT(B8:F8) -> 0 | I8: =IF(H8=0,"",DEVSQ(B8:F8))
A9: =Libel!A9 -> Jour (Série) 5 | H9: =COUNT(B9:F9) -> 0 | I9: =IF(H9=0,"",DEVSQ(B9:F9))
A10: =Libel!A10 -> Jour (Série) 6 | H10: =COUNT(B10:F10) -> 0 | I10: =IF(H10=0,"",DEVSQ(B10:F10))
A11: =Libel!A11 -> Jour (Série) 7 | H11: =COUNT(B11:F11) -> 0 | I11: =IF(H11=0,"",DEVSQ(B11:F11))
A12: =Libel!A12 -> Jour (Série) 8 | H12: =COUNT(B12:F12) -> 0 | I12: =IF(H12=0,"",DEVSQ(B12:F12))
A13: =Libel!A13 -> Jour (Série) 9 | H13: =COUNT(B13:F13) -> 0 | I13: =IF(H13=0,"",DEVSQ(B13:F13))
A14: =Libel!A14 -> Jour (Série) 10 | H14: =COUNT(B14:F14) -> 0 | I14: =IF(H14=0,"",DEVSQ(B14:F14))
A15: =Libel!A15 -> Jour (Série) 11 | H15: =COUNT(B15:F15) -> 0 | I15: =IF(H15=0,"",DEVSQ(B15:F15))
A16: =Libel!A16 -> Jour (Série) 12 | H16: =COUNT(B16:F16) -> 0 | I16: =IF(H16=0,"",DEVSQ(B16:F16))
A17: =Libel!A17 -> Jour (Série) 13 | H17: =COUNT(B17:F17) -> 0 | I17: =IF(H17=0,"",DEVSQ(B17:F17))
A19: =Libel!A19 -> Nombre de séries (K) | B19: =COUNT(B5:B17) -> 3
A20: =Libel!A20 -> Nombre de mesures (IK) | B20: =COUNT(B5:F17) -> 9
A21: =Libel!A21 -> Nombre de répétitions (I) | B21: =IF(H5*B19<>B20,"Calcul impossible",H5) -> 3
A22: =Libel!A22 -> SCE résiduelle | B22: =SUM(I5:I17) -> 9.0767485e-05
A23: =Libel!A23 -> SCE totale | B23: =DEVSQ(B5:F17) -> 0.0005868077
A24: =Libel!A24 -> SCE inter-séries | B24: =B23-B22 -> 0.00049604021
A25: =Libel!A25 -> Valeur intermédiaire de s²L | B25: =((B24/(B19-1))-B26)/B21 -> 7.7630731e-05
A26: =Libel!A26 -> Variance de répétabilité (s²r) | B26: =B22/(B20-B19) -> 1.5127914e-05
A27: =Libel!A27 -> Variance inter-séries (s²L) | B27: =IF(B25<0,0,B25) -> 7.7630731e-05
A28: =Libel!A28 -> Variance de fidélité (s²FI) | B28: =SUM(B26:B27) -> 9.2758645e-05
A29: =Libel!A29 -> Fidélité
A30: =Libel!A30 -> Moyenne niveau | B30: =AVERAGE(B5:F17) -> 2.0176632
A31: =Libel!A31 -> Ecart-type de répétabilité (sr) | B31: =SQRT(B26) -> 0.0038894619
A32: =Libel!A32 -> Ecart-type inter-séries (sL) | B32: =SQRT(B27) -> 0.0088108303
A33: =Libel!A33 -> Ecart-type de fidélité (sFI) | B33: =SQRT(B28) -> 0.0096311289
A34: =Libel!A34 -> Justesse
A35: =Libel!A35 -> Biais (%) | B35: =B30/B2-1 -> 0.0048173616
A36: =Libel!A36 -> Facteur de couverture
A37: =Libel!A37 -> Rapport des variances (R) | B37: =B27/B26 -> 5.1316216
A38: =Libel!A38 -> Coefficient B² | B38: =(B37+1)/(B21*B37+1) -> 0.37399647
A39: =Libel!A39 -> Coefficient intermédiaire | B39: =SQRT(1+1/(B20*B38)) -> 1.1388992
A40: =Libel!A40 -> Nombre de degrés liberté | B40: =(B37+1)^2/((B37+1/B21)^2/(B19-1)+(1-1/B21)/B20) -> 2.5052931
A41: =Libel!A41 -> Probabilité tolérance (bêta) | B41: =Récapitulatif!C2 -> 0.99
A42: =Libel!A42 -> t Student bas | B42: =TINV(1-B41,ROUNDDOWN(B40,0)) -> 9.9248432
...

Sheet Niveau B
A1: Niveau B
A2: =Libel!A2 -> Valeur cible | B2: 4.01598
B4: Répétition 1 | C4: Répétition 2 | D4: Répétition 3 | E4: Répétition 4 | F4: Répétition 5 | H4: nk | I4: SCEk
A5: =Libel!A5 -> Jour (Série) 1 | B5: 3.9989732 | C5: 4.0053959 | D5: 4.0072884 | H5: =COUNT(B5:F5) -> 3 | I5: =IF(H5=0,"",DEVSQ(B5:F5)) -> 3.79921e-05
A6: =Libel!A6 -> Jour (Série) 2 | B6: 4.0105536 | C6: 4.0189688 | D6: 4.0180235 | H6: =COUNT(B6:F6) -> 3 | I6: =IF(H6=0,"",DEVSQ(B6:F6)) -> 4.2502788e-05
A7: =Libel!A7 -> Jour (Série) 3 | B7: 4.0196892 | C7: 4.0357807 | D7: 4.0342884 | H7: =COUNT(B7:F7) -> 3 | I7: =IF(H7=0,"",DEVSQ(B7:F7)) -> 0.00015810041
A8: =Libel!A8 -> Jour (Série) 4 | H8: =COUNT(B8:F8) -> 0 | I8: =IF(H8=0,"",DEVSQ(B8:F8))
A9: =Libel!A9 -> Jour (Série) 5 | H9: =COUNT(B9:F9) -> 0 | I9: =IF(H9=0,"",DEVSQ(B9:F9))
A10: =Libel!A10 -> Jour (Série) 6 | H10: =COUNT(B10:F10) -> 0 | I10: =IF(H10=0,"",DEVSQ(B10:F10))
A11: =Libel!A11 -> Jour (Série) 7 | H11: =COUNT(B11:F11) -> 0 | I11: =IF(H11=0,"",DEVSQ(B11:F11))
A12: =Libel!A12 -> Jour (Série) 8 | H12: =COUNT(B12:F12) -> 0 | I12: =IF(H12=0,"",DEVSQ(B12:F12))
A13: =Libel!A13 -> Jour (Série) 9 | H13: =COUNT(B13:F13) -> 0 | I13: =IF(H13=0,"",DEVSQ(B13:F13))
A14: =Libel!A14 -> Jour (Série) 10 | H14: =COUNT(B14:F14) -> 0 | I14: =IF(H14=0,"",DEVSQ(B14:F14))
A15: =Libel!A15 -> Jour (Série) 11 | H15: =COUNT(B15:F15) -> 0 | I15: =IF(H15=0,"",DEVSQ(B15:F15))
A16: =Libel!A16 -> Jour (Série) 12 | H16: =COUNT(B16:F16) -> 0 | I16: =IF(H16=0,"",DEVSQ(B16:F16))
A17: =Libel!A17 -> Jour (Série) 13 | H17: =COUNT(B17:F17) -> 0 | I17: =IF(H17=0,"",DEVSQ(B17:F17))
A19: =Libel!A19 -> Nombre de séries (K) | B19: =COUNT(B5:B17) -> 3
A20: =Libel!A20 -> Nombre de mesures (IK) | B20: =COUNT(B5:F17) -> 9
A21: =Libel!A21 -> Nombre de répétitions (I) | B21: =IF(H5*B19<>B20,"Calcul impossible",H5) -> 3
A22: =Libel!A22 -> SCE résiduelle | B22: =SUM(I5:I17) -> 0.0002385953
A23: =Libel!A23 -> SCE totale | B23: =DEVSQ(B5:F17) -> 0.0012574415
A24: =Libel!A24 -> SCE inter-séries | B24: =B23-B22 -> 0.0010188462
A25: =Libel!A25 -> Valeur intermédiaire de s²L | B25: =((B24/(B19-1))-B26)/B21 -> 0.00015655241
A26: =Libel!A26 -> Variance de répétabilité (s²r) | B26: =B22/(B20-B19) -> 3.9765883e-05
A27: =Libel!A27 -> Variance inter-séries (s²L) | B27: =IF(B25<0,0,B25) -> 0.00015655241
A28: =Libel!A28 -> Variance de fidélité (s²FI) | B28: =SUM(B26:B27) -> 0.00019631829
A29: =Libel!A29 -> Fidélité
A30: =Libel!A30 -> Moyenne niveau | B30: =AVERAGE(B5:F17) -> 4.0165513
A31: =Libel!A31 -> Ecart-type de répétabilité (sr) | B31: =SQRT(B26) -> 0.0063060196
A32: =Libel!A32 -> Ecart-type inter-séries (sL) | B32: =SQRT(B27) -> 0.01251209
A33: =Libel!A33 -> Ecart-type de fidélité (sFI) | B33: =SQRT(B28) -> 0.014011363
A34: =Libel!A34 -> Justesse
A35: =Libel!A35 -> Biais (%) | B35: =B30/B2-1 -> 0.00014226148
A36: =Libel!A36 -> Facteur de couverture
A37: =Libel!A37 -> Rapport des variances (R) | B37: =B27/B26 -> 3.9368523
A38: =Libel!A38 -> Coefficient B² | B38: =(B37+1)/(B21*B37+1) -> 0.38537375
A39: =Libel!A39 -> Coefficient intermédiaire | B39: =SQRT(1+1/(B20*B38)) -> 1.135042
A40: =Libel!A40 -> Nombre de degrés liberté | B40: =(B37+1)^2/((B37+1/B21)^2/(B19-1)+(1-1/B21)/B20) -> 2.6516887
A41: =Libel!A41 -> Probabilité tolérance (bêta) | B41: =Récapitulatif!C2 -> 0.99
A42: =Libel!A42 -> t Student bas | B42: =TINV(1-B41,ROUNDDOWN(B40,0)) -> 9.9248432
...

Sheet Niveau C
A1: Niveau C
A2: =Libel!A2 -> Valeur cible | B2: 8.03196
B4: Répétition 1 | C4: Répétition 2 | D4: Répétition 3 | E4: Répétition 4 | F4: Répétition 5 | H4: nk | I4: SCEk
A5: =Libel!A5 -> Jour (Série) 1 | B5: 7.972969 | C5: 8.0019831 | D5: 7.9953794 | H5: =COUNT(B5:F5) -> 3 | I5: =IF(H5=0,"",DEVSQ(B5:F5)) -> 0.00046255273
A6: =Libel!A6 -> Jour (Série) 2 | B6: 8.0033636 | C6: 8.0240316 | D6: 8.0184616 | H6: =COUNT(B6:F6) -> 3 | I6: =IF(H6=0,"",DEVSQ(B6:F6)) -> 0.00022871501
A7: =Libel!A7 -> Jour (Série) 3 | B7: 8.0115563 | C7: 8.0192971 | D7: 8.0169642 | H7: =COUNT(B7:F7) -> 3 | I7: =IF(H7=0,"",DEVSQ(B7:F7)) -> 3.1535564e-05
A8: =Libel!A8 -> Jour (Série) 4 | H8: =COUNT(B8:F8) -> 0 | I8: =IF(H8=0,"",DEVSQ(B8:F8))
A9: =Libel!A9 -> Jour (Série) 5 | H9: =COUNT(B9:F9) -> 0 | I9: =IF(H9=0,"",DEVSQ(B9:F9))
A10: =Libel!A10 -> Jour (Série) 6 | H10: =COUNT(B10:F10) -> 0 | I10: =IF(H10=0,"",DEVSQ(B10:F10))
A11: =Libel!A11 -> Jour (Série) 7 | H11: =COUNT(B11:F11) -> 0 | I11: =IF(H11=0,"",DEVSQ(B11:F11))
A12: =Libel!A12 -> Jour (Série) 8 | H12: =COUNT(B12:F12) -> 0 | I12: =IF(H12=0,"",DEVSQ(B12:F12))
A13: =Libel!A13 -> Jour (Série) 9 | H13: =COUNT(B13:F13) -> 0 | I13: =IF(H13=0,"",DEVSQ(B13:F13))
A14: =Libel!A14 -> Jour (Série) 10 | H14: =COUNT(B14:F14) -> 0 | I14: =IF(H14=0,"",DEVSQ(B14:F14))
A15: =Libel!A15 -> Jour (Série) 11 | H15: =COUNT(B15:F15) -> 0 | I15: =IF(H15=0,"",DEVSQ(B15:F15))
A16: =Libel!A16 -> Jour (Série) 12 | H16: =COUNT(B16:F16) -> 0 | I16: =IF(H16=0,"",DEVSQ(B16:F16))
A17: =Libel!A17 -> Jour (Série) 13 | H17: =COUNT(B17:F17) -> 0 | I17: =IF(H17=0,"",DEVSQ(B17:F17))
A19: =Libel!A19 -> Nombre de séries (K) | B19: =COUNT(B5:B17) -> 3
A20: =Libel!A20 -> Nombre de mesures (IK) | B20: =COUNT(B5:F17) -> 9
A21: =Libel!A21 -> Nombre de répétitions (I) | B21: =IF(H5*B19<>B20,"Calcul impossible",H5) -> 3
A22: =Libel!A22 -> SCE résiduelle | B22: =SUM(I5:I17) -> 0.00072280331
A23: =Libel!A23 -> SCE totale | B23: =DEVSQ(B5:F17) -> 0.0020241376
A24: =Libel!A24 -> SCE inter-séries | B24: =B23-B22 -> 0.0013013343
A25: =Libel!A25 -> Valeur intermédiaire de s²L | B25: =((B24/(B19-1))-B26)/B21 -> 0.00017673331
A26: =Libel!A26 -> Variance de répétabilité (s²r) | B26: =B22/(B20-B19) -> 0.00012046722
A27: =Libel!A27 -> Variance inter-séries (s²L) | B27: =IF(B25<0,0,B25) -> 0.00017673331
A28: =Libel!A28 -> Variance de fidélité (s²FI) | B28: =SUM(B26:B27) -> 0.00029720053
A29: =Libel!A29 -> Fidélité
A30: =Libel!A30 -> Moyenne niveau | B30: =AVERAGE(B5:F17) -> 8.0071118
A31: =Libel!A31 -> Ecart-type de répétabilité (sr) | B31: =SQRT(B26) -> 0.010975756
A32: =Libel!A32 -> Ecart-type inter-séries (sL) | B32: =SQRT(B27) -> 0.013294108
A33: =Libel!A33 -> Ecart-type de fidélité (sFI) | B33: =SQRT(B28) -> 0.017239505
A34: =Libel!A34 -> Justesse
A35: =Libel!A35 -> Biais (%) | B35: =B30/B2-1 -> -0.0030936688
A36: =Libel!A36 -> Facteur de couverture
A37: =Libel!A37 -> Rapport des variances (R) | B37: =B27/B26 -> 1.4670656
A38: =Libel!A38 -> Coefficient B² | B38: =(B37+1)/(B21*B37+1) -> 0.45676277
A39: =Libel!A39 -> Coefficient intermédiaire | B39: =SQRT(1+1/(B20*B38)) -> 1.1150147
A40: =Libel!A40 -> Nombre de degrés liberté | B40: =(B37+1)^2/((B37+1/B21)^2/(B19-1)+(1-1/B21)/B20) -> 3.5912441
A41: =Libel!A41 -> Probabilité tolérance (bêta) | B41: =Récapitulatif!C2 -> 0.99
A42: =Libel!A42 -> t Student bas | B42: =TINV(1-B41,ROUNDDOWN(B40,0)) -> 5.8409093
...

Sheet Niveau D
A1: Niveau D
A2: =Libel!A2 -> Valeur cible | B2: 10.03995
B4: Répétition 1 | C4: Répétition 2 | D4: Répétition 3 | E4: Répétition 4 | F4: Répétition 5 | H4: nk | I4: SCEk
A5: =Libel!A5 -> Jour (Série) 1 | B5: 10.024916 | C5: 10.029755 | D5: 10.027473 | H5: =COUNT(B5:F5) -> 3 | I5: =IF(H5=0,"",DEVSQ(B5:F5)) -> 1.1718994e-05
A6: =Libel!A6 -> Jour (Série) 2 | B6: 10.01127 | C6: 10.017208 | D6: 10.01487 | H6: =COUNT(B6:F6) -> 3 | I6: =IF(H6=0,"",DEVSQ(B6:F6)) -> 1.7894566e-05
A7: =Libel!A7 -> Jour (Série) 3 | B7: 10.053188 | C7: 10.058207 | D7: 10.059576 | H7: =COUNT(B7:F7) -> 3 | I7: =IF(H7=0,"",DEVSQ(B7:F7)) -> 2.2621304e-05
A8: =Libel!A8 -> Jour (Série) 4 | H8: =COUNT(B8:F8) -> 0 | I8: =IF(H8=0,"",DEVSQ(B8:F8))
A9: =Libel!A9 -> Jour (Série) 5 | H9: =COUNT(B9:F9) -> 0 | I9: =IF(H9=0,"",DEVSQ(B9:F9))
A10: =Libel!A10 -> Jour (Série) 6 | H10: =COUNT(B10:F10) -> 0 | I10: =IF(H10=0,"",DEVSQ(B10:F10))
A11: =Libel!A11 -> Jour (Série) 7 | H11: =COUNT(B11:F11) -> 0 | I11: =IF(H11=0,"",DEVSQ(B11:F11))
A12: =Libel!A12 -> Jour (Série) 8 | H12: =COUNT(B12:F12) -> 0 | I12: =IF(H12=0,"",DEVSQ(B12:F12))
A13: =Libel!A13 -> Jour (Série) 9 | H13: =COUNT(B13:F13) -> 0 | I13: =IF(H13=0,"",DEVSQ(B13:F13))
A14: =Libel!A14 -> Jour (Série) 10 | H14: =COUNT(B14:F14) -> 0 | I14: =IF(H14=0,"",DEVSQ(B14:F14))
A15: =Libel!A15 -> Jour (Série) 11 | H15: =COUNT(B15:F15) -> 0 | I15: =IF(H15=0,"",DEVSQ(B15:F15))
A16: =Libel!A16 -> Jour (Série) 12 | H16: =COUNT(B16:F16) -> 0 | I16: =IF(H16=0,"",DEVSQ(B16:F16))
A17: =Libel!A17 -> Jour (Série) 13 | H17: =COUNT(B17:F17) -> 0 | I17: =IF(H17=0,"",DEVSQ(B17:F17))
A19: =Libel!A19 -> Nombre de séries (K) | B19: =COUNT(B5:B17) -> 3
A20: =Libel!A20 -> Nombre de mesures (IK) | B20: =COUNT(B5:F17) -> 9
A21: =Libel!A21 -> Nombre de répétitions (I) | B21: =IF(H5*B19<>B20,"Calcul impossible",H5) -> 3
A22: =Libel!A22 -> SCE résiduelle | B22: =SUM(I5:I17) -> 5.2234864e-05
A23: =Libel!A23 -> SCE totale | B23: =DEVSQ(B5:F17) -> 0.0029058995
A24: =Libel!A24 -> SCE inter-séries | B24: =B23-B22 -> 0.0028536646
A25: =Libel!A25 -> Valeur intermédiaire de s²L | B25: =((B24/(B19-1))-B26)/B21 -> 0.00047270884
A26: =Libel!A26 -> Variance de répétabilité (s²r) | B26: =B22/(B20-B19) -> 8.7058107e-06
A27: =Libel!A27 -> Variance inter-séries (s²L) | B27: =IF(B25<0,0,B25) -> 0.00047270884
A28: =Libel!A28 -> Variance de fidélité (s²FI) | B28: =SUM(B26:B27) -> 0.00048141465
A29: =Libel!A29 -> Fidélité
A30: =Libel!A30 -> Moyenne niveau | B30: =AVERAGE(B5:F17) -> 10.03294
A31: =Libel!A31 -> Ecart-type de répétabilité (sr) | B31: =SQRT(B26) -> 0.0029505611
A32: =Libel!A32 -> Ecart-type inter-séries (sL) | B32: =SQRT(B27) -> 0.021741868
A33: =Libel!A33 -> Ecart-type de fidélité (sFI) | B33: =SQRT(B28) -> 0.021941163
A34: =Libel!A34 -> Justesse
A35: =Libel!A35 -> Biais (%) | B35: =B30/B2-1 -> -0.00069818106
A36: =Libel!A36 -> Facteur de couverture
A37: =Libel!A37 -> Rapport des variances (R) | B37: =B27/B26 -> 54.298084
A38: =Libel!A38 -> Coefficient B² | B38: =(B37+1)/(B21*B37+1) -> 0.337401
A39: =Libel!A39 -> Coefficient intermédiaire | B39: =SQRT(1+1/(B20*B38)) -> 1.1529591
A40: =Libel!A40 -> Nombre de degrés liberté | B40: =(B37+1)^2/((B37+1/B21)^2/(B19-1)+(1-1/B21)/B20) -> 2.0490081
A41: =Libel!A41 -> Probabilité tolérance (bêta) | B41: =Récapitulatif!C2 -> 0.99
A42: =Libel!A42 -> t Student bas | B42: =TINV(1-B41,ROUNDDOWN(B40,0)) -> 9.9248432
...

Sheet Niveau E
A1: Niveau E
A2: =Libel!A2 -> Valeur cible | B2: 12.04794
B4: Répétition 1 | C4: Répétition 2 | D4: Répétition 3 | E4: Répétition 4 | F4: Répétition 5 | H4: nk | I4: SCEk
A5: =Libel!A5 -> Jour (Série) 1 | B5: 12.043883 | C5: 12.022015 | D5: 12.054547 | H5: =COUNT(B5:F5) -> 3 | I5: =IF(H5=0,"",DEVSQ(B5:F5)) -> 0.00055008768
A6: =Libel!A6 -> Jour (Série) 2 | B6: 12.039038 | C6: 12.070807 | D6: 12.074916 | H6: =COUNT(B6:F6) -> 3 | I6: =IF(H6=0,"",DEVSQ(B6:F6)) -> 0.00077115826
A7: =Libel!A7 -> Jour (Série) 3 | B7: 12.05174 | C7: 12.055486 | D7: 12.063714 | H7: =COUNT(B7:F7) -> 3 | I7: =IF(H7=0,"",DEVSQ(B7:F7)) -> 7.5035047e-05
A8: =Libel!A8 -> Jour (Série) 4 | H8: =COUNT(B8:F8) -> 0 | I8: =IF(H8=0,"",DEVSQ(B8:F8))
A9: =Libel!A9 -> Jour (Série) 5 | H9: =COUNT(B9:F9) -> 0 | I9: =IF(H9=0,"",DEVSQ(B9:F9))
A10: =Libel!A10 -> Jour (Série) 6 | H10: =COUNT(B10:F10) -> 0 | I10: =IF(H10=0,"",DEVSQ(B10:F10))
A11: =Libel!A11 -> Jour (Série) 7 | H11: =COUNT(B11:F11) -> 0 | I11: =IF(H11=0,"",DEVSQ(B11:F11))
A12: =Libel!A12 -> Jour (Série) 8 | H12: =COUNT(B12:F12) -> 0 | I12: =IF(H12=0,"",DEVSQ(B12:F12))
A13: =Libel!A13 -> Jour (Série) 9 | H13: =COUNT(B13:F13) -> 0 | I13: =IF(H13=0,"",DEVSQ(B13:F13))
A14: =Libel!A14 -> Jour (Série) 10 | H14: =COUNT(B14:F14) -> 0 | I14: =IF(H14=0,"",DEVSQ(B14:F14))
A15: =Libel!A15 -> Jour (Série) 11 | H15: =COUNT(B15:F15) -> 0 | I15: =IF(H15=0,"",DEVSQ(B15:F15))
A16: =Libel!A16 -> Jour (Série) 12 | H16: =COUNT(B16:F16) -> 0 | I16: =IF(H16=0,"",DEVSQ(B16:F16))
A17: =Libel!A17 -> Jour (Série) 13 | H17: =COUNT(B17:F17) -> 0 | I17: =IF(H17=0,"",DEVSQ(B17:F17))
A19: =Libel!A19 -> Nombre de séries (K) | B19: =COUNT(B5:B17) -> 3
A20: =Libel!A20 -> Nombre de mesures (IK) | B20: =COUNT(B5:F17) -> 9
A21: =Libel!A21 -> Nombre de répétitions (I) | B21: =IF(H5*B19<>B20,"Calcul impossible",H5) -> 3
A22: =Libel!A22 -> SCE résiduelle | B22: =SUM(I5:I17) -> 0.001396281
A23: =Libel!A23 -> SCE totale | B23: =DEVSQ(B5:F17) -> 0.0021604211
A24: =Libel!A24 -> SCE inter-séries | B24: =B23-B22 -> 0.00076414011
A25: =Libel!A25 -> Valeur intermédiaire de s²L | B25: =((B24/(B19-1))-B26)/B21 -> 4.9785519e-05
A26: =Libel!A26 -> Variance de répétabilité (s²r) | B26: =B22/(B20-B19) -> 0.0002327135
A27: =Libel!A27 -> Variance inter-séries (s²L) | B27: =IF(B25<0,0,B25) -> 4.9785519e-05
A28: =Libel!A28 -> Variance de fidélité (s²FI) | B28: =SUM(B26:B27) -> 0.00028249902
A29: =Libel!A29 -> Fidélité
A30: =Libel!A30 -> Moyenne niveau | B30: =AVERAGE(B5:F17) -> 12.052905
A31: =Libel!A31 -> Ecart-type de répétabilité (sr) | B31: =SQRT(B26) -> 0.01525495
A32: =Libel!A32 -> Ecart-type inter-séries (sL) | B32: =SQRT(B27) -> 0.0070558854
A33: =Libel!A33 -> Ecart-type de fidélité (sFI) | B33: =SQRT(B28) -> 0.016807707
A34: =Libel!A34 -> Justesse
A35: =Libel!A35 -> Biais (%) | B35: =B30/B2-1 -> 0.00041211621
A36: =Libel!A36 -> Facteur de couverture
A37: =Libel!A37 -> Rapport des variances (R) | B37: =B27/B26 -> 0.21393481
A38: =Libel!A38 -> Coefficient B² | B38: =(B37+1)/(B21*B37+1) -> 0.73939063
A39: =Libel!A39 -> Coefficient intermédiaire | B39: =SQRT(1+1/(B20*B38)) -> 1.0725082
A40: =Libel!A40 -> Nombre de degrés liberté | B40: =(B37+1)^2/((B37+1/B21)^2/(B19-1)+(1-1/B21)/B20) -> 6.5838751
A41: =Libel!A41 -> Probabilité tolérance (bêta) | B41: =Récapitulatif!C2 -> 0.99
A42: =Libel!A42 -> t Student bas | B42: =TINV(1-B41,ROUNDDOWN(B40,0)) -> 3.707428
...

Sheet Niveau F
A1: Niveau F
A2: =Libel!A2 -> Valeur cible | B2: 16.06392
B4: Répétition 1 | C4: Répétition 2 | D4: Répétition 3 | E4: Répétition 4 | F4: Répétition 5 | H4: nk | I4: SCEk
A5: =Libel!A5 -> Jour (Série) 1 | B5: 16.127872 | C5: 16.155241 | D5: 16.13969 | H5: =COUNT(B5:F5) -> 3 | I5: =IF(H5=0,"",DEVSQ(B5:F5)) -> 0.0003768639
A6: =Libel!A6 -> Jour (Série) 2 | B6: 16.080851 | C6: 16.092867 | D6: 16.118403 | H6: =COUNT(B6:F6) -> 3 | I6: =IF(H6=0,"",DEVSQ(B6:F6)) -> 0.00073551203
A7: =Libel!A7 -> Jour (Série) 3 | B7: 16.05134 | C7: 16.04977 | D7: 16.086161 | H7: =COUNT(B7:F7) -> 3 | I7: =IF(H7=0,"",DEVSQ(B7:F7)) -> 0.00084639948
A8: =Libel!A8 -> Jour (Série) 4 | H8: =COUNT(B8:F8) -> 0 | I8: =IF(H8=0,"",DEVSQ(B8:F8))
A9: =Libel!A9 -> Jour (Série) 5 | H9: =COUNT(B9:F9) -> 0 | I9: =IF(H9=0,"",DEVSQ(B9:F9))
A10: =Libel!A10 -> Jour (Série) 6 | H10: =COUNT(B10:F10) -> 0 | I10: =IF(H10=0,"",DEVSQ(B10:F10))
A11: =Libel!A11 -> Jour (Série) 7 | H11: =COUNT(B11:F11) -> 0 | I11: =IF(H11=0,"",DEVSQ(B11:F11))
A12: =Libel!A12 -> Jour (Série) 8 | H12: =COUNT(B12:F12) -> 0 | I12: =IF(H12=0,"",DEVSQ(B12:F12))
A13: =Libel!A13 -> Jour (Série) 9 | H13: =COUNT(B13:F13) -> 0 | I13: =IF(H13=0,"",DEVSQ(B13:F13))
A14: =Libel!A14 -> Jour (Série) 10 | H14: =COUNT(B14:F14) -> 0 | I14: =IF(H14=0,"",DEVSQ(B14:F14))
A15: =Libel!A15 -> Jour (Série) 11 | H15: =COUNT(B15:F15) -> 0 | I15: =IF(H15=0,"",DEVSQ(B15:F15))
A16: =Libel!A16 -> Jour (Série) 12 | H16: =COUNT(B16:F16) -> 0 | I16: =IF(H16=0,"",DEVSQ(B16:F16))
A17: =Libel!A17 -> Jour (Série) 13 | H17: =COUNT(B17:F17) -> 0 | I17: =IF(H17=0,"",DEVSQ(B17:F17))
A19: =Libel!A19 -> Nombre de séries (K) | B19: =COUNT(B5:B17) -> 3
A20: =Libel!A20 -> Nombre de mesures (IK) | B20: =COUNT(B5:F17) -> 9
A21: =Libel!A21 -> Nombre de répétitions (I) | B21: =IF(H5*B19<>B20,"Calcul impossible",H5) -> 3
A22: =Libel!A22 -> SCE résiduelle | B22: =SUM(I5:I17) -> 0.0019587754
A23: =Libel!A23 -> SCE totale | B23: =DEVSQ(B5:E17) -> 0.011241702
A24: =Libel!A24 -> SCE inter-séries | B24: =B23-B22 -> 0.0092829263
A25: =Libel!A25 -> Valeur intermédiaire de s²L | B25: =((B24/(B19-1))-B26)/B21 -> 0.0014383335
A26: =Libel!A26 -> Variance de répétabilité (s²r) | B26: =B22/(B20-B19) -> 0.00032646257
A27: =Libel!A27 -> Variance inter-séries (s²L) | B27: =IF(B25<0,0,B25) -> 0.0014383335
A28: =Libel!A28 -> Variance de fidélité (s²FI) | B28: =SUM(B26:B27) -> 0.0017647961
A29: =Libel!A29 -> Fidélité
A30: =Libel!A30 -> Moyenne niveau | B30: =AVERAGE(B5:F17) -> 16.100244
A31: =Libel!A31 -> Ecart-type de répétabilité (sr) | B31: =SQRT(B26) -> 0.018068275
A32: =Libel!A32 -> Ecart-type inter-séries (sL) | B32: =SQRT(B27) -> 0.037925368
A33: =Libel!A33 -> Ecart-type de fidélité (sFI) | B33: =SQRT(B28) -> 0.042009476
A34: =Libel!A34 -> Justesse
A35: =Libel!A35 -> Biais (%) | B35: =B30/B2-1 -> 0.0022612094
A36: =Libel!A36 -> Facteur de couverture
A37: =Libel!A37 -> Rapport des variances (R) | B37: =B27/B26 -> 4.4058145
A38: =Libel!A38 -> Coefficient B² | B38: =(B37+1)/(B21*B37+1) -> 0.38022409
A39: =Libel!A39 -> Coefficient intermédiaire | B39: =SQRT(1+1/(B20*B38)) -> 1.1367609
A40: =Libel!A40 -> Nombre de degrés liberté | B40: =(B37+1)^2/((B37+1/B21)^2/(B19-1)+(1-1/B21)/B20) -> 2.5852138
A41: =Libel!A41 -> Probabilité tolérance (bêta) | B41: =Récapitulatif!C2 -> 0.99
A42: =Libel!A42 -> t Student bas | B42: =TINV(1-B41,ROUNDDOWN(B40,0)) -> 9.9248432
...

Sheet Niveau G
A1: Niveau F
A2: =Libel!A2 -> Valeur cible | B2: 20.0799
B4: Répétition 1 | C4: Répétition 2 | D4: Répétition 3 | E4: Répétition 4 | F4: Répétition 5 | H4: nk | I4: SCEk
A5: =Libel!A5 -> Jour (Série) 1 | B5: 20.066903 | C5: 20.054139 | D5: 20.078681 | H5: =COUNT(B5:F5) -> 3 | I5: =IF(H5=0,"",DEVSQ(B5:F5)) -> 0.00030131106
A6: =Libel!A6 -> Jour (Série) 2 | B6: 20.047059 | C6: 20.048724 | D6: 20.052387 | H6: =COUNT(B6:F6) -> 3 | I6: =IF(H6=0,"",DEVSQ(B6:F6)) -> 1.4859338e-05
A7: =Libel!A7 -> Jour (Série) 3 | B7: 20.056816 | C7: 20.062448 | D7: 20.074863 | H7: =COUNT(B7:F7) -> 3 | I7: =IF(H7=0,"",DEVSQ(B7:F7)) -> 0.00017050358
A8: =Libel!A8 -> Jour (Série) 4 | H8: =COUNT(B8:F8) -> 0 | I8: =IF(H8=0,"",DEVSQ(B8:F8))
A9: =Libel!A9 -> Jour (Série) 5 | H9: =COUNT(B9:F9) -> 0 | I9: =IF(H9=0,"",DEVSQ(B9:F9))
A10: =Libel!A10 -> Jour (Série) 6 | H10: =COUNT(B10:F10) -> 0 | I10: =IF(H10=0,"",DEVSQ(B10:F10))
A11: =Libel!A11 -> Jour (Série) 7 | H11: =COUNT(B11:F11) -> 0 | I11: =IF(H11=0,"",DEVSQ(B11:F11))
A12: =Libel!A12 -> Jour (Série) 8 | H12: =COUNT(B12:F12) -> 0 | I12: =IF(H12=0,"",DEVSQ(B12:F12))
A13: =Libel!A13 -> Jour (Série) 9 | H13: =COUNT(B13:F13) -> 0 | I13: =IF(H13=0,"",DEVSQ(B13:F13))
A14: =Libel!A14 -> Jour (Série) 10 | H14: =COUNT(B14:F14) -> 0 | I14: =IF(H14=0,"",DEVSQ(B14:F14))
A15: =Libel!A15 -> Jour (Série) 11 | H15: =COUNT(B15:F15) -> 0 | I15: =IF(H15=0,"",DEVSQ(B15:F15))
A16: =Libel!A16 -> Jour (Série) 12 | H16: =COUNT(B16:F16) -> 0 | I16: =IF(H16=0,"",DEVSQ(B16:F16))
A17: =Libel!A17 -> Jour (Série) 13 | H17: =COUNT(B17:F17) -> 0 | I17: =IF(H17=0,"",DEVSQ(B17:F17))
A19: =Libel!A19 -> Nombre de séries (K) | B19: =COUNT(B5:B17) -> 3
A20: =Libel!A20 -> Nombre de mesures (IK) | B20: =COUNT(B5:F17) -> 9
A21: =Libel!A21 -> Nombre de répétitions (I) | B21: =IF(H5*B19<>B20,"Calcul impossible",H5) -> 3
A22: =Libel!A22 -> SCE résiduelle | B22: =SUM(I5:I17) -> 0.00048667398
A23: =Libel!A23 -> SCE totale | B23: =DEVSQ(B5:E17) -> 0.0010201452
A24: =Libel!A24 -> SCE inter-séries | B24: =B23-B22 -> 0.00053347118
A25: =Libel!A25 -> Valeur intermédiaire de s²L | B25: =((B24/(B19-1))-B26)/B21 -> 6.1874419e-05
A26: =Libel!A26 -> Variance de répétabilité (s²r) | B26: =B22/(B20-B19) -> 8.1112331e-05
A27: =Libel!A27 -> Variance inter-séries (s²L) | B27: =IF(B25<0,0,B25) -> 6.1874419e-05
A28: =Libel!A28 -> Variance de fidélité (s²FI) | B28: =SUM(B26:B27) -> 0.00014298675
A29: =Libel!A29 -> Fidélité
A30: =Libel!A30 -> Moyenne niveau | B30: =AVERAGE(B5:F17) -> 20.060224
A31: =Libel!A31 -> Ecart-type de répétabilité (sr) | B31: =SQRT(B26) -> 0.0090062384
A32: =Libel!A32 -> Ecart-type inter-séries (sL) | B32: =SQRT(B27) -> 0.0078660294
A33: =Libel!A33 -> Ecart-type de fidélité (sFI) | B33: =SQRT(B28) -> 0.011957707
A34: =Libel!A34 -> Justesse
A35: =Libel!A35 -> Biais (%) | B35: =B30/B2-1 -> -0.00097986764
A36: =Libel!A36 -> Facteur de couverture
A37: =Libel!A37 -> Rapport des variances (R) | B37: =B27/B26 -> 0.76282383
A38: =Libel!A38 -> Coefficient B² | B38: =(B37+1)/(B21*B37+1) -> 0.53606176
A39: =Libel!A39 -> Coefficient intermédiaire | B39: =SQRT(1+1/(B20*B38)) -> 1.0987597
A40: =Libel!A40 -> Nombre de degrés liberté | B40: =(B37+1)^2/((B37+1/B21)^2/(B19-1)+(1-1/B21)/B20) -> 4.6047683
A41: =Libel!A41 -> Probabilité tolérance (bêta) | B41: =Récapitulatif!C2 -> 0.99
A42: =Libel!A42 -> t Student bas | B42: =TINV(1-B41,ROUNDDOWN(B40,0)) -> 4.6040949
...

Sheet Libel
A2: Valeur cible
A5: Jour (Série) 1
A6: Jour (Série) 2
A7: Jour (Série) 3
A8: Jour (Série) 4
A9: Jour (Série) 5
A10: Jour (Série) 6
A11: Jour (Série) 7
A12: Jour (Série) 8
A13: Jour (Série) 9
A14: Jour (Série) 10
A15: Jour (Série) 11
... A48: Valeur haute tolérance
