Workbook
Name ANALYTES: #REF!

Sheet Analytique
O3: Carré de Youden: 3 facteurs a 5 niveaux | AG3: R² | AH3: =L32 -> 0.45414687
C4: Essais | D4: opérateur | E4: outils A | F4: outils B | G4: 0.8 | H4: 0.9 | I4: cible | J4: 1.1 | K4: 1.2 | L4: total | M4: jour 1 | AG4: R²ajusté | AH4: =(I32-I34)/I32 -> -0.37582393
C5: 1 | D5: 1 | E5: 1 | F5: -1 | G5: =1+(RAND()-RAND())/100 -> 0.9954785 | H5: =1+(RAND()-RAND())/100 -> 0.99704295 | I5: =1+(RAND()-RAND())/100 -> 1.0059112 | J5: =1+(RAND()-RAND())/100 -> 0.99846785 | K5: =1+(RAND()-RAND())/100 -> 1.0046622 | L5: =SUM(G5:K6) -> 10.002913 | M5: jour 2 | O5: limite | P5: 0.02
G6: =1+(RAND()-RAND())/100 -> 1.0013236 | H6: =1+(RAND()-RAND())/100 -> 0.99946188 | I6: =1+(RAND()-RAND())/100 -> 1.0049943 | J6: =1+(RAND()-RAND())/100 -> 0.99696094 | K6: =1+(RAND()-RAND())/100 -> 0.99860901 | M6: jour 3 | O6: Beta | P6: 0.95
C7: 2 | D7: -1 | E7: 1 | F7: 1 | G7: =1+(RAND()-RAND())/100 -> 0.99314522 | H7: =1+(RAND()-RAND())/100 -> 1.0014037 | I7: =1+(RAND()-RAND())/100 -> 1.000748 | J7: =1+(RAND()-RAND())/100 -> 0.99561687 | K7: =1+(RAND()-RAND())/100 -> 1.0023702 | L7: =SUM(G7:K8) -> 9.993574 | M7: jour 4
G8: =1+(RAND()-RAND())/100 -> 0.99803463 | H8: =1+(RAND()-RAND())/100 -> 0.99662642 | I8: =1+(RAND()-RAND())/100 -> 1.0034568 | J8: =1+(RAND()-RAND())/100 -> 1.0002685 | K8: =1+(RAND()-RAND())/100 -> 1.0019037 | M8: jour 5 | O8: moyenne | P8: =AVERAGE(G5:K12) -> 0.99957233
C9: 3 | D9: 1 | E9: -1 | F9: 1 | G9: =1+(RAND()-RAND())/100 -> 1.0032293 | H9: =1+(RAND()-RAND())/100 -> 1.0003504 | I9: =1+(RAND()-RAND())/100 -> 1.001477 | J9: =1+(RAND()-RAND())/100 -> 0.99356136 | K9: =1+(RAND()-RAND())/100 -> 1.0037441 | L9: =SUM(G9:K10) -> 9.9897183 | O9: S² totale | P9: =I31 -> 1.2069589e-05
G10: =1+(RAND()-RAND())/100 -> 1.0001412 | H10: =1+(RAND()-RAND())/100 -> 0.99623933 | I10: =1+(RAND()-RAND())/100 -> 0.99170438 | J10: =1+(RAND()-RAND())/100 -> 0.99684116 | K10: =1+(RAND()-RAND())/100 -> 1.0024301 | O10: S totale | P10: =SQRT(P9) -> 0.0034741314
C11: 4 | D11: -1 | E11: -1 | F11: -1 | G11: =1+(RAND()-RAND())/100 -> 0.99668881 | H11: =1+(RAND()-RAND())/100 -> 0.997216 | I11: =1+(RAND()-RAND())/100 -> 0.9966256 | J11: =1+(RAND()-RAND())/100 -> 1.0030811 | K11: =1+(RAND()-RAND())/100 -> 1.0006856 | L11: =SUM(G11:K12) -> 9.9966883 | O11: Min | P11: =MIN(G5:K12) -> 0.99170438
G12: =1+(RAND()-RAND())/100 -> 1.0034457 | H12: =1+(RAND()-RAND())/100 -> 0.9985657 | I12: =1+(RAND()-RAND())/100 -> 1.0030013 | J12: =1+(RAND()-RAND())/100 -> 0.99614813 | K12: =1+(RAND()-RAND())/100 -> 1.0012304 | O12: Max | P12: =MAX(G5:K12) -> 1.0059112 | Q12: Cpk | R12: =MIN((P11-(1-P5))/(3*P10),((1+P5)-P12)/(3*P10)) -> 1.1230028
Q13: Cp | R13: =(P5*2)/(6*P10) -> 1.9189449
F14: total | G14: =SUM(G5:G12) -> 7.991487 | H14: =SUM(H5:H12) -> 7.9869065 | I14: =SUM(I5:I12) -> 8.0079186 | J14: =SUM(J5:J12) -> 7.9809459 | K14: =SUM(K5:K12) -> 8.0156352 | T14: traitement l | U14: 5
T15: bloc b | U15: 5
T16: l/b = k | U16: 4
T17: h (ok?) | U17: =U15*U16/U14 -> 4 | V17: h= nombre de fois ou l'on observe un niveau
T18: λ (ok?) | U18: =U17*(U16-1)/(U14-1) -> 3 | V18: λ = nombre de fois ou l'on répète une combinaison
T19: E | U19: =(U16-1)*U14/((U14-1)*U16) -> 0.9375 | V19: Efficacité
T20: Er | U20: =U17*U19 -> 3.75 | V20: coeff ajustement
U22: j1 | V22: j2 | W22: j3 | X22: j4 | Y22: j5
T23: Somme niv | U23: =SUM(G5:G6,H7:H8,I9:I10,J11:J12) -> 7.9872429 | V23: =SUM(H5:H6,I7:I8,J9:J10,K11:K12) -> 7.9930281 | W23: =SUM(I5:I6,J7:J8,K9:K10,G11:G12) -> 8.0130997 | X23: =SUM(J5:J6,K7:K8,G9:G10,H11:H12) -> 7.9988548 | Y23: =SUM(K5:K6,G7:G8,H9:H10,I11:I12) -> 7.9906677
T24: Somme b | U24: =+G14+H14+I14+J14 -> 31.967258 | V24: =+H14+I14+J14+K14 -> 31.991406 | W24: =+I14+J14+K14+G14 -> 31.995987 | X24: =+J14+K14+G14+H14 -> 31.974975 | Y24: =+K14+G14+H14+I14 -> 32.001947
T25: biais | U25: =U23-U24/$U16 -> -0.0045715964 | V25: =V23-V24/$U16 -> -0.0048234545 | W25: =W23-W24/$U16 -> 0.014102999 | X25: =X23-X24/$U16 -> 0.0051111673 | Y25: =Y23-Y24/$U16 -> -0.0098191155 | Z25: =SUM(U25:Y25) -> 8.8817842e-16
T26: biais*Er | U26: =U25/$U20 -> -0.0012190924 | V26: =V25/$U20 -> -0.0012862545 | W26: =W25/$U20 -> 0.0037607998 | X26: =X25/$U20 -> 0.0013629779 | Y26: =Y25/$U20 -> -0.0026184308 | Z26: =SUM(U26:Y26) -> 2.3678975e-16 | AA26: vaut zéro si OK
T27: SCE traitement | U27: =SUMSQ(U25:Y25)/U20 -> 9.7493027e-05
C30: Origine | D30: niveau | E30: SB² | F30: CI | G30: SCE | H30: ddl | I30: CM | J30: Fobs | K30: F5% | L30: contrib% | M30: équiv β | P30: Prérequis | U30: 0.8 | W30: 0.9 | Y30: 1 | AA30: 1.1 | AC30: 1.2
C31: Total | D31: =COUNT(G5:K12) -> 40 | E31: =SUM(G5:K12)^2 -> 1598.6317 | F31: =E31/D31 -> 39.965794 | G31: =DEVSQ(G5:K12) -> 0.00047071397 | H31: =D31-1 -> 39 | I31: =G31/H31 -> 1.2069589e-05 | J31: x | K31: x | L31: =SUM(L33:L38) -> 1 | M31: x | P31: Cochran | T31: jour 1 | U31: =G5 -> 0.9954785 | V31: =G6 -> 1.0013236 | W31: =H7 -> 1.0014037 | X31: =H8 -> 0.99662642 | Y31: =I9 -> 1.001477 | Z31: =I10 -> 0.99170438 | AA31: =J11 -> 1.0030811 | AB31: =J12 -> 0.99614813
C32: modèle | D32: x | E32: x | F32: x | G32: =SUM(G34:G38) -> 0.00021377328 | H32: =SUM(H34:H38) -> 11 | I32: =G32/H32 -> 1.9433934e-05 | J32: =I32/I33 -> 2.1178045 | K32: =FINV(0.05,H32,H33) -> 2.1511975 | L32: =G32/G31 -> 0.45414687 | M32: x | P32: Cobs | Q32: =MAX(T38:X41)/SUM(T38:X41) -> 0.22387013 | R32: 20 | T32: jour 2 | W32: =J5 -> 0.99846785 | X32: =J6 -> 0.99696094 | Y32: =I7 -> 1.000748 | Z32: =I8 -> 1.0034568 | AA32: =J9 -> 0.99356136 | AB32: =J10 -> 0.99684116 | AC32: =K11 -> 1.0006856 | AD32: =K12 -> 1.0012304
C33: résiduel | D33: x | E33: x | F33: x | G33: =G31-G32 -> 0.00025694069 | H33: =H31-H32 -> 28 | I33: =G33/H33 -> 9.1764534e-06 | J33: x | K33: x | L33: =G33/G31 -> 0.54585313 | M33: x | P33: C1% | Q33: =1/((1+(R32-1)/FINV(0.01/R32,R33-1,(R32)*(R33-1)))) -> 0.47498652 | R33: 2 | T33: jour 3 | U33: =G11 -> 0.99668881 | V33: =G12 -> 1.0034457 | Y33: =I5 -> 1.0059112 | Z33: =I6 -> 1.0049943 | AA33: =J7 -> 0.99561687 | AB33: =J8 -> 1.0002685 | AC33: =K9 -> 1.0037441 | AD33: =K10 -> 1.0024301
C34: [X] | D34: 5 | E34: =SUMSQ(G14:K14) -> 319.72721 | F34: =E34*D34/$D$31 -> 39.965901 | G34: =F34-F$31 -> 0.00010695069 | H34: =D34-1 -> 4 | I34: =G34/H34 -> 2.6737672e-05 | J34: =I34/I$33 -> 2.9137261 | K34: =FINV(0.05,H34,H$33) -> 2.7140758 | L34: =G34/$G$31 -> 0.2272095 | M34: =1-FDIST(K34/J34,H34,H$33) -> 0.54005769 | P34: Cobs < C 1% = OK | T34: jour 4 | U34: =G9 -> 1.0032293 | V34: =G10 -> 1.0001412 | W34: =H11 -> 0.997216 | X34: =H12 -> 0.9985657 | AA34: =J5 -> 0.99846785 | AB34: =J6 -> 0.99696094 | AC34: =K7 -> 1.0023702 | AD34: =K8 -> 1.0019037
C35: jour | D35: 5 | E35: x | F35: x | G35: =U27 -> 9.7493027e-05 | H35: =D35-1 -> 4 | I35: =G35/H35 -> 2.4373257e-05 | J35: =I35/I$33 -> 2.656065 | K35: =FINV(0.05,H35,H$33) -> 2.7140758 | L35: =G35/$G$31 -> 0.20711734 | M35: =1-FDIST(K35/J35,H35,H$33) -> 0.58685337 | T35: jour 5 | U35: =G7 -> 0.99314522 | V35: =G8 -> 0.99803463 | W35: =H9 -> 1.0003504 | X35: =H10 -> 0.99623933 | Y35: =I11 -> 0.9966256 | Z35: =I12 -> 1.0030013 | AC35: =K5 -> 1.0046622 | AD35: =K6 -> 0.99860901
C36: =D4 -> opérateur | D36: 2 | E36: =SUM(L5,L9)^2+SUM(L7,L11)^2 -> 799.31588 | F36: =E36*D36/$D$31 -> 39.965794 | G36: =F36-F$31 -> 1.4024911e-07 | H36: =D36-1 -> 1 | I36: =G36/H36 -> 1.4024911e-07 | J36: =I36/I$33 -> 0.015283586 | K36: =FINV(0.05,H36,H$33) -> 4.1959718 | L36: =G36/$G$31 -> 0.00029794976 | M36: =1-FDIST(K36/J36,H36,H$33) -> 1
C37: =E4 -> outils A | D37: 2 | E37: =SUM(L5:L8)^2+SUM(L9:L12)^2 -> 799.31592 | F37: =E37*D37/$D$31 -> 39.965796 | G37: =F37-F$31 -> 2.5401308e-06 | H37: =D37-1 -> 1 | I37: =G37/H37 -> 2.5401308e-06 | J37: =I37/I$33 -> 0.27680964 | K37: =FINV(0.05,H37,H$33) -> 4.1959718 | L37: =G37/$G$31 -> 0.0053963361 | M37: =1-FDIST(K37/J37,H37,H$33) -> 0.99944112
C38: =F4 -> outils B | D38: 2 | E38: =SUM(L5,L11)^2+SUM(L7:L10)^2 -> 799.31601 | F38: =E38*D38/$D$31 -> 39.9658 | G38: =F38-$F$31 -> 6.6491822e-06 | H38: =D38-1 -> 1 | I38: =G38/H38 -> 6.6491822e-06 | J38: =I38/I$33 -> 0.72459173 | K38: =FINV(0.05,H38,H$33) -> 4.1959718 | L38: =G38/$G$31 -> 0.014125738 | M38: =1-FDIST(K38/J38,H38,H$33) -> 0.97704481 | T38: =VAR(G5:G6) -> 1.7082866e-05 | U38: =VAR(H5:H6) -> 2.9256237e-06 | V38: =VAR(I5:I6) -> 4.2032689e-07 | W38: =VAR(J5:J6) -> 1.1353994e-06 | X38: =VAR(K5:K6) -> 1.832053e-05
T39: =VAR(G7:G8) -> 1.1953127e-05 | U39: =VAR(H7:H8) -> 1.1411443e-05 | V39: =VAR(I7:I8) -> 3.6688881e-06 | W39: =VAR(J7:J8) -> 1.0819043e-05 | X39: =VAR(K7:K8) -> 1.0881937e-07
C40: R² | D40: =L32 -> 0.45414687 | E40: < coefficient de détermination | J40: LOQ | L40: < limite de quantification | T40: =VAR(G9:G10) -> 4.7679578e-06 | U40: =VAR(H9:H10) -> 8.4505056e-06 | V40: =VAR(I9:I10) -> 4.7752284e-05 | W40: =VAR(J9:J10) -> 5.3785534e-06 | X40: =VAR(K9:K10) -> 8.6329721e-07
T41: =VAR(G11:G12) -> 2.2828006e-05 | U41: =VAR(H11:H12) -> 9.1084819e-07 | V41: =VAR(I11:I12) -> 2.0324761e-05 | W41: =VAR(J11:J12) -> 2.4032817e-05 | X41: =VAR(K11:K12) -> 1.4840613e-07
C42: R²aj | D42: =(I31-I33)/I31 -> 0.23970457 | E42: < coefficient de détermination ajusté
T43: =AVERAGE(T38:X41) -> 1.0665175e-05
C44: Catégorie | D44: =TRUNC(SQRT(I31/I33)*SQRT(2),0) -> 1 | E44: < nombre de catégorie détectable par la méthode
B46: Morgan GERMA | R46: version 1
...

Sheet Récapitulatif
B1: Profil d'exactitude
B2: Probabilité tolérance (bêta) | C2: =Analytique!P6 -> 0.95 | E2: 20 | F2: 100
B3: Limite d'acceptabilité | C3: =Analytique!P5 -> 0.02 | E3: 0.01 | F3: =E3*F2/E2 -> 0.05
B5: Niveaux | C5: Niveau A | D5: Niveau B | E5: Niveau C | F5: Niveau D | G5: Niveau E
A6: 2 | B6: Valeur cible | C6: ='80%'!B2 -> 80 | D6: ='90%'!B2 -> 90 | E6: ='100%'!B2 -> 100 | F6: ='110%'!B2 -> 110 | G6: ='120%'!B2 -> 120
A7: 30 | B7: Moyenne niveau | C7: ='80%'!B22 -> 79.91487 | D7: ='90%'!B22 -> 89.840592 | E7: ='100%'!B22 -> 100.09898 | F7: ='110%'!B22 -> 109.73801 | G7: ='120%'!B22 -> 120.23453 | K7: =ADDRESS($A8,2,,,C$5) -> 'Niveau A'!$B$31
A8: 31 | B8: Ecart-type de répétabilité (sr) | C8: ='80%'!B23 -> 0.30101683 | D8: ='90%'!B23 -> 0.21062787 | E8: ='100%'!B23 -> 0.42475363 | F8: ='110%'!B23 -> 0.35373943 | G8: ='120%'!B23 -> 0.26455206
A9: 32 | B9: Ecart-type inter-séries (sL) | C9: ='80%'!B24 -> 0 | D9: ='90%'!B24 -> 0 | E9: ='100%'!B24 -> 0.22233302 | F9: ='110%'!B24 -> 0 | G9: ='120%'!B24 -> 0
A10: 33 | B10: Ecart-type de fidélité (sFI) | C10: ='80%'!B25 -> 0.30101683 | D10: ='90%'!B25 -> 0.21062787 | E10: ='100%'!B25 -> 0.47942426 | F10: ='110%'!B25 -> 0.35373943 | G10: ='120%'!B25 -> 0.26455206
A11: 37 | B11: Rapport des variances (R) | C11: ='80%'!B29 -> 0 | D11: ='90%'!B29 -> 0 | E11: ='100%'!B29 -> 0.27398937 | F11: ='110%'!B29 -> 0 | G11: ='120%'!B29 -> 0
A12: 39 | B12: Coefficient intermédiaire | C12: ='80%'!B31 -> 1.0606602 | D12: ='90%'!B31 -> 1.0606602 | E12: ='100%'!B31 -> 1.0732581 | F12: ='110%'!B31 -> 1.0606602 | G12: ='120%'!B31 -> 1.0606602
A13: 40 | B13: Nombre de degrés liberté | C13: ='80%'!B32 -> 6.8571429 | D13: ='90%'!B32 -> 6.8571429 | E13: ='100%'!B32 -> 6.1904363 | F13: ='110%'!B32 -> 6.8571429 | G13: ='120%'!B32 -> 6.8571429
A14: 47 | B14: Valeur basse tolérance | C14: ='80%'!B39 -> 79.156148 | D14: ='90%'!B39 -> 89.309698 | E14: ='100%'!B39 -> 98.847997 | F14: ='110%'!B39 -> 108.84639 | G14: ='120%'!B39 -> 119.56772
A15: 48 | B15: Valeur haute tolérance | C15: ='80%'!B40 -> 80.673593 | D15: ='90%'!B40 -> 90.371486 | E15: ='100%'!B40 -> 101.34997 | F15: ='110%'!B40 -> 110.62962 | G15: ='120%'!B40 -> 120.90134
A16: 35 | B16: Biais (%) | C16: ='80%'!B27 -> -0.0010641226 | D16: ='90%'!B27 -> -0.0017711995 | E16: ='100%'!B27 -> 0.00098982774 | F16: ='110%'!B27 -> -0.0023817618 | G16: ='120%'!B27 -> 0.0019543987
B17: Recouvrement (justesse) | C17: =C7/C$6 -> 0.99893588 | D17: =D7/D$6 -> 0.9982288 | E17: =E7/E$6 -> 1.0009898 | F17: =F7/F$6 -> 0.99761824 | G17: =G7/G$6 -> 1.0019544
B18: Limite basse tolérance (%) | C18: =C14/C$6 -> 0.98945185 | D18: =D14/D$6 -> 0.99232998 | E18: =E14/E$6 -> 0.98847997 | F18: =F14/F$6 -> 0.98951268 | G18: =G14/G$6 -> 0.99639763
B19: Limite haute tolérance (%) | C19: =C15/C$6 -> 1.0084199 | D19: =D15/D$6 -> 1.0041276 | E19: =E15/E$6 -> 1.0134997 | F19: =F15/F$6 -> 1.0057238 | G19: =G15/G$6 -> 1.0075112
B20: Limite d'acceptabilité basse | C20: =1-$C$3 -> 0.98 | D20: =1-$C$3 -> 0.98 | E20: =1-$C$3 -> 0.98 | F20: =1-$C$3 -> 0.98 | G20: =1-$C$3 -> 0.98
B21: Limite d'acceptabilité haute | C21: =1+$C$3 -> 1.02 | D21: =1+$C$3 -> 1.02 | E21: =1+$C$3 -> 1.02 | F21: =1+$C$3 -> 1.02 | G21: =1+$C$3 -> 1.02
B27: Incertitude
B28: Ecart-type de l'IT (sIT) | C28: =C$12*C$10 -> 0.31927656 | D28: =D$12*D$10 -> 0.22340459 | E28: =E$12*E$10 -> 0.51454598 | F28: =F$12*F$10 -> 0.37519732 | G28: =G$12*G$10 -> 0.28059983
B29: Incertitude élargie relative | C29: =2*C28/C7 -> 0.0079904168 | D29: =2*D28/D7 -> 0.0049733552 | E29: =2*E28/E7 -> 0.010280743 | F29: =2*F28/F7 -> 0.0068380561 | G29: =2*G28/G7 -> 0.0046675416

Sheet 80%
A1: Niveau A
A2: Valeur cible | B2: 80
B4: Répétition 1 | C4: Répétition 2 | D4: Répétition 3 | E4: Répétition 4 | F4: Répétition 5 | H4: nk | I4: SCEk
A5: Jour (Série) 1 | B5: =Analytique!U31*$B$2 -> 79.63828 | C5: =Analytique!V31*$B$2 -> 80.105892 | H5: =COUNT(B5:F5) -> 2 | I5: =IF(H5=0,"",DEVSQ(B5:F5)) -> 0.10933034
A6: Jour (Série) 2
A7: Jour (Série) 3 | B7: =Analytique!U33*$B$2 -> 79.735105 | C7: =Analytique!V33*$B$2 -> 80.275659 | H7: =COUNT(B7:F7) -> 2 | I7: =IF(H7=0,"",DEVSQ(B7:F7)) -> 0.14609924
A8: Jour (Série) 4 | B8: =Analytique!U34*$B$2 -> 80.25834 | C8: =Analytique!V34*$B$2 -> 80.011298 | H8: =COUNT(B8:F8) -> 2 | I8: =IF(H8=0,"",DEVSQ(B8:F8)) -> 0.03051493
A9: Jour (Série) 5 | B9: =Analytique!U35*$B$2 -> 79.451618 | C9: =Analytique!V35*$B$2 -> 79.84277 | H9: =COUNT(B9:F9) -> 2 | I9: =IF(H9=0,"",DEVSQ(B9:F9)) -> 0.076500013
A11: Nombre de séries (K) | B11: =COUNT(B5:B9) -> 4
A12: Nombre de mesures (IK) | B12: =COUNT(B5:F9) -> 8
A13: Nombre de répétitions (I) | B13: =IF(H5*B11<>B12,"Calcul impossible",H5) -> 2
A14: SCE résiduelle | B14: =SUM(I5:I9) -> 0.36244452
A15: SCE totale | B15: =DEVSQ(B5:F9) -> 0.62254626
A16: SCE inter-séries | B16: =B15-B14 -> 0.26010174
A17: Valeur intermédiaire de s²L | B17: =((B16/(B11-1))-B18)/B13 -> -0.001955276
A18: Variance de répétabilité (s²r) | B18: =B14/(B12-B11) -> 0.09061113
A19: Variance inter-séries (s²L) | B19: =IF(B17<0,0,B17) -> 0
A20: Variance de fidélité (s²FI) | B20: =SUM(B18:B19) -> 0.09061113
A21: Fidélité
A22: Moyenne niveau | B22: =AVERAGE(B5:F9) -> 79.91487
A23: Ecart-type de répétabilité (sr) | B23: =SQRT(B18) -> 0.30101683
A24: Ecart-type inter-séries (sL) | B24: =SQRT(B19) -> 0
A25: Ecart-type de fidélité (sFI) | B25: =SQRT(B20) -> 0.30101683
A26: Justesse
A27: Biais (%) | B27: =B22/B2-1 -> -0.0010641226
A28: Facteur de couverture
A29: Rapport des variances (R) | B29: =B19/B18 -> 0
A30: Coefficient B² | B30: =(B29+1)/(B13*B29+1) -> 1
A31: Coefficient intermédiaire | B31: =SQRT(1+1/(B12*B30)) -> 1.0606602
A32: Nombre de degrés liberté | B32: =(B29+1)^2/((B29+1/B13)^2/(B11-1)+(1-1/B13)/B12) -> 6.8571429
A33: Probabilité tolérance (bêta) | B33: =Récapitulatif!C2 -> 0.95
A34: t Student bas | B34: =TINV(1-B33,ROUNDDOWN(B32,0)) -> 2.4469119
A35: t Student haut | B35: =TINV(1-B33,ROUNDUP(B32,0)) -> 2.3646243
A36: t Student interpolé | B36: =B34-(B34-B35)*(B32-ROUNDDOWN(B32,0)) -> 2.3763796
A37: Facteur de couverture (ktol) | B37: =B36*B31 -> 2.5205312
A38: Intervalle de tolérance
A39: Valeur basse tolérance | B39: =B22-B37*B25 -> 79.156148
A40: Valeur haute tolérance | B40: =B22+B37*B25 -> 80.673593

Sheet 90%
A1: Niveau B
A2: Valeur cible | B2: 90
B4: Répétition 1 | C4: Répétition 2 | D4: Répétition 3 | E4: Répétition 4 | F4: Répétition 5 | H4: nk | I4: SCEk
A5: Jour (Série) 1 | B5: =Analytique!W31*$B$2 -> 90.126337 | C5: =Analytique!X31*$B$2 -> 89.696378 | H5: =COUNT(B5:F5) -> 2 | I5: =IF(H5=0,"",DEVSQ(B5:F5)) -> 0.092432691
A6: Jour (Série) 2 | B6: =Analytique!W32*$B$2 -> 89.862107 | C6: =Analytique!X32*$B$2 -> 89.726484 | H6: =COUNT(B6:F6) -> 2 | I6: =IF(H6=0,"",DEVSQ(B6:F6)) -> 0.0091967349
A7: Jour (Série) 3 | I7: =IF(H7=0,"",DEVSQ(B7:F7))
A8: Jour (Série) 4 | B8: =Analytique!W34*$B$2 -> 89.74944 | C8: =Analytique!X34*$B$2 -> 89.870913 | H8: =COUNT(B8:F8) -> 2 | I8: =IF(H8=0,"",DEVSQ(B8:F8)) -> 0.0073778703
A9: Jour (Série) 5 | B9: =Analytique!W35*$B$2 -> 90.031538 | C9: =Analytique!X35*$B$2 -> 89.66154 | H9: =COUNT(B9:F9) -> 2 | I9: =IF(H9=0,"",DEVSQ(B9:F9)) -> 0.068449095
A11: Nombre de séries (K) | B11: =COUNT(B5:B9) -> 4
A12: Nombre de mesures (IK) | B12: =COUNT(B5:F9) -> 8
A13: Nombre de répétitions (I) | B13: =IF(H5*B11<>B12,"Calcul impossible",H5) -> 2
A14: SCE résiduelle | B14: =SUM(I5:I9) -> 0.17745639
A15: SCE totale | B15: =DEVSQ(B5:F9) -> 0.19367956
A16: SCE inter-séries | B16: =B15-B14 -> 0.016223165
A17: Valeur intermédiaire de s²L | B17: =((B16/(B11-1))-B18)/B13 -> -0.019478188
A18: Variance de répétabilité (s²r) | B18: =B14/(B12-B11) -> 0.044364098
A19: Variance inter-séries (s²L) | B19: =IF(B17<0,0,B17) -> 0
A20: Variance de fidélité (s²FI) | B20: =SUM(B18:B19) -> 0.044364098
A21: Fidélité
A22: Moyenne niveau | B22: =AVERAGE(B5:F9) -> 89.840592
A23: Ecart-type de répétabilité (sr) | B23: =SQRT(B18) -> 0.21062787
A24: Ecart-type inter-séries (sL) | B24: =SQRT(B19) -> 0
A25: Ecart-type de fidélité (sFI) | B25: =SQRT(B20) -> 0.21062787
A26: Justesse
A27: Biais (%) | B27: =B22/B2-1 -> -0.0017711995
A28: Facteur de couverture
A29: Rapport des variances (R) | B29: =B19/B18 -> 0
A30: Coefficient B² | B30: =(B29+1)/(B13*B29+1) -> 1
A31: Coefficient intermédiaire | B31: =SQRT(1+1/(B12*B30)) -> 1.0606602
A32: Nombre de degrés liberté | B32: =(B29+1)^2/((B29+1/B13)^2/(B11-1)+(1-1/B13)/B12) -> 6.8571429
A33: Probabilité tolérance (bêta) | B33: =Récapitulatif!C2 -> 0.95
A34: t Student bas | B34: =TINV(1-B33,ROUNDDOWN(B32,0)) -> 2.4469119
A35: t Student haut | B35: =TINV(1-B33,ROUNDUP(B32,0)) -> 2.3646243
A36: t Student interpolé | B36: =B34-(B34-B35)*(B32-ROUNDDOWN(B32,0)) -> 2.3763796
A37: Facteur de couverture (ktol) | B37: =B36*B31 -> 2.5205312
A38: Intervalle de tolérance
A39: Valeur basse tolérance | B39: =B22-B37*B25 -> 89.309698
A40: Valeur haute tolérance | B40: =B22+B37*B25 -> 90.371486

Sheet 100%
A1: Niveau C
A2: Valeur cible | B2: 100
B4: Répétition 1 | C4: Répétition 2 | D4: Répétition 3 | E4: Répétition 4 | F4: Répétition 5 | H4: nk | I4: SCEk
A5: Jour (Série) 1 | B5: =Analytique!Y31*$B$2 -> 100.1477 | C5: =Analytique!Z31*$B$2 -> 99.170438 | H5: =COUNT(B5:F5) -> 2 | I5: =IF(H5=0,"",DEVSQ(B5:F5)) -> 0.47752284
A6: Jour (Série) 2 | B6: =Analytique!Y32*$B$2 -> 100.0748 | C6: =Analytique!Z32*$B$2 -> 100.34568 | H6: =COUNT(B6:F6) -> 2 | I6: =IF(H6=0,"",DEVSQ(B6:F6)) -> 0.036688881
A7: Jour (Série) 3 | B7: =Analytique!Y33*$B$2 -> 100.59112 | C7: =Analytique!Z33*$B$2 -> 100.49943 | H7: =COUNT(B7:F7) -> 2 | I7: =IF(H7=0,"",DEVSQ(B7:F7)) -> 0.0042032689
A8: Jour (Série) 4 | I8: =IF(H8=0,"",DEVSQ(B8:F8))
A9: Jour (Série) 5 | B9: =Analytique!Y35*$B$2 -> 99.66256 | C9: =Analytique!Z35*$B$2 -> 100.30013 | H9: =COUNT(B9:F9) -> 2 | I9: =IF(H9=0,"",DEVSQ(B9:F9)) -> 0.20324761
A11: Nombre de séries (K) | B11: =COUNT(B5:B9) -> 4
A12: Nombre de mesures (IK) | B12: =COUNT(B5:F9) -> 8
A13: Nombre de répétitions (I) | B13: =IF(H5*B11<>B12,"Calcul impossible",H5) -> 2
A14: SCE résiduelle | B14: =SUM(I5:I9) -> 0.7216626
A15: SCE totale | B15: =DEVSQ(B5:F9) -> 1.5595014
A16: SCE inter-séries | B16: =B15-B14 -> 0.83783877
A17: Valeur intermédiaire de s²L | B17: =((B16/(B11-1))-B18)/B13 -> 0.04943197
A18: Variance de répétabilité (s²r) | B18: =B14/(B12-B11) -> 0.18041565
A19: Variance inter-séries (s²L) | B19: =IF(B17<0,0,B17) -> 0.04943197
A20: Variance de fidélité (s²FI) | B20: =SUM(B18:B19) -> 0.22984762
A21: Fidélité
A22: Moyenne niveau | B22: =AVERAGE(B5:F9) -> 100.09898
A23: Ecart-type de répétabilité (sr) | B23: =SQRT(B18) -> 0.42475363
A24: Ecart-type inter-séries (sL) | B24: =SQRT(B19) -> 0.22233302
A25: Ecart-type de fidélité (sFI) | B25: =SQRT(B20) -> 0.47942426
A26: Justesse
A27: Biais (%) | B27: =B22/B2-1 -> 0.00098982774
A28: Facteur de couverture
A29: Rapport des variances (R) | B29: =B19/B18 -> 0.27398937
A30: Coefficient B² | B30: =(B29+1)/(B13*B29+1) -> 0.82300185
A31: Coefficient intermédiaire | B31: =SQRT(1+1/(B12*B30)) -> 1.0732581
A32: Nombre de degrés liberté | B32: =(B29+1)^2/((B29+1/B13)^2/(B11-1)+(1-1/B13)/B12) -> 6.1904363
A33: Probabilité tolérance (bêta) | B33: =Récapitulatif!C2 -> 0.95
A34: t Student bas | B34: =TINV(1-B33,ROUNDDOWN(B32,0)) -> 2.4469119
A35: t Student haut | B35: =TINV(1-B33,ROUNDUP(B32,0)) -> 2.3646243
A36: t Student interpolé | B36: =B34-(B34-B35)*(B32-ROUNDDOWN(B32,0)) -> 2.4312413
A37: Facteur de couverture (ktol) | B37: =B36*B31 -> 2.6093495
A38: Intervalle de tolérance
A39: Valeur basse tolérance | B39: =B22-B37*B25 -> 98.847997
A40: Valeur haute tolérance | B40: =B22+B37*B25 -> 101.34997

Sheet 110%
A1: Niveau D
A2: Valeur cible | B2: 110
B4: Répétition 1 | C4: Répétition 2 | D4: Répétition 3 | E4: Répétition 4 | F4: Répétition 5 | H4: nk | I4: SCEk
A5: Jour (Série) 1 | B5: =Analytique!AA31*$B$2 -> 110.33892 | C5: =Analytique!AB31*$B$2 -> 109.57629 | H5: =COUNT(B5:F5) -> 2 | I5: =IF(H5=0,"",DEVSQ(B5:F5)) -> 0.29079708
A6: Jour (Série) 2 | B6: =Analytique!AA32*$B$2 -> 109.29175 | C6: =Analytique!AB32*$B$2 -> 109.65253 | H6: =COUNT(B6:F6) -> 2 | I6: =IF(H6=0,"",DEVSQ(B6:F6)) -> 0.065080496
A7: Jour (Série) 3 | B7: =Analytique!AA33*$B$2 -> 109.51786 | C7: =Analytique!AB33*$B$2 -> 110.02954 | H7: =COUNT(B7:F7) -> 2 | I7: =IF(H7=0,"",DEVSQ(B7:F7)) -> 0.13091042
A8: Jour (Série) 4 | B8: =Analytique!AA34*$B$2 -> 109.83146 | C8: =Analytique!AB34*$B$2 -> 109.6657 | H8: =COUNT(B8:F8) -> 2 | I8: =IF(H8=0,"",DEVSQ(B8:F8)) -> 0.013738332
A9: Jour (Série) 5 | I9: =IF(H9=0,"",DEVSQ(B9:F9))
A11: Nombre de séries (K) | B11: =COUNT(B5:B9) -> 4
A12: Nombre de mesures (IK) | B12: =COUNT(B5:F9) -> 8
A13: Nombre de répétitions (I) | B13: =IF(H5*B11<>B12,"Calcul impossible",H5) -> 2
A14: SCE résiduelle | B14: =SUM(I5:I9) -> 0.50052633
A15: SCE totale | B15: =DEVSQ(B5:F9) -> 0.74111641
A16: SCE inter-séries | B16: =B15-B14 -> 0.24059008
A17: Valeur intermédiaire de s²L | B17: =((B16/(B11-1))-B18)/B13 -> -0.022467444
A18: Variance de répétabilité (s²r) | B18: =B14/(B12-B11) -> 0.12513158
A19: Variance inter-séries (s²L) | B19: =IF(B17<0,0,B17) -> 0
A20: Variance de fidélité (s²FI) | B20: =SUM(B18:B19) -> 0.12513158
A21: Fidélité
A22: Moyenne niveau | B22: =AVERAGE(B5:F9) -> 109.73801
A23: Ecart-type de répétabilité (sr) | B23: =SQRT(B18) -> 0.35373943
A24: Ecart-type inter-séries (sL) | B24: =SQRT(B19) -> 0
A25: Ecart-type de fidélité (sFI) | B25: =SQRT(B20) -> 0.35373943
A26: Justesse
A27: Biais (%) | B27: =B22/B2-1 -> -0.0023817618
A28: Facteur de couverture
A29: Rapport des variances (R) | B29: =B19/B18 -> 0
A30: Coefficient B² | B30: =(B29+1)/(B13*B29+1) -> 1
A31: Coefficient intermédiaire | B31: =SQRT(1+1/(B12*B30)) -> 1.0606602
A32: Nombre de degrés liberté | B32: =(B29+1)^2/((B29+1/B13)^2/(B11-1)+(1-1/B13)/B12) -> 6.8571429
A33: Probabilité tolérance (bêta) | B33: =Récapitulatif!C2 -> 0.95
A34: t Student bas | B34: =TINV(1-B33,ROUNDDOWN(B32,0)) -> 2.4469119
A35: t Student haut | B35: =TINV(1-B33,ROUNDUP(B32,0)) -> 2.3646243
A36: t Student interpolé | B36: =B34-(B34-B35)*(B32-ROUNDDOWN(B32,0)) -> 2.3763796
A37: Facteur de couverture (ktol) | B37: =B36*B31 -> 2.5205312
A38: Intervalle de tolérance
A39: Valeur basse tolérance | B39: =B22-B37*B25 -> 108.84639
A40: Valeur haute tolérance | B40: =B22+B37*B25 -> 110.62962

Sheet 120%
A1: Niveau E
A2: Valeur cible | B2: 120
B4: Répétition 1 | C4: Répétition 2 | D4: Répétition 3 | E4: Répétition 4 | F4: Répétition 5 | H4: nk | I4: SCEk
A5: Jour (Série) 1
A6: Jour (Série) 2 | B6: =Analytique!AC32*$B$2 -> 120.08227 | C6: =Analytique!AD32*$B$2 -> 120.14765 | H6: =COUNT(B6:F6) -> 2 | I6: =IF(H6=0,"",DEVSQ(B6:F6)) -> 0.0021370483
A7: Jour (Série) 3 | B7: =Analytique!AC33*$B$2 -> 120.44929 | C7: =Analytique!AD33*$B$2 -> 120.29161 | H7: =COUNT(B7:F7) -> 2 | I7: =IF(H7=0,"",DEVSQ(B7:F7)) -> 0.01243148
A8: Jour (Série) 4 | B8: =Analytique!AC34*$B$2 -> 120.28442 | C8: =Analytique!AD34*$B$2 -> 120.22844 | H8: =COUNT(B8:F8) -> 2 | I8: =IF(H8=0,"",DEVSQ(B8:F8)) -> 0.0015669989
A9: Jour (Série) 5 | B9: =Analytique!AC35*$B$2 -> 120.55946 | C9: =Analytique!AD35*$B$2 -> 119.83308 | H9: =COUNT(B9:F9) -> 2 | I9: =IF(H9=0,"",DEVSQ(B9:F9)) -> 0.26381563
A11: Nombre de séries (K) | B11: =COUNT(B5:B9) -> 4
A12: Nombre de mesures (IK) | B12: =COUNT(B5:F9) -> 8
A13: Nombre de répétitions (I) | B13: =IF(H6*B11<>B12,"Calcul impossible",H6) -> 2
A14: SCE résiduelle | B14: =SUM(I5:I9) -> 0.27995116
A15: SCE totale | B15: =DEVSQ(B5:F9) -> 0.34938102
A16: SCE inter-séries | B16: =B15-B14 -> 0.069429859
A17: Valeur intermédiaire de s²L | B17: =((B16/(B11-1))-B18)/B13 -> -0.023422252
A18: Variance de répétabilité (s²r) | B18: =B14/(B12-B11) -> 0.06998779
A19: Variance inter-séries (s²L) | B19: =IF(B17<0,0,B17) -> 0
A20: Variance de fidélité (s²FI) | B20: =SUM(B18:B19) -> 0.06998779
A21: Fidélité
A22: Moyenne niveau | B22: =AVERAGE(B5:F9) -> 120.23453
A23: Ecart-type de répétabilité (sr) | B23: =SQRT(B18) -> 0.26455206
A24: Ecart-type inter-séries (sL) | B24: =SQRT(B19) -> 0
A25: Ecart-type de fidélité (sFI) | B25: =SQRT(B20) -> 0.26455206
A26: Justesse
A27: Biais (%) | B27: =B22/B2-1 -> 0.0019543987
A28: Facteur de couverture
A29: Rapport des variances (R) | B29: =B19/B18 -> 0
A30: Coefficient B² | B30: =(B29+1)/(B13*B29+1) -> 1
A31: Coefficient intermédiaire | B31: =SQRT(1+1/(B12*B30)) -> 1.0606602
A32: Nombre de degrés liberté | B32: =(B29+1)^2/((B29+1/B13)^2/(B11-1)+(1-1/B13)/B12) -> 6.8571429
A33: Probabilité tolérance (bêta) | B33: =Récapitulatif!C2 -> 0.95
A34: t Student bas | B34: =TINV(1-B33,ROUNDDOWN(B32,0)) -> 2.4469119
A35: t Student haut | B35: =TINV(1-B33,ROUNDUP(B32,0)) -> 2.3646243
A36: t Student interpolé | B36: =B34-(B34-B35)*(B32-ROUNDDOWN(B32,0)) -> 2.3763796
A37: Facteur de couverture (ktol) | B37: =B36*B31 -> 2.5205312
A38: Intervalle de tolérance
A39: Valeur basse tolérance | B39: =B22-B37*B25 -> 119.56772
A40: Valeur haute tolérance | B40: =B22+B37*B25 -> 120.90134
