Workbook
Name ANALYTES: #REF!

Sheet CGL4f4n
G3: débit | H3: pression | I3: T°C | J3: colonne | K3: gaz | L3: lg onde | M3: alcool | N3: < Veuillez étudier de 4 à 7 paramètres avec de "petites" variations cohérentes
F4: -1 | G4: 1ml | H4: 1mbar | I4: 24 | J4: A | K4: oui | L4: 274 | M4: oui | N4: susceptible de se produire en routine
F5: 1 | G5: 2ml | H5: 2mbar | I5: 26 | J5: B | K5: non | L5: 276 | M5: non
C7: X | D7: opérateur | G7: paramètre équipement | N7: X
C8: Y | D8: jour | G8: =G3 -> débit | H8: =H3 -> pression | I8: =I3 -> T°C | J8: =J3 -> colonne | K8: =K3 -> gaz | L8: =L3 -> lg onde | M8: =M3 -> alcool | N8: pierre | O8: paul | P8: jack | Q8: marie | S8: Tolérance - | T8: 199 | U8: =+T8 -> 199 | V8: 0 | W8: =AA44 -> 0.64620853
D9: lundi | G9: 1 | H9: 1 | I9: 1 | J9: -1 | K9: 1 | L9: -1 | M9: -1 | N9: =201+RAND() -> 201.31786 | O9: =200+RAND() -> 200.62185 | P9: =200+RAND() -> 200.39461 | Q9: =201+RAND() -> 201.47614 | R9: =SUM(N9:Q9) -> 803.81046 | S9: Tolérance + | T9: 202 | U9: =+T9 -> 202 | V9: 0 | W9: =W8 -> 0.64620853
D10: mardi | G10: -1 | H10: 1 | I10: 1 | J10: 1 | K10: -1 | L10: 1 | M10: -1 | N10: =200+RAND() -> 200.00106 | O10: =201+RAND() -> 201.83046 | P10: =201+RAND() -> 201.84305 | Q10: =200+RAND() -> 200.17104 | R10: =SUM(N10:Q10) -> 803.84562
D11: mercredi | G11: -1 | H11: -1 | I11: 1 | J11: 1 | K11: 1 | L11: -1 | M11: 1 | N11: =200+RAND() -> 200.16603 | O11: =201+RAND() -> 201.82911 | P11: =201+RAND() -> 201.40221 | Q11: =200+RAND() -> 200.4552 | R11: =SUM(N11:Q11) -> 803.85254 | S11: moyenne | T11: =AVERAGE(N9:Q16) -> 201.00133
D12: jeudi | G12: 1 | H12: -1 | I12: -1 | J12: 1 | K12: 1 | L12: 1 | M12: -1 | N12: =201+RAND() -> 201.65279 | O12: =200+RAND() -> 200.23558 | P12: =200+RAND() -> 200.72889 | Q12: =201+RAND() -> 201.72089 | R12: =SUM(N12:Q12) -> 804.33816 | S12: S² totale | T12: =K40 -> 0.38113142
C13: Z | D13: échantillon | G13: -1 | H13: 1 | I13: -1 | J13: -1 | K13: 1 | L13: 1 | M13: 1 | N13: =200+RAND() -> 200.44919 | O13: =201+RAND() -> 201.00363 | P13: =201+RAND() -> 201.1396 | Q13: =200+RAND() -> 200.73781 | R13: =SUM(N13:Q13) -> 803.33023 | S13: S totale | T13: =SQRT(T12) -> 0.61735842
D14: X | G14: 1 | H14: -1 | I14: 1 | J14: -1 | K14: -1 | L14: 1 | M14: 1 | N14: =201+RAND() -> 201.9711 | O14: =200+RAND() -> 200.52201 | P14: =200+RAND() -> 200.09897 | Q14: =201+RAND() -> 201.27865 | R14: =SUM(N14:Q14) -> 803.87073 | S14: Min | T14: =MIN(N9:Q16) -> 200.00106 | Y14: -3 | Z14: =T$11+Y14*SQRT(T$12) -> 199.14926 | AA14: =NORMDIST(Z14,T$11,SQRT(T$12),0) -> 0.0071787284
D15: X | G15: 1 | H15: 1 | I15: -1 | J15: 1 | K15: -1 | L15: -1 | M15: 1 | N15: =201+RAND() -> 201.59445 | O15: =200+RAND() -> 200.9596 | P15: =200+RAND() -> 200.39423 | Q15: =201+RAND() -> 201.00999 | R15: =SUM(N15:Q15) -> 803.95827 | S15: Max | T15: =MAX(N9:Q16) -> 201.9711 | Y15: -2.9 | Z15: =T$11+Y15*SQRT(T$12) -> 199.21099 | AA15: =NORMDIST(Z15,T$11,SQRT(T$12),0) -> 0.0096419393
D16: X | G16: -1 | H16: -1 | I16: -1 | J16: -1 | K16: -1 | L16: -1 | M16: -1 | N16: =200+RAND() -> 200.7838 | O16: =201+RAND() -> 201.84791 | P16: =201+RAND() -> 201.66337 | Q16: =200+RAND() -> 200.74157 | R16: =SUM(N16:Q16) -> 805.03665 | S16: Cpk | T16: =MIN((T9-T11)/(3*SQRT(T12)),(T11-T8)/(3*SQRT(T12))) -> 0.53921519 | Y16: -2.8 | Z16: =T$11+Y16*SQRT(T$12) -> 199.27273 | AA16: =NORMDIST(Z16,T$11,SQRT(T$12),0) -> 0.012821485
D17: X | Q17: =SUM(M14:P14) -> 603.59208 | Y17: -2.7 | Z17: =T$11+Y17*SQRT(T$12) -> 199.33447 | AA17: =NORMDIST(Z17,T$11,SQRT(T$12),0) -> 0.016879878
Y18: -2.6 | Z18: =T$11+Y18*SQRT(T$12) -> 199.3962 | AA18: =NORMDIST(Z18,T$11,SQRT(T$12),0) -> 0.022001756
Y19: -2.5 | Z19: =T$11+Y19*SQRT(T$12) -> 199.45794 | AA19: =NORMDIST(Z19,T$11,SQRT(T$12),0) -> 0.028392421
Y20: -2.4 | Z20: =T$11+Y20*SQRT(T$12) -> 199.51967 | AA20: =NORMDIST(Z20,T$11,SQRT(T$12),0) -> 0.036274763
Y21: -2.3 | Z21: =T$11+Y21*SQRT(T$12) -> 199.58141 | AA21: =NORMDIST(Z21,T$11,SQRT(T$12),0) -> 0.045884266
Y22: -2.2 | Z22: =T$11+Y22*SQRT(T$12) -> 199.64314 | AA22: =NORMDIST(Z22,T$11,SQRT(T$12),0) -> 0.057461908
Y23: -2.1 | Z23: =T$11+Y23*SQRT(T$12) -> 199.70488 | AA23: =NORMDIST(Z23,T$11,SQRT(T$12),0) -> 0.07124483
Y24: -2 | Z24: =T$11+Y24*SQRT(T$12) -> 199.76662 | AA24: =NORMDIST(Z24,T$11,SQRT(T$12),0) -> 0.087454815
Y25: -1.9 | Z25: =T$11+Y25*SQRT(T$12) -> 199.82835 | AA25: =NORMDIST(Z25,T$11,SQRT(T$12),0) -> 0.1062848
Y26: -1.8 | Z26: =T$11+Y26*SQRT(T$12) -> 199.89009 | AA26: =NORMDIST(Z26,T$11,SQRT(T$12),0) -> 0.12788383
Y27: -1.7 | Z27: =T$11+Y27*SQRT(T$12) -> 199.95182 | AA27: =NORMDIST(Z27,T$11,SQRT(T$12),0) -> 0.15234113
Y28: -1.6 | Z28: =T$11+Y28*SQRT(T$12) -> 200.01356 | AA28: =NORMDIST(Z28,T$11,SQRT(T$12),0) -> 0.17967008
Y29: -1.5 | Z29: =T$11+Y29*SQRT(T$12) -> 200.0753 | AA29: =NORMDIST(Z29,T$11,SQRT(T$12),0) -> 0.2097932
... Y37: -0.7 | Z37: =T$11+Y37*SQRT(T$12) -> 200.56918 | AA37: =NORMDIST(Z37,T$11,SQRT(T$12),0) -> 0.50579035
E38: étape d'identification | I38: ANOVA | Y38: -0.6 | Z38: =T$11+Y38*SQRT(T$12) -> 200.63092 | AA38: =NORMDIST(Z38,T$11,SQRT(T$12),0) -> 0.53975874
E39: Origine | F39: niveau | G39: SB² | H39: CI | I39: SCE | J39: ddl | K39: CM | L39: Fobs | M39: F5% | N39: contrib% | O39: équiv β | Y39: -0.5 | Z39: =T$11+Y39*SQRT(T$12) -> 200.69265 | AA39: =NORMDIST(Z39,T$11,SQRT(T$12),0) -> 0.57027703
E40: Total | F40: =COUNT(N9:Q16) -> 32 | G40: =SUM(N9:Q16)^2 -> 41371173 | H40: =G40/F40 -> 1292849.1 | I40: =DEVSQ(N9:Q16) -> 11.815074 | J40: =F40-1 -> 31 | K40: =I40/J40 -> 0.38113142 | L40: x | M40: x | N40: =SUM(N42:N52) -> 1 | O40: x | Y40: -0.4 | Z40: =T$11+Y40*SQRT(T$12) -> 200.75439 | AA40: =NORMDIST(Z40,T$11,SQRT(T$12),0) -> 0.59652566
E41: modèle | F41: x | G41: x | H41: x | I41: =SUM(I43:I52) -> 9.8118521 | J41: =SUM(J43:J52) -> 14 | K41: =I41/J41 -> 0.70084658 | L41: =K41/K42 -> 5.9476147 | M41: =FINV(0.05,J41,J42) -> 2.328952 | N41: =I41/I40 -> 0.83045202 | O41: x | Y41: -0.3 | Z41: =T$11+Y41*SQRT(T$12) -> 200.81613 | AA41: =NORMDIST(Z41,T$11,SQRT(T$12),0) -> 0.61777373
E42: résiduel | F42: x | G42: x | H42: x | I42: =I40-I41 -> 2.0032219 | J42: =J40-J41 -> 17 | K42: =I42/J42 -> 0.11783658 | L42: x | M42: x | N42: =I42/I40 -> 0.16954798 | O42: x | Y42: -0.2 | Z42: =T$11+Y42*SQRT(T$12) -> 200.87786 | AA42: =NORMDIST(Z42,T$11,SQRT(T$12),0) -> 0.63341275
E43: =D7 -> opérateur | F43: 2 | G43: =SUM(N9:O16)^2+SUM(P9:Q16)^2 -> 20685588 | H43: =G43*F43/$F$40 -> 1292849.2 | I43: =H43-$H$40 -> 0.073174785 | J43: =F43-1 -> 1 | K43: =I43/J43 -> 0.073174785 | L43: =K43/K$42 -> 0.6209853 | M43: =FINV(0.05,J43,J$42) -> 4.4513218 | N43: =I43/$I$40 -> 0.0061933412 | O43: =1-FDIST(M43/L43,J43,J$42) -> 0.98409071 | Y43: -0.1 | Z43: =T$11+Y43*SQRT(T$12) -> 200.9396 | AA43: =NORMDIST(Z43,T$11,SQRT(T$12),0) -> 0.64298556
E44: =D13 -> échantillon | F44: 4 | G44: =SUM(N9,O10,P11,Q12,P13,Q14,N15,O16)^2+SUM(O9,N10,Q11,P12,Q13,P14,O15,N16)^2+SUM(P9,Q10,N11,O12,N13,O14,P15,Q16)^2+SUM(Q9,P10,O11,N12,O13,N14,Q15,P16)^2 -> 10342867 | H44: =G44*F44/$F$40 -> 1292858.4 | I44: =H44-$H$40 -> 9.2730073 | J44: 3 | K44: =I44/J44 -> 3.0910024 | L44: =K44/K$42 -> 26.231263 | M44: =FINV(0.05,J44,J$42) -> 3.1967768 | N44: =I44/$I$40 -> 0.78484546 | O44: =1-FDIST(M44/L44,J44,J$42) -> 0.054055885 | Y44: 0 | Z44: =T$11+Y44*SQRT(T$12) -> 201.00133 | AA44: =NORMDIST(Z44,T$11,SQRT(T$12),0) -> 0.64620853
E45: =D8 -> jour | F45: 4 | G45: =SUM(N9,Q10,O11,P12,N13,O15,P16,Q14)^2+SUM(O9,P10,N11,O13,P14,Q12,N15,Q16)^2+SUM(P9,O10,Q11,N12,P13,O14,Q15,N16)^2+SUM(Q9,N10,P11,O12,Q13,N14,P15,O16)^2 -> 10342793 | H45: =G45*F45/$F$40 -> 1292849.2 | I45: =H45-$H$40 -> 0.031341534 | J45: =F45-1 -> 3 | K45: =I45/J45 -> 0.010447178 | L45: =K45/K$42 -> 0.088658191 | M45: =FINV(0.05,J45,J$42) -> 3.1967768 | N45: =I45/$I$40 -> 0.0026526735 | O45: =1-FDIST(M45/L45,J45,J$42) -> 0.99999986 | Y45: 0.1 | Z45: =T$11+Y45*SQRT(T$12) -> 201.06307 | AA45: =NORMDIST(Z45,T$11,SQRT(T$12),0) -> 0.64298556
E46: =G3 -> débit | F46: 2 | G46: =SUM(R9,R12,R14,R15)^2+SUM(R10,R11,R13,R16)^2 -> 20685586 | H46: =G46*F46/$F$40 -> 1292849.1 | I46: =H46-$H$40 -> 0.00023880135 | J46: =F46-1 -> 1 | K46: =I46/J46 -> 0.00023880135 | L46: =K46/K$42 -> 0.0020265468 | M46: =FINV(0.05,J46,J$42) -> 4.4513218 | N46: =I46/$I$40 -> 2.0211583e-05 | O46: =1-FDIST(M46/L46,J46,J$42) -> 1 | Y46: 0.2 | Z46: =T$11+Y46*SQRT(T$12) -> 201.1248 | AA46: =NORMDIST(Z46,T$11,SQRT(T$12),0) -> 0.63341275
E47: =H3 -> pression | F47: 2 | G47: =SUM(R9,R10,R13,R15)^2+SUM(R11,R12,R14,R16)^2 -> 20685589 | H47: =G47*F47/$F$40 -> 1292849.3 | I47: =H47-$H$40 -> 0.14492357 | J47: =F47-1 -> 1 | K47: =I47/J47 -> 0.14492357 | L47: =K47/K$42 -> 1.2298691 | M47: =FINV(0.05,J47,J$42) -> 4.4513218 | N47: =I47/$I$40 -> 0.012265989 | O47: =1-FDIST(M47/L47,J47,J$42) -> 0.92580923 | Y47: 0.3 | Z47: =T$11+Y47*SQRT(T$12) -> 201.18654 | AA47: =NORMDIST(Z47,T$11,SQRT(T$12),0) -> 0.61777373
E48: =I3 -> T°C | F48: 2 | G48: =SUM(R9,R10,R11,R14)^2+SUM(R12,R13,R15,R16)^2 -> 20685587 | H48: =G48*F48/$F$40 -> 1292849.2 | I48: =H48-$H$40 -> 0.051517804 | J48: =F48-1 -> 1 | K48: =I48/J48 -> 0.051517804 | L48: =K48/K$42 -> 0.43719704 | M48: =FINV(0.05,J48,J$42) -> 4.4513218 | N48: =I48/$I$40 -> 0.0043603454 | O48: =1-FDIST(M48/L48,J48,J$42) -> 0.99464808 | Y48: 0.4 | Z48: =T$11+Y48*SQRT(T$12) -> 201.24828 | AA48: =NORMDIST(Z48,T$11,SQRT(T$12),0) -> 0.59652566
E49: =J3 -> colonne | F49: 2 | G49: =SUM(R10,R11,R12,R15)^2+SUM(R9,R13,R14,R16)^2 -> 20685586 | H49: =G49*F49/$F$40 -> 1292849.1 | I49: =H49-$H$40 -> 8.9371111e-05 | J49: =F49-1 -> 1 | K49: =I49/J49 -> 8.9371111e-05 | L49: =K49/K$42 -> 0.00075843265 | M49: =FINV(0.05,J49,J$42) -> 4.4513218 | N49: =I49/$I$40 -> 7.5641601e-06 | O49: =1-FDIST(M49/L49,J49,J$42) -> 1 | Y49: 0.5 | Z49: =T$11+Y49*SQRT(T$12) -> 201.31001 | AA49: =NORMDIST(Z49,T$11,SQRT(T$12),0) -> 0.57027703
E50: =K3 -> gaz | F50: 2 | G50: =SUM(R9,R11,R12,R13)^2+SUM(R10,R14,R15,R16)^2 -> 20685587 | H50: =G50*F50/$F$40 -> 1292849.2 | I50: =H50-$H$40 -> 0.059502353 | J50: =F50-1 -> 1 | K50: =I50/J50 -> 0.059502353 | L50: =K50/K$42 -> 0.50495654 | M50: =FINV(0.05,J50,J$42) -> 4.4513218 | N50: =I50/$I$40 -> 0.0050361388 | O50: =1-FDIST(M50/L50,J50,J$42) -> 0.99139637 | Y50: 0.6 | Z50: =T$11+Y50*SQRT(T$12) -> 201.37175 | AA50: =NORMDIST(Z50,T$11,SQRT(T$12),0) -> 0.53975874
...

Sheet CGL4f4n (2)
G3: pression | H3: température | I3: tps | J3: lot | K3: solvant | L3: débit | M3: lg d'onde | N3: < Veuillez étudier de 4 à 7 paramètres avec de "petites" variations cohérentes
F4: -1 | G4: 1ml | H4: 1mbar | I4: 24 | J4: A | K4: oui | L4: 274 | M4: oui | N4: susceptible de se produire en routine
F5: 1 | G5: 2ml | H5: 2mbar | I5: 26 | J5: B | K5: non | L5: 276 | M5: non
C7: X | D7: niveau | G7: Production | K7: Analytique | N7: niveau (% de la valeur cible)
C8: Y | D8: jour (4j) | G8: pression | H8: température | I8: tps | J8: lot | K8: solvant | L8: débit | M8: lg d'onde | N8: 0.7 | O8: 0.8 | P8: 1 | Q8: 1.2 | S8: Tolérance - | T8: 0.98 | U8: =+T8 -> 0.98 | V8: 0 | W8: =AA44 -> 113.961
D9: lundi | G9: 1 | H9: 1 | I9: 1 | J9: -1 | K9: 1 | L9: -1 | M9: -1 | N9: =1+(RAND()-RAND())/100 -> 0.99515814 | O9: =1+(RAND()-RAND())/100 -> 0.99378232 | P9: =1+(RAND()-RAND())/100 -> 0.99866025 | Q9: =1+(RAND()-RAND())/100 -> 0.99824922 | R9: =SUM(N9:Q9) -> 3.9858499 | S9: Tolérance + | T9: 1.02 | U9: =+T9 -> 1.02 | V9: 0 | W9: =W8 -> 113.961
D10: mardi | G10: -1 | H10: 1 | I10: 1 | J10: 1 | K10: -1 | L10: 1 | M10: -1 | N10: =1+(RAND()-RAND())/100 -> 1.0018323 | O10: =1+(RAND()-RAND())/100 -> 1.0053193 | P10: =1+(RAND()-RAND())/100 -> 0.99749081 | Q10: =1+(RAND()-RAND())/100 -> 0.99702195 | R10: =SUM(N10:Q10) -> 4.0016643
D11: mercredi | G11: -1 | H11: -1 | I11: 1 | J11: 1 | K11: 1 | L11: -1 | M11: 1 | N11: =1+(RAND()-RAND())/100 -> 1.0006305 | O11: =1+(RAND()-RAND())/100 -> 1.0069601 | P11: =1+(RAND()-RAND())/100 -> 1.0013289 | Q11: =1+(RAND()-RAND())/100 -> 0.99290708 | R11: =SUM(N11:Q11) -> 4.0018266 | S11: moyenne | T11: =AVERAGE(N9:Q16) -> 0.99988499
D12: jeudi | G12: 1 | H12: -1 | I12: -1 | J12: 1 | K12: 1 | L12: 1 | M12: -1 | N12: =1+(RAND()-RAND())/100 -> 1.0004045 | O12: =1+(RAND()-RAND())/100 -> 1.0029829 | P12: =1+(RAND()-RAND())/100 -> 1.0041678 | Q12: =1+(RAND()-RAND())/100 -> 0.99994109 | R12: =SUM(N12:Q12) -> 4.0074964 | S12: S² totale | T12: =K40 -> 1.2254839e-05
C13: Z | D13: échantillon (4 éch) | G13: -1 | H13: 1 | I13: -1 | J13: -1 | K13: 1 | L13: 1 | M13: 1 | N13: =1+(RAND()-RAND())/100 -> 0.9989523 | O13: =1+(RAND()-RAND())/100 -> 1.0017169 | P13: =1+(RAND()-RAND())/100 -> 1.001163 | Q13: =1+(RAND()-RAND())/100 -> 0.99737072 | R13: =SUM(N13:Q13) -> 3.9992029 | S13: S totale | T13: =SQRT(T12) -> 0.0035006913
D14: X | G14: 1 | H14: -1 | I14: 1 | J14: -1 | K14: -1 | L14: 1 | M14: 1 | N14: =1+(RAND()-RAND())/100 -> 1.0028941 | O14: =1+(RAND()-RAND())/100 -> 0.99507246 | P14: =1+(RAND()-RAND())/100 -> 0.99986305 | Q14: =1+(RAND()-RAND())/100 -> 1.006754 | R14: =SUM(N14:Q14) -> 4.0045836 | S14: Min | T14: =MIN(N9:Q16) -> 0.99290708 | Y14: -3 | Z14: =T$11+Y14*SQRT(T$12) -> 0.98938292 | AA14: =NORMDIST(Z14,T$11,SQRT(T$12),0) -> 1.2659924
D15: X | G15: 1 | H15: 1 | I15: -1 | J15: 1 | K15: -1 | L15: -1 | M15: 1 | N15: =1+(RAND()-RAND())/100 -> 0.99933335 | O15: =1+(RAND()-RAND())/100 -> 0.99963912 | P15: =1+(RAND()-RAND())/100 -> 0.99802931 | Q15: =1+(RAND()-RAND())/100 -> 1.0042273 | R15: =SUM(N15:Q15) -> 4.0012291 | S15: Max | T15: =MAX(N9:Q16) -> 1.0069601 | Y15: -2.9 | Z15: =T$11+Y15*SQRT(T$12) -> 0.98973299 | AA15: =NORMDIST(Z15,T$11,SQRT(T$12),0) -> 1.7003877
D16: X | G16: -1 | H16: -1 | I16: -1 | J16: -1 | K16: -1 | L16: -1 | M16: -1 | N16: =1+(RAND()-RAND())/100 -> 0.99670542 | O16: =1+(RAND()-RAND())/100 -> 1.0022216 | P16: =1+(RAND()-RAND())/100 -> 0.99725815 | Q16: =1+(RAND()-RAND())/100 -> 0.99828179 | R16: =SUM(N16:Q16) -> 3.994467 | S16: Cpk | T16: =MIN((T9-T11)/(3*SQRT(T12)),(T11-T8)/(3*SQRT(T12))) -> 1.8934351 | Y16: -2.8 | Z16: =T$11+Y16*SQRT(T$12) -> 0.99008306 | AA16: =NORMDIST(Z16,T$11,SQRT(T$12),0) -> 2.261111
D17: X | Q17: =SUM(M14:P14) -> 3.9978296 | Y17: -2.7 | Z17: =T$11+Y17*SQRT(T$12) -> 0.99043313 | AA17: =NORMDIST(Z17,T$11,SQRT(T$12),0) -> 2.976822
Y18: -2.6 | Z18: =T$11+Y18*SQRT(T$12) -> 0.9907832 | AA18: =NORMDIST(Z18,T$11,SQRT(T$12),0) -> 3.880082
Y19: -2.5 | Z19: =T$11+Y19*SQRT(T$12) -> 0.99113327 | AA19: =NORMDIST(Z19,T$11,SQRT(T$12),0) -> 5.0070969
Y20: -2.4 | Z20: =T$11+Y20*SQRT(T$12) -> 0.99148334 | AA20: =NORMDIST(Z20,T$11,SQRT(T$12),0) -> 6.3971737
Y21: -2.3 | Z21: =T$11+Y21*SQRT(T$12) -> 0.9918334 | AA21: =NORMDIST(Z21,T$11,SQRT(T$12),0) -> 8.0918412
Y22: -2.2 | Z22: =T$11+Y22*SQRT(T$12) -> 0.99218347 | AA22: =NORMDIST(Z22,T$11,SQRT(T$12),0) -> 10.133596
Y23: -2.1 | Z23: =T$11+Y23*SQRT(T$12) -> 0.99253354 | AA23: =NORMDIST(Z23,T$11,SQRT(T$12),0) -> 12.56426
Y24: -2 | Z24: =T$11+Y24*SQRT(T$12) -> 0.99288361 | AA24: =NORMDIST(Z24,T$11,SQRT(T$12),0) -> 15.422944
Y25: -1.9 | Z25: =T$11+Y25*SQRT(T$12) -> 0.99323368 | AA25: =NORMDIST(Z25,T$11,SQRT(T$12),0) -> 18.743674
Y26: -1.8 | Z26: =T$11+Y26*SQRT(T$12) -> 0.99358375 | AA26: =NORMDIST(Z26,T$11,SQRT(T$12),0) -> 22.552734
Y27: -1.7 | Z27: =T$11+Y27*SQRT(T$12) -> 0.99393382 | AA27: =NORMDIST(Z27,T$11,SQRT(T$12),0) -> 26.865859
Y28: -1.6 | Z28: =T$11+Y28*SQRT(T$12) -> 0.99428389 | AA28: =NORMDIST(Z28,T$11,SQRT(T$12),0) -> 31.685409
Y29: -1.5 | Z29: =T$11+Y29*SQRT(T$12) -> 0.99463396 | AA29: =NORMDIST(Z29,T$11,SQRT(T$12),0) -> 36.99772
... Y37: -0.7 | Z37: =T$11+Y37*SQRT(T$12) -> 0.99743451 | AA37: =NORMDIST(Z37,T$11,SQRT(T$12),0) -> 89.197792
E38: étape d'identification | I38: ANOVA | Y38: -0.6 | Z38: =T$11+Y38*SQRT(T$12) -> 0.99778458 | AA38: =NORMDIST(Z38,T$11,SQRT(T$12),0) -> 95.188229
E39: Origine | F39: niveau | G39: SB² | H39: CI | I39: SCE | J39: ddl | K39: CM | L39: Fobs | M39: F5% | N39: contrib% | O39: risque β | Y39: -0.5 | Z39: =T$11+Y39*SQRT(T$12) -> 0.99813465 | AA39: =NORMDIST(Z39,T$11,SQRT(T$12),0) -> 100.57023
E40: Total | F40: =COUNT(N9:Q16) -> 32 | G40: =SUM(N9:Q16)^2 -> 1023.7645 | H40: =G40/F40 -> 31.99264 | I40: =DEVSQ(N9:Q16) -> 0.00037990002 | J40: =F40-1 -> 31 | K40: =I40/J40 -> 1.2254839e-05 | L40: x | M40: x | N40: =SUM(N42:N52) -> 1 | O40: x | Y40: -0.4 | Z40: =T$11+Y40*SQRT(T$12) -> 0.99848472 | AA40: =NORMDIST(Z40,T$11,SQRT(T$12),0) -> 105.19926
E41: modèle | F41: x | G41: x | H41: x | I41: =SUM(I43:I52) -> 0.0001660914 | J41: =SUM(J43:J52) -> 14 | K41: =I41/J41 -> 1.1863672e-05 | L41: =K41/K42 -> 0.9432848 | M41: =FINV(0.05,J41,J42) -> 2.328952 | N41: =I41/I40 -> 0.43719767 | O41: x | Y41: -0.3 | Z41: =T$11+Y41*SQRT(T$12) -> 0.99883479 | AA41: =NORMDIST(Z41,T$11,SQRT(T$12),0) -> 108.94643
E42: résiduel | F42: x | G42: x | H42: x | I42: =I40-I41 -> 0.00021380862 | J42: =J40-J41 -> 17 | K42: =I42/J42 -> 1.2576978e-05 | L42: x | M42: x | N42: =I42/I40 -> 0.56280233 | O42: x | Y42: -0.2 | Z42: =T$11+Y42*SQRT(T$12) -> 0.99918486 | AA42: =NORMDIST(Z42,T$11,SQRT(T$12),0) -> 111.70442
E43: =D7 -> niveau | F43: 2 | G43: =SUM(N9:O16)^2+SUM(P9:Q16)^2 -> 511.8823 | H43: =G43*F43/$F$40 -> 31.992644 | I43: =H43-$H$40 -> 3.706677e-06 | J43: =F43-1 -> 1 | K43: =I43/J43 -> 3.706677e-06 | L43: =K43/K$42 -> 0.29471922 | M43: =FINV(0.05,J43,J$42) -> 4.4513218 | N43: =I43/$I$40 -> 0.0097569802 | O43: =1-FDIST(M43/L43,J43,J$42) -> 0.99881365 | Y43: -0.1 | Z43: =T$11+Y43*SQRT(T$12) -> 0.99953493 | AA43: =NORMDIST(Z43,T$11,SQRT(T$12),0) -> 113.39262
E44: =D13 -> échantillon (4 éch) | F44: 4 | G44: =SUM(N9,O10,P11,Q12,P13,Q14,N15,O16)^2+SUM(O9,N10,Q11,P12,Q13,P14,O15,N16)^2+SUM(P9,Q10,N11,O12,N13,O14,P15,Q16)^2+SUM(Q9,P10,O11,N12,O13,N14,Q15,P16)^2 -> 255.94162 | H44: =G44*F44/$F$40 -> 31.992703 | I44: =H44-$H$40 -> 6.2903457e-05 | J44: 3 | K44: =I44/J44 -> 2.0967819e-05 | L44: =K44/K$42 -> 1.6671588 | M44: =FINV(0.05,J44,J$42) -> 3.1967768 | N44: =I44/$I$40 -> 0.16557898 | O44: =1-FDIST(M44/L44,J44,J$42) -> 0.83492854 | Y44: 0 | Z44: =T$11+Y44*SQRT(T$12) -> 0.99988499 | AA44: =NORMDIST(Z44,T$11,SQRT(T$12),0) -> 113.961
E45: =D8 -> jour (4j) | F45: 4 | G45: =SUM(N9,Q10,O11,P12,N13,O15,P16,Q14)^2+SUM(O9,P10,N11,O13,P14,Q12,N15,Q16)^2+SUM(P9,O10,Q11,N12,P13,O14,Q15,N16)^2+SUM(Q9,N10,P11,O12,Q13,N14,P15,O16)^2 -> 255.94129 | H45: =G45*F45/$F$40 -> 31.992661 | I45: =H45-$H$40 -> 2.0830662e-05 | J45: =F45-1 -> 3 | K45: =I45/J45 -> 6.9435541e-06 | L45: =K45/K$42 -> 0.55208448 | M45: =FINV(0.05,J45,J$42) -> 3.1967768 | N45: =I45/$I$40 -> 0.054831958 | O45: =1-FDIST(M45/L45,J45,J$42) -> 0.99355063 | Y45: 0.1 | Z45: =T$11+Y45*SQRT(T$12) -> 1.0002351 | AA45: =NORMDIST(Z45,T$11,SQRT(T$12),0) -> 113.39262
E46: =G3 -> pression | F46: 2 | G46: =SUM(R9,R12,R14,R15)^2+SUM(R10,R11,R13,R16)^2 -> 511.88224 | H46: =G46*F46/$F$40 -> 31.99264 | I46: =H46-$H$40 -> 1.2476728e-07 | J46: =F46-1 -> 1 | K46: =I46/J46 -> 1.2476728e-07 | L46: =K46/K$42 -> 0.0099202912 | M46: =FINV(0.05,J46,J$42) -> 4.4513218 | N46: =I46/$I$40 -> 0.00032842135 | O46: =1-FDIST(M46/L46,J46,J$42) -> 1 | Y46: 0.2 | Z46: =T$11+Y46*SQRT(T$12) -> 1.0005851 | AA46: =NORMDIST(Z46,T$11,SQRT(T$12),0) -> 111.70442
E47: =H3 -> température | F47: 2 | G47: =SUM(R9,R10,R13,R15)^2+SUM(R11,R12,R14,R16)^2 -> 511.88245 | H47: =G47*F47/$F$40 -> 31.992653 | I47: =H47-$H$40 -> 1.3039804e-05 | J47: =F47-1 -> 1 | K47: =I47/J47 -> 1.3039804e-05 | L47: =K47/K$42 -> 1.0367995 | M47: =FINV(0.05,J47,J$42) -> 4.4513218 | N47: =I47/$I$40 -> 0.034324305 | O47: =1-FDIST(M47/L47,J47,J$42) -> 0.94621268 | Y47: 0.3 | Z47: =T$11+Y47*SQRT(T$12) -> 1.0009352 | AA47: =NORMDIST(Z47,T$11,SQRT(T$12),0) -> 108.94643
E48: =I3 -> tps | F48: 2 | G48: =SUM(R9,R10,R11,R14)^2+SUM(R12,R13,R15,R16)^2 -> 511.88228 | H48: =G48*F48/$F$40 -> 31.992642 | I48: =H48-$H$40 -> 2.2423714e-06 | J48: =F48-1 -> 1 | K48: =I48/J48 -> 2.2423714e-06 | L48: =K48/K$42 -> 0.17829176 | M48: =FINV(0.05,J48,J$42) -> 4.4513218 | N48: =I48/$I$40 -> 0.0059025304 | O48: =1-FDIST(M48/L48,J48,J$42) -> 0.99988965 | Y48: 0.4 | Z48: =T$11+Y48*SQRT(T$12) -> 1.0012853 | AA48: =NORMDIST(Z48,T$11,SQRT(T$12),0) -> 105.19926
E49: =J3 -> lot | F49: 2 | G49: =SUM(R10,R11,R12,R15)^2+SUM(R9,R13,R14,R16)^2 -> 511.88264 | H49: =G49*F49/$F$40 -> 31.992665 | I49: =H49-$H$40 -> 2.4698039e-05 | J49: =F49-1 -> 1 | K49: =I49/J49 -> 2.4698039e-05 | L49: =K49/K$42 -> 1.9637499 | M49: =FINV(0.05,J49,J$42) -> 4.4513218 | N49: =I49/$I$40 -> 0.065011944 | O49: =1-FDIST(M49/L49,J49,J$42) -> 0.84946856 | Y49: 0.5 | Z49: =T$11+Y49*SQRT(T$12) -> 1.0016353 | AA49: =NORMDIST(Z49,T$11,SQRT(T$12),0) -> 100.57023
E50: =K3 -> solvant | F50: 2 | G50: =SUM(R9,R11,R12,R13)^2+SUM(R10,R14,R15,R16)^2 -> 511.88227 | H50: =G50*F50/$F$40 -> 31.992642 | I50: =H50-$H$40 -> 1.7899342e-06 | J50: =F50-1 -> 1 | K50: =I50/J50 -> 1.7899342e-06 | L50: =K50/K$42 -> 0.14231831 | M50: =FINV(0.05,J50,J$42) -> 4.4513218 | N50: =I50/$I$40 -> 0.0047115929 | O50: =1-FDIST(M50/L50,J50,J$42) -> 0.99996765 | Y50: 0.6 | Z50: =T$11+Y50*SQRT(T$12) -> 1.0019854 | AA50: =NORMDIST(Z50,T$11,SQRT(T$12),0) -> 95.188229
...

Sheet Récapitulatif
B1: Profil d'exactitude
B2: Probabilité tolérance (bêta) | C2: =#REF! -> #REF! | E2: 20 | F2: 100
B3: Limite d'acceptabilité | C3: =#REF! -> #REF! | E3: 0.01 | F3: =E3*F2/E2 -> 0.05
B5: Niveaux | C5: Niveau A | D5: Niveau B | E5: Niveau C | F5: Niveau D | G5: Niveau E
A6: 2 | B6: Valeur cible | C6: ='80%'!B2 -> 80 | D6: ='90%'!B2 -> 90 | E6: ='100%'!B2 -> 100 | F6: ='110%'!B2 -> 110 | G6: ='120%'!B2 -> 120
A7: 30 | B7: Moyenne niveau | C7: ='80%'!B22 -> #REF! | D7: ='90%'!B22 -> #REF! | E7: ='100%'!B22 -> #REF! | F7: ='110%'!B22 -> #REF! | G7: ='120%'!B22 -> #REF! | K7: =ADDRESS($A8,2,,,C$5) -> 'Niveau A'!$B$31
A8: 31 | B8: Ecart-type de répétabilité (sr) | C8: ='80%'!B23 -> #DIV/0! | D8: ='90%'!B23 -> #DIV/0! | E8: ='100%'!B23 -> #DIV/0! | F8: ='110%'!B23 -> #DIV/0! | G8: ='120%'!B23 -> #DIV/0!
A9: 32 | B9: Ecart-type inter-séries (sL) | C9: ='80%'!B24 -> #REF! | D9: ='90%'!B24 -> #REF! | E9: ='100%'!B24 -> #REF! | F9: ='110%'!B24 -> #REF! | G9: ='120%'!B24 -> #REF!
A10: 33 | B10: Ecart-type de fidélité (sFI) | C10: ='80%'!B25 -> #DIV/0! | D10: ='90%'!B25 -> #DIV/0! | E10: ='100%'!B25 -> #DIV/0! | F10: ='110%'!B25 -> #DIV/0! | G10: ='120%'!B25 -> #DIV/0!
A11: 37 | B11: Rapport des variances (R) | C11: ='80%'!B29 -> #REF! | D11: ='90%'!B29 -> #REF! | E11: ='100%'!B29 -> #REF! | F11: ='110%'!B29 -> #REF! | G11: ='120%'!B29 -> #REF!
A12: 39 | B12: Coefficient intermédiaire | C12: ='80%'!B31 -> #REF! | D12: ='90%'!B31 -> #REF! | E12: ='100%'!B31 -> #REF! | F12: ='110%'!B31 -> #REF! | G12: ='120%'!B31 -> #REF!
A13: 40 | B13: Nombre de degrés liberté | C13: ='80%'!B32 -> #REF! | D13: ='90%'!B32 -> #REF! | E13: ='100%'!B32 -> #REF! | F13: ='110%'!B32 -> #REF! | G13: ='120%'!B32 -> #REF!
A14: 47 | B14: Valeur basse tolérance | C14: ='80%'!B39 -> #REF! | D14: ='90%'!B39 -> #REF! | E14: ='100%'!B39 -> #REF! | F14: ='110%'!B39 -> #REF! | G14: ='120%'!B39 -> #REF!
A15: 48 | B15: Valeur haute tolérance | C15: ='80%'!B40 -> #REF! | D15: ='90%'!B40 -> #REF! | E15: ='100%'!B40 -> #REF! | F15: ='110%'!B40 -> #REF! | G15: ='120%'!B40 -> #REF!
A16: 35 | B16: Biais (%) | C16: ='80%'!B27 -> #REF! | D16: ='90%'!B27 -> #REF! | E16: ='100%'!B27 -> #REF! | F16: ='110%'!B27 -> #REF! | G16: ='120%'!B27 -> #REF!
B17: Recouvrement (justesse) | C17: =C7/C$6 -> #REF! | D17: =D7/D$6 -> #REF! | E17: =E7/E$6 -> #REF! | F17: =F7/F$6 -> #REF! | G17: =G7/G$6 -> #REF!
B18: Limite basse tolérance (%) | C18: =C14/C$6 -> #REF! | D18: =D14/D$6 -> #REF! | E18: =E14/E$6 -> #REF! | F18: =F14/F$6 -> #REF! | G18: =G14/G$6 -> #REF!
B19: Limite haute tolérance (%) | C19: =C15/C$6 -> #REF! | D19: =D15/D$6 -> #REF! | E19: =E15/E$6 -> #REF! | F19: =F15/F$6 -> #REF! | G19: =G15/G$6 -> #REF!
B20: Limite d'acceptabilité basse | C20: =1-$C$3 -> #REF! | D20: =1-$C$3 -> #REF! | E20: =1-$C$3 -> #REF! | F20: =1-$C$3 -> #REF! | G20: =1-$C$3 -> #REF!
B21: Limite d'acceptabilité haute | C21: =1+$C$3 -> #REF! | D21: =1+$C$3 -> #REF! | E21: =1+$C$3 -> #REF! | F21: =1+$C$3 -> #REF! | G21: =1+$C$3 -> #REF!
B27: Incertitude
B28: Ecart-type de l'IT (sIT) | C28: =C$12*C$10 -> #REF! | D28: =D$12*D$10 -> #REF! | E28: =E$12*E$10 -> #REF! | F28: =F$12*F$10 -> #REF! | G28: =G$12*G$10 -> #REF!
B29: Incertitude élargie relative | C29: =2*C28/C7 -> #REF! | D29: =2*D28/D7 -> #REF! | E29: =2*E28/E7 -> #REF! | F29: =2*F28/F7 -> #REF! | G29: =2*G28/G7 -> #REF!

Sheet 80%
A1: Niveau A
A2: Valeur cible | B2: 80
B4: Répétition 1 | C4: Répétition 2 | D4: Répétition 3 | E4: Répétition 4 | F4: Répétition 5 | H4: nk | I4: SCEk
A5: Jour (Série) 1 | B5: =#REF!*$B$2 -> #REF! | C5: =#REF!*$B$2 -> #REF! | H5: =COUNT(B5:F5) -> 0 | I5: =IF(H5=0,"",DEVSQ(B5:F5))
A6: Jour (Série) 2
A7: Jour (Série) 3 | B7: =#REF!*$B$2 -> #REF! | C7: =#REF!*$B$2 -> #REF! | H7: =COUNT(B7:F7) -> 0 | I7: =IF(H7=0,"",DEVSQ(B7:F7))
A8: Jour (Série) 4 | B8: =#REF!*$B$2 -> #REF! | C8: =#REF!*$B$2 -> #REF! | H8: =COUNT(B8:F8) -> 0 | I8: =IF(H8=0,"",DEVSQ(B8:F8))
A9: Jour (Série) 5 | B9: =#REF!*$B$2 -> #REF! | C9: =#REF!*$B$2 -> #REF! | H9: =COUNT(B9:F9) -> 0 | I9: =IF(H9=0,"",DEVSQ(B9:F9))
A11: Nombre de séries (K) | B11: =COUNT(B5:B9) -> 0
A12: Nombre de mesures (IK) | B12: =COUNT(B5:F9) -> 0
A13: Nombre de répétitions (I) | B13: =IF(H5*B11<>B12,"Calcul impossible",H5) -> 0
A14: SCE résiduelle | B14: =SUM(I5:I9) -> 0
A15: SCE totale | B15: =DEVSQ(B5:F9) -> #REF!
A16: SCE inter-séries | B16: =B15-B14 -> #REF!
A17: Valeur intermédiaire de s²L | B17: =((B16/(B11-1))-B18)/B13 -> #REF!
A18: Variance de répétabilité (s²r) | B18: =B14/(B12-B11) -> #DIV/0!
A19: Variance inter-séries (s²L) | B19: =IF(B17<0,0,B17) -> #REF!
A20: Variance de fidélité (s²FI) | B20: =SUM(B18:B19) -> #DIV/0!
A21: Fidélité
A22: Moyenne niveau | B22: =AVERAGE(B5:F9) -> #REF!
A23: Ecart-type de répétabilité (sr) | B23: =SQRT(B18) -> #DIV/0!
A24: Ecart-type inter-séries (sL) | B24: =SQRT(B19) -> #REF!
A25: Ecart-type de fidélité (sFI) | B25: =SQRT(B20) -> #DIV/0!
A26: Justesse
A27: Biais (%) | B27: =B22/B2-1 -> #REF!
A28: Facteur de couverture
A29: Rapport des variances (R) | B29: =B19/B18 -> #REF!
A30: Coefficient B² | B30: =(B29+1)/(B13*B29+1) -> #REF!
A31: Coefficient intermédiaire | B31: =SQRT(1+1/(B12*B30)) -> #REF!
A32: Nombre de degrés liberté | B32: =(B29+1)^2/((B29+1/B13)^2/(B11-1)+(1-1/B13)/B12) -> #REF!
A33: Probabilité tolérance (bêta) | B33: =Récapitulatif!C2 -> #REF!
A34: t Student bas | B34: =TINV(1-B33,ROUNDDOWN(B32,0)) -> #REF!
A35: t Student haut | B35: =TINV(1-B33,ROUNDUP(B32,0)) -> #REF!
A36: t Student interpolé | B36: =B34-(B34-B35)*(B32-ROUNDDOWN(B32,0)) -> #REF!
A37: Facteur de couverture (ktol) | B37: =B36*B31 -> #REF!
A38: Intervalle de tolérance
A39: Valeur basse tolérance | B39: =B22-B37*B25 -> #REF!
A40: Valeur haute tolérance | B40: =B22+B37*B25 -> #REF!

Sheet 90%
A1: Niveau B
A2: Valeur cible | B2: 90
B4: Répétition 1 | C4: Répétition 2 | D4: Répétition 3 | E4: Répétition 4 | F4: Répétition 5 | H4: nk | I4: SCEk
A5: Jour (Série) 1 | B5: =#REF!*$B$2 -> #REF! | C5: =#REF!*$B$2 -> #REF! | H5: =COUNT(B5:F5) -> 0 | I5: =IF(H5=0,"",DEVSQ(B5:F5))
A6: Jour (Série) 2 | B6: =#REF!*$B$2 -> #REF! | C6: =#REF!*$B$2 -> #REF! | H6: =COUNT(B6:F6) -> 0 | I6: =IF(H6=0,"",DEVSQ(B6:F6))
A7: Jour (Série) 3 | I7: =IF(H7=0,"",DEVSQ(B7:F7))
A8: Jour (Série) 4 | B8: =#REF!*$B$2 -> #REF! | C8: =#REF!*$B$2 -> #REF! | H8: =COUNT(B8:F8) -> 0 | I8: =IF(H8=0,"",DEVSQ(B8:F8))
A9: Jour (Série) 5 | B9: =#REF!*$B$2 -> #REF! | C9: =#REF!*$B$2 -> #REF! | H9: =COUNT(B9:F9) -> 0 | I9: =IF(H9=0,"",DEVSQ(B9:F9))
A11: Nombre de séries (K) | B11: =COUNT(B5:B9) -> 0
A12: Nombre de mesures (IK) | B12: =COUNT(B5:F9) -> 0
A13: Nombre de répétitions (I) | B13: =IF(H5*B11<>B12,"Calcul impossible",H5) -> 0
A14: SCE résiduelle | B14: =SUM(I5:I9) -> 0
A15: SCE totale | B15: =DEVSQ(B5:F9) -> #REF!
A16: SCE inter-séries | B16: =B15-B14 -> #REF!
A17: Valeur intermédiaire de s²L | B17: =((B16/(B11-1))-B18)/B13 -> #REF!
A18: Variance de répétabilité (s²r) | B18: =B14/(B12-B11) -> #DIV/0!
A19: Variance inter-séries (s²L) | B19: =IF(B17<0,0,B17) -> #REF!
A20: Variance de fidélité (s²FI) | B20: =SUM(B18:B19) -> #DIV/0!
A21: Fidélité
A22: Moyenne niveau | B22: =AVERAGE(B5:F9) -> #REF!
A23: Ecart-type de répétabilité (sr) | B23: =SQRT(B18) -> #DIV/0!
A24: Ecart-type inter-séries (sL) | B24: =SQRT(B19) -> #REF!
A25: Ecart-type de fidélité (sFI) | B25: =SQRT(B20) -> #DIV/0!
A26: Justesse
A27: Biais (%) | B27: =B22/B2-1 -> #REF!
A28: Facteur de couverture
A29: Rapport des variances (R) | B29: =B19/B18 -> #REF!
A30: Coefficient B² | B30: =(B29+1)/(B13*B29+1) -> #REF!
A31: Coefficient intermédiaire | B31: =SQRT(1+1/(B12*B30)) -> #REF!
A32: Nombre de degrés liberté | B32: =(B29+1)^2/((B29+1/B13)^2/(B11-1)+(1-1/B13)/B12) -> #REF!
A33: Probabilité tolérance (bêta) | B33: =Récapitulatif!C2 -> #REF!
A34: t Student bas | B34: =TINV(1-B33,ROUNDDOWN(B32,0)) -> #REF!
A35: t Student haut | B35: =TINV(1-B33,ROUNDUP(B32,0)) -> #REF!
A36: t Student interpolé | B36: =B34-(B34-B35)*(B32-ROUNDDOWN(B32,0)) -> #REF!
A37: Facteur de couverture (ktol) | B37: =B36*B31 -> #REF!
A38: Intervalle de tolérance
A39: Valeur basse tolérance | B39: =B22-B37*B25 -> #REF!
A40: Valeur haute tolérance | B40: =B22+B37*B25 -> #REF!

Sheet 100%
A1: Niveau C
A2: Valeur cible | B2: 100
B4: Répétition 1 | C4: Répétition 2 | D4: Répétition 3 | E4: Répétition 4 | F4: Répétition 5 | H4: nk | I4: SCEk
A5: Jour (Série) 1 | B5: =#REF!*$B$2 -> #REF! | C5: =#REF!*$B$2 -> #REF! | H5: =COUNT(B5:F5) -> 0 | I5: =IF(H5=0,"",DEVSQ(B5:F5))
A6: Jour (Série) 2 | B6: =#REF!*$B$2 -> #REF! | C6: =#REF!*$B$2 -> #REF! | H6: =COUNT(B6:F6) -> 0 | I6: =IF(H6=0,"",DEVSQ(B6:F6))
A7: Jour (Série) 3 | B7: =#REF!*$B$2 -> #REF! | C7: =#REF!*$B$2 -> #REF! | H7: =COUNT(B7:F7) -> 0 | I7: =IF(H7=0,"",DEVSQ(B7:F7))
A8: Jour (Série) 4 | I8: =IF(H8=0,"",DEVSQ(B8:F8))
A9: Jour (Série) 5 | B9: =#REF!*$B$2 -> #REF! | C9: =#REF!*$B$2 -> #REF! | H9: =COUNT(B9:F9) -> 0 | I9: =IF(H9=0,"",DEVSQ(B9:F9))
A11: Nombre de séries (K) | B11: =COUNT(B5:B9) -> 0
A12: Nombre de mesures (IK) | B12: =COUNT(B5:F9) -> 0
A13: Nombre de répétitions (I) | B13: =IF(H5*B11<>B12,"Calcul impossible",H5) -> 0
A14: SCE résiduelle | B14: =SUM(I5:I9) -> 0
A15: SCE totale | B15: =DEVSQ(B5:F9) -> #REF!
A16: SCE inter-séries | B16: =B15-B14 -> #REF!
A17: Valeur intermédiaire de s²L | B17: =((B16/(B11-1))-B18)/B13 -> #REF!
A18: Variance de répétabilité (s²r) | B18: =B14/(B12-B11) -> #DIV/0!
A19: Variance inter-séries (s²L) | B19: =IF(B17<0,0,B17) -> #REF!
A20: Variance de fidélité (s²FI) | B20: =SUM(B18:B19) -> #DIV/0!
A21: Fidélité
A22: Moyenne niveau | B22: =AVERAGE(B5:F9) -> #REF!
A23: Ecart-type de répétabilité (sr) | B23: =SQRT(B18) -> #DIV/0!
A24: Ecart-type inter-séries (sL) | B24: =SQRT(B19) -> #REF!
A25: Ecart-type de fidélité (sFI) | B25: =SQRT(B20) -> #DIV/0!
A26: Justesse
A27: Biais (%) | B27: =B22/B2-1 -> #REF!
A28: Facteur de couverture
A29: Rapport des variances (R) | B29: =B19/B18 -> #REF!
A30: Coefficient B² | B30: =(B29+1)/(B13*B29+1) -> #REF!
A31: Coefficient intermédiaire | B31: =SQRT(1+1/(B12*B30)) -> #REF!
A32: Nombre de degrés liberté | B32: =(B29+1)^2/((B29+1/B13)^2/(B11-1)+(1-1/B13)/B12) -> #REF!
A33: Probabilité tolérance (bêta) | B33: =Récapitulatif!C2 -> #REF!
A34: t Student bas | B34: =TINV(1-B33,ROUNDDOWN(B32,0)) -> #REF!
A35: t Student haut | B35: =TINV(1-B33,ROUNDUP(B32,0)) -> #REF!
A36: t Student interpolé | B36: =B34-(B34-B35)*(B32-ROUNDDOWN(B32,0)) -> #REF!
A37: Facteur de couverture (ktol) | B37: =B36*B31 -> #REF!
A38: Intervalle de tolérance
A39: Valeur basse tolérance | B39: =B22-B37*B25 -> #REF!
A40: Valeur haute tolérance | B40: =B22+B37*B25 -> #REF!

Sheet 110%
A1: Niveau D
A2: Valeur cible | B2: 110
B4: Répétition 1 | C4: Répétition 2 | D4: Répétition 3 | E4: Répétition 4 | F4: Répétition 5 | H4: nk | I4: SCEk
A5: Jour (Série) 1 | B5: =#REF!*$B$2 -> #REF! | C5: =#REF!*$B$2 -> #REF! | H5: =COUNT(B5:F5) -> 0 | I5: =IF(H5=0,"",DEVSQ(B5:F5))
A6: Jour (Série) 2 | B6: =#REF!*$B$2 -> #REF! | C6: =#REF!*$B$2 -> #REF! | H6: =COUNT(B6:F6) -> 0 | I6: =IF(H6=0,"",DEVSQ(B6:F6))
A7: Jour (Série) 3 | B7: =#REF!*$B$2 -> #REF! | C7: =#REF!*$B$2 -> #REF! | H7: =COUNT(B7:F7) -> 0 | I7: =IF(H7=0,"",DEVSQ(B7:F7))
A8: Jour (Série) 4 | B8: =#REF!*$B$2 -> #REF! | C8: =#REF!*$B$2 -> #REF! | H8: =COUNT(B8:F8) -> 0 | I8: =IF(H8=0,"",DEVSQ(B8:F8))
A9: Jour (Série) 5 | I9: =IF(H9=0,"",DEVSQ(B9:F9))
A11: Nombre de séries (K) | B11: =COUNT(B5:B9) -> 0
A12: Nombre de mesures (IK) | B12: =COUNT(B5:F9) -> 0
A13: Nombre de répétitions (I) | B13: =IF(H5*B11<>B12,"Calcul impossible",H5) -> 0
A14: SCE résiduelle | B14: =SUM(I5:I9) -> 0
A15: SCE totale | B15: =DEVSQ(B5:F9) -> #REF!
A16: SCE inter-séries | B16: =B15-B14 -> #REF!
A17: Valeur intermédiaire de s²L | B17: =((B16/(B11-1))-B18)/B13 -> #REF!
A18: Variance de répétabilité (s²r) | B18: =B14/(B12-B11) -> #DIV/0!
A19: Variance inter-séries (s²L) | B19: =IF(B17<0,0,B17) -> #REF!
A20: Variance de fidélité (s²FI) | B20: =SUM(B18:B19) -> #DIV/0!
A21: Fidélité
A22: Moyenne niveau | B22: =AVERAGE(B5:F9) -> #REF!
A23: Ecart-type de répétabilité (sr) | B23: =SQRT(B18) -> #DIV/0!
A24: Ecart-type inter-séries (sL) | B24: =SQRT(B19) -> #REF!
A25: Ecart-type de fidélité (sFI) | B25: =SQRT(B20) -> #DIV/0!
A26: Justesse
A27: Biais (%) | B27: =B22/B2-1 -> #REF!
A28: Facteur de couverture
A29: Rapport des variances (R) | B29: =B19/B18 -> #REF!
A30: Coefficient B² | B30: =(B29+1)/(B13*B29+1) -> #REF!
A31: Coefficient intermédiaire | B31: =SQRT(1+1/(B12*B30)) -> #REF!
A32: Nombre de degrés liberté | B32: =(B29+1)^2/((B29+1/B13)^2/(B11-1)+(1-1/B13)/B12) -> #REF!
A33: Probabilité tolérance (bêta) | B33: =Récapitulatif!C2 -> #REF!
A34: t Student bas | B34: =TINV(1-B33,ROUNDDOWN(B32,0)) -> #REF!
A35: t Student haut | B35: =TINV(1-B33,ROUNDUP(B32,0)) -> #REF!
A36: t Student interpolé | B36: =B34-(B34-B35)*(B32-ROUNDDOWN(B32,0)) -> #REF!
A37: Facteur de couverture (ktol) | B37: =B36*B31 -> #REF!
A38: Intervalle de tolérance
A39: Valeur basse tolérance | B39: =B22-B37*B25 -> #REF!
A40: Valeur haute tolérance | B40: =B22+B37*B25 -> #REF!

Sheet 120%
A1: Niveau E
A2: Valeur cible | B2: 120
B4: Répétition 1 | C4: Répétition 2 | D4: Répétition 3 | E4: Répétition 4 | F4: Répétition 5 | H4: nk | I4: SCEk
A5: Jour (Série) 1
A6: Jour (Série) 2 | B6: =#REF!*$B$2 -> #REF! | C6: =#REF!*$B$2 -> #REF! | H6: =COUNT(B6:F6) -> 0 | I6: =IF(H6=0,"",DEVSQ(B6:F6))
A7: Jour (Série) 3 | B7: =#REF!*$B$2 -> #REF! | C7: =#REF!*$B$2 -> #REF! | H7: =COUNT(B7:F7) -> 0 | I7: =IF(H7=0,"",DEVSQ(B7:F7))
A8: Jour (Série) 4 | B8: =#REF!*$B$2 -> #REF! | C8: =#REF!*$B$2 -> #REF! | H8: =COUNT(B8:F8) -> 0 | I8: =IF(H8=0,"",DEVSQ(B8:F8))
A9: Jour (Série) 5 | B9: =#REF!*$B$2 -> #REF! | C9: =#REF!*$B$2 -> #REF! | H9: =COUNT(B9:F9) -> 0 | I9: =IF(H9=0,"",DEVSQ(B9:F9))
A11: Nombre de séries (K) | B11: =COUNT(B5:B9) -> 0
A12: Nombre de mesures (IK) | B12: =COUNT(B5:F9) -> 0
A13: Nombre de répétitions (I) | B13: =IF(H6*B11<>B12,"Calcul impossible",H6) -> 0
A14: SCE résiduelle | B14: =SUM(I5:I9) -> 0
A15: SCE totale | B15: =DEVSQ(B5:F9) -> #REF!
A16: SCE inter-séries | B16: =B15-B14 -> #REF!
A17: Valeur intermédiaire de s²L | B17: =((B16/(B11-1))-B18)/B13 -> #REF!
A18: Variance de répétabilité (s²r) | B18: =B14/(B12-B11) -> #DIV/0!
A19: Variance inter-séries (s²L) | B19: =IF(B17<0,0,B17) -> #REF!
A20: Variance de fidélité (s²FI) | B20: =SUM(B18:B19) -> #DIV/0!
A21: Fidélité
A22: Moyenne niveau | B22: =AVERAGE(B5:F9) -> #REF!
A23: Ecart-type de répétabilité (sr) | B23: =SQRT(B18) -> #DIV/0!
A24: Ecart-type inter-séries (sL) | B24: =SQRT(B19) -> #REF!
A25: Ecart-type de fidélité (sFI) | B25: =SQRT(B20) -> #DIV/0!
A26: Justesse
A27: Biais (%) | B27: =B22/B2-1 -> #REF!
A28: Facteur de couverture
A29: Rapport des variances (R) | B29: =B19/B18 -> #REF!
A30: Coefficient B² | B30: =(B29+1)/(B13*B29+1) -> #REF!
A31: Coefficient intermédiaire | B31: =SQRT(1+1/(B12*B30)) -> #REF!
A32: Nombre de degrés liberté | B32: =(B29+1)^2/((B29+1/B13)^2/(B11-1)+(1-1/B13)/B12) -> #REF!
A33: Probabilité tolérance (bêta) | B33: =Récapitulatif!C2 -> #REF!
A34: t Student bas | B34: =TINV(1-B33,ROUNDDOWN(B32,0)) -> #REF!
A35: t Student haut | B35: =TINV(1-B33,ROUNDUP(B32,0)) -> #REF!
A36: t Student interpolé | B36: =B34-(B34-B35)*(B32-ROUNDDOWN(B32,0)) -> #REF!
A37: Facteur de couverture (ktol) | B37: =B36*B31 -> #REF!
A38: Intervalle de tolérance
A39: Valeur basse tolérance | B39: =B22-B37*B25 -> #REF!
A40: Valeur haute tolérance | B40: =B22+B37*B25 -> #REF!
