Workbook
Name ANALYTES: '[1]validation de méthode'!$AD$6:$AD$461

Sheet Bilan
B2: VALIDATION D'UNE METHODE DE DOSAGE INDIRECTE D'UN ANALYTE DANS UNE FORME PHARMACEUTIQUE
B6: période de test | K6: Rapport
K7: Excel V. | L7: 1.0
B9: Linéarité | H9: LOD - LOQ
B10: Domaine d'étude | E10: =linéarité!D6 -> 0 | F10: - | G10: =linéarité!D20 -> 0 | H10: LOD
B11: R > 0,998 | E11: =SQRT(linéarité!C45) -> #VALUE! | H11: LOQ retenue
B12: Système de référence retenu | E12: =linéarité!C127 -> étalon 100% | H12: Exactitude de la LOQ vérifiée
B13: Spécificité | H13: Exactitude / Justesse
B14: Effet de matrice | E14: =linéarité!H105 -> #VALUE! | H14: Justesse de la méthode | J14: =linéarité!E111 -> #VALUE!
B15: Recouvrement | H15: Fidélité
B16: Recouvrement moyen | E16: =justesse!L10 -> #DIV/0! | H16: CV% répétabilité | J16: =fidélité!K11 -> #DIV/0! | K16: < 1% | L16: =IF(J16<K16,"ok","NC") -> #DIV/0!
B17: Intervalle de confiance 95% | D17: [ | E17: =justesse!L13 -> #DIV/0! | F17: =justesse!L14 -> #DIV/0! | G17: ] | H17: CV% fidélité intermédiaire | J17: =fidélité!K13 -> #DIV/0! | K17: < 2% | L17: =IF(J17<K17,"ok","NC") -> #DIV/0!
B18: Recouvrement [98% - 102%] | E18: =IF(justesse!L13>=0.98,IF(justesse!L14<=1,"oui","non")) -> #DIV/0! | H18: Ecart accéptable entre 2 mesures | J18: =fidélité!K18 -> #DIV/0!
B43: =robustesse!#REF! -> #REF!
J61: Paramètre | K61: Effet
J62: =robustesse!M9 -> A- | K62: =robustesse!N9 -> 0
J63: =robustesse!M10 -> A+ | K63: =robustesse!N10 -> 0
J64: =robustesse!M11 -> B- | K64: =robustesse!N11 -> 0
J65: =robustesse!M12 -> B+ | K65: =robustesse!N12 -> 0
J66: =robustesse!M13 -> C- | K66: =robustesse!N13 -> 0
J67: =robustesse!M14 -> C+ | K67: =robustesse!N14 -> 0
J69: =robustesse!M16 -> cible (100%) | K69: =robustesse!N16 -> 0
J70: =robustesse!M17 -> T+ (+2%) | K70: =robustesse!N17 -> 0
J71: =robustesse!M18 -> T- (-2%) | K71: =robustesse!N18 -> 0
B74: Conclusion
B76: Méthode Validée : | D76: oui | E76: non | I76: Visa / date :
B80: www.methodesdevalidation.com
B81: Morgan GERMA

Sheet linéarité
B2: Etude de la linéarité
B4: Gamme étalon | H4: Gamme forme reconstituée
B5: level | C5: serie | D5: masse | E5: Aire | H5: level | I5: serie | J5: masse | K5: Aire-1
B6: 0.8 | C6: Op1 / J1 | H6: 0.8 | I6: Op1 / J1
C7: Op 2 / J2 | I7: Op 2 / J2
C8: Op 3 / J3 | I8: Op 3 / J3
B9: 0.9 | C9: 1 | H9: 0.9 | I9: 1
C10: 2 | I10: 2
C11: 3 | I11: 3 | L11: Aire-2 | M11: Aire-3 | N11: Aire-4 | O11: Aire-5 | P11: Aire-6
B12: 1 | C12: 1 | H12: 1 | I12: 1 | Q12: < répétabilité
C13: 2 | I13: 2 | Q13: < répétabilité
C14: 3 | I14: 3 | Q14: < répétabilité
B15: 1.1 | C15: 1 | H15: 1.1 | I15: 1
C16: 2 | I16: 2
C17: 3 | I17: 3
B18: 1.2 | C18: 1 | H18: 1.2 | I18: 1
C19: 2 | I19: 2
C20: 3 | I20: 3
B22: Changement de variable
B24: Gamme étalon | H24: Gamme forme reconstituée
B25: level | C25: serie | D25: mean X | E25: Y' | F25: S² | H25: level | I25: serie | J25: mean X | K25: Y'
B26: 0.8 | C26: 1 | D26: =AVERAGE(D6:D8) -> #DIV/0! | E26: =E6*D26/D6 -> #DIV/0! | F26: =VAR(E26:E28) -> #DIV/0! | H26: 0.8 | I26: 1 | J26: =AVERAGE(J6:J8) -> #DIV/0! | K26: =K6*J26/J6 -> #DIV/0! | R26: S²
C27: 2 | D27: =D26 -> #DIV/0! | E27: =E7*D27/D7 -> #DIV/0! | I27: 2 | J27: =J26 -> #DIV/0! | K27: =K7*J27/J7 -> #DIV/0! | R27: =VAR(K26:K28) -> #DIV/0!
C28: 3 | D28: =D27 -> #DIV/0! | E28: =E8*D28/D8 -> #DIV/0! | I28: 3 | J28: =J27 -> #DIV/0! | K28: =K8*J28/J8 -> #DIV/0!
B29: 0.9 | C29: 1 | D29: =AVERAGE(D9:D11) -> #DIV/0! | E29: =E9*D29/D9 -> #DIV/0! | F29: =VAR(E29:E31) -> #DIV/0! | H29: 0.9 | I29: 1 | J29: =AVERAGE(J9:J11) -> #DIV/0! | K29: =K9*J29/J9 -> #DIV/0!
C30: 2 | D30: =D29 -> #DIV/0! | E30: =E10*D30/D10 -> #DIV/0! | I30: 2 | J30: =J29 -> #DIV/0! | K30: =K10*J30/J10 -> #DIV/0! | R30: =VAR(K29:K31) -> #DIV/0!
C31: 3 | D31: =D30 -> #DIV/0! | E31: =E11*D31/D11 -> #DIV/0! | I31: 3 | J31: =J30 -> #DIV/0! | K31: =K11*J31/J11 -> #DIV/0! | L31: Y'-2 | M31: Y'-3 | N31: Y'-4 | O31: Y'-5 | P31: Y'-6
B32: 1 | C32: 1 | D32: =AVERAGE(D12:D14) -> #DIV/0! | E32: =E12*D32/D12 -> #DIV/0! | F32: =VAR(E32:E34) -> #DIV/0! | H32: 1 | I32: 1 | J32: =AVERAGE(J12:J14) -> #DIV/0! | K32: =K12*J32/J12 -> #DIV/0! | L32: =L12*$J32/$J12 -> #DIV/0! | M32: =M12*$J32/$J12 -> #DIV/0! | N32: =N12*$J32/$J12 -> #DIV/0! | O32: =O12*$J32/$J12 -> #DIV/0! | P32: =P12*$J32/$J12 -> #DIV/0!
C33: 2 | D33: =D32 -> #DIV/0! | E33: =E13*D33/D13 -> #DIV/0! | I33: 2 | J33: =J32 -> #DIV/0! | K33: =K13*J33/J13 -> #DIV/0! | L33: =L13*$J33/$J13 -> #DIV/0! | M33: =M13*$J33/$J13 -> #DIV/0! | N33: =N13*$J33/$J13 -> #DIV/0! | O33: =O13*$J33/$J13 -> #DIV/0! | P33: =P13*$J33/$J13 -> #DIV/0! | R33: =VAR(K32:K34) -> #DIV/0!
C34: 3 | D34: =D33 -> #DIV/0! | E34: =E14*D34/D14 -> #DIV/0! | I34: 3 | J34: =J33 -> #DIV/0! | K34: =K14*J34/J14 -> #DIV/0! | L34: =L14*$J34/$J14 -> #DIV/0! | M34: =M14*$J34/$J14 -> #DIV/0! | N34: =N14*$J34/$J14 -> #DIV/0! | O34: =O14*$J34/$J14 -> #DIV/0! | P34: =P14*$J34/$J14 -> #DIV/0!
B35: 1.1 | C35: 1 | D35: =AVERAGE(D15:D17) -> #DIV/0! | E35: =E15*D35/D15 -> #DIV/0! | F35: =VAR(E35:E37) -> #DIV/0! | H35: 1.1 | I35: 1 | J35: =AVERAGE(J15:J17) -> #DIV/0! | K35: =K15*J35/J15 -> #DIV/0!
C36: 2 | D36: =D35 -> #DIV/0! | E36: =E16*D36/D16 -> #DIV/0! | I36: 2 | J36: =J35 -> #DIV/0! | K36: =K16*J36/J16 -> #DIV/0! | R36: =VAR(K35:K37) -> #DIV/0!
C37: 3 | D37: =D36 -> #DIV/0! | E37: =E17*D37/D17 -> #DIV/0! | I37: 3 | J37: =J36 -> #DIV/0! | K37: =K17*J37/J17 -> #DIV/0!
B38: 1.2 | C38: 1 | D38: =AVERAGE(D18:D20) -> #DIV/0! | E38: =E18*D38/D18 -> #DIV/0! | F38: =VAR(E38:E40) -> #DIV/0! | H38: 1.2 | I38: 1 | J38: =AVERAGE(J18:J20) -> #DIV/0! | K38: =K18*J38/J18 -> #DIV/0!
C39: 2 | D39: =D38 -> #DIV/0! | E39: =E19*D39/D19 -> #DIV/0! | I39: 2 | J39: =J38 -> #DIV/0! | K39: =K19*J39/J19 -> #DIV/0! | R39: =VAR(K38:K40) -> #DIV/0!
C40: 3 | D40: =D39 -> #DIV/0! | E40: =E20*D40/D20 -> #DIV/0! | I40: 3 | J40: =J39 -> #DIV/0! | K40: =K20*J40/J20 -> #DIV/0!
B42: Gamme étalon | H42: Gamme forme reconstituée
B43: slope b1 | C43: {=LINEST(E26:E40,D26:D40,1,1)} -> #VALUE! | D43: #VALUE! | E43: intercept a1 | H43: slope b1 | I43: {=LINEST(K26:K40,J26:J40,1,1)} -> #VALUE! | J43: #VALUE! | K43: intercept a1
B44: SD b1 | C44: #VALUE! | D44: #VALUE! | E44: SD a1 | H44: SD b1 | I44: #VALUE! | J44: #VALUE! | K44: SD a1
B45: R² | C45: #VALUE! | D45: #VALUE! | E45: SD y/x | H45: R² | I45: #VALUE! | J45: #VALUE! | K45: SD y/x
...

Sheet justesse
B2: Etude de la justesse | K2: Test de Cochran | O2: Test de Grubbs
B4: Niveau | C4: jour | D4: X | E4: Y1 | F4: Z | G4: Rdt % | H4: Rdt% moyen | I4: S² | K4: Cobs | L4: =MAX(I5:I19)/SUM(I5:I19) -> #DIV/0! | P4: Gmax | Q4: Gmin | S4: Si il n'y a pas de données aberrantes
B5: 0.8 | C5: 1 | D5: =linéarité!J26 -> #DIV/0! | E5: =linéarité!K26 -> #DIV/0! | F5: =IF(linéarité!C$127="étalon 100%",E5/linéarité!G$126,(E5-linéarité!$J$127)/linéarité!$J$126) -> #DIV/0! | G5: =F5/D5 -> #DIV/0! | H5: =AVERAGE(G5:G7) -> #DIV/0! | I5: =VAR(G5:G7) -> #DIV/0! | K5: C5% | L5: =linéarité!F69 -> 0.68377223 | O5: 0.8 | P5: =(MAX(G5:G7)-H5)/STDEV(G5:G7) -> #DIV/0! | Q5: =(H5-MIN(G5:G7))/STDEV(G5:G7) -> #DIV/0! | S5: Ne pas tenir compte du test de Cochran
C6: 2 | D6: =linéarité!J27 -> #DIV/0! | E6: =linéarité!K27 -> #DIV/0! | F6: =IF(linéarité!C$127="étalon 100%",E6/linéarité!G$127,(E6-linéarité!$J$127)/linéarité!$J$126) -> #DIV/0! | G6: =F6/D6 -> #DIV/0! | K6: C1% | L6: =linéarité!F70 -> 0.78852575 | O6: 0.9 | P6: =(MAX(G8:G10)-H8)/STDEV(G8:G10) -> #DIV/0! | Q6: =(MAX(G8:G10)-H8)/STDEV(G8:G10) -> #DIV/0!
C7: 3 | D7: =linéarité!J28 -> #DIV/0! | E7: =linéarité!K28 -> #DIV/0! | F7: =IF(linéarité!C$127="étalon 100%",E7/linéarité!G$128,(E7-linéarité!$J$127)/linéarité!$J$126) -> #DIV/0! | G7: =F7/D7 -> #DIV/0! | O7: 1 | P7: =(MAX(G11:G13)-H11)/STDEV(G11:G13) -> #DIV/0! | Q7: =(MAX(G11:G13)-H11)/STDEV(G11:G13) -> #DIV/0!
B8: 0.9 | C8: 1 | D8: =linéarité!J29 -> #DIV/0! | E8: =linéarité!K29 -> #DIV/0! | F8: =IF(linéarité!C$127="étalon 100%",E8/linéarité!G$126,(E8-linéarité!$J$127)/linéarité!$J$126) -> #DIV/0! | G8: =F8/D8 -> #DIV/0! | H8: =AVERAGE(G8:G10) -> #DIV/0! | I8: =VAR(G8:G10) -> #DIV/0! | K8: Recouvrement moyen | O8: 1.1 | P8: =(MAX(G14:G16)-H14)/STDEV(G14:G16) -> #DIV/0! | Q8: =(MAX(G14:G16)-H14)/STDEV(G14:G16) -> #DIV/0!
C9: 2 | D9: =linéarité!J30 -> #DIV/0! | E9: =linéarité!K30 -> #DIV/0! | F9: =IF(linéarité!C$127="étalon 100%",E9/linéarité!G$127,(E9-linéarité!$J$127)/linéarité!$J$126) -> #DIV/0! | G9: =F9/D9 -> #DIV/0! | O9: 1.2 | P9: =(MAX(G17:G19)-H17)/STDEV(G17:G19) -> #DIV/0! | Q9: =(MAX(G17:G19)-H17)/STDEV(G17:G19) -> #DIV/0!
C10: 3 | D10: =linéarité!J31 -> #DIV/0! | E10: =linéarité!K31 -> #DIV/0! | F10: =IF(linéarité!C$127="étalon 100%",E10/linéarité!G$128,(E10-linéarité!$J$127)/linéarité!$J$126) -> #DIV/0! | G10: =F10/D10 -> #DIV/0! | K10: Rdt% global | L10: =AVERAGE(H5:H19) -> #DIV/0! | P10: G 5% | Q10: 1.153
B11: 1 | C11: 1 | D11: =linéarité!J32 -> #DIV/0! | E11: =linéarité!K32 -> #DIV/0! | F11: =IF(linéarité!C$127="étalon 100%",E11/linéarité!G$126,(E11-linéarité!$J$127)/linéarité!$J$126) -> #DIV/0! | G11: =F11/D11 -> #DIV/0! | H11: =AVERAGE(G11:G13) -> #DIV/0! | I11: =VAR(G11:G13) -> #DIV/0! | K11: écart-type S | L11: =STDEV(G5:G19) -> #DIV/0! | P11: G 1% | Q11: 1.155
C12: 2 | D12: =linéarité!J33 -> #DIV/0! | E12: =linéarité!K33 -> #DIV/0! | F12: =IF(linéarité!C$127="étalon 100%",E12/linéarité!G$127,(E12-linéarité!$J$127)/linéarité!$J$126) -> #DIV/0! | G12: =F12/D12 -> #DIV/0! | K12: Student t | L12: =TINV(0.05,14) -> 2.1447867
C13: 3 | D13: =linéarité!J34 -> #DIV/0! | E13: =linéarité!K34 -> #DIV/0! | F13: =IF(linéarité!C$127="étalon 100%",E13/linéarité!G$128,(E13-linéarité!$J$127)/linéarité!$J$126) -> #DIV/0! | G13: =F13/D13 -> #DIV/0! | K13: IC- (95%) | L13: =L10-L12*L11/SQRT(15) -> #DIV/0!
B14: 1.1 | C14: 1 | D14: =linéarité!J35 -> #DIV/0! | E14: =linéarité!K35 -> #DIV/0! | F14: =IF(linéarité!C$127="étalon 100%",E14/linéarité!G$126,(E14-linéarité!$J$127)/linéarité!$J$126) -> #DIV/0! | G14: =F14/D14 -> #DIV/0! | H14: =AVERAGE(G14:G16) -> #DIV/0! | I14: =VAR(G14:G16) -> #DIV/0! | K14: IC+ (95%) | L14: =L10+L12*L11/SQRT(15) -> #DIV/0!
C15: 2 | D15: =linéarité!J36 -> #DIV/0! | E15: =linéarité!K36 -> #DIV/0! | F15: =IF(linéarité!C$127="étalon 100%",E15/linéarité!G$127,(E15-linéarité!$J$127)/linéarité!$J$126) -> #DIV/0! | G15: =F15/D15 -> #DIV/0!
C16: 3 | D16: =linéarité!J37 -> #DIV/0! | E16: =linéarité!K37 -> #DIV/0! | F16: =IF(linéarité!C$127="étalon 100%",E16/linéarité!G$128,(E16-linéarité!$J$127)/linéarité!$J$126) -> #DIV/0! | G16: =F16/D16 -> #DIV/0! | K16: Analyse de variances
B17: 1.2 | C17: 1 | D17: =linéarité!J38 -> #DIV/0! | E17: =linéarité!K38 -> #DIV/0! | F17: =IF(linéarité!C$127="étalon 100%",E17/linéarité!G$126,(E17-linéarité!$J$127)/linéarité!$J$126) -> #DIV/0! | G17: =F17/D17 -> #DIV/0! | H17: =AVERAGE(G17:G19) -> #DIV/0! | I17: =VAR(G17:G19) -> #DIV/0!
C18: 2 | D18: =linéarité!J39 -> #DIV/0! | E18: =linéarité!K39 -> #DIV/0! | F18: =IF(linéarité!C$127="étalon 100%",E18/linéarité!G$127,(E18-linéarité!$J$127)/linéarité!$J$126) -> #DIV/0! | G18: =F18/D18 -> #DIV/0! | K18: Identification | O18: ANOVA
C19: 3 | D19: =linéarité!J40 -> #DIV/0! | E19: =linéarité!K40 -> #DIV/0! | F19: =IF(linéarité!C$127="étalon 100%",E19/linéarité!G$128,(E19-linéarité!$J$127)/linéarité!$J$126) -> #DIV/0! | G19: =F19/D19 -> #DIV/0! | K19: Origine | L19: niveau | M19: SB² | N19: Ci | O19: SCE | P19: ddl | Q19: CM | R19: Fobs | S19: F5% | T19: contribution%
K20: total | L20: =COUNT(G5:G19) -> 0 | M20: =SUM(G5:G19)^2 -> #DIV/0! | N20: =M20/L20 -> #DIV/0! | O20: =DEVSQ(G5:G19) -> #DIV/0! | P20: =L20-1 -> -1 | Q20: =O20/P20 -> #DIV/0! | R20: x | S20: x | T20: =SUM(T21:T22) -> #DIV/0!
F21: =H5 -> #DIV/0! | G21: 1 | H21: 0.98 | I21: 1.02 | K21: niveau | L21: 5 | M21: =SUM(G5:G7)^2+SUM(G8:G10)^2+SUM(G11:G13)^2+SUM(G14:G16)^2+SUM(G17:G19)^2 -> #DIV/0! | N21: =M21*L21/L20 -> #DIV/0! | O21: =N21-N20 -> #DIV/0! | P21: 4 | Q21: =O21/P21 -> #DIV/0! | R21: =Q21/Q22 -> #DIV/0! | S21: =FINV(0.05,P21,P22) -> #NUM! | T21: =O21/O20 -> #DIV/0! | U21: =IF(ABS(R21)<S21,"pas d'effet niveau","effet de niveau") -> #DIV/0!
F22: =H5 -> #DIV/0! | G22: 1 | H22: 0.98 | I22: 1.02 | K22: résiduel | L22: x | M22: x | N22: x | O22: =O20-O21 -> #DIV/0! | P22: =P20-P21 -> -5 | Q22: =O22/P22 -> #DIV/0! | R22: x | S22: x | T22: =O22/O20 -> #DIV/0!
F23: =H5 -> #DIV/0! | G23: 1 | H23: 0.98 | I23: 1.02 | K23: Si F < F5%, l'homogénéité des recouvrements est observée
F24: =H8 -> #DIV/0! | G24: 1 | H24: 0.98 | I24: 1.02
F25: =H8 -> #DIV/0! | G25: 1 | H25: 0.98 | I25: 1.02
F26: =H8 -> #DIV/0! | G26: 1 | H26: 0.98 | I26: 1.02
F27: =H11 -> #DIV/0! | G27: 1 | H27: 0.98 | I27: 1.02
F28: =H11 -> #DIV/0! | G28: 1 | H28: 0.98 | I28: 1.02
F29: =H11 -> #DIV/0! | G29: 1 | H29: 0.98 | I29: 1.02
F30: =H14 -> #DIV/0! | G30: 1 | H30: 0.98 | I30: 1.02
F31: =H14 -> #DIV/0! | G31: 1 | H31: 0.98 | I31: 1.02
F32: =H14 -> #DIV/0! | G32: 1 | H32: 0.98 | I32: 1.02
F33: =H17 -> #DIV/0! | G33: 1 | H33: 0.98 | I33: 1.02
F34: =H17 -> #DIV/0! | G34: 1 | H34: 0.98 | I34: 1.02
F35: =H17 -> #DIV/0! | G35: 1 | H35: 0.98 | I35: 1.02

Sheet fidélité
B2: Etude de la fidélité | I2: Test de Cochran | P2: Test de Grubbs
B4: jour | C4: X | D4: Y' | E4: S² | F4: moyenne | I4: Cobs | J4: =MAX(E5:E22)/SUM(E5:E22) -> #DIV/0! | K4: S i le test de Cochran est NC, | Q4: Gmax | R4: Gmin | T4: Si il n'y a pas de données aberrantes
B5: 1 | C5: =linéarité!J32 -> #DIV/0! | D5: =IF(linéarité!C127="étalon 100%",linéarité!K32/linéarité!$G$126,(linéarité!K32-linéarité!$J$127)/linéarité!$J$126) -> #DIV/0! | E5: =VAR(D5:D10) -> #DIV/0! | F5: =AVERAGE(D5:D10) -> #DIV/0! | I5: C5% | J5: =1/((1+(COUNT(B5:B22)-1)/FINV(0.05/COUNT(B5:B22),COUNT(C5:C10)-1,(COUNT(B5:B22)-1)*(COUNT(C5:C10)-1)))) -> #NUM! | K5: Vérifiez la présence de données aberrante (test de Grubbs) | P5: jour 1 | Q5: =(MAX(D5:D10)-F5)/STDEV(D5:D10) -> #DIV/0! | R5: =(F5-MIN(D5:D10))/STDEV(D5:D10) -> #DIV/0! | T5: Ne pas tenir compte du test de Cochran
C6: =C5 -> #DIV/0! | D6: =IF(linéarité!C127="étalon 100%",linéarité!L32/linéarité!$G$126,(linéarité!L32-linéarité!$J$127)/linéarité!$J$126) -> #DIV/0! | I6: C1% | J6: =1/((1+(COUNT(B5:B22)-1)/FINV(0.01/COUNT(B5:B22),COUNT(C5:C10)-1,(COUNT(B5:B22)-1)*(COUNT(C5:C10)-1)))) -> #NUM! | P6: jour 2 | Q6: =(MAX(D11:D16)-F11)/STDEV(D11:D16) -> #DIV/0! | R6: =(F11-MIN(D11:D16))/STDEV(D11:D16) -> #DIV/0!
C7: =C6 -> #DIV/0! | D7: =linéarité!M32/linéarité!$G$126 -> #DIV/0! | P7: jour 3 | Q7: =(MAX(D17:D22)-F17)/STDEV(D17:D22) -> #DIV/0! | R7: =(F17-MIN(D17:D22))/STDEV(D17:D22) -> #DIV/0!
C8: =C7 -> #DIV/0! | D8: =linéarité!N32/linéarité!$G$126 -> #DIV/0! | I8: Fidélité | Q8: G 5% | R8: 1.822
C9: =C8 -> #DIV/0! | D9: =linéarité!O32/linéarité!$G$126 -> #DIV/0! | Q9: G 1% | R9: 1.944
C10: =C9 -> #DIV/0! | D10: =linéarité!P32/linéarité!$G$126 -> #DIV/0! | J10: S² | K10: CV% | L10: CV+ (95%)
B11: 2 | C11: =linéarité!J33 -> #DIV/0! | D11: =linéarité!K33/linéarité!$G$127 -> #DIV/0! | E11: =VAR(D11:D16) -> #DIV/0! | F11: =AVERAGE(D11:D16) -> #DIV/0! | I11: intra-série | J11: =AVERAGE(E5:E22) -> #DIV/0! | K11: =SQRT(J11)/AVERAGE(F5:F22) -> #DIV/0! | L11: =K11*SQRT(CHIINV(0.05,17)/17) -> #DIV/0! | M11: < répétabilité
C12: =C11 -> #DIV/0! | D12: =linéarité!L33/linéarité!$G$127 -> #DIV/0! | I12: inter serie | J12: =IF(VAR(F5:F22)-J11/6<0,0,VAR(F5:F22)-J11/6) -> #DIV/0!
C13: =C12 -> #DIV/0! | D13: =linéarité!M33/linéarité!$G$127 -> #DIV/0! | I13: total | J13: =J12+J11 -> #DIV/0! | K13: =SQRT(J13)/AVERAGE(F5:F22) -> #DIV/0! | L13: =K13*SQRT(CHIINV(0.05,17)/17) -> #DIV/0! | M13: < fidélité intermédiaire
C14: =C13 -> #DIV/0! | D14: =linéarité!N33/linéarité!$G$127 -> #DIV/0!
C15: =C14 -> #DIV/0! | D15: =linéarité!O33/linéarité!$G$127 -> #DIV/0! | I15: Ecart acceptable
C16: =C15 -> #DIV/0! | D16: =linéarité!P33/linéarité!$G$127 -> #DIV/0!
B17: 3 | C17: =linéarité!J34 -> #DIV/0! | D17: =linéarité!K34/linéarité!$G$128 -> #DIV/0! | E17: =VAR(D17:D22) -> #DIV/0! | F17: =AVERAGE(D17:D22) -> #DIV/0! | J17: 0.95 | K17: 0.99
C18: =C17 -> #DIV/0! | D18: =linéarité!L34/linéarité!$G$128 -> #DIV/0! | I18: limite r | J18: =2.83*SQRT(J11) -> #DIV/0! | K18: =4.24*SQRT(J11) -> #DIV/0! | L18: < écart accaptable entre 2 mesures d'une même série
C19: =C18 -> #DIV/0! | D19: =linéarité!M34/linéarité!$G$128 -> #DIV/0! | I19: limite Fi | J19: =2.83*SQRT(J13) -> #DIV/0! | K19: =4.24*SQRT(J13) -> #DIV/0! | L19: < écart accaptable entre 2 mesures de différentes séries
C20: =C19 -> #DIV/0! | D20: =linéarité!N34/linéarité!$G$128 -> #DIV/0!
C21: =C20 -> #DIV/0! | D21: =linéarité!O34/linéarité!$G$128 -> #DIV/0!
C22: =C21 -> #DIV/0! | D22: =linéarité!P34/linéarité!$G$128 -> #DIV/0!

Sheet robustesse
B2: Etude de la Robustesse
B3: Placket Burman est un plan d'exépriences utilisé pour découvrir comment les réponses (ex: aires) sont affectées par un faible changement des paramètres (T°C, pH), sans tenir compte cependant des interactions.
B4: Le plan ci-dessous peut étudier de 4 à 7 facteurs à 2 niveaux en seulement 8 essais, l'équivalent de 128 essais si le plan était complet.
B6: Etude de 3 paramètres | G6: Essais | M6: Analyse
C8: parametre | G8: essais | H8: =C9 -> 0 | I8: =D9 -> 0 | J8: =E9 -> 0 | K8: Responses | M8: moyenne | N8: =SUMPRODUCT(K15:K18,$K$9:$K$12)/4 -> 0
B9: parameter | G9: 1 | H9: =C12 -> 0 | I9: =D12 -> 0 | J9: =E11 -> 0 | M9: A- | N9: =-N10 -> 0 | O9: =N18 -> 0 | P9: =N17 -> 0
B10: niveau 0 | G10: 2 | H10: =C11 -> 0 | I10: =D12 -> 0 | J10: =E12 -> 0 | M10: A+ | N10: =SUMPRODUCT(H15:H18,$K$9:$K$12)/4 -> 0 | O10: =O9 -> 0 | P10: =P9 -> 0
B11: niveau -1 | G11: 3 | H11: =C12 -> 0 | I11: =D11 -> 0 | J11: =E12 -> 0 | M11: B- | N11: =-N12 -> 0 | O11: =O10 -> 0 | P11: =P10 -> 0
B12: niveau +1 | G12: 4 | H12: =C11 -> 0 | I12: =D11 -> 0 | J12: =E11 -> 0 | M12: B+ | N12: =SUMPRODUCT(I15:I18,$K$9:$K$12)/4 -> 0 | O12: =O11 -> 0 | P12: =P11 -> 0
M13: C- | N13: =-N14 -> 0 | O13: =O12 -> 0 | P13: =P12 -> 0
G14: essais | H14: =C9 -> 0 | I14: =D9 -> 0 | J14: =E9 -> 0 | K14: I | M14: C+ | N14: =SUMPRODUCT(J15:J18,$K$9:$K$12)/4 -> 0 | O14: =O13 -> 0 | P14: =P13 -> 0
G15: 1 | H15: 1 | I15: 1 | J15: -1 | K15: 1
G16: 2 | H16: -1 | I16: 1 | J16: 1 | K16: 1 | M16: cible (100%) | N16: =linéarité!D12 -> 0
G17: 3 | H17: 1 | I17: -1 | J17: 1 | K17: 1 | M17: T+ (+2%) | N17: =2/100*N16 -> 0
G18: 4 | H18: -1 | I18: -1 | J18: -1 | K18: 1 | M18: T- (-2%) | N18: =-2/100*N16 -> 0
