Workbook
Name ANALYTES: '[1]validation de méthode'!$AD$6:$AD$461

Sheet Bilan
B1: VALIDATION D'UNE METHODE DE DOSAGE INDIRECTE D'UN ANALYTE DANS UNE FORME PHARMACEUTIQUE
C5: les cases bleues sont à compléter | K5: Date début
C6: les cases vertes sont préremplies mais peuvent etre modifiées | K6: Date fin | L6: =TODAY() -> 45979
C7: les cases oranges sont des listes déroulantes | K7: Doc Qual. | L7: IP15XXX
B8: 3.2 | C8: un résultat vert est un résultat conforme d'un point de vue statistique | K8: Excel V. | L8: 1.0
B9: 3.2 | C9: un résultat jaune est un résultat suspect
B10: 3.2 | C10: un résultat rouge est un résultat aberrant
B12: Range | H12: Sensibilité
B13: Domaine d'étude | D13: [ | G13: ] | H13: Ecart en concentration minimal | J13: =sensibilité!E9 -> 0.01604564
B15: Linéarité / Linearity | H15: LOD - LOQ
B16: Matrix effect | E16: =linéarité!H111 -> spécifique | H16: LOD | J16: =LOQLOD!F8 -> #DIV/0! | K16: =LOQLOD!G5 -> mg/L
B17: Biais | E17: =linéarité!E117 -> pas de biais | H17: LOQ retenue | J17: =LOQLOD!I16 -> #DIV/0! | K17: =K16 -> mg/L
B18: Système de référence retenu | E18: =linéarité!C132 -> étalon 100% | H18: Recovery LOQ | J18: =LOQLOD!F22 -> #DIV/0!
B19: R > 0,998 | E19: =SQRT(linéarité!C45) -> 0.99812519 | H19: RSD% LOQ | J19: =LOQLOD!G22 -> #DIV/0!
B20: Justesse / Accuracy | H20: Fidélité / Precision
B21: Mean Recovery | E21: =justesse!C28 -> 1.0256371 | H21: RSDr % | J21: =fidélité!D35 -> 0.0011551653 | K21: =fidélité!B43 -> 0.0014715425 | L21: RSDr95%
B22: IC 95% | D22: [ | E22: =justesse!C31 -> 1.0127915 | F22: =justesse!C32 -> 1.0384828 | G22: ] | H22: RSDR % | J22: =fidélité!D37 -> 0.0046141159 | K22: =fidélité!B44 -> 0.0058778318 | L22: RSDfi95%
B31: =robustesse!B93 -> éthanol
B40: Robustness
B67: Stability
B68: Durée de vie estimée
B69: Stabilité vérifiée
B70: Stress degradation
B73: Commentaire
B78: Conclusion
B80: Méthode Validée : | D80: oui | E80: non | G80: Visa : | K80: Date :
D81: x

Sheet matériel
B1: Préparation du dosage du BDDE Résiduel dans les fils de HA
B3: Référence de la série analytique :
B5: Equipements / ECME :
C7: N° ID | D7: Date de validité
B8: Balance Classe A
B9: Système chromatographique
B10: Colonne
B11: Pipettes
B12: Bain thermostaté
B13: Producteur d'eau MilliQ
B15: Réactifs / Produits chimiques :
C17: N° de lot | D17: Date de validité
B18: Acétonitrile LC-MS
B19: Acide trifluoroacétique
B20: 1,4-Butanediol diglycidyl éther (BDDE) | C20: Lot : Pureté :
B21: Diglycidyl ether of neo-Pentyl glycol 95% (NPGDE)
B22: N,N-diéthyldithiocarbamate de sodium (DTC)
B24: Préparation des standards :
B25: 1) Préparation des standards de BDDE
B27: Date de préparation :
B28: Durée de validité :
B29: Date de validité :
B31: 2) Préparation de la solution d'Etalon Interne
B33: Date de préparation :
B34: Durée de validité :
B35: Date de validité :
B36: Référence de la série analytique :
B38: Préparation des échantillons :
B72: Préparation de la solution de dérivatisation : | C72: 740 mg ≤ m DTC ≤ 760 mg | D72: pour 25 mL
B74: Durée de validité : Le jour de préparation

Sheet linéarité
B2: linearity study
B4: standard calibration (API) | H4: standard calibration (API + matrix)
B5: level | C5: serie | D5: X | E5: Y | H5: level | I5: serie | J5: X | K5: Y
B6: 0.8 | C6: 1 | D6: 0.24162984 | E6: 0.93308457 | H6: 0.8 | I6: 1 | J6: 0.24162984 | K6: 0.95196425
C7: 2 | D7: 0.23965308 | E7: 0.90947933 | I7: 2 | J7: 0.23965308 | K7: 1.0072514
C8: 3 | D8: 0.24383916 | E8: 0.92964765 | I8: 3 | J8: 0.24383916 | K8: 0.9867055
B9: 0.9 | C9: 1 | D9: 0.26915913 | E9: 1.0487784 | H9: 0.9 | I9: 1 | J9: 0.26915913 | K9: 1.0587645
C10: 2 | D10: 0.26956611 | E10: 1.0212268 | I10: 2 | J10: 0.26956611 | K10: 1.041609
C11: 3 | D11: 0.27174636 | E11: 1.0366375 | I11: 3 | J11: 0.27174636 | K11: 1.0721775 | L11: Y-2 | M11: Y-3 | N11: Y-4 | O11: Y-5 | P11: Y-6
B12: 1 | C12: 1 | D12: 0.29378142 | E12: 1.1425547 | H12: 1 | I12: 1 | J12: 0.29378142 | K12: 1.1562472 | L12: 1.1512583 | M12: 1.1538772 | N12: 1.1537055 | O12: 1.1534857 | P12: 1.1527778
C13: 2 | D13: 0.29776401 | E13: 1.1387554 | I13: 2 | J13: 0.29776401 | K13: 1.1586805 | L13: 1.1599179 | M13: 1.1576806 | N13: 1.1609211 | O13: 1.1571684 | P13: 1.1592237
C14: 3 | D14: 0.32485725 | E14: 1.2453744 | I14: 3 | J14: 0.32485725 | K14: 1.2723748 | L14: 1.2722286 | M14: 1.2729451 | N14: 1.2719805 | O14: 1.2717011 | P14: 1.2701611
B15: 1.1 | C15: 1 | D15: 0.32154327 | E15: 1.2533607 | H15: 1.1 | I15: 1 | J15: 0.32154327 | K15: 1.2681855
C16: 2 | D16: 0.32378166 | E16: 1.2340843 | I16: 2 | J16: 0.32378166 | K16: 1.2658045
C17: 3 | D17: 0.3482586 | E17: 1.3326614 | I17: 3 | J17: 0.3482586 | K17: 1.3540644
B18: 1.2 | C18: 1 | D18: 0.36032265 | E18: 1.3919347 | H18: 1.2 | I18: 1 | J18: 0.36032265 | K18: 1.4246526
C19: 2 | D19: 0.3642471 | E19: 1.3991415 | I19: 2 | J19: 0.3642471 | K19: 1.4218196
C20: 3 | D20: 0.3607587 | E20: 1.3745959 | I20: 3 | J20: 0.3607587 | K20: 1.4202601
B22: change of variables
B24: standard calibration (API) | H24: standard calibration (API + matrix)
B25: level | C25: serie | D25: mean X | E25: Y' | F25: S² | H25: level | I25: serie | J25: mean X | K25: Y' | L25: S²
B26: 0.8 | C26: 1 | D26: =AVERAGE(D6:D8) -> 0.24170736 | E26: =E6*D26/D6 -> 0.93338392 | F26: =VAR(E26:E28) -> 6.9709559e-05 | H26: 0.8 | I26: 1 | J26: =AVERAGE(J6:J8) -> 0.24170736 | K26: =K6*J26/J6 -> 0.95226966 | L26: =VAR(K26:K28) -> 0.0010237364
C27: 2 | D27: =D26 -> 0.24170736 | E27: =E7*D27/D7 -> 0.91727529 | I27: 2 | J27: =J26 -> 0.24170736 | K27: =K7*J27/J7 -> 1.0158855
C28: 3 | D28: =D27 -> 0.24170736 | E28: =E8*D28/D8 -> 0.92152006 | I28: 3 | J28: =J27 -> 0.24170736 | K28: =K8*J28/J8 -> 0.97807908
B29: 0.9 | C29: 1 | D29: =AVERAGE(D9:D11) -> 0.2701572 | E29: =E9*D29/D9 -> 1.0526674 | F29: =VAR(E29:E31) -> 0.00023188552 | H29: 0.9 | I29: 1 | J29: =AVERAGE(J9:J11) -> 0.2701572 | K29: =K9*J29/J9 -> 1.0626905 | L29: =VAR(K29:K31) -> 0.00014138895
C30: 2 | D30: =D29 -> 0.2701572 | E30: =E10*D30/D10 -> 1.0234661 | I30: 2 | J30: =J29 -> 0.2701572 | K30: =K10*J30/J10 -> 1.043893
C31: 3 | D31: =D30 -> 0.2701572 | E31: =E11*D31/D11 -> 1.0305753 | I31: 3 | J31: =J30 -> 0.2701572 | K31: =K11*J31/J11 -> 1.0659075 | M31: Y'-2 | N31: Y'-3 | O31: Y'-4 | P31: Y'-5 | Q31: Y'-6
B32: 1 | C32: 1 | D32: =AVERAGE(D12:D14) -> 0.30546756 | E32: =E12*D32/D12 -> 1.1880036 | F32: =VAR(E32:E34) -> 0.00011453523 | H32: 1 | I32: 1 | J32: =AVERAGE(J12:J14) -> 0.30546756 | K32: =K12*J32/J12 -> 1.2022408 | L32: =VAR(K32:K34) -> 4.6450753e-05 | M32: =L12*$J32/$J12 -> 1.1970534 | N32: =M12*$J32/$J12 -> 1.1997765 | O32: =N12*$J32/$J12 -> 1.199598 | P32: =O12*$J32/$J12 -> 1.1993694 | Q32: =P12*$J32/$J12 -> 1.1986334
C33: 2 | D33: =D32 -> 0.30546756 | E33: =E13*D33/D13 -> 1.1682165 | I33: 2 | J33: =J32 -> 0.30546756 | K33: =K13*J33/J13 -> 1.1886571 | M33: =L13*$J33/$J13 -> 1.1899265 | N33: =M13*$J33/$J13 -> 1.1876313 | O33: =N13*$J33/$J13 -> 1.1909557 | P33: =O13*$J33/$J13 -> 1.1871059 | Q33: =P13*$J33/$J13 -> 1.1892144
C34: 3 | D34: =D33 -> 0.30546756 | E34: =E14*D34/D14 -> 1.171042 | I34: 3 | J34: =J33 -> 0.30546756 | K34: =K14*J34/J14 -> 1.1964308 | M34: =L14*$J34/$J14 -> 1.1962934 | N34: =M14*$J34/$J14 -> 1.196967 | O34: =N14*$J34/$J14 -> 1.1960601 | P34: =O14*$J34/$J14 -> 1.1957973 | Q34: =P14*$J34/$J14 -> 1.1943493
B35: 1.1 | C35: 1 | D35: =AVERAGE(D15:D17) -> 0.33119451 | E35: =E15*D35/D15 -> 1.2909808 | F35: =VAR(E35:E37) -> 0.00023390668 | H35: 1.1 | I35: 1 | J35: =AVERAGE(J15:J17) -> 0.33119451 | K35: =K15*J35/J15 -> 1.3062505 | L35: =VAR(K35:K37) -> 8.7480676e-05
C36: 2 | D36: =D35 -> 0.33119451 | E36: =E16*D36/D16 -> 1.2623381 | I36: 2 | J36: =J35 -> 0.33119451 | K36: =K16*J36/J16 -> 1.2947846
C37: 3 | D37: =D36 -> 0.33119451 | E37: =E17*D37/D17 -> 1.2673633 | I37: 3 | J37: =J36 -> 0.33119451 | K37: =K17*J37/J17 -> 1.2877175
B38: 1.2 | C38: 1 | D38: =AVERAGE(D18:D20) -> 0.36177615 | E38: =E18*D38/D18 -> 1.3975496 | F38: =VAR(E38:E40) -> 9.1877241e-05 | H38: 1.2 | I38: 1 | J38: =AVERAGE(J18:J20) -> 0.36177615 | K38: =K18*J38/J18 -> 1.4303995 | L38: =VAR(K38:K40) -> 8.5995813e-05
C39: 2 | D39: =D38 -> 0.36177615 | E39: =E19*D39/D19 -> 1.3896501 | I39: 2 | J39: =J38 -> 0.36177615 | K39: =K19*J39/J19 -> 1.4121744
C40: 3 | D40: =D39 -> 0.36177615 | E40: =E20*D40/D20 -> 1.3784727 | I40: 3 | J40: =J39 -> 0.36177615 | K40: =K20*J40/J20 -> 1.4242656
B42: linest API | H42: linest API + matrix
B43: slope b1 | C43: {=LINEST(E26:E40,D26:D40,1,1)} -> 3.8760128 | D43: -0.01129028 | E43: intercept a1 | H43: slope b1 | I43: {=LINEST(K26:K40,J26:J40,1,1)} -> 3.7155444 | J43: 0.068457001 | K43: intercept a1
B44: SD b1 | C44: 0.065920147 | D44: 0.020109201 | E44: SD a1 | H44: SD b1 | I44: 0.11423124 | J44: 0.03484669 | K44: SD a1
B45: R² | C45: 0.9962539 | D45: 0.010883821 | E45: SD y/x | H45: R² | I45: 0.98786152 | J45: 0.018860279 | K45: SD y/x
...

Sheet justesse
B2: Accuracy study
B4: level | C4: serie | D4: X | E4: Y1 | F4: Z | G4: Rdt % | H4: Rdt% moyen | I4: S²
B5: 0.8 | C5: 1 | D5: =linéarité!J26 -> 0.24170736 | E5: =linéarité!K26 -> 0.95226966 | F5: =IF(linéarité!C$132="étalon 100%",E5/linéarité!G$131,(E5-linéarité!$J$132)/linéarité!$J$131) -> 0.24485404 | G5: =F5/D5 -> 1.0130186 | H5: =AVERAGE(G5:G7) -> 1.0558536 | I5: =VAR(G5:G7) -> 0.0018481582
C6: 2 | D6: =linéarité!J27 -> 0.24170736 | E6: =linéarité!K27 -> 1.0158855 | F6: =IF(linéarité!C$132="étalon 100%",E6/linéarité!G$132,(E6-linéarité!$J$132)/linéarité!$J$131) -> 0.26563574 | G6: =F6/D6 -> 1.0989973
C7: 3 | D7: =linéarité!J28 -> 0.24170736 | E7: =linéarité!K28 -> 0.97807908 | F7: =IF(linéarité!C$132="étalon 100%",E7/linéarité!G$133,(E7-linéarité!$J$132)/linéarité!$J$131) -> 0.25513297 | G7: =F7/D7 -> 1.0555449
B8: 0.9 | C8: 1 | D8: =linéarité!J29 -> 0.2701572 | E8: =linéarité!K29 -> 1.0626905 | F8: =IF(linéarité!C$132="étalon 100%",E8/linéarité!G$131,(E8-linéarité!$J$132)/linéarité!$J$131) -> 0.27324619 | G8: =F8/D8 -> 1.011434 | H8: =AVERAGE(G8:G10) -> 1.0169986 | I8: =VAR(G8:G10) -> 0.0001117559
C9: 2 | D9: =linéarité!J30 -> 0.2701572 | E9: =linéarité!K30 -> 1.043893 | F9: =IF(linéarité!C$132="étalon 100%",E9/linéarité!G$132,(E9-linéarité!$J$132)/linéarité!$J$131) -> 0.2729592 | G9: =F9/D9 -> 1.0103717
C10: 3 | D10: =linéarité!J31 -> 0.2701572 | E10: =linéarité!K31 -> 1.0659075 | F10: =IF(linéarité!C$132="étalon 100%",E10/linéarité!G$133,(E10-linéarité!$J$132)/linéarité!$J$131) -> 0.27804311 | G10: =F10/D10 -> 1.0291901
B11: 1 | C11: 1 | D11: =linéarité!J32 -> 0.30546756 | E11: =linéarité!K32 -> 1.2022408 | F11: =IF(linéarité!C$132="étalon 100%",E11/linéarité!G$131,(E11-linéarité!$J$132)/linéarité!$J$131) -> 0.30912832 | G11: =F11/D11 -> 1.0119841 | H11: =AVERAGE(G11:G13) -> 1.017054 | I11: =VAR(G11:G13) -> 2.3652566e-05
C12: 2 | D12: =linéarité!J33 -> 0.30546756 | E12: =linéarité!K33 -> 1.1886571 | F12: =IF(linéarité!C$132="étalon 100%",E12/linéarité!G$132,(E12-linéarité!$J$132)/linéarité!$J$131) -> 0.31081241 | G12: =F12/D12 -> 1.0174973
C13: 3 | D13: =linéarité!J34 -> 0.30546756 | E13: =linéarité!K34 -> 1.1964308 | F13: =IF(linéarité!C$132="étalon 100%",E13/linéarité!G$133,(E13-linéarité!$J$132)/linéarité!$J$131) -> 0.31209027 | G13: =F13/D13 -> 1.0216806
B14: 1.1 | C14: 1 | D14: =linéarité!J35 -> 0.33119451 | E14: =linéarité!K35 -> 1.3062505 | F14: =IF(linéarité!C$132="étalon 100%",E14/linéarité!G$131,(E14-linéarité!$J$132)/linéarité!$J$131) -> 0.33587201 | G14: =F14/D14 -> 1.0141231 | H14: =AVERAGE(G14:G16) -> 1.016862 | I14: =VAR(G14:G16) -> 2.1756767e-05
C15: 2 | D15: =linéarité!J36 -> 0.33119451 | E15: =linéarité!K36 -> 1.2947846 | F15: =IF(linéarité!C$132="étalon 100%",E15/linéarité!G$132,(E15-linéarité!$J$132)/linéarité!$J$131) -> 0.33856284 | G15: =F15/D15 -> 1.0222478
C16: 3 | D16: =linéarité!J37 -> 0.33119451 | E16: =linéarité!K37 -> 1.2877175 | F16: =IF(linéarité!C$132="étalon 100%",E16/linéarité!G$133,(E16-linéarité!$J$132)/linéarité!$J$131) -> 0.3359025 | G16: =F16/D16 -> 1.0142152
B17: 1.2 | C17: 1 | D17: =linéarité!J38 -> 0.36177615 | E17: =linéarité!K38 -> 1.4303995 | F17: =IF(linéarité!C$132="étalon 100%",E17/linéarité!G$131,(E17-linéarité!$J$132)/linéarité!$J$131) -> 0.36779402 | G17: =F17/D17 -> 1.0166342 | H17: =AVERAGE(G17:G19) -> 1.0214174 | I17: =VAR(G17:G19) -> 2.6941681e-05
C18: 2 | D18: =linéarité!J39 -> 0.36177615 | E18: =linéarité!K39 -> 1.4121744 | F18: =IF(linéarité!C$132="étalon 100%",E18/linéarité!G$132,(E18-linéarité!$J$132)/linéarité!$J$131) -> 0.36925816 | G18: =F18/D18 -> 1.0206813
C19: 3 | D19: =linéarité!J40 -> 0.36177615 | E19: =linéarité!K40 -> 1.4242656 | F19: =IF(linéarité!C$132="étalon 100%",E19/linéarité!G$133,(E19-linéarité!$J$132)/linéarité!$J$131) -> 0.37152122 | G19: =F19/D19 -> 1.0269367
B21: critical analisys of data
B22: Cochran Test
B23: Cobs | C23: =MAX(I5:I19)/SUM(I5:I19) -> 0.90940802
B24: C5% | C24: =linéarité!G70 -> 0.68377223
B25: C1% | C25: =linéarité!G71 -> 0.78852575
B27: Recouvrement Rdt%
B28: Rdt% moyen | C28: =AVERAGE(H5:H19) -> 1.0256371
B29: écart-type | C29: =STDEV(G5:G19) -> 0.023196279
B30: t (bilatéral,5%) | C30: =TINV(0.05,14) -> 2.1447867
B31: IC- (95%) | C31: =C28-C30*C29/SQRT(15) -> 1.0127915
B32: IC+ (95%) | C32: =C28+C30*C29/SQRT(15) -> 1.0384828 | D32: If 100% isn't witgin the intervall of confidente, a biais is detected
B34: End
B36: Identification | F36: ANOVA
B37: Origine | C37: niveau | D37: SS² | E37: CI | F37: SCE | G37: ddl | H37: CM | I37: Fobs | J37: F5% | K37: contribution%
B38: total | C38: =COUNT(G5:G19) -> 15 | D38: =SUM(G5:G19)^2 -> 236.68459 | E38: =D38/C38 -> 15.778973 | F38: =DEVSQ(G5:G19) -> 0.0075329429 | G38: =C38-1 -> 14 | H38: =F38/G38 -> 0.00053806735 | I38: x | J38: x | K38: =SUM(K39:K40) -> 1
B39: niveau | C39: 5 | D39: =SUM(G5:G7)^2+SUM(G8:G10)^2+SUM(G11:G13)^2+SUM(G14:G16)^2+SUM(G17:G19)^2 -> 47.347324 | E39: =D39*C39/C38 -> 15.782441 | F39: =E39-E38 -> 0.0034684126 | G39: 4 | H39: =F39/G39 -> 0.00086710315 | I39: =H39/H40 -> 2.1333416 | J39: =FINV(0.05,G39,G40) -> 3.4780497 | K39: =F39/F38 -> 0.46043262 | L39: =IF(ABS(I39)<J39,"pas d'effet niveau","effet de niveau") -> pas d'effet niveau
B40: résiduel | C40: x | D40: x | E40: x | F40: =F38-F39 -> 0.0040645303 | G40: =G38-G39 -> 10 | H40: =F40/G40 -> 0.00040645303 | I40: x | J40: x | K40: =F40/F38 -> 0.53956738
B41: Si F concentration < F5%, l'homogénéité des recouvrements est observée

Sheet fidélité
B2: Precision study
B4: serie | C4: X | D4: Y | E4: S² | F4: moyenne
B5: 1 | C5: =linéarité!J32 -> 0.30546756 | D5: =linéarité!K32 -> 1.2022408 | E5: =VAR(D5:D10) -> 2.8668135e-06 | F5: =AVERAGE(D5:D10) -> 1.1994453
C6: =C5 -> 0.30546756 | D6: =linéarité!M32 -> 1.1970534
C7: =C6 -> 0.30546756 | D7: =linéarité!N32 -> 1.1997765
C8: =C7 -> 0.30546756 | D8: =linéarité!O32 -> 1.199598
C9: =C8 -> 0.30546756 | D9: =linéarité!P32 -> 1.1993694
C10: =C9 -> 0.30546756 | D10: =linéarité!Q32 -> 1.1986334
B11: 2 | C11: =C10 -> 0.30546756 | D11: =linéarité!K33 -> 1.1886571 | E11: =VAR(D11:D16) -> 2.0528438e-06 | F11: =AVERAGE(D11:D16) -> 1.1889151
C12: =C11 -> 0.30546756 | D12: =linéarité!M33 -> 1.1899265
C13: =C12 -> 0.30546756 | D13: =linéarité!N33 -> 1.1876313
C14: =C13 -> 0.30546756 | D14: =linéarité!O33 -> 1.1909557
C15: =C14 -> 0.30546756 | D15: =linéarité!P33 -> 1.1871059
C16: =C15 -> 0.30546756 | D16: =linéarité!Q33 -> 1.1892144
B17: 3 | C17: =C16 -> 0.30546756 | D17: =linéarité!K34 -> 1.1964308 | E17: =VAR(D17:D22) -> 7.9494835e-07 | F17: =AVERAGE(D17:D22) -> 1.195983
C18: =C17 -> 0.30546756 | D18: =linéarité!M34 -> 1.1962934
C19: =C18 -> 0.30546756 | D19: =linéarité!N34 -> 1.196967
C20: =C19 -> 0.30546756 | D20: =linéarité!O34 -> 1.1960601
C21: =C20 -> 0.30546756 | D21: =linéarité!P34 -> 1.1957973
C22: =C21 -> 0.30546756 | D22: =linéarité!Q34 -> 1.1943493
B24: Critical analisys of data
B26: Cochran Test
B27: Cobs | C27: =MAX(E5:E22)/SUM(E5:E22) -> 0.50166427
B28: C5% | C28: =1/((1+(COUNT(B5:B22)-1)/FINV(0.05/COUNT(B5:B22),COUNT(C5:C10)-1,(COUNT(B5:B22)-1)*(COUNT(C5:C10)-1)))) -> 0.70698869
B29: C1% | C29: =1/((1+(COUNT(B5:B22)-1)/FINV(0.01/COUNT(B5:B22),COUNT(C5:C10)-1,(COUNT(B5:B22)-1)*(COUNT(C5:C10)-1)))) -> 0.79331907
B30: If Cobs > C5%, Identify the widest variance and the presence of outlier within (Dixon Test)
B32: Presicion
C34: S² | D34: CV%
B35: intra-série | C35: =AVERAGE(E5:E22) -> 1.9048685e-06 | D35: =SQRT(C35)/AVERAGE(F5:F22) -> 0.0011551653
B36: inter serie | C36: =IF(VAR(F5:F22)-C35/6<0,0,VAR(F5:F22)-C35/6) -> 2.8486742e-05 | D36: NA
B37: fidélité intermédiaire | C37: =C36+C35 -> 3.039161e-05 | D37: =SQRT(C37)/AVERAGE(F5:F22) -> 0.0046141159
B39: End
D41: Ecart acceptable entre 2 mesures
B42: CV+ | E42: 0.95 | F42: 0.99
B43: =D35*SQRT(CHIINV(0.05,17)/17) -> 0.0014715425 | D43: limite r | E43: =2.8*SQRT(C35) -> 0.0038644753 | F43: =4.2*SQRT(C35) -> 0.0057967129
B44: =D37*SQRT(CHIINV(0.05,17)/17) -> 0.0058778318 | D44: limite Fi | E44: =2.8*SQRT(C37) -> 0.015436004 | F44: =4.2*SQRT(C37) -> 0.023154006
B45: CV+ est l'incertitude élargie à 95% du CV calculé

Sheet robustesse
B2: Introduction
B3: Plackett-Burman designs is used for screening experiments because is very useful for detecting large main effects, assuming all interactions are negligible when compared with the few important main effects.
B4: The Plackett Burman design in 8 runs may be used for an experiment containing up to 7 factors.
B6: Parameters (from 4 to 7)
B8: Parameter
C9: parameter studied | G9: optional parameter
B10: parameter | C10: débit | D10: pH | E10: volume | F10: T°C | G10: colonne | H10: gaz | I10: éthanol
B11: level 0 | C11: 1 | D11: 7 | E11: 10 | F11: 30 | G11: 1 | H11: 20 | I11: oui
B12: level -1 | C12: 0.9 | D12: 6 | E12: 9 | F12: 29 | G12: 1 | H12: 16 | I12: non
B13: level +1 | C13: 1.1 | D13: 8 | E13: 11 | F13: 31 | G13: 2 | H13: 24 | I13: oui
B15: Experimental design
B16: The design study until 7 parameters at 2 levels
B17: 3 more essay at standard level (level 0) are performed at the beginning, the middle and at the end in order to calculate the drift of experiment
C20: Parameters | J20: Responses
B21: essay | C21: =C10 -> débit | D21: =D10 -> pH | E21: =E10 -> volume | F21: =F10 -> T°C | G21: =IF(G10="","NA",G10) -> colonne | H21: =IF(H10="","NA",H10) -> gaz | I21: =IF(I10="","NA",I10) -> éthanol | J21: Aire
B22: essai 0-1 | C22: =C11 -> 1 | D22: =D11 -> 7 | E22: =E11 -> 10 | F22: =F11 -> 30 | G22: =G11 -> 1 | H22: =H11 -> 20 | I22: =I11 -> oui | K22: 469 | U22: =C10 -> débit | V22: =D10 -> pH | W22: =E10 -> volume | X22: =F10 -> T°C | Y22: =G10 -> colonne | Z22: =H10 -> gaz | AA22: =I10 -> éthanol
B23: 1 | C23: =C13 -> 1.1 | D23: =D13 -> 8 | E23: =E13 -> 11 | F23: =F12 -> 29 | G23: =G13 -> 2 | H23: =H12 -> 16 | I23: =I12 -> non | J23: 479 | T23: 1 | U23: 1 | V23: 1 | W23: 1 | X23: -1 | Y23: 1 | Z23: -1 | AA23: -1
B24: 2 | C24: =C12 -> 0.9 | D24: =D13 -> 8 | E24: =E13 -> 11 | F24: =F13 -> 31 | G24: =G12 -> 1 | H24: =H13 -> 24 | I24: =I12 -> non | J24: 484.5 | T24: 1 | U24: -1 | V24: 1 | W24: 1 | X24: 1 | Y24: -1 | Z24: 1 | AA24: -1
B25: 3 | C25: =C12 -> 0.9 | D25: =D12 -> 6 | E25: =E13 -> 11 | F25: =F13 -> 31 | G25: =G13 -> 2 | H25: =H12 -> 16 | I25: =I13 -> oui | J25: 498.4 | T25: 1 | U25: -1 | V25: -1 | W25: 1 | X25: 1 | Y25: 1 | Z25: -1 | AA25: 1
B26: 4 | C26: =C13 -> 1.1 | D26: =D12 -> 6 | E26: =E12 -> 9 | F26: =F13 -> 31 | G26: =G13 -> 2 | H26: =H13 -> 24 | I26: =I12 -> non | J26: 465.2 | T26: 1 | U26: 1 | V26: -1 | W26: -1 | X26: 1 | Y26: 1 | Z26: 1 | AA26: -1
B27: essai 0-2 | C27: =C22 -> 1 | D27: =D22 -> 7 | E27: =E22 -> 10 | F27: =F22 -> 30 | G27: =G22 -> 1 | H27: =H22 -> 20 | I27: =I22 -> oui | K27: 469
B28: 5 | C28: =C12 -> 0.9 | D28: =D13 -> 8 | E28: =E12 -> 9 | F28: =F12 -> 29 | G28: =G13 -> 2 | H28: =H13 -> 24 | I28: =I13 -> oui | J28: 461.7 | T28: 1 | U28: -1 | V28: 1 | W28: -1 | X28: -1 | Y28: 1 | Z28: 1 | AA28: 1
B29: 6 | C29: =C13 -> 1.1 | D29: =D12 -> 6 | E29: =E13 -> 11 | F29: =F12 -> 29 | G29: =G12 -> 1 | H29: =H13 -> 24 | I29: =I13 -> oui | J29: 482.7 | T29: 1 | U29: 1 | V29: -1 | W29: 1 | X29: -1 | Y29: -1 | Z29: 1 | AA29: 1
B30: 7 | C30: =C13 -> 1.1 | D30: =D13 -> 8 | E30: =E12 -> 9 | F30: =F13 -> 31 | G30: =G12 -> 1 | H30: =H12 -> 16 | I30: =I13 -> oui | J30: 456.8 | T30: 1 | U30: 1 | V30: 1 | W30: -1 | X30: 1 | Y30: -1 | Z30: -1 | AA30: 1
B31: 8 | C31: =C12 -> 0.9 | D31: =D12 -> 6 | E31: =E12 -> 9 | F31: =F12 -> 29 | G31: =G12 -> 1 | H31: =H12 -> 16 | I31: =I12 -> non | J31: 477.6 | T31: 1 | U31: -1 | V31: -1 | W31: -1 | X31: -1 | Y31: -1 | Z31: -1 | AA31: -1
B32: essai 0-3 | C32: =C27 -> 1 | D32: =D27 -> 7 | E32: =E27 -> 10 | F32: =F27 -> 30 | G32: =G27 -> 1 | H32: =H27 -> 20 | I32: =I27 -> oui | K32: 471
B34: Critical analysis of data
B37: Contraste | C37: moyenne | D37: =C21 -> débit | E37: =D21 -> pH | F37: =E21 -> volume | G37: =F21 -> T°C | H37: =G21 -> colonne | I37: =H21 -> gaz | J37: =I21 -> éthanol | K37: dérive%
B38: =J21 -> Aire | C38: =SUMPRODUCT(T23:T31,$J$23:$J$31)/8 -> 475.7375 | D38: =SUMPRODUCT(U23:U31,$J$23:$J$31)/8 -> -4.8125 | E38: =SUMPRODUCT(V23:V31,$J$23:$J$31)/8 -> -5.2375 | F38: =SUMPRODUCT(W23:W31,$J$23:$J$31)/8 -> 10.4125 | G38: =SUMPRODUCT(X23:X31,$J$23:$J$31)/8 -> 0.4875 | H38: =SUMPRODUCT(Y23:Y31,$J$23:$J$31)/8 -> 0.3375 | I38: =SUMPRODUCT(Z23:Z31,$J$23:$J$31)/8 -> -2.2125 | J38: =IF(I10="","",SUMPRODUCT(AA23:AA31,$J$23:$J$31)/8) -> -0.8375 | K38: =(K22-K32)/K32 -> -0.0042462845
B39: Résol. Ap | C39: =SUMPRODUCT(T23:T31,$L$23:$L$31)/8 -> 0 | D39: =SUMPRODUCT(U23:U31,$L$23:$L$31)/8 -> 0 | E39: =SUMPRODUCT(V23:V31,$L$23:$L$31)/8 -> 0 | F39: =SUMPRODUCT(W23:W31,$L$23:$L$31)/8 -> 0 | G39: =SUMPRODUCT(X23:X31,$L$23:$L$31)/8 -> 0 | H39: =IF(G10="","",SUMPRODUCT(Y23:Y31,$L$23:$L$31)/8) -> 0 | I39: =IF(H10="","",SUMPRODUCT(Z23:Z31,$L$23:$L$31)/8) -> 0 | J39: =IF(I10="","",SUMPRODUCT(AA23:AA31,$L$23:$L$31)/8) -> 0 | K39: =(M22-M32)/M32 -> #DIV/0!
B40: Tr BDDE | C40: =SUMPRODUCT(T23:T31,$N$23:$N$31)/8 -> 0 | D40: =SUMPRODUCT(U23:U31,$N$23:$N$31)/8 -> 0 | E40: =SUMPRODUCT(V23:V31,$N$23:$N$31)/8 -> 0 | F40: =SUMPRODUCT(W23:W31,$N$23:$N$31)/8 -> 0 | G40: =SUMPRODUCT(X23:X31,$N$23:$N$31)/8 -> 0 | H40: =IF(G10="","",SUMPRODUCT(Y23:Y31,$N$23:$N$31)/8) -> 0 | I40: =IF(H10="","",SUMPRODUCT(Z23:Z31,$N$23:$N$31)/8) -> 0 | J40: =IF(I10="","",SUMPRODUCT(AA23:AA31,$N$23:$N$31)/8) -> 0 | K40: =(O22-O32)/O32 -> #DIV/0!
B41: Tr EI | D41: =SUMPRODUCT(U23:U31,$P$23:$P$31)/8 -> 0 | E41: =SUMPRODUCT(V23:V31,$P$23:$P$31)/8 -> 0 | F41: =SUMPRODUCT(W23:W31,$P$23:$P$31)/8 -> 0 | G41: =SUMPRODUCT(X23:X31,$P$23:$P$31)/8 -> 0 | H41: =IF(G10="","",SUMPRODUCT(Y23:Y31,$P$23:$P$31)/8) -> 0 | I41: =IF(H10="","",SUMPRODUCT(Z23:Z31,$P$23:$P$31)/8) -> 0 | J41: =IF(I10="","",SUMPRODUCT(AA23:AA31,$P$23:$P$31)/8) -> 0 | K41: =(Q22-Q32)/Q32 -> #DIV/0!
B42: Aire | C42: =SUMPRODUCT(T23:T31,$R$23:$R$31)/8 -> 0 | D42: =SUMPRODUCT(U23:U31,$R$23:$R$31)/8 -> 0 | E42: =SUMPRODUCT(V23:V31,$R$23:$R$31)/8 -> 0 | F42: =SUMPRODUCT(W23:W31,$R$23:$R$31)/8 -> 0 | G42: =SUMPRODUCT(X23:X31,$R$23:$R$31)/8 -> 0 | H42: =IF(G11="","",SUMPRODUCT(Y23:Y31,$R$23:$R$31)/8) -> 0 | I42: =IF(H11="","",SUMPRODUCT(Z23:Z31,$R$23:$R$31)/8) -> 0 | J42: =IF(I11="","",SUMPRODUCT(AA23:AA31,$R$23:$R$31)/8) -> 0 | K42: =(S22-S32)/S32 -> #DIV/0!
B44: Contrast : du niveau 0 à +1 l'impact est de :
B60: End
B62: Graphiques des contributions
C76: R² | D76: =J85 -> 0.94077545 | F76: R² | G76: =S85 -> #NUM! | J76: R² | K76: =J101 -> #NUM! | N76: R² | O76: =S101 -> #NUM! | R76: R² | S76: =J117 -> #NUM!
B77: R² > 90 is considered as a good model
B81: Résolution avant | K81: Résolution après
B82: Identification | E82: ANOVA | K82: Identification | N82: ANOVA
...

Sheet LOQLOD
B2: Limit of detection
B3: perform 6 indenpdants samples
C5: blank | E5: unité de la réponse | G5: mg/L
B6: série 1
B7: série 2 | E7: Sb | F7: LOD
B8: série 3 | E8: =STDEV(C6:C11) -> #DIV/0! | F8: =3.3*E8 -> #DIV/0!
B9: série 4
B10: série 5 | E10: LOD is estimate at k = 3,3 blank standard deviation devide by slope calibration
B11: série 6 | E11: Blank is the matrix without API
B13: Limit of quantification
B15: LOD est estimated at k = 10 blank standard deviation | I15: LOQ
B16: its accuracy and precision are verified | I16: =10*E8 -> #DIV/0!
B18: Accuracy of the LOQ
B19: 6 independants samples preparation at "LOQ concentration" are analysed in repetability condition
C21: Y | D21: LOQ | E21: Rdt % | F21: mean Rdt% | G21: RSD
B22: série 1 | D22: =I16 -> #DIV/0! | E22: =C22/D22 -> #DIV/0! | F22: =AVERAGE(E22:E27) -> #DIV/0! | G22: =STDEV(C22:C27)/AVERAGE(C22:C27) -> #DIV/0!
B23: série 2 | D23: =D22 -> #DIV/0! | E23: =C23/D23 -> #DIV/0!
B24: série 3 | D24: =D23 -> #DIV/0! | E24: =C24/D24 -> #DIV/0!
B25: série 4 | D25: =D24 -> #DIV/0! | E25: =C25/D25 -> #DIV/0!
B26: série 5 | D26: =D25 -> #DIV/0! | E26: =C26/D26 -> #DIV/0!
B27: série 6 | D27: =D26 -> #DIV/0! | E27: =C27/D27 -> #DIV/0!
F28: "+ ou - 10%" | G28: <10%
B31: End

Sheet inter-operators
A2: inter operator effect
C4: Operator | H4: Cochran
B5: sample | C5: 1 | D5: 2 | E5: 3 | H5: Cobs | I5: =MAX(C13:E13)/AVERAGE(C12:E12) -> #DIV/0!
B6: 1 | H6: C5% | I6: 0.707
B7: 2
B8: 3 | H8: S²r | I8: =AVERAGE(C13:E13) -> #DIV/0!
B9: 4 | H9: S²R | I9: =IF(VAR(C12:E12)-I8/6<0,0+I8,VAR(C12:E12)-I8/6+I8) -> #DIV/0!
B10: 5
B11: 6 | H11: SDR%r | I11: =I8/AVERAGE(C12:E12) -> #DIV/0! | J11: < 2,0%
B12: Mean | C12: =AVERAGE(C6:C11) -> #DIV/0! | D12: =AVERAGE(D6:D11) -> #DIV/0! | E12: =AVERAGE(E6:E11) -> #DIV/0! | H12: SDR%R | I12: =I9/AVERAGE(C12:E12) -> #DIV/0! | J12: < 3,0%
B13: S²r | C13: =VAR(C6:C11) -> #DIV/0! | D13: =VAR(D6:D11) -> #DIV/0! | E13: =VAR(E6:E11) -> #DIV/0!
A15: End

Sheet system suitability
B1: SYSTEM SUITABILITY
B2: Référence de la série analytique :
B4: Calibration - Standards
B6: Standard | C6: Ratio Aire BDDE/ Aire EI | D6: Moyenne | E6: % RSD | F6: Critère d'acceptation | G6: Conformité
B7: WS-1 | C7: =#REF! -> #REF! | D7: =AVERAGE(C7:C12) -> #REF! | E7: =STDEV(C7:C12)/D7 -> #REF! | F7: % RSD ≤ 2% | G7: =IF(E7<=2%,"CONFORME","NON CONFORME") -> #REF!
C8: =#REF! -> #REF!
C9: =#REF! -> #REF!
C10: =#REF! -> #REF!
C11: =#REF! -> #REF!
C12: =#REF! -> #REF!
B13: WS-2 | C13: =#REF! -> #REF! | D13: =AVERAGE(C13:C18) -> #REF! | E13: =STDEV(C13:C18)/D13 -> #REF! | G13: =IF(E13<=2%,"CONFORME","NON CONFORME") -> #REF!
C14: =#REF! -> #REF!
C15: =#REF! -> #REF!
C16: =#REF! -> #REF!
C17: =#REF! -> #REF!
C18: =#REF! -> #REF!
B20: Tailing Factor (USP Tailing) : Critère d'acceptation : 0.8 ≤ TF ≤ 1.5
C22: TF BDDE | D22: Conformité | E22: TF EI | F22: Conformité
B23: WS-1 1 | C23: / | D23: N/A | E23: / | F23: N/A
B24: WS-2 1 | C24: / | D24: N/A | E24: / | F24: N/A
B25: WS-2 dérive 1 | C25: / | D25: N/A | E25: / | F25: N/A
B26: WS-2 dérive 2 | C26: / | D26: N/A | E26: / | F26: N/A
B27: WS-2 dérive 3 | C27: / | D27: N/A | E27: / | F27: N/A
B28: WS-2 dérive 4 | C28: / | D28: N/A | E28: / | F28: N/A
B30: Résolution : Critère d'acceptation : R1 et R2 ≥ 1.5
C31: R1 | D31: Conformité | E31: R2 | F31: Conformité
B32: WS-1 1 | C32: / | D32: N/A | E32: / | F32: N/A
B33: WS-2 1 | C33: / | D33: N/A | E33: / | F33: N/A
B34: WS-2 dérive 1 | C34: / | D34: N/A | E34: / | F34: N/A
B35: WS-2 dérive 2 | C35: / | D35: N/A | E35: / | F35: N/A
B36: WS-2 dérive 3 | C36: / | D36: N/A | E36: / | F36: N/A
B37: WS-2 dérive 4 | C37: / | D37: N/A | E37: / | F37: N/A
B39: Contrôle de pesée
C40: m (mg) | D40: Ratio WS moyen | E40: Contrôle de pesée | F40: Critère d'acceptation | G40: Conformité
B41: BDDE SS1 | C41: =#REF! -> #REF! | D41: =D7 -> #REF! | E41: =(C41*D42)/(C42*D41) -> #REF! | F41: 98.0% - 102.0% | G41: =IF(AND(E41>=98%,E41<=102%),"CONFORME","NON CONFORME") -> #REF!
B42: BDDE SS2 | C42: =#REF! -> #REF! | D42: =D13 -> #REF!
B44: Recouvrements - Dérives
C45: [BDDE]théo | D45: Ratio | E45: Recouvrement | F45: Moyenne | G45: Critère d'acceptation | H45: Conformité
B46: WS3-2 | C46: =#REF! -> #REF! | D46: / | E46: =IF(D46="/","/",(D46*#REF!/AVERAGE($C$7:$C$12))/$C$46) -> / | F46: =AVERAGE(E46:E51) -> #DIV/0! | G46: 98.0% - 102.0% | H46: =IF(AND(F46<=102%,F46>=98%),"CONFORME","NON CONFORME") -> #DIV/0!
D47: / | E47: =IF(D47="/","/",(D47*#REF!/AVERAGE($C$7:$C$12))/$C$46) -> /
...

Sheet stabilité
B2: Introduction
B3: standard
B4: dérivatisation | C4: conservation | D4: réplique | E4: échant 1 | F4: échant 2 | G4: moyenne
B5: j=0 | C5: j=0 | D5: r1 | E5: 1.1825568 | F5: 1.1820513 | G5: =AVERAGE(E5:G6) -> 1.1818711
D6: r2 | E6: 1.1811854 | F6: 1.1824702
C7: j=7 | E7: 1.173 | F7: 1.171 | G7: =AVERAGE(E7:F7) -> 1.172
B8: j=7 | E8: 1.184 | F8: 1.181 | G8: =AVERAGE(E8:F8) -> 1.1825
D9: moyenne | E9: =AVERAGE(E5:E8) -> 1.1801855 | F9: =AVERAGE(F5:F8) -> 1.1791304
B11: Identification | F11: ANOVA irrégulièrement emboité
B12: origine | C12: moyenne | D12: écart | E12: coefficient C | F12: SCE | G12: ddl | H12: CM | I12: F% | J12: F%5 | K12: contribution
B13: total | C13: x | D13: x | E13: x | F13: =DEVSQ(E5:F8) -> 0.00016431597 | G13: =COUNT(E5:F8)-1 -> 7 | H13: =F13/G13 -> 2.3473709e-05 | I13: x | J13: x | K13: =SUM(K15:K19) -> 1
B14: modèle | C14: x | D14: x | E14: x | F14: =SUM(F16:F19) -> 0.00015908942 | G14: =SUM(G16:G19) -> 7 | H14: =F14/G14 -> 2.272706e-05 | I14: =H14/H16 -> 200.43403 | J14: =FINV(0.05,G14,G16) -> 19.353218 | K14: =F14/F13 -> 0.96819211
B15: résiduel | C15: x | D15: x | E15: x | F15: =F13-F14 -> 5.2265441e-06 | G15: =G13-G14 -> 0 | H15: x | I15: x | J15: x | K15: =F15/$F$13 -> 0.03180789
B16: réplique | C16: =AVERAGE(E5:F6) -> 1.1820659 | D16: =ABS(AVERAGE(E5:F5)-AVERAGE(E6:F6)) -> 0.00047621262 | E16: =0.5*2 -> 1 | F16: =D16^2*E16 -> 2.2677846e-07 | G16: =(COUNT(E5:E6)-1)*COUNT(E5:F5) -> 2 | H16: =F16/G16 -> 1.1338923e-07 | I16: x | J16: x | K16: =F16/$F$13 -> 0.0013801365
B17: conservation | C17: =AVERAGE(E5:F7) -> 1.1787106 | D17: =ABS(C16-AVERAGE(E7:F7)) -> 0.01006591 | E17: =0.666666666666667*2 -> 1.3333333 | F17: =D17^2*E17 -> 0.00013509672 | G17: =G16 -> 2 | H17: =F17/G17 -> 6.7548361e-05 | I17: =H17/H16 -> 595.72113 | J17: =FINV(0.05,G17,G$16) -> 19 | K17: =F17/$F$13 -> 0.82217648
B18: dérivatisation | C18: =AVERAGE(E5:F8) -> 1.179658 | D18: =ABS(C17-AVERAGE(E8:F8)) -> 0.0037893934 | E18: =0.75*2 -> 1.5 | F18: =D18^2*E18 -> 2.1539254e-05 | G18: =G17 -> 2 | H18: =F18/G18 -> 1.0769627e-05 | I18: =H18/H16 -> 94.979275 | J18: =FINV(0.05,G18,G$16) -> 19 | K18: =F18/$F$13 -> 0.13108436
B19: échantillon | C19: x | D19: x | E19: x | F19: =(SUM(E5:E8)^2+SUM(F5:F8)^2)*2/COUNT(E5:F8)-SUM(E5:F8)^2/COUNT(E5:F8) -> 2.2266673e-06 | G19: =COUNT(E5:F5)-1 -> 1 | H19: =F19/G19 -> 2.2266673e-06 | I19: =H19/H16 -> 19.637379 | J19: =FINV(0.05,G19,G$16) -> 18.512821 | K19: =F19/$F$13 -> 0.013551132
B21: Fin

Sheet sensibilité
B2: Sensitivity
B3: plus petite différence détectable
C5: erreur expérimentale Sy/x | E5: =linéarité!D45 -> 0.010883821
C6: fractile t(alpha = 5%) | E6: =TINV(0.05,linéarité!G86) -> 2.2281389
C7: factile t(beta = 5%) | E7: =TINV(0.1,linéarité!G86) -> 1.8124611
C8: pente b1 | E8: =linéarité!C43 -> 3.8760128
C9: Ecart minimal en x | E9: =((E6+E7)*E5*SQRT(2))/E8 -> 0.01604564 | F9: <= Sensibilité
B14: Fin

Sheet Risque
C2: N° | D2: Pré-analytique | E2: Défailances possibles (si quantitatif : trop,pas assez, pas du tout / si qualitatif : bon ou mauvais) | F2: Effets de la défaillances | G2: Causes de la défaillances | H2: Actions de préventiopn mise en place
B3: Pré-analytique | C3: 1 | D3: ex : prélèvement, transport
C4: 2 | D4: ex : préparation de l'échantillon
C5: 3
C6: 4
C7: 5
C8: 6
C9: 7
C10: 8
C11: 9
C12: 10
C15: N° | D15: Post-analytique | E15: Défailances possibles (si quantitatif : trop,pas assez, pas du tout / si qualitatif : bon ou mauvais) | F15: Effets de la défaillances | G15: Causes de la défaillances | H15: Actions de préventiopn mise en place
B16: Post-analytique | C16: 1 | D16: ex : stockage de l'échantillon
C17: 2 | D17: ex ; envoie des résultats
C18: 3
C19: 4
C20: 5
C21: 6
C22: 7
C23: 8
C24: 9
C25: 10

Sheet Sheet1
